Workbook

Sheet Characterization
A1: LoadID | B1: Pc | C1: Qc | D1: FL Ratio
A2: 1 | B2: {=MAX(ABS('Pc, Original'!$D2:$AA2))} -> 4.9725394 | C2: {=MAX(ABS('Qc, Original'!$D2:$AA2))} -> 0.70631105 | D2: =B2/SUM($B$2:$B$15) -> 0.077823812
A3: 2 | B3: {=MAX(ABS('Pc, Original'!$D3:$AA3))} -> 2.4083493 | C3: {=MAX(ABS('Qc, Original'!$D3:$AA3))} -> 0.27046915 | D3: =B3/SUM($B$2:$B$15) -> 0.037692396
A4: 3 | B4: {=MAX(ABS('Pc, Original'!$D4:$AA4))} -> 6.8515722 | C4: {=MAX(ABS('Qc, Original'!$D4:$AA4))} -> 0.74228888 | D4: =B4/SUM($B$2:$B$15) -> 0.10723202
A5: 4 | B5: {=MAX(ABS('Pc, Original'!$D5:$AA5))} -> 1.5967813 | C5: {=MAX(ABS('Qc, Original'!$D5:$AA5))} -> 0.74264352 | D5: =B5/SUM($B$2:$B$15) -> 0.024990774
A6: 5 | B6: {=MAX(ABS('Pc, Original'!$D6:$AA6))} -> 5.5241481 | C6: {=MAX(ABS('Qc, Original'!$D6:$AA6))} -> 0.79455308 | D6: =B6/SUM($B$2:$B$15) -> 0.086456884
A7: 6 | B7: {=MAX(ABS('Pc, Original'!$D7:$AA7))} -> 8.2055502 | C7: {=MAX(ABS('Qc, Original'!$D7:$AA7))} -> 1.3087633 | D7: =B7/SUM($B$2:$B$15) -> 0.12842275
A8: 7 | B8: {=MAX(ABS('Pc, Original'!$D8:$AA8))} -> 4.8921795 | C8: {=MAX(ABS('Qc, Original'!$D8:$AA8))} -> 0.545137 | D8: =B8/SUM($B$2:$B$15) -> 0.076566122
A9: 8 | B9: {=MAX(ABS('Pc, Original'!$D9:$AA9))} -> 4.3726958 | C9: {=MAX(ABS('Qc, Original'!$D9:$AA9))} -> 1.6808471 | D9: =B9/SUM($B$2:$B$15) -> 0.068435829
A10: 9 | B10: {=MAX(ABS('Pc, Original'!$D10:$AA10))} -> 1.8897161 | C10: {=MAX(ABS('Qc, Original'!$D10:$AA10))} -> 0.0553131 | D10: =B10/SUM($B$2:$B$15) -> 0.029575414
A11: 10 | B11: {=MAX(ABS('Pc, Original'!$D11:$AA11))} -> 3.8577528 | C11: {=MAX(ABS('Qc, Original'!$D11:$AA11))} -> 0.67294557 | D11: =B11/SUM($B$2:$B$15) -> 0.060376601
A12: 11 | B12: {=MAX(ABS('Pc, Original'!$D12:$AA12))} -> 1.6013075 | C12: {=MAX(ABS('Qc, Original'!$D12:$AA12))} -> 0.49011867 | D12: =B12/SUM($B$2:$B$15) -> 0.025061612
A13: 12 | B13: {=MAX(ABS('Pc, Original'!$D13:$AA13))} -> 5.0122006 | C13: {=MAX(ABS('Qc, Original'!$D13:$AA13))} -> 0.95377995 | D13: =B13/SUM($B$2:$B$15) -> 0.078444538
... A15: 14 | B15: {=MAX(ABS('Pc, Original'!$D15:$AA15))} -> 0.5221471 | C15: {=MAX(ABS('Qc, Original'!$D15:$AA15))} -> 0.20917235 | D15: =B15/SUM($B$2:$B$15) -> 0.008171977

Sheet Growth Factors
A1: Growth Factor | B1: Value, [%]
A2: Load | B2: 0.0125
A3: Flexible Load | B3: 0.03

Sheet Pc, Original
A1: LoadID | B1: Season | C1: Scenario | D1: 0 | E1: 1 | F1: 2 | G1: 3 | H1: 4 | I1: 5 | J1: 6 | K1: 7 | L1: 8 | M1: 9 | N1: 10 | O1: 11 | P1: 12 | Q1: 13 | R1: 14 | S1: 15 | T1: 16 | U1: 17 | V1: 18 | W1: 19 | X1: 20 | Y1: 21 | Z1: 22 | AA1: 23
A2: 1 | B2: Winter | C2: 1 | D2: 3.9664378 | E2: 3.8182077 | F2: 3.6822064 | G2: 3.7933432 | H2: 3.6863035 | I2: 3.6912132 | J2: 3.7252831 | K2: 4.8354045 | L2: 4.9320779 | M2: 4.8850233 | N2: 4.8701922 | O2: 4.9725394 | P2: 4.9190118 | Q2: 4.8319353 | R2: 4.203334 | S2: 4.5221286 | T2: 4.9164572 | U2: 4.8415698 | V2: 4.592091 | W2: 4.3791631 | X2: 4.3482258 | Y2: 4.154981 | Z2: 3.7525698 | AA2: 3.6712699
A3: 2 | B3: Winter | C3: 1 | D3: 1.3469303 | E3: 1.3085964 | F3: 1.2530124 | G3: 1.2426371 | H3: 1.2551234 | I3: 1.3401108 | J3: 1.6155734 | K3: 1.8861192 | L3: 2.050469 | M3: 2.1124004 | N3: 2.107831 | O3: 2.0576357 | P3: 1.9829956 | Q3: 1.8858414 | R3: 1.7563949 | S3: 1.8109097 | T3: 2.0143573 | U3: 2.4083493 | V3: 2.2938198 | W3: 2.1188171 | X3: 2.0540523 | Y3: 1.9156891 | Z3: 1.7532421 | AA3: 1.5508224
A4: 3 | B4: Winter | C4: 1 | D4: 3.2306823 | E4: 3.0376044 | F4: 2.9394167 | G4: 3.0009034 | H4: 3.0291338 | I4: 3.4633889 | J4: 5.5933806 | K4: 6.5579916 | L4: 6.8515722 | M4: 6.6350334 | N4: 6.3911639 | O4: 6.7988722 | P4: 6.3028887 | Q4: 6.0014417 | R4: 5.1905722 | S4: 5.1691334 | T4: 5.3862417 | U4: 5.8172584 | V4: 5.3159667 | W4: 5.5242391 | X4: 5.3637333 | Y4: 5.044125 | Z4: 4.1902861 | AA4: 3.6957973
A5: 4 | B5: Winter | C5: 1 | D5: 0.31695602 | E5: 0.20592678 | F5: 0.20602405 | G5: 0.18353757 | H5: 0.19330165 | I5: 0.39442965 | J5: 0.79092173 | K5: 0.98453572 | L5: 1.0852596 | M5: 1.0163278 | N5: 1.00755 | O5: 0.93645155 | P5: 0.91225685 | Q5: 0.85918667 | R5: 0.8201305 | S5: 0.83881138 | T5: 1.0586758 | U5: 1.5967813 | V5: 1.4354871 | W5: 1.2148171 | X5: 1.1745248 | Y5: 1.0455644 | Z5: 0.78249108 | AA5: 0.60829385
A6: 5 | B6: Winter | C6: 1 | D6: 3.1223201 | E6: 2.8399508 | F6: 2.6025217 | G6: 2.6365972 | H6: 2.6953889 | I6: 3.0366966 | J6: 3.9254174 | K6: 4.3475885 | L6: 4.4951371 | M6: 4.6742178 | N6: 4.8057565 | O6: 4.8861018 | P6: 4.791284 | Q6: 4.5593989 | R6: 4.5451036 | S6: 4.5082792 | T6: 4.8186029 | U6: 5.5241481 | V6: 5.4521998 | W6: 5.3330491 | X6: 5.2848421 | Y6: 4.9343088 | Z6: 4.3903111 | AA6: 3.9782812
A7: 6 | B7: Winter | C7: 1 | D7: 5.4370723 | E7: 5.1124 | F7: 4.9824443 | G7: 5.0431166 | H7: 5.0983276 | I7: 5.5250083 | J7: 6.2409945 | K7: 7.5679834 | L7: 7.9355057 | M7: 8.2055502 | N7: 8.0730359 | O7: 8.1967974 | P7: 8.1556555 | Q7: 8.034525 | R7: 7.4874472 | S7: 7.5051305 | T7: 7.2808833 | U7: 7.630511 | V7: 7.3928334 | W7: 7.2766777 | X7: 7.1157609 | Y7: 6.8715749 | Z7: 6.1675389 | AA7: 5.7297194
A8: 7 | B8: Winter | C8: 1 | D8: 2.4848462 | E8: 2.2901391 | F8: 2.2707748 | G8: 2.2247033 | H8: 2.3025185 | I8: 2.6464364 | J8: 3.3604055 | K8: 4.1094199 | L8: 4.6653819 | M8: 4.7890672 | N8: 4.8921795 | O8: 4.8644944 | P8: 4.7943722 | Q8: 4.6630277 | R8: 4.2589344 | S8: 4.1542189 | T8: 4.4952536 | U8: 4.5898975 | V8: 4.439437 | W8: 4.3784062 | X8: 4.0716383 | Y8: 3.3711413 | Z8: 3.1099388 | AA8: 2.7719868
A9: 8 | B9: Winter | C9: 1 | D9: 1.7447967 | E9: 1.6529287 | F9: 1.6162822 | G9: 1.5988821 | H9: 1.6939672 | I9: 2.0663351 | J9: 3.393633 | K9: 4.0820923 | L9: 4.2405405 | M9: 4.2173506 | N9: 4.3726958 | O9: 4.3429277 | P9: 4.0828196 | Q9: 3.9836503 | R9: 3.5224356 | S9: 3.176734 | T9: 3.2617008 | U9: 3.5521165 | V9: 3.4906286 | W9: 3.3783392 | X9: 3.3083158 | Y9: 3.0517668 | Z9: 2.4095817 | AA9: 2.0880992
A10: 9 | B10: Winter | C10: 1 | D10: 1.8897161 | E10: 1.8897161 | F10: 1.8897161 | G10: 1.8897161 | H10: 1.8897161 | I10: 1.8897161 | J10: 1.8897161 | K10: 1.8897161 | L10: 1.8897161 | M10: 1.8897161 | N10: 1.8897161 | O10: 1.8897161 | P10: 1.8897161 | Q10: 1.8897161 | R10: 1.8897161 | S10: 1.8897161 | T10: 1.8897161 | U10: 1.8897161 | V10: 1.8897161 | W10: 1.8897161 | X10: 1.8897161 | Y10: 1.8897161 | Z10: 1.8897161 | AA10: 1.8897161
A11: 10 | B11: Winter | C11: 1 | D11: 2.0627189 | E11: 1.9039239 | F11: 1.8160903 | G11: 1.8342234 | H11: 1.8489692 | I11: 2.1291361 | J11: 2.7847914 | K11: 3.2607061 | L11: 3.5628277 | M11: 3.8026112 | N11: 3.7137611 | O11: 3.7027694 | P11: 3.6924944 | Q11: 3.5274509 | R11: 3.420545 | S11: 3.2249616 | T11: 3.3934464 | U11: 3.8577528 | V11: 3.7688056 | W11: 3.6339786 | X11: 3.4886308 | Y11: 3.2909819 | Z11: 2.8832967 | AA11: 2.5310748
A12: 11 | B12: Winter | C12: 1 | D12: 0.77426555 | E12: 0.7088858 | F12: 0.67349385 | G12: 0.6700788 | H12: 0.69101073 | I12: 0.85882392 | J12: 1.1452093 | K12: 1.2658395 | L12: 1.3655526 | M12: 1.4261514 | N12: 1.369028 | O12: 1.3795914 | P12: 1.3300044 | Q12: 1.2770506 | R12: 1.1947383 | S12: 1.228029 | T12: 1.3271345 | U12: 1.6013075 | V12: 1.5072818 | W12: 1.4071417 | X12: 1.3619803 | Y12: 1.3541238 | Z12: 1.193756 | AA12: 1.0225907
A13: 12 | B13: Winter | C13: 1 | D13: 3.8462983 | E13: 3.8279696 | F13: 3.8263723 | G13: 3.9381014 | H13: 3.919593 | I13: 4.0271544 | J13: 4.1801566 | K13: 4.053379 | L13: 3.3788628 | M13: 3.2407013 | N13: 4.4128701 | O13: 4.0239311 | P13: 4.0775638 | Q13: 4.1682122 | R13: 4.2642434 | S13: 4.3993003 | T13: 4.8655533 | U13: 5.0122006 | V13: 4.6866207 | W13: 4.4439739 | X13: 4.51363 | Y13: 4.5011535 | Z13: 4.5232681 | AA13: 4.7433875
... A169: 14 | B169: Autumn | C169: 3 | D169: -0.3416898 | E169: -0.30635422 | F169: -0.30290885 | G169: -0.28751273 | H169: -0.29609175 | I169: -0.3092959 | J169: -0.3130216 | K169: -0.37074308 | L169: -0.46787545 | M169: -0.5341764 | N169: -0.57514968 | O169: -0.6267498 | P169: -0.63726087 | Q169: -0.55345825 | R169: -0.50834333 | S169: -0.45600715 | T169: -0.4248559 | U169: -0.45236145 | V169: -0.51148213 | W169: -0.5267611 | X169: -0.52271128 | Y169: -0.491528 | Z169: -0.45749717 | AA169: -0.3931226

Sheet Qc, Original
A1: LoadID | B1: Season | C1: Scenario | D1: 0 | E1: 1 | F1: 2 | G1: 3 | H1: 4 | I1: 5 | J1: 6 | K1: 7 | L1: 8 | M1: 9 | N1: 10 | O1: 11 | P1: 12 | Q1: 13 | R1: 14 | S1: 15 | T1: 16 | U1: 17 | V1: 18 | W1: 19 | X1: 20 | Y1: 21 | Z1: 22 | AA1: 23
A2: 1 | B2: Winter | C2: 1 | D2: 0.42029098 | E2: 0.29694267 | F2: 0.25741732 | G2: 0.32996435 | H2: 0.28410905 | I2: 0.23358612 | J2: 0.19326883 | K2: 0.67538455 | L2: 0.70631105 | M2: 0.60580648 | N2: 0.70580853 | O2: 0.65583645 | P2: 0.65872592 | Q2: 0.58821715 | R2: 0.34905067 | S2: 0.54650615 | T2: 0.65544985 | U2: 0.61157577 | V2: 0.42743112 | W2: 0.4434344 | X2: 0.4130204 | Y2: 0.25619988 | Z2: 0.20437222 | AA2: 0.211823
A3: 2 | B3: Winter | C3: 1 | D3: -0.25173265 | E3: -0.25167715 | F3: -0.25862167 | G3: -0.27046915 | H3: -0.2678718 | I3: -0.2458437 | J3: -0.15588425 | K3: -0.029965425 | L3: -0.03220165 | M3: -0.02134025 | N3: -0.018798575 | O3: -0.083896825 | P3: -0.12256425 | Q3: -0.15888427 | R3: -0.15768978 | S3: -0.1603565 | T3: -0.12607823 | U3: 0.041438325 | V3: -0.0058401 | W3: -0.0689383 | X3: -0.12778662 | Y3: -0.16809267 | Z3: -0.18435668 | AA3: -0.21107957
A4: 3 | B4: Winter | C4: 1 | D4: -0.6755486 | E4: -0.7289189 | F4: -0.74228888 | G4: -0.73236197 | H4: -0.7329711 | I4: -0.61206225 | J4: -0.022791375 | K4: 0.31555875 | L4: 0.40218552 | M4: 0.28017192 | N4: 0.16541995 | O4: 0.3281175 | P4: 0.20689447 | Q4: 0.062770375 | R4: -0.2483343 | S4: -0.24843997 | T4: -0.20465458 | U4: -0.1032441 | V4: -0.25163275 | W4: -0.14337332 | X4: -0.19684393 | Y4: -0.32648842 | Z4: -0.51580667 | AA4: -0.58226223
A5: 4 | B5: Winter | C5: 1 | D5: -0.71840688 | E5: -0.72553203 | F5: -0.73293498 | G5: -0.73935175 | H5: -0.74264352 | I5: -0.67896172 | J5: -0.58907158 | K5: -0.53782077 | L5: -0.55357113 | M5: -0.61325232 | N5: -0.65410025 | O5: -0.69258692 | P5: -0.69340627 | Q5: -0.70615665 | R5: -0.71236502 | S5: -0.6911146 | T5: -0.58507145 | U5: -0.34870685 | V5: -0.44977785 | W5: -0.5455849 | X5: -0.58733557 | Y5: -0.62137752 | Z5: -0.65685013 | AA5: -0.66003073
A6: 5 | B6: Winter | C6: 1 | D6: -0.72312247 | E6: -0.7594586 | F6: -0.79172953 | G6: -0.79455308 | H6: -0.792794 | I6: -0.66826273 | J6: -0.50928685 | K6: -0.4121479 | L6: -0.40484542 | M6: -0.33912035 | N6: -0.33560212 | O6: -0.3285358 | P6: -0.3953991 | Q6: -0.42549715 | R6: -0.41405517 | S6: -0.51326345 | T6: -0.45472295 | U6: -0.22796753 | V6: -0.2699512 | W6: -0.33564653 | X6: -0.3624329 | Y6: -0.47048143 | Z6: -0.5203149 | AA6: -0.54432205
A7: 6 | B7: Winter | C7: 1 | D7: 0.40113277 | E7: 0.3137815 | F7: 0.23791593 | G7: 0.3544406 | H7: 0.29105355 | I7: 0.41932112 | J7: 0.55925143 | K7: 1.0893065 | L7: 1.2545189 | M7: 1.2926264 | N7: 1.2269127 | O7: 1.3087633 | P7: 1.2990386 | Q7: 1.2839764 | R7: 1.079897 | S7: 1.0272208 | T7: 0.89278972 | U7: 0.97668195 | V7: 0.82790002 | W7: 0.8639378 | X7: 0.73044193 | Y7: 0.76890445 | Z7: 0.47733972 | AA7: 0.49020418
A8: 7 | B8: Winter | C8: 1 | D8: -0.49552778 | E8: -0.49010955 | F8: -0.5055083 | G8: -0.51465543 | H8: -0.545137 | I8: -0.48809315 | J8: -0.4146598 | K8: -0.21539028 | L8: -0.10672057 | M8: -0.0990603 | N8: -0.075292125 | O8: -0.15059844 | P8: -0.10273318 | Q8: -0.10720432 | R8: -0.19539435 | S8: -0.27922595 | T8: -0.25201113 | U8: -0.28109577 | V8: -0.31610573 | W8: -0.30348917 | X8: -0.34556293 | Y8: -0.40737163 | Z8: -0.45961667 | AA8: -0.45586354
A9: 8 | B9: Winter | C9: 1 | D9: -1.6460469 | E9: -1.6808471 | F9: -1.6741892 | G9: -1.6717834 | H9: -1.6373189 | I9: -1.5711593 | J9: -1.2010598 | K9: -0.95549523 | L9: -0.88231405 | M9: -1.0076675 | N9: -0.95152285 | O9: -0.8673757 | P9: -0.91943615 | Q9: -0.99544267 | R9: -1.2094752 | S9: -1.341321 | T9: -1.3377677 | U9: -1.3192156 | V9: -1.3905284 | W9: -1.4377772 | X9: -1.4623947 | Y9: -1.5052796 | Z9: -1.5709915 | AA9: -1.6010921
A10: 9 | B10: Winter | C10: 1 | D10: -0.0553131 | E10: -0.0553131 | F10: -0.0553131 | G10: -0.0553131 | H10: -0.0553131 | I10: -0.0553131 | J10: -0.0553131 | K10: -0.0553131 | L10: -0.0553131 | M10: -0.0553131 | N10: -0.0553131 | O10: -0.0553131 | P10: -0.0553131 | Q10: -0.0553131 | R10: -0.0553131 | S10: -0.0553131 | T10: -0.0553131 | U10: -0.0553131 | V10: -0.0553131 | W10: -0.0553131 | X10: -0.0553131 | Y10: -0.0553131 | Z10: -0.0553131 | AA10: -0.0553131
A11: 10 | B11: Winter | C11: 1 | D11: -0.65291055 | E11: -0.67194918 | F11: -0.67294557 | G11: -0.67105417 | H11: -0.66918692 | I11: -0.62560362 | J11: -0.46894002 | K11: -0.38273655 | L11: -0.2467047 | M11: -0.14246968 | N11: -0.18226492 | O11: -0.14071075 | P11: -0.16778957 | Q11: -0.2426789 | R11: -0.30336645 | S11: -0.31289818 | T11: -0.32174775 | U11: -0.21715408 | V11: -0.26313465 | W11: -0.32621448 | X11: -0.3836295 | Y11: -0.4881027 | Z11: -0.61008585 | AA11: -0.62094213
A12: 11 | B12: Winter | C12: 1 | D12: -0.47248575 | E12: -0.4770354 | F12: -0.48580272 | G12: -0.49011867 | H12: -0.47914275 | I12: -0.38667683 | J12: -0.29339362 | K12: -0.26214423 | L12: -0.24305396 | M12: -0.23614753 | N12: -0.2767577 | O12: -0.26098267 | P12: -0.29414272 | Q12: -0.2935411 | R12: -0.32659502 | S12: -0.32690465 | T12: -0.27845155 | U12: -0.18621233 | V12: -0.2543806 | W12: -0.29881863 | X12: -0.32102972 | Y12: -0.32875335 | Z12: -0.35499115 | AA12: -0.37652847
A13: 12 | B13: Winter | C13: 1 | D13: -0.065384525 | E13: 0.10970355 | F13: 0.2320791 | G13: 0.20067992 | H13: 0.15603433 | I13: -0.15718693 | J13: -0.00518945 | K13: 0.1874034 | L13: 0.40675295 | M13: 0.47984065 | N13: 0.23308183 | O13: -0.000605575 | P13: 0.73827445 | Q13: 0.83693688 | R13: 0.7939172 | S13: 0.91147275 | T13: 0.50074257 | U13: 0.69164932 | V13: 0.74268015 | W13: 0.66205362 | X13: 0.74300502 | Y13: 0.95377995 | Z13: 0.8835325 | AA13: 0.5952055
... A169: 14 | B169: Autumn | C169: 3 | D169: 0.02180585 | E169: 0.02410035 | F169: 0.0210645 | G169: 0.025870275 | H169: 0.024253 | I169: 0.022080125 | J169: 0.0254871 | K169: 0.0210608 | L169: -0.000880075 | M169: -0.013684875 | N169: -0.016333725 | O169: -0.012370375 | P169: -0.013757175 | Q169: -0.0039907 | R169: 0.00088975 | S169: -0.001213 | T169: -0.0003882 | U169: 0.001994525 | V169: 0.0062178 | W169: 0.003690675 | X169: 0.00616505 | Y169: 0.0085515 | Z169: 0.006691425 | AA169: 0.013715925

Sheet Pc
A1: LoadID | B1: Season | C1: Scenario | D1: 0 | E1: 1 | F1: 2 | G1: 3 | H1: 4 | I1: 5 | J1: 6 | K1: 7 | L1: 8 | M1: 9 | N1: 10 | O1: 11 | P1: 12 | Q1: 13 | R1: 14 | S1: 15 | T1: 16 | U1: 17 | V1: 18 | W1: 19 | X1: 20 | Y1: 21 | Z1: 22 | AA1: 23
A2: 1 | B2: Winter | C2: 1 | D2: {='Pc, Original'!D2/MAX(ABS('Pc, Original'!$D2:$AA2))} -> 0.79766844 | E2: {='Pc, Original'!E2/MAX(ABS('Pc, Original'!$D2:$AA2))} -> 0.76785871 | F2: {='Pc, Original'!F2/MAX(ABS('Pc, Original'!$D2:$AA2))} -> 0.74050825 | G2: {='Pc, Original'!G2/MAX(ABS('Pc, Original'!$D2:$AA2))} -> 0.76285834 | H2: {='Pc, Original'!H2/MAX(ABS('Pc, Original'!$D2:$AA2))} -> 0.74133219 | I2: {='Pc, Original'!I2/MAX(ABS('Pc, Original'!$D2:$AA2))} -> 0.74231955 | J2: {='Pc, Original'!J2/MAX(ABS('Pc, Original'!$D2:$AA2))} -> 0.74917115 | K2: {='Pc, Original'!K2/MAX(ABS('Pc, Original'!$D2:$AA2))} -> 0.97242156 | ... AA2: {='Pc, Original'!AA2/MAX(ABS('Pc, Original'!$D2:$AA2))} -> 0.73830886
A3: 1 | B3: Winter | C3: 2 | D3: {='Pc, Original'!D16/MAX(ABS('Pc, Original'!$D16:$AA16))} -> 1 | E3: {='Pc, Original'!E16/MAX(ABS('Pc, Original'!$D16:$AA16))} -> 0.94829699 | F3: {='Pc, Original'!F16/MAX(ABS('Pc, Original'!$D16:$AA16))} -> 0.91457089 | G3: {='Pc, Original'!G16/MAX(ABS('Pc, Original'!$D16:$AA16))} -> 0.92757695 | H3: {='Pc, Original'!H16/MAX(ABS('Pc, Original'!$D16:$AA16))} -> 0.91252175 | I3: {='Pc, Original'!I16/MAX(ABS('Pc, Original'!$D16:$AA16))} -> 0.88618305 | J3: {='Pc, Original'!J16/MAX(ABS('Pc, Original'!$D16:$AA16))} -> 0.81212108 | K3: {='Pc, Original'!K16/MAX(ABS('Pc, Original'!$D16:$AA16))} -> 0.87392989 | ... AA3: {='Pc, Original'!AA16/MAX(ABS('Pc, Original'!$D16:$AA16))} -> 0.79994105
A4: 1 | B4: Winter | C4: 3 | D4: {='Pc, Original'!D30/MAX(ABS('Pc, Original'!$D30:$AA30))} -> 0.98008583 | E4: {='Pc, Original'!E30/MAX(ABS('Pc, Original'!$D30:$AA30))} -> 0.96141879 | F4: {='Pc, Original'!F30/MAX(ABS('Pc, Original'!$D30:$AA30))} -> 0.9330413 | G4: {='Pc, Original'!G30/MAX(ABS('Pc, Original'!$D30:$AA30))} -> 0.94280702 | H4: {='Pc, Original'!H30/MAX(ABS('Pc, Original'!$D30:$AA30))} -> 0.91016414 | I4: {='Pc, Original'!I30/MAX(ABS('Pc, Original'!$D30:$AA30))} -> 0.92550694 | J4: {='Pc, Original'!J30/MAX(ABS('Pc, Original'!$D30:$AA30))} -> 0.92181555 | K4: {='Pc, Original'!K30/MAX(ABS('Pc, Original'!$D30:$AA30))} -> 0.99085234 | ... AA4: {='Pc, Original'!AA30/MAX(ABS('Pc, Original'!$D30:$AA30))} -> 0.94098259
A5: 1 | B5: Spring | C5: 1 | D5: {='Pc, Original'!D44/MAX(ABS('Pc, Original'!$D44:$AA44))} -> 0.78562204 | E5: {='Pc, Original'!E44/MAX(ABS('Pc, Original'!$D44:$AA44))} -> 0.78783004 | F5: {='Pc, Original'!F44/MAX(ABS('Pc, Original'!$D44:$AA44))} -> 0.75295167 | G5: {='Pc, Original'!G44/MAX(ABS('Pc, Original'!$D44:$AA44))} -> 0.75996565 | H5: {='Pc, Original'!H44/MAX(ABS('Pc, Original'!$D44:$AA44))} -> 0.7787142 | I5: {='Pc, Original'!I44/MAX(ABS('Pc, Original'!$D44:$AA44))} -> 0.78473197 | J5: {='Pc, Original'!J44/MAX(ABS('Pc, Original'!$D44:$AA44))} -> 0.76628383 | K5: {='Pc, Original'!K44/MAX(ABS('Pc, Original'!$D44:$AA44))} -> 0.9084596 | ... AA5: {='Pc, Original'!AA44/MAX(ABS('Pc, Original'!$D44:$AA44))} -> 0.75054032
A6: 1 | B6: Spring | C6: 2 | D6: {='Pc, Original'!D58/MAX(ABS('Pc, Original'!$D58:$AA58))} -> 0.9980138 | E6: {='Pc, Original'!E58/MAX(ABS('Pc, Original'!$D58:$AA58))} -> 1 | F6: {='Pc, Original'!F58/MAX(ABS('Pc, Original'!$D58:$AA58))} -> 0.97624971 | G6: {='Pc, Original'!G58/MAX(ABS('Pc, Original'!$D58:$AA58))} -> 0.98656028 | H6: {='Pc, Original'!H58/MAX(ABS('Pc, Original'!$D58:$AA58))} -> 0.94042013 | I6: {='Pc, Original'!I58/MAX(ABS('Pc, Original'!$D58:$AA58))} -> 0.90464123 | J6: {='Pc, Original'!J58/MAX(ABS('Pc, Original'!$D58:$AA58))} -> 0.80242758 | K6: {='Pc, Original'!K58/MAX(ABS('Pc, Original'!$D58:$AA58))} -> 0.89248386 | ... AA6: {='Pc, Original'!AA58/MAX(ABS('Pc, Original'!$D58:$AA58))} -> 0.73882589
A7: 1 | B7: Spring | C7: 3 | D7: {='Pc, Original'!D72/MAX(ABS('Pc, Original'!$D72:$AA72))} -> 0.89222244 | E7: {='Pc, Original'!E72/MAX(ABS('Pc, Original'!$D72:$AA72))} -> 0.87352014 | F7: {='Pc, Original'!F72/MAX(ABS('Pc, Original'!$D72:$AA72))} -> 0.8867848 | G7: {='Pc, Original'!G72/MAX(ABS('Pc, Original'!$D72:$AA72))} -> 0.86373597 | H7: {='Pc, Original'!H72/MAX(ABS('Pc, Original'!$D72:$AA72))} -> 0.84898648 | I7: {='Pc, Original'!I72/MAX(ABS('Pc, Original'!$D72:$AA72))} -> 0.87239482 | J7: {='Pc, Original'!J72/MAX(ABS('Pc, Original'!$D72:$AA72))} -> 0.84061581 | K7: {='Pc, Original'!K72/MAX(ABS('Pc, Original'!$D72:$AA72))} -> 0.86720376 | ... AA7: {='Pc, Original'!AA72/MAX(ABS('Pc, Original'!$D72:$AA72))} -> 0.93019853
A8: 1 | B8: Summer | C8: 1 | D8: {='Pc, Original'!D86/MAX(ABS('Pc, Original'!$D86:$AA86))} -> 0.79737138 | E8: {='Pc, Original'!E86/MAX(ABS('Pc, Original'!$D86:$AA86))} -> 0.7891799 | F8: {='Pc, Original'!F86/MAX(ABS('Pc, Original'!$D86:$AA86))} -> 0.76060174 | G8: {='Pc, Original'!G86/MAX(ABS('Pc, Original'!$D86:$AA86))} -> 0.74671229 | H8: {='Pc, Original'!H86/MAX(ABS('Pc, Original'!$D86:$AA86))} -> 0.74176372 | I8: {='Pc, Original'!I86/MAX(ABS('Pc, Original'!$D86:$AA86))} -> 0.75238782 | J8: {='Pc, Original'!J86/MAX(ABS('Pc, Original'!$D86:$AA86))} -> 0.74622783 | K8: {='Pc, Original'!K86/MAX(ABS('Pc, Original'!$D86:$AA86))} -> 0.9121625 | ... AA8: {='Pc, Original'!AA86/MAX(ABS('Pc, Original'!$D86:$AA86))} -> 0.75321016
A9: 1 | B9: Summer | C9: 2 | D9: {='Pc, Original'!D100/MAX(ABS('Pc, Original'!$D100:$AA100))} -> 1 | E9: {='Pc, Original'!E100/MAX(ABS('Pc, Original'!$D100:$AA100))} -> 0.98195759 | F9: {='Pc, Original'!F100/MAX(ABS('Pc, Original'!$D100:$AA100))} -> 0.97139881 | G9: {='Pc, Original'!G100/MAX(ABS('Pc, Original'!$D100:$AA100))} -> 0.97209068 | H9: {='Pc, Original'!H100/MAX(ABS('Pc, Original'!$D100:$AA100))} -> 0.93056558 | I9: {='Pc, Original'!I100/MAX(ABS('Pc, Original'!$D100:$AA100))} -> 0.91359681 | J9: {='Pc, Original'!J100/MAX(ABS('Pc, Original'!$D100:$AA100))} -> 0.85959073 | K9: {='Pc, Original'!K100/MAX(ABS('Pc, Original'!$D100:$AA100))} -> 0.84960387 | ... AA9: {='Pc, Original'!AA100/MAX(ABS('Pc, Original'!$D100:$AA100))} -> 0.80736605
A10: 1 | B10: Summer | C10: 3 | D10: {='Pc, Original'!D114/MAX(ABS('Pc, Original'!$D114:$AA114))} -> 0.88721716 | E10: {='Pc, Original'!E114/MAX(ABS('Pc, Original'!$D114:$AA114))} -> 0.84611348 | F10: {='Pc, Original'!F114/MAX(ABS('Pc, Original'!$D114:$AA114))} -> 0.8209614 | G10: {='Pc, Original'!G114/MAX(ABS('Pc, Original'!$D114:$AA114))} -> 0.82446869 | H10: {='Pc, Original'!H114/MAX(ABS('Pc, Original'!$D114:$AA114))} -> 0.81720275 | I10: {='Pc, Original'!I114/MAX(ABS('Pc, Original'!$D114:$AA114))} -> 0.81934064 | J10: {='Pc, Original'!J114/MAX(ABS('Pc, Original'!$D114:$AA114))} -> 0.81579076 | K10: {='Pc, Original'!K114/MAX(ABS('Pc, Original'!$D114:$AA114))} -> 0.84242748 | ... AA10: {='Pc, Original'!AA114/MAX(ABS('Pc, Original'!$D114:$AA114))} -> 0.86633546
A11: 1 | B11: Autumn | C11: 1 | D11: {='Pc, Original'!D128/MAX(ABS('Pc, Original'!$D128:$AA128))} -> 0.54688603 | E11: {='Pc, Original'!E128/MAX(ABS('Pc, Original'!$D128:$AA128))} -> 0.54584589 | F11: {='Pc, Original'!F128/MAX(ABS('Pc, Original'!$D128:$AA128))} -> 0.55416999 | G11: {='Pc, Original'!G128/MAX(ABS('Pc, Original'!$D128:$AA128))} -> 0.54462493 | H11: {='Pc, Original'!H128/MAX(ABS('Pc, Original'!$D128:$AA128))} -> 0.55052821 | I11: {='Pc, Original'!I128/MAX(ABS('Pc, Original'!$D128:$AA128))} -> 0.56266046 | J11: {='Pc, Original'!J128/MAX(ABS('Pc, Original'!$D128:$AA128))} -> 0.61514854 | K11: {='Pc, Original'!K128/MAX(ABS('Pc, Original'!$D128:$AA128))} -> 0.85784089 | ... AA11: {='Pc, Original'!AA128/MAX(ABS('Pc, Original'!$D128:$AA128))} -> 0.71048869
A12: 1 | B12: Autumn | C12: 2 | D12: {='Pc, Original'!D142/MAX(ABS('Pc, Original'!$D142:$AA142))} -> 0.99225839 | E12: {='Pc, Original'!E142/MAX(ABS('Pc, Original'!$D142:$AA142))} -> 1 | F12: {='Pc, Original'!F142/MAX(ABS('Pc, Original'!$D142:$AA142))} -> 0.9556947 | G12: {='Pc, Original'!G142/MAX(ABS('Pc, Original'!$D142:$AA142))} -> 0.97238158 | H12: {='Pc, Original'!H142/MAX(ABS('Pc, Original'!$D142:$AA142))} -> 0.92810023 | I12: {='Pc, Original'!I142/MAX(ABS('Pc, Original'!$D142:$AA142))} -> 0.90976925 | J12: {='Pc, Original'!J142/MAX(ABS('Pc, Original'!$D142:$AA142))} -> 0.86244287 | K12: {='Pc, Original'!K142/MAX(ABS('Pc, Original'!$D142:$AA142))} -> 0.85260084 | ... AA12: {='Pc, Original'!AA142/MAX(ABS('Pc, Original'!$D142:$AA142))} -> 0.83657048
A13: 1 | B13: Autumn | C13: 3 | D13: {='Pc, Original'!D156/MAX(ABS('Pc, Original'!$D156:$AA156))} -> 0.98944695 | E13: {='Pc, Original'!E156/MAX(ABS('Pc, Original'!$D156:$AA156))} -> 0.99776571 | F13: {='Pc, Original'!F156/MAX(ABS('Pc, Original'!$D156:$AA156))} -> 0.95218035 | G13: {='Pc, Original'!G156/MAX(ABS('Pc, Original'!$D156:$AA156))} -> 0.99001004 | H13: {='Pc, Original'!H156/MAX(ABS('Pc, Original'!$D156:$AA156))} -> 0.94771115 | I13: {='Pc, Original'!I156/MAX(ABS('Pc, Original'!$D156:$AA156))} -> 1 | J13: {='Pc, Original'!J156/MAX(ABS('Pc, Original'!$D156:$AA156))} -> 0.9415835 | K13: {='Pc, Original'!K156/MAX(ABS('Pc, Original'!$D156:$AA156))} -> 0.96672272 | ... AA13: {='Pc, Original'!AA156/MAX(ABS('Pc, Original'!$D156:$AA156))} -> 0.89279599
A14: 2 | B14: Winter | C14: 1 | D14: {='Pc, Original'!D3/MAX(ABS('Pc, Original'!$D3:$AA3))} -> 0.55927531 | E14: {='Pc, Original'!E3/MAX(ABS('Pc, Original'!$D3:$AA3))} -> 0.5433582 | F14: {='Pc, Original'!F3/MAX(ABS('Pc, Original'!$D3:$AA3))} -> 0.52027848 | G14: {='Pc, Original'!G3/MAX(ABS('Pc, Original'!$D3:$AA3))} -> 0.51597047 | H14: {='Pc, Original'!H3/MAX(ABS('Pc, Original'!$D3:$AA3))} -> 0.52115505 | I14: {='Pc, Original'!I3/MAX(ABS('Pc, Original'!$D3:$AA3))} -> 0.55644369 | J14: {='Pc, Original'!J3/MAX(ABS('Pc, Original'!$D3:$AA3))} -> 0.67082185 | K14: {='Pc, Original'!K3/MAX(ABS('Pc, Original'!$D3:$AA3))} -> 0.78315847 | ... AA14: {='Pc, Original'!AA3/MAX(ABS('Pc, Original'!$D3:$AA3))} -> 0.64393582
A15: 2 | B15: Winter | C15: 2 | D15: {='Pc, Original'!D17/MAX(ABS('Pc, Original'!$D17:$AA17))} -> 0.57111467 | E15: {='Pc, Original'!E17/MAX(ABS('Pc, Original'!$D17:$AA17))} -> 0.51968446 | F15: {='Pc, Original'!F17/MAX(ABS('Pc, Original'!$D17:$AA17))} -> 0.51211025 | G15: {='Pc, Original'!G17/MAX(ABS('Pc, Original'!$D17:$AA17))} -> 0.45925655 | H15: {='Pc, Original'!H17/MAX(ABS('Pc, Original'!$D17:$AA17))} -> 0.4993817 | I15: {='Pc, Original'!I17/MAX(ABS('Pc, Original'!$D17:$AA17))} -> 0.53114373 | J15: {='Pc, Original'!J17/MAX(ABS('Pc, Original'!$D17:$AA17))} -> 0.57253221 | K15: {='Pc, Original'!K17/MAX(ABS('Pc, Original'!$D17:$AA17))} -> 0.68556471 | ... AA15: {='Pc, Original'!AA17/MAX(ABS('Pc, Original'!$D17:$AA17))} -> 0.62686285
A16: 2 | B16: Winter | C16: 3 | D16: {='Pc, Original'!D31/MAX(ABS('Pc, Original'!$D31:$AA31))} -> 0.62461116 | E16: {='Pc, Original'!E31/MAX(ABS('Pc, Original'!$D31:$AA31))} -> 0.57375759 | F16: {='Pc, Original'!F31/MAX(ABS('Pc, Original'!$D31:$AA31))} -> 0.5454784 | G16: {='Pc, Original'!G31/MAX(ABS('Pc, Original'!$D31:$AA31))} -> 0.52398403 | H16: {='Pc, Original'!H31/MAX(ABS('Pc, Original'!$D31:$AA31))} -> 0.53057015 | I16: {='Pc, Original'!I31/MAX(ABS('Pc, Original'!$D31:$AA31))} -> 0.57282337 | J16: {='Pc, Original'!J31/MAX(ABS('Pc, Original'!$D31:$AA31))} -> 0.6198472 | K16: {='Pc, Original'!K31/MAX(ABS('Pc, Original'!$D31:$AA31))} -> 0.73878158 | ... AA16: {='Pc, Original'!AA31/MAX(ABS('Pc, Original'!$D31:$AA31))} -> 0.67376189
A17: 2 | B17: Spring | C17: 1 | D17: {='Pc, Original'!D45/MAX(ABS('Pc, Original'!$D45:$AA45))} -> 0.59045724 | E17: {='Pc, Original'!E45/MAX(ABS('Pc, Original'!$D45:$AA45))} -> 0.54374011 | F17: {='Pc, Original'!F45/MAX(ABS('Pc, Original'!$D45:$AA45))} -> 0.50461407 | G17: {='Pc, Original'!G45/MAX(ABS('Pc, Original'!$D45:$AA45))} -> 0.49112971 | H17: {='Pc, Original'!H45/MAX(ABS('Pc, Original'!$D45:$AA45))} -> 0.51003795 | I17: {='Pc, Original'!I45/MAX(ABS('Pc, Original'!$D45:$AA45))} -> 0.4950064 | J17: {='Pc, Original'!J45/MAX(ABS('Pc, Original'!$D45:$AA45))} -> 0.5022672 | K17: {='Pc, Original'!K45/MAX(ABS('Pc, Original'!$D45:$AA45))} -> 0.66614802 | ... AA17: {='Pc, Original'!AA45/MAX(ABS('Pc, Original'!$D45:$AA45))} -> 0.69760763
A18: 2 | B18: Spring | C18: 2 | D18: {='Pc, Original'!D59/MAX(ABS('Pc, Original'!$D59:$AA59))} -> 0.74075679 | E18: {='Pc, Original'!E59/MAX(ABS('Pc, Original'!$D59:$AA59))} -> 0.6954028 | F18: {='Pc, Original'!F59/MAX(ABS('Pc, Original'!$D59:$AA59))} -> 0.66656067 | G18: {='Pc, Original'!G59/MAX(ABS('Pc, Original'!$D59:$AA59))} -> 0.63099227 | H18: {='Pc, Original'!H59/MAX(ABS('Pc, Original'!$D59:$AA59))} -> 0.60708943 | I18: {='Pc, Original'!I59/MAX(ABS('Pc, Original'!$D59:$AA59))} -> 0.53983401 | J18: {='Pc, Original'!J59/MAX(ABS('Pc, Original'!$D59:$AA59))} -> 0.51069164 | K18: {='Pc, Original'!K59/MAX(ABS('Pc, Original'!$D59:$AA59))} -> 0.68598176 | ... AA18: {='Pc, Original'!AA59/MAX(ABS('Pc, Original'!$D59:$AA59))} -> 0.64297945
A19: 2 | B19: Spring | C19: 3 | D19: {='Pc, Original'!D73/MAX(ABS('Pc, Original'!$D73:$AA73))} -> 0.56142384 | E19: {='Pc, Original'!E73/MAX(ABS('Pc, Original'!$D73:$AA73))} -> 0.5169566 | F19: {='Pc, Original'!F73/MAX(ABS('Pc, Original'!$D73:$AA73))} -> 0.47613767 | G19: {='Pc, Original'!G73/MAX(ABS('Pc, Original'!$D73:$AA73))} -> 0.46486096 | H19: {='Pc, Original'!H73/MAX(ABS('Pc, Original'!$D73:$AA73))} -> 0.45486352 | I19: {='Pc, Original'!I73/MAX(ABS('Pc, Original'!$D73:$AA73))} -> 0.4938978 | J19: {='Pc, Original'!J73/MAX(ABS('Pc, Original'!$D73:$AA73))} -> 0.49833577 | K19: {='Pc, Original'!K73/MAX(ABS('Pc, Original'!$D73:$AA73))} -> 0.68718933 | ... AA19: {='Pc, Original'!AA73/MAX(ABS('Pc, Original'!$D73:$AA73))} -> 0.66094018
A20: 2 | B20: Summer | C20: 1 | D20: {='Pc, Original'!D87/MAX(ABS('Pc, Original'!$D87:$AA87))} -> 0.70948912 | E20: {='Pc, Original'!E87/MAX(ABS('Pc, Original'!$D87:$AA87))} -> 0.66817499 | F20: {='Pc, Original'!F87/MAX(ABS('Pc, Original'!$D87:$AA87))} -> 0.64253904 | G20: {='Pc, Original'!G87/MAX(ABS('Pc, Original'!$D87:$AA87))} -> 0.5842604 | H20: {='Pc, Original'!H87/MAX(ABS('Pc, Original'!$D87:$AA87))} -> 0.56296084 | I20: {='Pc, Original'!I87/MAX(ABS('Pc, Original'!$D87:$AA87))} -> 0.59209669 | J20: {='Pc, Original'!J87/MAX(ABS('Pc, Original'!$D87:$AA87))} -> 0.62975159 | K20: {='Pc, Original'!K87/MAX(ABS('Pc, Original'!$D87:$AA87))} -> 0.84570064 | ... AA20: {='Pc, Original'!AA87/MAX(ABS('Pc, Original'!$D87:$AA87))} -> 0.7272208
A21: 2 | B21: Summer | C21: 2 | D21: {='Pc, Original'!D101/MAX(ABS('Pc, Original'!$D101:$AA101))} -> 0.79435039 | E21: {='Pc, Original'!E101/MAX(ABS('Pc, Original'!$D101:$AA101))} -> 0.73853012 | F21: {='Pc, Original'!F101/MAX(ABS('Pc, Original'!$D101:$AA101))} -> 0.70351859 | G21: {='Pc, Original'!G101/MAX(ABS('Pc, Original'!$D101:$AA101))} -> 0.64599914 | H21: {='Pc, Original'!H101/MAX(ABS('Pc, Original'!$D101:$AA101))} -> 0.63441054 | I21: {='Pc, Original'!I101/MAX(ABS('Pc, Original'!$D101:$AA101))} -> 0.61504354 | J21: {='Pc, Original'!J101/MAX(ABS('Pc, Original'!$D101:$AA101))} -> 0.65741368 | K21: {='Pc, Original'!K101/MAX(ABS('Pc, Original'!$D101:$AA101))} -> 0.7840423 | ... AA21: {='Pc, Original'!AA101/MAX(ABS('Pc, Original'!$D101:$AA101))} -> 0.7488972
A22: 2 | B22: Summer | C22: 3 | D22: {='Pc, Original'!D115/MAX(ABS('Pc, Original'!$D115:$AA115))} -> 0.64198505 | E22: {='Pc, Original'!E115/MAX(ABS('Pc, Original'!$D115:$AA115))} -> 0.5909836 | F22: {='Pc, Original'!F115/MAX(ABS('Pc, Original'!$D115:$AA115))} -> 0.5527157 | G22: {='Pc, Original'!G115/MAX(ABS('Pc, Original'!$D115:$AA115))} -> 0.53127724 | H22: {='Pc, Original'!H115/MAX(ABS('Pc, Original'!$D115:$AA115))} -> 0.52379531 | I22: {='Pc, Original'!I115/MAX(ABS('Pc, Original'!$D115:$AA115))} -> 0.51139269 | J22: {='Pc, Original'!J115/MAX(ABS('Pc, Original'!$D115:$AA115))} -> 0.56508279 | K22: {='Pc, Original'!K115/MAX(ABS('Pc, Original'!$D115:$AA115))} -> 0.72639226 | ... AA22: {='Pc, Original'!AA115/MAX(ABS('Pc, Original'!$D115:$AA115))} -> 0.71637374
A23: 2 | B23: Autumn | C23: 1 | D23: {='Pc, Original'!D129/MAX(ABS('Pc, Original'!$D129:$AA129))} -> 0.37814252 | E23: {='Pc, Original'!E129/MAX(ABS('Pc, Original'!$D129:$AA129))} -> 0.35298318 | F23: {='Pc, Original'!F129/MAX(ABS('Pc, Original'!$D129:$AA129))} -> 0.3403832 | G23: {='Pc, Original'!G129/MAX(ABS('Pc, Original'!$D129:$AA129))} -> 0.33787837 | H23: {='Pc, Original'!H129/MAX(ABS('Pc, Original'!$D129:$AA129))} -> 0.36112302 | I23: {='Pc, Original'!I129/MAX(ABS('Pc, Original'!$D129:$AA129))} -> 0.42852052 | J23: {='Pc, Original'!J129/MAX(ABS('Pc, Original'!$D129:$AA129))} -> 0.58694497 | K23: {='Pc, Original'!K129/MAX(ABS('Pc, Original'!$D129:$AA129))} -> 0.80277069 | ... AA23: {='Pc, Original'!AA129/MAX(ABS('Pc, Original'!$D129:$AA129))} -> 0.6170716
A24: 2 | B24: Autumn | C24: 2 | D24: {='Pc, Original'!D143/MAX(ABS('Pc, Original'!$D143:$AA143))} -> 0.69274472 | E24: {='Pc, Original'!E143/MAX(ABS('Pc, Original'!$D143:$AA143))} -> 0.66931797 | F24: {='Pc, Original'!F143/MAX(ABS('Pc, Original'!$D143:$AA143))} -> 0.62691554 | G24: {='Pc, Original'!G143/MAX(ABS('Pc, Original'!$D143:$AA143))} -> 0.5781999 | H24: {='Pc, Original'!H143/MAX(ABS('Pc, Original'!$D143:$AA143))} -> 0.6102901 | I24: {='Pc, Original'!I143/MAX(ABS('Pc, Original'!$D143:$AA143))} -> 0.64246898 | J24: {='Pc, Original'!J143/MAX(ABS('Pc, Original'!$D143:$AA143))} -> 0.64842012 | K24: {='Pc, Original'!K143/MAX(ABS('Pc, Original'!$D143:$AA143))} -> 0.79020247 | ... AA24: {='Pc, Original'!AA143/MAX(ABS('Pc, Original'!$D143:$AA143))} -> 0.58931816
A25: 2 | B25: Autumn | C25: 3 | D25: {='Pc, Original'!D157/MAX(ABS('Pc, Original'!$D157:$AA157))} -> 0.5393673 | E25: {='Pc, Original'!E157/MAX(ABS('Pc, Original'!$D157:$AA157))} -> 0.50124042 | F25: {='Pc, Original'!F157/MAX(ABS('Pc, Original'!$D157:$AA157))} -> 0.47500852 | G25: {='Pc, Original'!G157/MAX(ABS('Pc, Original'!$D157:$AA157))} -> 0.45202772 | H25: {='Pc, Original'!H157/MAX(ABS('Pc, Original'!$D157:$AA157))} -> 0.44941376 | I25: {='Pc, Original'!I157/MAX(ABS('Pc, Original'!$D157:$AA157))} -> 0.46766791 | J25: {='Pc, Original'!J157/MAX(ABS('Pc, Original'!$D157:$AA157))} -> 0.51078255 | K25: {='Pc, Original'!K157/MAX(ABS('Pc, Original'!$D157:$AA157))} -> 0.62706541 | ... AA25: {='Pc, Original'!AA157/MAX(ABS('Pc, Original'!$D157:$AA157))} -> 0.67005541
A26: 3 | B26: Winter | C26: 1 | D26: {='Pc, Original'!D4/MAX(ABS('Pc, Original'!$D4:$AA4))} -> 0.47152422 | E26: {='Pc, Original'!E4/MAX(ABS('Pc, Original'!$D4:$AA4))} -> 0.44334414 | F26: {='Pc, Original'!F4/MAX(ABS('Pc, Original'!$D4:$AA4))} -> 0.42901346 | G26: {='Pc, Original'!G4/MAX(ABS('Pc, Original'!$D4:$AA4))} -> 0.43798756 | H26: {='Pc, Original'!H4/MAX(ABS('Pc, Original'!$D4:$AA4))} -> 0.44210785 | I26: {='Pc, Original'!I4/MAX(ABS('Pc, Original'!$D4:$AA4))} -> 0.5054882 | J26: {='Pc, Original'!J4/MAX(ABS('Pc, Original'!$D4:$AA4))} -> 0.81636454 | K26: {='Pc, Original'!K4/MAX(ABS('Pc, Original'!$D4:$AA4))} -> 0.95715136 | ... AA26: {='Pc, Original'!AA4/MAX(ABS('Pc, Original'!$D4:$AA4))} -> 0.53940865
A27: 3 | B27: Winter | C27: 2 | D27: {='Pc, Original'!D18/MAX(ABS('Pc, Original'!$D18:$AA18))} -> 0.64217374 | E27: {='Pc, Original'!E18/MAX(ABS('Pc, Original'!$D18:$AA18))} -> 0.60413996 | F27: {='Pc, Original'!F18/MAX(ABS('Pc, Original'!$D18:$AA18))} -> 0.57571979 | G27: {='Pc, Original'!G18/MAX(ABS('Pc, Original'!$D18:$AA18))} -> 0.58016086 | H27: {='Pc, Original'!H18/MAX(ABS('Pc, Original'!$D18:$AA18))} -> 0.58592591 | I27: {='Pc, Original'!I18/MAX(ABS('Pc, Original'!$D18:$AA18))} -> 0.6272762 | J27: {='Pc, Original'!J18/MAX(ABS('Pc, Original'!$D18:$AA18))} -> 0.79828689 | K27: {='Pc, Original'!K18/MAX(ABS('Pc, Original'!$D18:$AA18))} -> 0.84032892 | ... AA27: {='Pc, Original'!AA18/MAX(ABS('Pc, Original'!$D18:$AA18))} -> 0.66113973
A28: 3 | B28: Winter | C28: 3 | D28: {='Pc, Original'!D32/MAX(ABS('Pc, Original'!$D32:$AA32))} -> 0.67621717 | E28: {='Pc, Original'!E32/MAX(ABS('Pc, Original'!$D32:$AA32))} -> 0.63815133 | F28: {='Pc, Original'!F32/MAX(ABS('Pc, Original'!$D32:$AA32))} -> 0.61181784 | G28: {='Pc, Original'!G32/MAX(ABS('Pc, Original'!$D32:$AA32))} -> 0.60255841 | H28: {='Pc, Original'!H32/MAX(ABS('Pc, Original'!$D32:$AA32))} -> 0.59764612 | I28: {='Pc, Original'!I32/MAX(ABS('Pc, Original'!$D32:$AA32))} -> 0.61568585 | J28: {='Pc, Original'!J32/MAX(ABS('Pc, Original'!$D32:$AA32))} -> 0.67971242 | K28: {='Pc, Original'!K32/MAX(ABS('Pc, Original'!$D32:$AA32))} -> 0.7283396 | ... AA28: {='Pc, Original'!AA32/MAX(ABS('Pc, Original'!$D32:$AA32))} -> 0.70618607
A29: 3 | B29: Spring | C29: 1 | D29: {='Pc, Original'!D46/MAX(ABS('Pc, Original'!$D46:$AA46))} -> 0.62253365 | E29: {='Pc, Original'!E46/MAX(ABS('Pc, Original'!$D46:$AA46))} -> 0.56826289 | F29: {='Pc, Original'!F46/MAX(ABS('Pc, Original'!$D46:$AA46))} -> 0.53645735 | G29: {='Pc, Original'!G46/MAX(ABS('Pc, Original'!$D46:$AA46))} -> 0.54479693 | H29: {='Pc, Original'!H46/MAX(ABS('Pc, Original'!$D46:$AA46))} -> 0.55343949 | I29: {='Pc, Original'!I46/MAX(ABS('Pc, Original'!$D46:$AA46))} -> 0.57000002 | J29: {='Pc, Original'!J46/MAX(ABS('Pc, Original'!$D46:$AA46))} -> 0.68892618 | K29: {='Pc, Original'!K46/MAX(ABS('Pc, Original'!$D46:$AA46))} -> 0.88171446 | ... AA29: {='Pc, Original'!AA46/MAX(ABS('Pc, Original'!$D46:$AA46))} -> 0.69650294
A30: 3 | B30: Spring | C30: 2 | D30: {='Pc, Original'!D60/MAX(ABS('Pc, Original'!$D60:$AA60))} -> 0.8336549 | E30: {='Pc, Original'!E60/MAX(ABS('Pc, Original'!$D60:$AA60))} -> 0.77695974 | F30: {='Pc, Original'!F60/MAX(ABS('Pc, Original'!$D60:$AA60))} -> 0.71779592 | G30: {='Pc, Original'!G60/MAX(ABS('Pc, Original'!$D60:$AA60))} -> 0.72445174 | H30: {='Pc, Original'!H60/MAX(ABS('Pc, Original'!$D60:$AA60))} -> 0.71442219 | I30: {='Pc, Original'!I60/MAX(ABS('Pc, Original'!$D60:$AA60))} -> 0.71851552 | J30: {='Pc, Original'!J60/MAX(ABS('Pc, Original'!$D60:$AA60))} -> 0.77791948 | K30: {='Pc, Original'!K60/MAX(ABS('Pc, Original'!$D60:$AA60))} -> 0.86193687 | ... AA30: {='Pc, Original'!AA60/MAX(ABS('Pc, Original'!$D60:$AA60))} -> 0.80473579
A31: 3 | B31: Spring | C31: 3 | D31: {='Pc, Original'!D74/MAX(ABS('Pc, Original'!$D74:$AA74))} -> 0.70333773 | E31: {='Pc, Original'!E74/MAX(ABS('Pc, Original'!$D74:$AA74))} -> 0.66040606 | F31: {='Pc, Original'!F74/MAX(ABS('Pc, Original'!$D74:$AA74))} -> 0.63864254 | G31: {='Pc, Original'!G74/MAX(ABS('Pc, Original'!$D74:$AA74))} -> 0.61500819 | H31: {='Pc, Original'!H74/MAX(ABS('Pc, Original'!$D74:$AA74))} -> 0.61609738 | I31: {='Pc, Original'!I74/MAX(ABS('Pc, Original'!$D74:$AA74))} -> 0.62154068 | J31: {='Pc, Original'!J74/MAX(ABS('Pc, Original'!$D74:$AA74))} -> 0.64164656 | K31: {='Pc, Original'!K74/MAX(ABS('Pc, Original'!$D74:$AA74))} -> 0.70983277 | ... AA31: {='Pc, Original'!AA74/MAX(ABS('Pc, Original'!$D74:$AA74))} -> 0.74585068
A32: 3 | B32: Summer | C32: 1 | D32: {='Pc, Original'!D88/MAX(ABS('Pc, Original'!$D88:$AA88))} -> 0.56457199 | E32: {='Pc, Original'!E88/MAX(ABS('Pc, Original'!$D88:$AA88))} -> 0.53053638 | F32: {='Pc, Original'!F88/MAX(ABS('Pc, Original'!$D88:$AA88))} -> 0.48851003 | G32: {='Pc, Original'!G88/MAX(ABS('Pc, Original'!$D88:$AA88))} -> 0.50893146 | H32: {='Pc, Original'!H88/MAX(ABS('Pc, Original'!$D88:$AA88))} -> 0.49926151 | I32: {='Pc, Original'!I88/MAX(ABS('Pc, Original'!$D88:$AA88))} -> 0.50963047 | J32: {='Pc, Original'!J88/MAX(ABS('Pc, Original'!$D88:$AA88))} -> 0.72205461 | K32: {='Pc, Original'!K88/MAX(ABS('Pc, Original'!$D88:$AA88))} -> 0.92438846 | ... AA32: {='Pc, Original'!AA88/MAX(ABS('Pc, Original'!$D88:$AA88))} -> 0.60213639
A33: 3 | B33: Summer | C33: 2 | D33: {='Pc, Original'!D102/MAX(ABS('Pc, Original'!$D102:$AA102))} -> 0.72999595 | E33: {='Pc, Original'!E102/MAX(ABS('Pc, Original'!$D102:$AA102))} -> 0.68378894 | F33: {='Pc, Original'!F102/MAX(ABS('Pc, Original'!$D102:$AA102))} -> 0.6405757 | G33: {='Pc, Original'!G102/MAX(ABS('Pc, Original'!$D102:$AA102))} -> 0.6352821 | H33: {='Pc, Original'!H102/MAX(ABS('Pc, Original'!$D102:$AA102))} -> 0.63780271 | I33: {='Pc, Original'!I102/MAX(ABS('Pc, Original'!$D102:$AA102))} -> 0.63069686 | J33: {='Pc, Original'!J102/MAX(ABS('Pc, Original'!$D102:$AA102))} -> 0.69818569 | K33: {='Pc, Original'!K102/MAX(ABS('Pc, Original'!$D102:$AA102))} -> 0.80540876 | ... AA33: {='Pc, Original'!AA102/MAX(ABS('Pc, Original'!$D102:$AA102))} -> 0.71937498
A34: 3 | B34: Summer | C34: 3 | D34: {='Pc, Original'!D116/MAX(ABS('Pc, Original'!$D116:$AA116))} -> 0.7805957 | E34: {='Pc, Original'!E116/MAX(ABS('Pc, Original'!$D116:$AA116))} -> 0.72516843 | F34: {='Pc, Original'!F116/MAX(ABS('Pc, Original'!$D116:$AA116))} -> 0.70745584 | G34: {='Pc, Original'!G116/MAX(ABS('Pc, Original'!$D116:$AA116))} -> 0.66757087 | H34: {='Pc, Original'!H116/MAX(ABS('Pc, Original'!$D116:$AA116))} -> 0.62506422 | I34: {='Pc, Original'!I116/MAX(ABS('Pc, Original'!$D116:$AA116))} -> 0.6142601 | J34: {='Pc, Original'!J116/MAX(ABS('Pc, Original'!$D116:$AA116))} -> 0.63550224 | K34: {='Pc, Original'!K116/MAX(ABS('Pc, Original'!$D116:$AA116))} -> 0.74606257 | ... AA34: {='Pc, Original'!AA116/MAX(ABS('Pc, Original'!$D116:$AA116))} -> 0.76588379
A35: 3 | B35: Autumn | C35: 1 | D35: {='Pc, Original'!D130/MAX(ABS('Pc, Original'!$D130:$AA130))} -> 0.46851263 | E35: {='Pc, Original'!E130/MAX(ABS('Pc, Original'!$D130:$AA130))} -> 0.44600621 | F35: {='Pc, Original'!F130/MAX(ABS('Pc, Original'!$D130:$AA130))} -> 0.44626081 | G35: {='Pc, Original'!G130/MAX(ABS('Pc, Original'!$D130:$AA130))} -> 0.43880846 | H35: {='Pc, Original'!H130/MAX(ABS('Pc, Original'!$D130:$AA130))} -> 0.4751299 | I35: {='Pc, Original'!I130/MAX(ABS('Pc, Original'!$D130:$AA130))} -> 0.5187313 | J35: {='Pc, Original'!J130/MAX(ABS('Pc, Original'!$D130:$AA130))} -> 0.78091952 | K35: {='Pc, Original'!K130/MAX(ABS('Pc, Original'!$D130:$AA130))} -> 1 | ... AA35: {='Pc, Original'!AA130/MAX(ABS('Pc, Original'!$D130:$AA130))} -> 0.56528004
A36: 3 | B36: Autumn | C36: 2 | D36: {='Pc, Original'!D144/MAX(ABS('Pc, Original'!$D144:$AA144))} -> 0.73891579 | E36: {='Pc, Original'!E144/MAX(ABS('Pc, Original'!$D144:$AA144))} -> 0.69571152 | F36: {='Pc, Original'!F144/MAX(ABS('Pc, Original'!$D144:$AA144))} -> 0.62771872 | G36: {='Pc, Original'!G144/MAX(ABS('Pc, Original'!$D144:$AA144))} -> 0.63460628 | H36: {='Pc, Original'!H144/MAX(ABS('Pc, Original'!$D144:$AA144))} -> 0.62926645 | I36: {='Pc, Original'!I144/MAX(ABS('Pc, Original'!$D144:$AA144))} -> 0.6403357 | J36: {='Pc, Original'!J144/MAX(ABS('Pc, Original'!$D144:$AA144))} -> 0.73207469 | K36: {='Pc, Original'!K144/MAX(ABS('Pc, Original'!$D144:$AA144))} -> 0.83909366 | ... AA36: {='Pc, Original'!AA144/MAX(ABS('Pc, Original'!$D144:$AA144))} -> 0.70923368
A37: 3 | B37: Autumn | C37: 3 | D37: {='Pc, Original'!D158/MAX(ABS('Pc, Original'!$D158:$AA158))} -> 0.69532592 | E37: {='Pc, Original'!E158/MAX(ABS('Pc, Original'!$D158:$AA158))} -> 0.66124418 | F37: {='Pc, Original'!F158/MAX(ABS('Pc, Original'!$D158:$AA158))} -> 0.63227237 | G37: {='Pc, Original'!G158/MAX(ABS('Pc, Original'!$D158:$AA158))} -> 0.62554261 | H37: {='Pc, Original'!H158/MAX(ABS('Pc, Original'!$D158:$AA158))} -> 0.6149725 | I37: {='Pc, Original'!I158/MAX(ABS('Pc, Original'!$D158:$AA158))} -> 0.61811608 | J37: {='Pc, Original'!J158/MAX(ABS('Pc, Original'!$D158:$AA158))} -> 0.64820327 | K37: {='Pc, Original'!K158/MAX(ABS('Pc, Original'!$D158:$AA158))} -> 0.69959456 | ... AA37: {='Pc, Original'!AA158/MAX(ABS('Pc, Original'!$D158:$AA158))} -> 0.73849477
A38: 4 | B38: Winter | C38: 1 | D38: {='Pc, Original'!D5/MAX(ABS('Pc, Original'!$D5:$AA5))} -> 0.19849683 | E38: {='Pc, Original'!E5/MAX(ABS('Pc, Original'!$D5:$AA5))} -> 0.12896367 | F38: {='Pc, Original'!F5/MAX(ABS('Pc, Original'!$D5:$AA5))} -> 0.12902459 | G38: {='Pc, Original'!G5/MAX(ABS('Pc, Original'!$D5:$AA5))} -> 0.11494221 | H38: {='Pc, Original'!H5/MAX(ABS('Pc, Original'!$D5:$AA5))} -> 0.12105706 | I38: {='Pc, Original'!I5/MAX(ABS('Pc, Original'!$D5:$AA5))} -> 0.24701545 | J38: {='Pc, Original'!J5/MAX(ABS('Pc, Original'!$D5:$AA5))} -> 0.49532251 | K38: {='Pc, Original'!K5/MAX(ABS('Pc, Original'!$D5:$AA5))} -> 0.61657518 | ... AA38: {='Pc, Original'!AA5/MAX(ABS('Pc, Original'!$D5:$AA5))} -> 0.38095001
A39: 4 | B39: Winter | C39: 2 | D39: {='Pc, Original'!D19/MAX(ABS('Pc, Original'!$D19:$AA19))} -> 0.25468023 | E39: {='Pc, Original'!E19/MAX(ABS('Pc, Original'!$D19:$AA19))} -> 0.17359671 | F39: {='Pc, Original'!F19/MAX(ABS('Pc, Original'!$D19:$AA19))} -> 0.14984456 | G39: {='Pc, Original'!G19/MAX(ABS('Pc, Original'!$D19:$AA19))} -> 0.13969224 | H39: {='Pc, Original'!H19/MAX(ABS('Pc, Original'!$D19:$AA19))} -> 0.13869952 | I39: {='Pc, Original'!I19/MAX(ABS('Pc, Original'!$D19:$AA19))} -> 0.2226528 | J39: {='Pc, Original'!J19/MAX(ABS('Pc, Original'!$D19:$AA19))} -> 0.40766069 | K39: {='Pc, Original'!K19/MAX(ABS('Pc, Original'!$D19:$AA19))} -> 0.51112471 | ... AA39: {='Pc, Original'!AA19/MAX(ABS('Pc, Original'!$D19:$AA19))} -> 0.41071089
A40: 4 | B40: Winter | C40: 3 | D40: {='Pc, Original'!D33/MAX(ABS('Pc, Original'!$D33:$AA33))} -> 0.40266183 | E40: {='Pc, Original'!E33/MAX(ABS('Pc, Original'!$D33:$AA33))} -> 0.26334861 | F40: {='Pc, Original'!F33/MAX(ABS('Pc, Original'!$D33:$AA33))} -> 0.25000784 | G40: {='Pc, Original'!G33/MAX(ABS('Pc, Original'!$D33:$AA33))} -> 0.21907582 | H40: {='Pc, Original'!H33/MAX(ABS('Pc, Original'!$D33:$AA33))} -> 0.086796434 | I40: {='Pc, Original'!I33/MAX(ABS('Pc, Original'!$D33:$AA33))} -> 0.17858954 | J40: {='Pc, Original'!J33/MAX(ABS('Pc, Original'!$D33:$AA33))} -> 0.33519326 | K40: {='Pc, Original'!K33/MAX(ABS('Pc, Original'!$D33:$AA33))} -> 0.45492153 | ... AA40: {='Pc, Original'!AA33/MAX(ABS('Pc, Original'!$D33:$AA33))} -> 0.3465528
...

Sheet Pc2
A1: LoadID | B1: Season | C1: Scenario | D1: 0 | E1: 1 | F1: 2 | G1: 3 | H1: 4 | I1: 5 | J1: 6 | K1: 7 | L1: 8 | M1: 9 | N1: 10 | O1: 11 | P1: 12 | Q1: 13 | R1: 14 | S1: 15 | T1: 16 | U1: 17 | V1: 18 | W1: 19 | X1: 20 | Y1: 21 | Z1: 22 | AA1: 23
A2: 1 | B2: Winter | C2: 1 | D2: 0.99004291 | E2: 0.95485789 | F2: 0.92380609 | G2: 0.93519198 | H2: 0.91134295 | I2: 0.90584499 | J2: 0.86696831 | K2: 0.93239112 | L2: 0.9477077 | M2: 0.91824517 | N2: 0.91700555 | O2: 0.90910636 | P2: 0.92872965 | Q2: 0.89793275 | R2: 0.88695536 | S2: 0.90053541 | T2: 0.91800172 | U2: 0.90732778 | V2: 0.90752341 | W2: 0.87905027 | X2: 0.87532605 | Y2: 0.86167739 | Z2: 0.84920154 | AA2: 0.87046182
A3: 1 | B3: Winter | C3: 2 | D3: 1 | E3: 0.94829699 | F3: 0.91457089 | G3: 0.92757695 | H3: 0.91252175 | I3: 0.88618305 | J3: 0.81212108 | K3: 0.87392989 | L3: 0.89541541 | M3: 0.87750836 | N3: 0.86380314 | O3: 0.87609296 | P3: 0.87442863 | Q3: 0.8440194 | R3: 0.81626193 | S3: 0.82223563 | T3: 0.83754337 | U3: 0.81529139 | V3: 0.8228756 | W3: 0.81230281 | X3: 0.80178695 | Y3: 0.79055216 | Z3: 0.77405496 | AA3: 0.79994105
A4: 1 | B4: Winter | C4: 3 | D4: 0.98008583 | E4: 0.96141879 | F4: 0.9330413 | G4: 0.94280702 | H4: 0.91016414 | I4: 0.92550694 | J4: 0.92181555 | K4: 0.99085234 | L4: 1 | M4: 0.95898199 | N4: 0.97020795 | O4: 0.94211975 | P4: 0.98303067 | Q4: 0.9518461 | R4: 0.9576488 | S4: 0.97883518 | T4: 0.99846007 | U4: 0.99936416 | V4: 0.99217122 | W4: 0.94579774 | X4: 0.94886516 | Y4: 0.93280263 | Z4: 0.92434812 | AA4: 0.94098259
A5: 1 | B5: Spring | C5: 1 | D5: 0.78562204 | E5: 0.78783004 | F5: 0.75295167 | G5: 0.75996565 | H5: 0.7787142 | I5: 0.78473197 | J5: 0.76628383 | K5: 0.9084596 | L5: 0.99176387 | M5: 0.95526779 | N5: 0.98120796 | O5: 0.98536832 | P5: 1 | Q5: 0.96369175 | R5: 0.87054406 | S5: 0.92057287 | T5: 0.96935827 | U5: 0.92913006 | V5: 0.87634941 | W5: 0.85180972 | X5: 0.86280104 | Y5: 0.83487143 | Z5: 0.73815252 | AA5: 0.75054032
A6: 1 | B6: Spring | C6: 2 | D6: 0.83892224 | E6: 0.83067509 | F6: 0.81986824 | G6: 0.81185081 | H6: 0.81385034 | I6: 0.82856339 | J6: 0.80344982 | K6: 0.88783168 | L6: 0.93953607 | M6: 0.92707919 | N6: 0.94316549 | O6: 0.95130272 | P6: 0.9712479 | Q6: 0.93909511 | R6: 0.89803169 | S6: 0.94399465 | T6: 0.98467914 | U6: 0.95304222 | V6: 0.89982395 | W6: 0.87502816 | X6: 0.87643894 | Y6: 0.85664198 | Z6: 0.79669884 | AA6: 0.84036942
A7: 1 | B7: Spring | C7: 3 | D7: 0.89222244 | E7: 0.87352014 | F7: 0.8867848 | G7: 0.86373597 | H7: 0.84898648 | I7: 0.87239482 | J7: 0.84061581 | K7: 0.86720376 | L7: 0.88730827 | M7: 0.89889059 | N7: 0.90512303 | O7: 0.91723711 | P7: 0.94249581 | Q7: 0.91449847 | R7: 0.92551933 | S7: 0.96741644 | T7: 1 | U7: 0.97695439 | V7: 0.92329849 | W7: 0.8982466 | X7: 0.89007685 | Y7: 0.87841254 | Z7: 0.85524517 | AA7: 0.93019853
A8: 1 | B8: Summer | C8: 1 | D8: 0.79737138 | E8: 0.7891799 | F8: 0.76060174 | G8: 0.74671229 | H8: 0.74176372 | I8: 0.75238782 | J8: 0.74622783 | K8: 0.9121625 | L8: 0.98141743 | M8: 0.96866649 | N8: 0.9525864 | O8: 0.96429838 | P8: 1 | Q8: 0.98081933 | R8: 0.90490472 | S8: 0.93278525 | T8: 0.94351544 | U8: 0.91226951 | V8: 0.8659863 | W8: 0.85509977 | X8: 0.85250754 | Y8: 0.84290007 | Z8: 0.77896783 | AA8: 0.75321016
A9: 1 | B9: Summer | C9: 2 | D9: 0.84229427 | E9: 0.81764669 | F9: 0.79078157 | G9: 0.78559049 | H9: 0.77948323 | I9: 0.78586423 | J9: 0.7810093 | K9: 0.87729499 | L9: 0.9328569 | M9: 0.95904899 | N9: 0.9493588 | O9: 0.95016476 | P9: 0.96098533 | Q9: 0.96090792 | R9: 0.91847438 | S9: 0.94117383 | T9: 0.97175772 | U9: 0.93178413 | V9: 0.90419646 | W9: 0.90595116 | X9: 0.91331764 | Y9: 0.87631817 | Z9: 0.83166218 | AA9: 0.80977281
A10: 1 | B10: Summer | C10: 3 | D10: 0.88721716 | E10: 0.84611348 | F10: 0.8209614 | G10: 0.82446869 | H10: 0.81720275 | I10: 0.81934064 | J10: 0.81579076 | K10: 0.84242748 | L10: 0.88429638 | M10: 0.9494315 | N10: 0.9461312 | O10: 0.93603113 | P10: 0.92197066 | Q10: 0.9409965 | R10: 0.93204404 | S10: 0.9495624 | T10: 1 | U10: 0.95129875 | V10: 0.94240663 | W10: 0.95680254 | X10: 0.97412775 | Y10: 0.90973626 | Z10: 0.88435654 | AA10: 0.86633546
A11: 1 | B11: Autumn | C11: 1 | D11: 0.99085267 | E11: 0.99888285 | F11: 0.95393752 | G11: 0.98119581 | H11: 0.93790569 | I11: 0.95488463 | J11: 0.90201318 | K11: 0.90966178 | L11: 0.89486028 | M11: 0.79617434 | N11: 0.78619253 | O11: 0.77672309 | P11: 0.8461639 | Q11: 0.80400742 | R11: 0.85695013 | S11: 0.89922467 | T11: 0.91137089 | U11: 0.88544809 | V11: 0.88687295 | W11: 0.88841892 | X11: 0.88992029 | Y11: 0.84578878 | Z11: 0.85949522 | AA11: 0.86468323
A12: 1 | B12: Autumn | C12: 2 | D12: 0.99225839 | E12: 1 | F12: 0.9556947 | G12: 0.97238158 | H12: 0.92810023 | I12: 0.90976925 | J12: 0.86244287 | K12: 0.85260084 | L12: 0.89948238 | M12: 0.87123003 | N12: 0.88289446 | O12: 0.86116483 | P12: 0.89853493 | Q12: 0.86491655 | R12: 0.91038019 | S12: 0.87517637 | T12: 0.86809644 | U12: 0.83369119 | V12: 0.8464066 | W12: 0.82132391 | X12: 0.85526979 | Y12: 0.79190718 | Z12: 0.83628227 | AA12: 0.83657048
A13: 1 | B13: Autumn | C13: 3 | D13: 0.98944695 | E13: 0.99776571 | F13: 0.95218035 | G13: 0.99001004 | H13: 0.94771115 | I13: 1 | J13: 0.9415835 | K13: 0.96672272 | L13: 0.89023818 | M13: 0.72111866 | N13: 0.6894906 | O13: 0.69228134 | P13: 0.79379287 | Q13: 0.74309828 | R13: 0.80352006 | S13: 0.92327297 | T13: 0.95464535 | U13: 0.93720499 | V13: 0.92733929 | W13: 0.95551393 | X13: 0.92457079 | Y13: 0.89967038 | Z13: 0.88270816 | AA13: 0.89279599
... A169: 14 | B169: Autumn | C169: 3 | D169: 0.51932547 | E169: 0.4808909 | F169: 0.47320318 | G169: 0.46439245 | H169: 0.47653368 | I169: 0.52371931 | J169: 0.64998102 | K169: 0.78827856 | L169: 0.83735574 | M169: 0.88342416 | N169: 0.87844511 | O169: 0.89058657 | P169: 0.90381724 | Q169: 0.88936938 | R169: 0.86624082 | S169: 0.84217662 | T169: 0.86201957 | U169: 0.95547303 | V169: 1 | W169: 0.97486284 | X169: 0.89749 | Y169: 0.8010915 | Z169: 0.7156427 | AA169: 0.63558582

Sheet Qc
A1: LoadID | B1: Season | C1: Scenario | D1: 0 | E1: 1 | F1: 2 | G1: 3 | H1: 4 | I1: 5 | J1: 6 | K1: 7 | L1: 8 | M1: 9 | N1: 10 | O1: 11 | P1: 12 | Q1: 13 | R1: 14 | S1: 15 | T1: 16 | U1: 17 | V1: 18 | W1: 19 | X1: 20 | Y1: 21 | Z1: 22 | AA1: 23
A2: 1 | B2: Winter | C2: 1 | D2: {='Qc, Original'!D2/MAX(ABS('Qc, Original'!$D2:$AA2))} -> 0.59505083 | E2: {='Qc, Original'!E2/MAX(ABS('Qc, Original'!$D2:$AA2))} -> 0.42041346 | F2: {='Qc, Original'!F2/MAX(ABS('Qc, Original'!$D2:$AA2))} -> 0.3644532 | G2: {='Qc, Original'!G2/MAX(ABS('Qc, Original'!$D2:$AA2))} -> 0.46716578 | H2: {='Qc, Original'!H2/MAX(ABS('Qc, Original'!$D2:$AA2))} -> 0.40224353 | I2: {='Qc, Original'!I2/MAX(ABS('Qc, Original'!$D2:$AA2))} -> 0.33071283 | J2: {='Qc, Original'!J2/MAX(ABS('Qc, Original'!$D2:$AA2))} -> 0.27363132 | K2: {='Qc, Original'!K2/MAX(ABS('Qc, Original'!$D2:$AA2))} -> 0.95621405 | ... AA2: {='Qc, Original'!AA2/MAX(ABS('Qc, Original'!$D2:$AA2))} -> 0.29990045
A3: 1 | B3: Winter | C3: 2 | D3: {='Qc, Original'!D16/MAX(ABS('Qc, Original'!$D16:$AA16))} -> 1 | E3: {='Qc, Original'!E16/MAX(ABS('Qc, Original'!$D16:$AA16))} -> 0.67739174 | F3: {='Qc, Original'!F16/MAX(ABS('Qc, Original'!$D16:$AA16))} -> 0.56805464 | G3: {='Qc, Original'!G16/MAX(ABS('Qc, Original'!$D16:$AA16))} -> 0.53857764 | H3: {='Qc, Original'!H16/MAX(ABS('Qc, Original'!$D16:$AA16))} -> 0.59857411 | I3: {='Qc, Original'!I16/MAX(ABS('Qc, Original'!$D16:$AA16))} -> 0.32097491 | J3: {='Qc, Original'!J16/MAX(ABS('Qc, Original'!$D16:$AA16))} -> 0.13777161 | K3: {='Qc, Original'!K16/MAX(ABS('Qc, Original'!$D16:$AA16))} -> 0.42327599 | ... AA3: {='Qc, Original'!AA16/MAX(ABS('Qc, Original'!$D16:$AA16))} -> 0.48888959
A4: 1 | B4: Winter | C4: 3 | D4: {='Qc, Original'!D30/MAX(ABS('Qc, Original'!$D30:$AA30))} -> 0.97547591 | E4: {='Qc, Original'!E30/MAX(ABS('Qc, Original'!$D30:$AA30))} -> 1 | F4: {='Qc, Original'!F30/MAX(ABS('Qc, Original'!$D30:$AA30))} -> 0.74003707 | G4: {='Qc, Original'!G30/MAX(ABS('Qc, Original'!$D30:$AA30))} -> 0.56209922 | H4: {='Qc, Original'!H30/MAX(ABS('Qc, Original'!$D30:$AA30))} -> 0.6408729 | I4: {='Qc, Original'!I30/MAX(ABS('Qc, Original'!$D30:$AA30))} -> 0.62549913 | J4: {='Qc, Original'!J30/MAX(ABS('Qc, Original'!$D30:$AA30))} -> 0.48518363 | K4: {='Qc, Original'!K30/MAX(ABS('Qc, Original'!$D30:$AA30))} -> 0.52429159 | ... AA4: {='Qc, Original'!AA30/MAX(ABS('Qc, Original'!$D30:$AA30))} -> 0.82062233
A5: 1 | B5: Spring | C5: 1 | D5: {='Qc, Original'!D44/MAX(ABS('Qc, Original'!$D44:$AA44))} -> 0.44830857 | E5: {='Qc, Original'!E44/MAX(ABS('Qc, Original'!$D44:$AA44))} -> 0.40994863 | F5: {='Qc, Original'!F44/MAX(ABS('Qc, Original'!$D44:$AA44))} -> 0.40976361 | G5: {='Qc, Original'!G44/MAX(ABS('Qc, Original'!$D44:$AA44))} -> 0.37913423 | H5: {='Qc, Original'!H44/MAX(ABS('Qc, Original'!$D44:$AA44))} -> 0.38703269 | I5: {='Qc, Original'!I44/MAX(ABS('Qc, Original'!$D44:$AA44))} -> 0.4146225 | J5: {='Qc, Original'!J44/MAX(ABS('Qc, Original'!$D44:$AA44))} -> 0.44274678 | K5: {='Qc, Original'!K44/MAX(ABS('Qc, Original'!$D44:$AA44))} -> 0.73478243 | ... AA5: {='Qc, Original'!AA44/MAX(ABS('Qc, Original'!$D44:$AA44))} -> 0.36120143
A6: 1 | B6: Spring | C6: 2 | D6: {='Qc, Original'!D58/MAX(ABS('Qc, Original'!$D58:$AA58))} -> 0.7701522 | E6: {='Qc, Original'!E58/MAX(ABS('Qc, Original'!$D58:$AA58))} -> 0.78259648 | F6: {='Qc, Original'!F58/MAX(ABS('Qc, Original'!$D58:$AA58))} -> 0.84818651 | G6: {='Qc, Original'!G58/MAX(ABS('Qc, Original'!$D58:$AA58))} -> 0.9332284 | H6: {='Qc, Original'!H58/MAX(ABS('Qc, Original'!$D58:$AA58))} -> 0.74541139 | I6: {='Qc, Original'!I58/MAX(ABS('Qc, Original'!$D58:$AA58))} -> 0.67947202 | J6: {='Qc, Original'!J58/MAX(ABS('Qc, Original'!$D58:$AA58))} -> 0.38215304 | K6: {='Qc, Original'!K58/MAX(ABS('Qc, Original'!$D58:$AA58))} -> 0.81897937 | ... AA6: {='Qc, Original'!AA58/MAX(ABS('Qc, Original'!$D58:$AA58))} -> 0.44239601
A7: 1 | B7: Spring | C7: 3 | D7: {='Qc, Original'!D72/MAX(ABS('Qc, Original'!$D72:$AA72))} -> 0.58009688 | E7: {='Qc, Original'!E72/MAX(ABS('Qc, Original'!$D72:$AA72))} -> 0.57476864 | F7: {='Qc, Original'!F72/MAX(ABS('Qc, Original'!$D72:$AA72))} -> 0.61226291 | G7: {='Qc, Original'!G72/MAX(ABS('Qc, Original'!$D72:$AA72))} -> 0.532992 | H7: {='Qc, Original'!H72/MAX(ABS('Qc, Original'!$D72:$AA72))} -> 0.45060313 | I7: {='Qc, Original'!I72/MAX(ABS('Qc, Original'!$D72:$AA72))} -> 0.52576948 | J7: {='Qc, Original'!J72/MAX(ABS('Qc, Original'!$D72:$AA72))} -> 0.4581218 | K7: {='Qc, Original'!K72/MAX(ABS('Qc, Original'!$D72:$AA72))} -> 0.55685024 | ... AA7: {='Qc, Original'!AA72/MAX(ABS('Qc, Original'!$D72:$AA72))} -> 0.42406102
A8: 1 | B8: Summer | C8: 1 | D8: {='Qc, Original'!D86/MAX(ABS('Qc, Original'!$D86:$AA86))} -> 0.41521008 | E8: {='Qc, Original'!E86/MAX(ABS('Qc, Original'!$D86:$AA86))} -> 0.45516367 | F8: {='Qc, Original'!F86/MAX(ABS('Qc, Original'!$D86:$AA86))} -> 0.4317808 | G8: {='Qc, Original'!G86/MAX(ABS('Qc, Original'!$D86:$AA86))} -> 0.43101732 | H8: {='Qc, Original'!H86/MAX(ABS('Qc, Original'!$D86:$AA86))} -> 0.42243023 | I8: {='Qc, Original'!I86/MAX(ABS('Qc, Original'!$D86:$AA86))} -> 0.44684594 | J8: {='Qc, Original'!J86/MAX(ABS('Qc, Original'!$D86:$AA86))} -> 0.45818075 | K8: {='Qc, Original'!K86/MAX(ABS('Qc, Original'!$D86:$AA86))} -> 0.8595822 | ... AA8: {='Qc, Original'!AA86/MAX(ABS('Qc, Original'!$D86:$AA86))} -> 0.43505192
A9: 1 | B9: Summer | C9: 2 | D9: {='Qc, Original'!D100/MAX(ABS('Qc, Original'!$D100:$AA100))} -> 0.91777872 | E9: {='Qc, Original'!E100/MAX(ABS('Qc, Original'!$D100:$AA100))} -> 0.96511038 | F9: {='Qc, Original'!F100/MAX(ABS('Qc, Original'!$D100:$AA100))} -> 1 | G9: {='Qc, Original'!G100/MAX(ABS('Qc, Original'!$D100:$AA100))} -> 0.85463419 | H9: {='Qc, Original'!H100/MAX(ABS('Qc, Original'!$D100:$AA100))} -> 0.72452774 | I9: {='Qc, Original'!I100/MAX(ABS('Qc, Original'!$D100:$AA100))} -> 0.77348127 | J9: {='Qc, Original'!J100/MAX(ABS('Qc, Original'!$D100:$AA100))} -> 0.51728716 | K9: {='Qc, Original'!K100/MAX(ABS('Qc, Original'!$D100:$AA100))} -> 0.41869702 | ... AA9: {='Qc, Original'!AA100/MAX(ABS('Qc, Original'!$D100:$AA100))} -> 0.48488057
A10: 1 | B10: Summer | C10: 3 | D10: {='Qc, Original'!D114/MAX(ABS('Qc, Original'!$D114:$AA114))} -> 0.39020797 | E10: {='Qc, Original'!E114/MAX(ABS('Qc, Original'!$D114:$AA114))} -> 0.35403736 | F10: {='Qc, Original'!F114/MAX(ABS('Qc, Original'!$D114:$AA114))} -> 0.26844766 | G10: {='Qc, Original'!G114/MAX(ABS('Qc, Original'!$D114:$AA114))} -> 0.27896497 | H10: {='Qc, Original'!H114/MAX(ABS('Qc, Original'!$D114:$AA114))} -> 0.36008013 | I10: {='Qc, Original'!I114/MAX(ABS('Qc, Original'!$D114:$AA114))} -> 0.36926083 | J10: {='Qc, Original'!J114/MAX(ABS('Qc, Original'!$D114:$AA114))} -> 0.29203863 | K10: {='Qc, Original'!K114/MAX(ABS('Qc, Original'!$D114:$AA114))} -> 0.38227677 | ... AA10: {='Qc, Original'!AA114/MAX(ABS('Qc, Original'!$D114:$AA114))} -> 0.47736651
A11: 1 | B11: Autumn | C11: 1 | D11: {='Qc, Original'!D128/MAX(ABS('Qc, Original'!$D128:$AA128))} -> 0.058755511 | E11: {='Qc, Original'!E128/MAX(ABS('Qc, Original'!$D128:$AA128))} -> 0.065859926 | F11: {='Qc, Original'!F128/MAX(ABS('Qc, Original'!$D128:$AA128))} -> -0.00016976811 | G11: {='Qc, Original'!G128/MAX(ABS('Qc, Original'!$D128:$AA128))} -> 0.03528724 | H11: {='Qc, Original'!H128/MAX(ABS('Qc, Original'!$D128:$AA128))} -> 0.041085742 | I11: {='Qc, Original'!I128/MAX(ABS('Qc, Original'!$D128:$AA128))} -> 0.073290938 | J11: {='Qc, Original'!J128/MAX(ABS('Qc, Original'!$D128:$AA128))} -> 0.044559653 | K11: {='Qc, Original'!K128/MAX(ABS('Qc, Original'!$D128:$AA128))} -> 0.66567571 | ... AA11: {='Qc, Original'!AA128/MAX(ABS('Qc, Original'!$D128:$AA128))} -> 0.085786378
A12: 1 | B12: Autumn | C12: 2 | D12: {='Qc, Original'!D142/MAX(ABS('Qc, Original'!$D142:$AA142))} -> 1 | E12: {='Qc, Original'!E142/MAX(ABS('Qc, Original'!$D142:$AA142))} -> 0.73461794 | F12: {='Qc, Original'!F142/MAX(ABS('Qc, Original'!$D142:$AA142))} -> 0.94547553 | G12: {='Qc, Original'!G142/MAX(ABS('Qc, Original'!$D142:$AA142))} -> 0.36590752 | H12: {='Qc, Original'!H142/MAX(ABS('Qc, Original'!$D142:$AA142))} -> 0.56275543 | I12: {='Qc, Original'!I142/MAX(ABS('Qc, Original'!$D142:$AA142))} -> -0.0060710941 | J12: {='Qc, Original'!J142/MAX(ABS('Qc, Original'!$D142:$AA142))} -> 0.067017473 | K12: {='Qc, Original'!K142/MAX(ABS('Qc, Original'!$D142:$AA142))} -> 0.31115003 | ... AA12: {='Qc, Original'!AA142/MAX(ABS('Qc, Original'!$D142:$AA142))} -> 0.14197308
A13: 1 | B13: Autumn | C13: 3 | D13: {='Qc, Original'!D156/MAX(ABS('Qc, Original'!$D156:$AA156))} -> -0.19317648 | E13: {='Qc, Original'!E156/MAX(ABS('Qc, Original'!$D156:$AA156))} -> 0.094855555 | F13: {='Qc, Original'!F156/MAX(ABS('Qc, Original'!$D156:$AA156))} -> 0.069565917 | G13: {='Qc, Original'!G156/MAX(ABS('Qc, Original'!$D156:$AA156))} -> 0.21602448 | H13: {='Qc, Original'!H156/MAX(ABS('Qc, Original'!$D156:$AA156))} -> 0.55180121 | I13: {='Qc, Original'!I156/MAX(ABS('Qc, Original'!$D156:$AA156))} -> -0.30110984 | J13: {='Qc, Original'!J156/MAX(ABS('Qc, Original'!$D156:$AA156))} -> 0.64295295 | K13: {='Qc, Original'!K156/MAX(ABS('Qc, Original'!$D156:$AA156))} -> -0.11967195 | ... AA13: {='Qc, Original'!AA156/MAX(ABS('Qc, Original'!$D156:$AA156))} -> 0.27227597
A14: 2 | B14: Winter | C14: 1 | D14: {='Qc, Original'!D3/MAX(ABS('Qc, Original'!$D3:$AA3))} -> -0.93072593 | E14: {='Qc, Original'!E3/MAX(ABS('Qc, Original'!$D3:$AA3))} -> -0.93052073 | F14: {='Qc, Original'!F3/MAX(ABS('Qc, Original'!$D3:$AA3))} -> -0.95619658 | G14: {='Qc, Original'!G3/MAX(ABS('Qc, Original'!$D3:$AA3))} -> -1 | H14: {='Qc, Original'!H3/MAX(ABS('Qc, Original'!$D3:$AA3))} -> -0.99039687 | I14: {='Qc, Original'!I3/MAX(ABS('Qc, Original'!$D3:$AA3))} -> -0.90895283 | J14: {='Qc, Original'!J3/MAX(ABS('Qc, Original'!$D3:$AA3))} -> -0.57634762 | K14: {='Qc, Original'!K3/MAX(ABS('Qc, Original'!$D3:$AA3))} -> -0.11079055 | ... AA14: {='Qc, Original'!AA3/MAX(ABS('Qc, Original'!$D3:$AA3))} -> -0.78042015
