Workbook

Sheet Main
A1: numScenarios | B1: 9 | C1: =1/$B$1 -> 0.11111111 | D1: =1/$B$1 -> 0.11111111 | E1: =1/$B$1 -> 0.11111111 | F1: =1/$B$1 -> 0.11111111 | G1: =1/$B$1 -> 0.11111111 | H1: =1/$B$1 -> 0.11111111 | I1: =1/$B$1 -> 0.11111111 | J1: =1/$B$1 -> 0.11111111 | K1: =1/$B$1 -> 0.11111111
A3: Year | B3: 2035
A4: Load Scale Factor | B4: 1
A5: Load Growth (cumul.) | B5: =((1+[1]Main!$B$2)^($B$3-2020))*$B$4 -> 1.2502321
A6: Flex. Load Growth | B6: =((1+[1]Main!$B$3)^($B$3-2020))*$B$4 -> 1.0776827
A7: RES Installed, [MW] | B7: =SUM('RES installed'!$C$2:$C$7) -> 35
A8: ESS Installed, [MWh] | B8: =SUM('ES installed'!$C$2:$C$4) -> 0

Sheet RES installed
A1: GenID | B1: NodeID | C1: Pinst, [MW]
A2: 2 | B2: 22 | C2: 5
A3: 3 | B3: N/A | C3: 0
A4: 4 | B4: N/A | C4: 0
A5: 5 | B5: 25 | C5: 10
A6: 6 | B6: 23 | C6: 10
A7: 7 | B7: 18 | C7: 10

Sheet ES installed
A1: ESS ID | B1: Node ID | C1: Pinst, [MW]
A2: 1 | B2: N/A | C2: 0
A3: 2 | B3: N/A | C3: 0
A4: 3 | B4: N/A | C4: 0

Sheet FL Ratio
A1: LoadID | B1: Ratio, [%]
A2: 1 | B2: 0.0269179
A3: 2 | B3: 0.02422611
A4: 3 | B4: 0.03230148
A5: 4 | B5: 0.01615074
A6: 5 | B6: 0.01615074
A7: 6 | B7: 0.053835801
A8: 7 | B8: 0.053835801
A9: 8 | B9: 0.01615074
A10: 9 | B10: 0.01615074
A11: 10 | B11: 0.012113055
A12: 11 | B12: 0.01615074
A13: 12 | B13: 0.01615074
... A33: 32 | B33: 0.01615074

Sheet FL Characterization
A1: Time | B1: 0 | C1: 1 | D1: 2 | E1: 3 | F1: 4 | G1: 5 | H1: 6 | I1: 7 | J1: 8 | K1: 9 | L1: 10 | M1: 11 | N1: 12 | O1: 13 | P1: 14 | Q1: 15 | R1: 16 | S1: 17 | T1: 18 | U1: 19 | V1: 20 | W1: 21 | X1: 22 | Y1: 23
A2: FL, [MW] | B2: ='[1]EV Profiles'!B2*Main!$B$6 -> 1.0596639 | C2: ='[1]EV Profiles'!C2*Main!$B$6 -> 1.0950119 | D2: ='[1]EV Profiles'!D2*Main!$B$6 -> 0.98051886 | E2: ='[1]EV Profiles'!E2*Main!$B$6 -> 0.92939359 | F2: ='[1]EV Profiles'!F2*Main!$B$6 -> 0.76144752 | G2: ='[1]EV Profiles'!G2*Main!$B$6 -> 0.64626478 | H2: ='[1]EV Profiles'!H2*Main!$B$6 -> 0.79032941 | I2: ='[1]EV Profiles'!I2*Main!$B$6 -> 0.13725367 | ... Y2: ='[1]EV Profiles'!Y2*Main!$B$6 -> 0.97103525
A3: Minimum FL, [MW] | B3: ='[1]EV Profiles'!B3*Main!$B$6 -> -2.3924557 | C3: ='[1]EV Profiles'!C3*Main!$B$6 -> -2.5583326 | D3: ='[1]EV Profiles'!D3*Main!$B$6 -> -2.8773267 | E3: ='[1]EV Profiles'!E3*Main!$B$6 -> -3.1038125 | F3: ='[1]EV Profiles'!F3*Main!$B$6 -> -3.3175385 | G3: ='[1]EV Profiles'!G3*Main!$B$6 -> -3.6205829 | H3: ='[1]EV Profiles'!H3*Main!$B$6 -> -3.454706 | I3: ='[1]EV Profiles'!I3*Main!$B$6 -> -3.8752954 | ... Y3: ='[1]EV Profiles'!Y3*Main!$B$6 -> -2.1117409
A4: Maximum FL, [MW] | B4: ='[1]EV Profiles'!B4*Main!$B$6 -> 2.304853 | C4: ='[1]EV Profiles'!C4*Main!$B$6 -> 2.4658071 | D4: ='[1]EV Profiles'!D4*Main!$B$6 -> 2.764739 | E4: ='[1]EV Profiles'!E4*Main!$B$6 -> 2.9749303 | F4: ='[1]EV Profiles'!F4*Main!$B$6 -> 3.1665336 | G4: ='[1]EV Profiles'!G4*Main!$B$6 -> 3.4576373 | H4: ='[1]EV Profiles'!H4*Main!$B$6 -> 3.296416 | I4: ='[1]EV Profiles'!I4*Main!$B$6 -> 3.7199798 | ... Y4: ='[1]EV Profiles'!Y4*Main!$B$6 -> 2.0356996

Sheet Pc, Winter, S1
A1: LoadID | B1: 0 | C1: 1 | D1: 2 | E1: 3 | F1: 4 | G1: 5 | H1: 6 | I1: 7 | J1: 8 | K1: 9 | L1: 10 | M1: 11 | N1: 12 | O1: 13 | P1: 14 | Q1: 15 | R1: 16 | S1: 17 | T1: 18 | U1: 19 | V1: 20 | W1: 21 | X1: 22 | Y1: 23
A2: 1 | B2: =('[1]Pc, Winter, S1'!B2*Main!$B$5)+(_xlfn.IFNA(VLOOKUP($A2,'FL Ratio'!$A$3:$B$44,2,FALSE),0)*'FL Characterization'!B$2) -> 1.2613173 | C2: =('[1]Pc, Winter, S1'!C2*Main!$B$5)+(_xlfn.IFNA(VLOOKUP($A2,'FL Ratio'!$A$3:$B$44,2,FALSE),0)*'FL Characterization'!C$2) -> 1.2141805 | D2: =('[1]Pc, Winter, S1'!D2*Main!$B$5)+(_xlfn.IFNA(VLOOKUP($A2,'FL Ratio'!$A$3:$B$44,2,FALSE),0)*'FL Characterization'!D$2) -> 1.1709325 | E2: =('[1]Pc, Winter, S1'!E2*Main!$B$5)+(_xlfn.IFNA(VLOOKUP($A2,'FL Ratio'!$A$3:$B$44,2,FALSE),0)*'FL Characterization'!E$2) -> 1.2062737 | F2: =('[1]Pc, Winter, S1'!F2*Main!$B$5)+(_xlfn.IFNA(VLOOKUP($A2,'FL Ratio'!$A$3:$B$44,2,FALSE),0)*'FL Characterization'!F$2) -> 1.1722353 | G2: =('[1]Pc, Winter, S1'!G2*Main!$B$5)+(_xlfn.IFNA(VLOOKUP($A2,'FL Ratio'!$A$3:$B$44,2,FALSE),0)*'FL Characterization'!G$2) -> 1.1737966 | H2: =('[1]Pc, Winter, S1'!H2*Main!$B$5)+(_xlfn.IFNA(VLOOKUP($A2,'FL Ratio'!$A$3:$B$44,2,FALSE),0)*'FL Characterization'!H$2) -> 1.1846307 | I2: =('[1]Pc, Winter, S1'!I2*Main!$B$5)+(_xlfn.IFNA(VLOOKUP($A2,'FL Ratio'!$A$3:$B$44,2,FALSE),0)*'FL Characterization'!I$2) -> 1.5376466 | ... Y2: =('[1]Pc, Winter, S1'!Y2*Main!$B$5)+(_xlfn.IFNA(VLOOKUP($A2,'FL Ratio'!$A$3:$B$44,2,FALSE),0)*'FL Characterization'!Y$2) -> 1.1674547
A3: 2 | B3: =('[1]Pc, Winter, S1'!B3*Main!$B$5)+(_xlfn.IFNA(VLOOKUP($A3,'FL Ratio'!$A$3:$B$44,2,FALSE),0)*'FL Characterization'!B$2) -> 0.68473241 | C3: =('[1]Pc, Winter, S1'!C3*Main!$B$5)+(_xlfn.IFNA(VLOOKUP($A3,'FL Ratio'!$A$3:$B$44,2,FALSE),0)*'FL Characterization'!C$2) -> 0.66683173 | D3: =('[1]Pc, Winter, S1'!D3*Main!$B$5)+(_xlfn.IFNA(VLOOKUP($A3,'FL Ratio'!$A$3:$B$44,2,FALSE),0)*'FL Characterization'!D$2) -> 0.63686042 | E3: =('[1]Pc, Winter, S1'!E3*Main!$B$5)+(_xlfn.IFNA(VLOOKUP($A3,'FL Ratio'!$A$3:$B$44,2,FALSE),0)*'FL Characterization'!E$2) -> 0.63054521 | F3: =('[1]Pc, Winter, S1'!F3*Main!$B$5)+(_xlfn.IFNA(VLOOKUP($A3,'FL Ratio'!$A$3:$B$44,2,FALSE),0)*'FL Characterization'!F$2) -> 0.63258614 | G3: =('[1]Pc, Winter, S1'!G3*Main!$B$5)+(_xlfn.IFNA(VLOOKUP($A3,'FL Ratio'!$A$3:$B$44,2,FALSE),0)*'FL Characterization'!G$2) -> 0.67138052 | H3: =('[1]Pc, Winter, S1'!H3*Main!$B$5)+(_xlfn.IFNA(VLOOKUP($A3,'FL Ratio'!$A$3:$B$44,2,FALSE),0)*'FL Characterization'!H$2) -> 0.8096561 | I3: =('[1]Pc, Winter, S1'!I3*Main!$B$5)+(_xlfn.IFNA(VLOOKUP($A3,'FL Ratio'!$A$3:$B$44,2,FALSE),0)*'FL Characterization'!I$2) -> 0.92621426 | ... Y3: =('[1]Pc, Winter, S1'!Y3*Main!$B$5)+(_xlfn.IFNA(VLOOKUP($A3,'FL Ratio'!$A$3:$B$44,2,FALSE),0)*'FL Characterization'!Y$2) -> 0.78235088
A4: 3 | B4: =('[1]Pc, Winter, S1'!B4*Main!$B$5)+(_xlfn.IFNA(VLOOKUP($A4,'FL Ratio'!$A$3:$B$44,2,FALSE),0)*'FL Characterization'!B$2) -> 1.5056575 | C4: =('[1]Pc, Winter, S1'!C4*Main!$B$5)+(_xlfn.IFNA(VLOOKUP($A4,'FL Ratio'!$A$3:$B$44,2,FALSE),0)*'FL Characterization'!C$2) -> 1.4188611 | D4: =('[1]Pc, Winter, S1'!D4*Main!$B$5)+(_xlfn.IFNA(VLOOKUP($A4,'FL Ratio'!$A$3:$B$44,2,FALSE),0)*'FL Characterization'!D$2) -> 1.3704428 | E4: =('[1]Pc, Winter, S1'!E4*Main!$B$5)+(_xlfn.IFNA(VLOOKUP($A4,'FL Ratio'!$A$3:$B$44,2,FALSE),0)*'FL Characterization'!E$2) -> 1.3967957 | F4: =('[1]Pc, Winter, S1'!F4*Main!$B$5)+(_xlfn.IFNA(VLOOKUP($A4,'FL Ratio'!$A$3:$B$44,2,FALSE),0)*'FL Characterization'!F$2) -> 1.4042285 | G4: =('[1]Pc, Winter, S1'!G4*Main!$B$5)+(_xlfn.IFNA(VLOOKUP($A4,'FL Ratio'!$A$3:$B$44,2,FALSE),0)*'FL Characterization'!G$2) -> 1.5982913 | H4: =('[1]Pc, Winter, S1'!H4*Main!$B$5)+(_xlfn.IFNA(VLOOKUP($A4,'FL Ratio'!$A$3:$B$44,2,FALSE),0)*'FL Characterization'!H$2) -> 2.5730591 | I4: =('[1]Pc, Winter, S1'!I4*Main!$B$5)+(_xlfn.IFNA(VLOOKUP($A4,'FL Ratio'!$A$3:$B$44,2,FALSE),0)*'FL Characterization'!I$2) -> 2.9913003 | ... Y4: =('[1]Pc, Winter, S1'!Y4*Main!$B$5)+(_xlfn.IFNA(VLOOKUP($A4,'FL Ratio'!$A$3:$B$44,2,FALSE),0)*'FL Characterization'!Y$2) -> 1.7146334
A5: 4 | B5: =('[1]Pc, Winter, S1'!B5*Main!$B$5)+(_xlfn.IFNA(VLOOKUP($A5,'FL Ratio'!$A$3:$B$44,2,FALSE),0)*'FL Characterization'!B$2) -> 0.083441485 | C5: =('[1]Pc, Winter, S1'!C5*Main!$B$5)+(_xlfn.IFNA(VLOOKUP($A5,'FL Ratio'!$A$3:$B$44,2,FALSE),0)*'FL Characterization'!C$2) -> 0.060778081 | D5: =('[1]Pc, Winter, S1'!D5*Main!$B$5)+(_xlfn.IFNA(VLOOKUP($A5,'FL Ratio'!$A$3:$B$44,2,FALSE),0)*'FL Characterization'!D$2) -> 0.058949291 | E5: =('[1]Pc, Winter, S1'!E5*Main!$B$5)+(_xlfn.IFNA(VLOOKUP($A5,'FL Ratio'!$A$3:$B$44,2,FALSE),0)*'FL Characterization'!E$2) -> 0.053417995 | F5: =('[1]Pc, Winter, S1'!F5*Main!$B$5)+(_xlfn.IFNA(VLOOKUP($A5,'FL Ratio'!$A$3:$B$44,2,FALSE),0)*'FL Characterization'!F$2) -> 0.0527488 | G5: =('[1]Pc, Winter, S1'!G5*Main!$B$5)+(_xlfn.IFNA(VLOOKUP($A5,'FL Ratio'!$A$3:$B$44,2,FALSE),0)*'FL Characterization'!G$2) -> 0.092977137 | H5: =('[1]Pc, Winter, S1'!H5*Main!$B$5)+(_xlfn.IFNA(VLOOKUP($A5,'FL Ratio'!$A$3:$B$44,2,FALSE),0)*'FL Characterization'!H$2) -> 0.17827496 | I5: =('[1]Pc, Winter, S1'!I5*Main!$B$5)+(_xlfn.IFNA(VLOOKUP($A5,'FL Ratio'!$A$3:$B$44,2,FALSE),0)*'FL Characterization'!I$2) -> 0.20824353 | ... Y5: =('[1]Pc, Winter, S1'!Y5*Main!$B$5)+(_xlfn.IFNA(VLOOKUP($A5,'FL Ratio'!$A$3:$B$44,2,FALSE),0)*'FL Characterization'!Y$2) -> 0.14297626
A6: 5 | B6: =('[1]Pc, Winter, S1'!B6*Main!$B$5)+(_xlfn.IFNA(VLOOKUP($A6,'FL Ratio'!$A$3:$B$44,2,FALSE),0)*'FL Characterization'!B$2) -> 0.40145888 | C6: =('[1]Pc, Winter, S1'!C6*Main!$B$5)+(_xlfn.IFNA(VLOOKUP($A6,'FL Ratio'!$A$3:$B$44,2,FALSE),0)*'FL Characterization'!C$2) -> 0.3672713 | D6: =('[1]Pc, Winter, S1'!D6*Main!$B$5)+(_xlfn.IFNA(VLOOKUP($A6,'FL Ratio'!$A$3:$B$44,2,FALSE),0)*'FL Characterization'!D$2) -> 0.33619562 | E6: =('[1]Pc, Winter, S1'!E6*Main!$B$5)+(_xlfn.IFNA(VLOOKUP($A6,'FL Ratio'!$A$3:$B$44,2,FALSE),0)*'FL Characterization'!E$2) -> 0.33956445 | F6: =('[1]Pc, Winter, S1'!F6*Main!$B$5)+(_xlfn.IFNA(VLOOKUP($A6,'FL Ratio'!$A$3:$B$44,2,FALSE),0)*'FL Characterization'!F$2) -> 0.34408902 | G6: =('[1]Pc, Winter, S1'!G6*Main!$B$5)+(_xlfn.IFNA(VLOOKUP($A6,'FL Ratio'!$A$3:$B$44,2,FALSE),0)*'FL Characterization'!G$2) -> 0.38424228 | H6: =('[1]Pc, Winter, S1'!H6*Main!$B$5)+(_xlfn.IFNA(VLOOKUP($A6,'FL Ratio'!$A$3:$B$44,2,FALSE),0)*'FL Characterization'!H$2) -> 0.49596683 | I6: =('[1]Pc, Winter, S1'!I6*Main!$B$5)+(_xlfn.IFNA(VLOOKUP($A6,'FL Ratio'!$A$3:$B$44,2,FALSE),0)*'FL Characterization'!I$2) -> 0.53738668 | ... Y6: =('[1]Pc, Winter, S1'!Y6*Main!$B$5)+(_xlfn.IFNA(VLOOKUP($A6,'FL Ratio'!$A$3:$B$44,2,FALSE),0)*'FL Characterization'!Y$2) -> 0.50539268
A7: 6 | B7: =('[1]Pc, Winter, S1'!B7*Main!$B$5)+(_xlfn.IFNA(VLOOKUP($A7,'FL Ratio'!$A$3:$B$44,2,FALSE),0)*'FL Characterization'!B$2) -> 2.8457179 | C7: =('[1]Pc, Winter, S1'!C7*Main!$B$5)+(_xlfn.IFNA(VLOOKUP($A7,'FL Ratio'!$A$3:$B$44,2,FALSE),0)*'FL Characterization'!C$2) -> 2.6810967 | D7: =('[1]Pc, Winter, S1'!D7*Main!$B$5)+(_xlfn.IFNA(VLOOKUP($A7,'FL Ratio'!$A$3:$B$44,2,FALSE),0)*'FL Characterization'!D$2) -> 2.6082787 | E7: =('[1]Pc, Winter, S1'!E7*Main!$B$5)+(_xlfn.IFNA(VLOOKUP($A7,'FL Ratio'!$A$3:$B$44,2,FALSE),0)*'FL Characterization'!E$2) -> 2.6366452 | F7: =('[1]Pc, Winter, S1'!F7*Main!$B$5)+(_xlfn.IFNA(VLOOKUP($A7,'FL Ratio'!$A$3:$B$44,2,FALSE),0)*'FL Characterization'!F$2) -> 2.6559213 | G7: =('[1]Pc, Winter, S1'!G7*Main!$B$5)+(_xlfn.IFNA(VLOOKUP($A7,'FL Ratio'!$A$3:$B$44,2,FALSE),0)*'FL Characterization'!G$2) -> 2.8685645 | H7: =('[1]Pc, Winter, S1'!H7*Main!$B$5)+(_xlfn.IFNA(VLOOKUP($A7,'FL Ratio'!$A$3:$B$44,2,FALSE),0)*'FL Characterization'!H$2) -> 3.2435491 | I7: =('[1]Pc, Winter, S1'!I7*Main!$B$5)+(_xlfn.IFNA(VLOOKUP($A7,'FL Ratio'!$A$3:$B$44,2,FALSE),0)*'FL Characterization'!I$2) -> 3.8890018 | ... Y7: =('[1]Pc, Winter, S1'!Y7*Main!$B$5)+(_xlfn.IFNA(VLOOKUP($A7,'FL Ratio'!$A$3:$B$44,2,FALSE),0)*'FL Characterization'!Y$2) -> 2.991045
A8: 7 | B8: =('[1]Pc, Winter, S1'!B8*Main!$B$5)+(_xlfn.IFNA(VLOOKUP($A8,'FL Ratio'!$A$3:$B$44,2,FALSE),0)*'FL Characterization'!B$2) -> 1.1785864 | C8: =('[1]Pc, Winter, S1'!C8*Main!$B$5)+(_xlfn.IFNA(VLOOKUP($A8,'FL Ratio'!$A$3:$B$44,2,FALSE),0)*'FL Characterization'!C$2) -> 1.0926081 | D8: =('[1]Pc, Winter, S1'!D8*Main!$B$5)+(_xlfn.IFNA(VLOOKUP($A8,'FL Ratio'!$A$3:$B$44,2,FALSE),0)*'FL Characterization'!D$2) -> 1.0777042 | E8: =('[1]Pc, Winter, S1'!E8*Main!$B$5)+(_xlfn.IFNA(VLOOKUP($A8,'FL Ratio'!$A$3:$B$44,2,FALSE),0)*'FL Characterization'!E$2) -> 1.0541574 | F8: =('[1]Pc, Winter, S1'!F8*Main!$B$5)+(_xlfn.IFNA(VLOOKUP($A8,'FL Ratio'!$A$3:$B$44,2,FALSE),0)*'FL Characterization'!F$2) -> 1.0802379 | G8: =('[1]Pc, Winter, S1'!G8*Main!$B$5)+(_xlfn.IFNA(VLOOKUP($A8,'FL Ratio'!$A$3:$B$44,2,FALSE),0)*'FL Characterization'!G$2) -> 1.2292647 | H8: =('[1]Pc, Winter, S1'!H8*Main!$B$5)+(_xlfn.IFNA(VLOOKUP($A8,'FL Ratio'!$A$3:$B$44,2,FALSE),0)*'FL Characterization'!H$2) -> 1.5592714 | I8: =('[1]Pc, Winter, S1'!I8*Main!$B$5)+(_xlfn.IFNA(VLOOKUP($A8,'FL Ratio'!$A$3:$B$44,2,FALSE),0)*'FL Characterization'!I$2) -> 1.8621812 | ... Y8: =('[1]Pc, Winter, S1'!Y8*Main!$B$5)+(_xlfn.IFNA(VLOOKUP($A8,'FL Ratio'!$A$3:$B$44,2,FALSE),0)*'FL Characterization'!Y$2) -> 1.3420995
A9: 8 | B9: =('[1]Pc, Winter, S1'!B9*Main!$B$5)+(_xlfn.IFNA(VLOOKUP($A9,'FL Ratio'!$A$3:$B$44,2,FALSE),0)*'FL Characterization'!B$2) -> 0.24263038 | C9: =('[1]Pc, Winter, S1'!C9*Main!$B$5)+(_xlfn.IFNA(VLOOKUP($A9,'FL Ratio'!$A$3:$B$44,2,FALSE),0)*'FL Characterization'!C$2) -> 0.23132727 | D9: =('[1]Pc, Winter, S1'!D9*Main!$B$5)+(_xlfn.IFNA(VLOOKUP($A9,'FL Ratio'!$A$3:$B$44,2,FALSE),0)*'FL Characterization'!D$2) -> 0.22474155 | E9: =('[1]Pc, Winter, S1'!E9*Main!$B$5)+(_xlfn.IFNA(VLOOKUP($A9,'FL Ratio'!$A$3:$B$44,2,FALSE),0)*'FL Characterization'!E$2) -> 0.22166686 | F9: =('[1]Pc, Winter, S1'!F9*Main!$B$5)+(_xlfn.IFNA(VLOOKUP($A9,'FL Ratio'!$A$3:$B$44,2,FALSE),0)*'FL Characterization'!F$2) -> 0.23124421 | G9: =('[1]Pc, Winter, S1'!G9*Main!$B$5)+(_xlfn.IFNA(VLOOKUP($A9,'FL Ratio'!$A$3:$B$44,2,FALSE),0)*'FL Characterization'!G$2) -> 0.27751271 | H9: =('[1]Pc, Winter, S1'!H9*Main!$B$5)+(_xlfn.IFNA(VLOOKUP($A9,'FL Ratio'!$A$3:$B$44,2,FALSE),0)*'FL Characterization'!H$2) -> 0.45139351 | I9: =('[1]Pc, Winter, S1'!I9*Main!$B$5)+(_xlfn.IFNA(VLOOKUP($A9,'FL Ratio'!$A$3:$B$44,2,FALSE),0)*'FL Characterization'!I$2) -> 0.52982963 | ... Y9: =('[1]Pc, Winter, S1'!Y9*Main!$B$5)+(_xlfn.IFNA(VLOOKUP($A9,'FL Ratio'!$A$3:$B$44,2,FALSE),0)*'FL Characterization'!Y$2) -> 0.28557101
A10: 9 | B10: =('[1]Pc, Winter, S1'!B10*Main!$B$5)+(_xlfn.IFNA(VLOOKUP($A10,'FL Ratio'!$A$3:$B$44,2,FALSE),0)*'FL Characterization'!B$2) -> 0.2613613 | C10: =('[1]Pc, Winter, S1'!C10*Main!$B$5)+(_xlfn.IFNA(VLOOKUP($A10,'FL Ratio'!$A$3:$B$44,2,FALSE),0)*'FL Characterization'!C$2) -> 0.26193219 | D10: =('[1]Pc, Winter, S1'!D10*Main!$B$5)+(_xlfn.IFNA(VLOOKUP($A10,'FL Ratio'!$A$3:$B$44,2,FALSE),0)*'FL Characterization'!D$2) -> 0.26008304 | E10: =('[1]Pc, Winter, S1'!E10*Main!$B$5)+(_xlfn.IFNA(VLOOKUP($A10,'FL Ratio'!$A$3:$B$44,2,FALSE),0)*'FL Characterization'!E$2) -> 0.25925733 | F10: =('[1]Pc, Winter, S1'!F10*Main!$B$5)+(_xlfn.IFNA(VLOOKUP($A10,'FL Ratio'!$A$3:$B$44,2,FALSE),0)*'FL Characterization'!F$2) -> 0.25654488 | G10: =('[1]Pc, Winter, S1'!G10*Main!$B$5)+(_xlfn.IFNA(VLOOKUP($A10,'FL Ratio'!$A$3:$B$44,2,FALSE),0)*'FL Characterization'!G$2) -> 0.25468459 | H10: =('[1]Pc, Winter, S1'!H10*Main!$B$5)+(_xlfn.IFNA(VLOOKUP($A10,'FL Ratio'!$A$3:$B$44,2,FALSE),0)*'FL Characterization'!H$2) -> 0.25701134 | I10: =('[1]Pc, Winter, S1'!I10*Main!$B$5)+(_xlfn.IFNA(VLOOKUP($A10,'FL Ratio'!$A$3:$B$44,2,FALSE),0)*'FL Characterization'!I$2) -> 0.24646369 | ... Y10: =('[1]Pc, Winter, S1'!Y10*Main!$B$5)+(_xlfn.IFNA(VLOOKUP($A10,'FL Ratio'!$A$3:$B$44,2,FALSE),0)*'FL Characterization'!Y$2) -> 0.25992988
A11: 10 | B11: =('[1]Pc, Winter, S1'!B11*Main!$B$5)+(_xlfn.IFNA(VLOOKUP($A11,'FL Ratio'!$A$3:$B$44,2,FALSE),0)*'FL Characterization'!B$2) -> 0.45083405 | C11: =('[1]Pc, Winter, S1'!C11*Main!$B$5)+(_xlfn.IFNA(VLOOKUP($A11,'FL Ratio'!$A$3:$B$44,2,FALSE),0)*'FL Characterization'!C$2) -> 0.41754366 | D11: =('[1]Pc, Winter, S1'!D11*Main!$B$5)+(_xlfn.IFNA(VLOOKUP($A11,'FL Ratio'!$A$3:$B$44,2,FALSE),0)*'FL Characterization'!D$2) -> 0.39750618 | E11: =('[1]Pc, Winter, S1'!E11*Main!$B$5)+(_xlfn.IFNA(VLOOKUP($A11,'FL Ratio'!$A$3:$B$44,2,FALSE),0)*'FL Characterization'!E$2) -> 0.40073728 | F11: =('[1]Pc, Winter, S1'!F11*Main!$B$5)+(_xlfn.IFNA(VLOOKUP($A11,'FL Ratio'!$A$3:$B$44,2,FALSE),0)*'FL Characterization'!F$2) -> 0.40183407 | G11: =('[1]Pc, Winter, S1'!G11*Main!$B$5)+(_xlfn.IFNA(VLOOKUP($A11,'FL Ratio'!$A$3:$B$44,2,FALSE),0)*'FL Characterization'!G$2) -> 0.45992958 | H11: =('[1]Pc, Winter, S1'!H11*Main!$B$5)+(_xlfn.IFNA(VLOOKUP($A11,'FL Ratio'!$A$3:$B$44,2,FALSE),0)*'FL Characterization'!H$2) -> 0.60089666 | I11: =('[1]Pc, Winter, S1'!I11*Main!$B$5)+(_xlfn.IFNA(VLOOKUP($A11,'FL Ratio'!$A$3:$B$44,2,FALSE),0)*'FL Characterization'!I$2) -> 0.69404177 | ... Y11: =('[1]Pc, Winter, S1'!Y11*Main!$B$5)+(_xlfn.IFNA(VLOOKUP($A11,'FL Ratio'!$A$3:$B$44,2,FALSE),0)*'FL Characterization'!Y$2) -> 0.5492113
A12: 11 | B12: =('[1]Pc, Winter, S1'!B12*Main!$B$5)+(_xlfn.IFNA(VLOOKUP($A12,'FL Ratio'!$A$3:$B$44,2,FALSE),0)*'FL Characterization'!B$2) -> 0.24109014 | C12: =('[1]Pc, Winter, S1'!C12*Main!$B$5)+(_xlfn.IFNA(VLOOKUP($A12,'FL Ratio'!$A$3:$B$44,2,FALSE),0)*'FL Characterization'!C$2) -> 0.2227483 | D12: =('[1]Pc, Winter, S1'!D12*Main!$B$5)+(_xlfn.IFNA(VLOOKUP($A12,'FL Ratio'!$A$3:$B$44,2,FALSE),0)*'FL Characterization'!D$2) -> 0.21066114 | E12: =('[1]Pc, Winter, S1'!E12*Main!$B$5)+(_xlfn.IFNA(VLOOKUP($A12,'FL Ratio'!$A$3:$B$44,2,FALSE),0)*'FL Characterization'!E$2) -> 0.20884754 | F12: =('[1]Pc, Winter, S1'!F12*Main!$B$5)+(_xlfn.IFNA(VLOOKUP($A12,'FL Ratio'!$A$3:$B$44,2,FALSE),0)*'FL Characterization'!F$2) -> 0.21219017 | G12: =('[1]Pc, Winter, S1'!G12*Main!$B$5)+(_xlfn.IFNA(VLOOKUP($A12,'FL Ratio'!$A$3:$B$44,2,FALSE),0)*'FL Characterization'!G$2) -> 0.25887408 | H12: =('[1]Pc, Winter, S1'!H12*Main!$B$5)+(_xlfn.IFNA(VLOOKUP($A12,'FL Ratio'!$A$3:$B$44,2,FALSE),0)*'FL Characterization'!H$2) -> 0.344045 | I12: =('[1]Pc, Winter, S1'!I12*Main!$B$5)+(_xlfn.IFNA(VLOOKUP($A12,'FL Ratio'!$A$3:$B$44,2,FALSE),0)*'FL Characterization'!I$2) -> 0.36839266 | ... Y12: =('[1]Pc, Winter, S1'!Y12*Main!$B$5)+(_xlfn.IFNA(VLOOKUP($A12,'FL Ratio'!$A$3:$B$44,2,FALSE),0)*'FL Characterization'!Y$2) -> 0.31149301
A13: 12 | B13: =('[1]Pc, Winter, S1'!B13*Main!$B$5)+(_xlfn.IFNA(VLOOKUP($A13,'FL Ratio'!$A$3:$B$44,2,FALSE),0)*'FL Characterization'!B$2) -> 0.91669443 | C13: =('[1]Pc, Winter, S1'!C13*Main!$B$5)+(_xlfn.IFNA(VLOOKUP($A13,'FL Ratio'!$A$3:$B$44,2,FALSE),0)*'FL Characterization'!C$2) -> 0.91297859 | D13: =('[1]Pc, Winter, S1'!D13*Main!$B$5)+(_xlfn.IFNA(VLOOKUP($A13,'FL Ratio'!$A$3:$B$44,2,FALSE),0)*'FL Characterization'!D$2) -> 0.91075585 | E13: =('[1]Pc, Winter, S1'!E13*Main!$B$5)+(_xlfn.IFNA(VLOOKUP($A13,'FL Ratio'!$A$3:$B$44,2,FALSE),0)*'FL Characterization'!E$2) -> 0.93606156 | F13: =('[1]Pc, Winter, S1'!F13*Main!$B$5)+(_xlfn.IFNA(VLOOKUP($A13,'FL Ratio'!$A$3:$B$44,2,FALSE),0)*'FL Characterization'!F$2) -> 0.92902033 | G13: =('[1]Pc, Winter, S1'!G13*Main!$B$5)+(_xlfn.IFNA(VLOOKUP($A13,'FL Ratio'!$A$3:$B$44,2,FALSE),0)*'FL Characterization'!G$2) -> 0.95231674 | H13: =('[1]Pc, Winter, S1'!H13*Main!$B$5)+(_xlfn.IFNA(VLOOKUP($A13,'FL Ratio'!$A$3:$B$44,2,FALSE),0)*'FL Characterization'!H$2) -> 0.99042794 | I13: =('[1]Pc, Winter, S1'!I13*Main!$B$5)+(_xlfn.IFNA(VLOOKUP($A13,'FL Ratio'!$A$3:$B$44,2,FALSE),0)*'FL Characterization'!I$2) -> 0.95022929 | ... Y13: =('[1]Pc, Winter, S1'!Y13*Main!$B$5)+(_xlfn.IFNA(VLOOKUP($A13,'FL Ratio'!$A$3:$B$44,2,FALSE),0)*'FL Characterization'!Y$2) -> 1.1250761
... A33: 32 | B33: =('[1]Pc, Winter, S1'!B33*Main!$B$5)+(_xlfn.IFNA(VLOOKUP($A33,'FL Ratio'!$A$3:$B$44,2,FALSE),0)*'FL Characterization'!B$2) -> 1.1548917 | C33: =('[1]Pc, Winter, S1'!C33*Main!$B$5)+(_xlfn.IFNA(VLOOKUP($A33,'FL Ratio'!$A$3:$B$44,2,FALSE),0)*'FL Characterization'!C$2) -> 1.0875208 | D33: =('[1]Pc, Winter, S1'!D33*Main!$B$5)+(_xlfn.IFNA(VLOOKUP($A33,'FL Ratio'!$A$3:$B$44,2,FALSE),0)*'FL Characterization'!D$2) -> 1.0584767 | E33: =('[1]Pc, Winter, S1'!E33*Main!$B$5)+(_xlfn.IFNA(VLOOKUP($A33,'FL Ratio'!$A$3:$B$44,2,FALSE),0)*'FL Characterization'!E$2) -> 1.0703475 | F33: =('[1]Pc, Winter, S1'!F33*Main!$B$5)+(_xlfn.IFNA(VLOOKUP($A33,'FL Ratio'!$A$3:$B$44,2,FALSE),0)*'FL Characterization'!F$2) -> 1.0791886 | G33: =('[1]Pc, Winter, S1'!G33*Main!$B$5)+(_xlfn.IFNA(VLOOKUP($A33,'FL Ratio'!$A$3:$B$44,2,FALSE),0)*'FL Characterization'!G$2) -> 1.1666168 | H33: =('[1]Pc, Winter, S1'!H33*Main!$B$5)+(_xlfn.IFNA(VLOOKUP($A33,'FL Ratio'!$A$3:$B$44,2,FALSE),0)*'FL Characterization'!H$2) -> 1.3187729 | I33: =('[1]Pc, Winter, S1'!I33*Main!$B$5)+(_xlfn.IFNA(VLOOKUP($A33,'FL Ratio'!$A$3:$B$44,2,FALSE),0)*'FL Characterization'!I$2) -> 1.5859147 | ... Y33: =('[1]Pc, Winter, S1'!Y33*Main!$B$5)+(_xlfn.IFNA(VLOOKUP($A33,'FL Ratio'!$A$3:$B$44,2,FALSE),0)*'FL Characterization'!Y$2) -> 1.2147005

Sheet Pc, Winter, S2
A1: LoadID | B1: 0 | C1: 1 | D1: 2 | E1: 3 | F1: 4 | G1: 5 | H1: 6 | I1: 7 | J1: 8 | K1: 9 | L1: 10 | M1: 11 | N1: 12 | O1: 13 | P1: 14 | Q1: 15 | R1: 16 | S1: 17 | T1: 18 | U1: 19 | V1: 20 | W1: 21 | X1: 22 | Y1: 23
A2: 1 | B2: =('[1]Pc, Winter, S1'!B2*Main!$B$5)+(_xlfn.IFNA(VLOOKUP($A2,'FL Ratio'!$A$3:$B$44,2,FALSE),0)*'FL Characterization'!B$2) -> 1.2613173 | C2: =('[1]Pc, Winter, S1'!C2*Main!$B$5)+(_xlfn.IFNA(VLOOKUP($A2,'FL Ratio'!$A$3:$B$44,2,FALSE),0)*'FL Characterization'!C$2) -> 1.2141805 | D2: =('[1]Pc, Winter, S1'!D2*Main!$B$5)+(_xlfn.IFNA(VLOOKUP($A2,'FL Ratio'!$A$3:$B$44,2,FALSE),0)*'FL Characterization'!D$2) -> 1.1709325 | E2: =('[1]Pc, Winter, S1'!E2*Main!$B$5)+(_xlfn.IFNA(VLOOKUP($A2,'FL Ratio'!$A$3:$B$44,2,FALSE),0)*'FL Characterization'!E$2) -> 1.2062737 | F2: =('[1]Pc, Winter, S1'!F2*Main!$B$5)+(_xlfn.IFNA(VLOOKUP($A2,'FL Ratio'!$A$3:$B$44,2,FALSE),0)*'FL Characterization'!F$2) -> 1.1722353 | G2: =('[1]Pc, Winter, S1'!G2*Main!$B$5)+(_xlfn.IFNA(VLOOKUP($A2,'FL Ratio'!$A$3:$B$44,2,FALSE),0)*'FL Characterization'!G$2) -> 1.1737966 | H2: =('[1]Pc, Winter, S1'!H2*Main!$B$5)+(_xlfn.IFNA(VLOOKUP($A2,'FL Ratio'!$A$3:$B$44,2,FALSE),0)*'FL Characterization'!H$2) -> 1.1846307 | I2: =('[1]Pc, Winter, S1'!I2*Main!$B$5)+(_xlfn.IFNA(VLOOKUP($A2,'FL Ratio'!$A$3:$B$44,2,FALSE),0)*'FL Characterization'!I$2) -> 1.5376466 | ... Y2: =('[1]Pc, Winter, S1'!Y2*Main!$B$5)+(_xlfn.IFNA(VLOOKUP($A2,'FL Ratio'!$A$3:$B$44,2,FALSE),0)*'FL Characterization'!Y$2) -> 1.1674547
A3: 2 | B3: =('[1]Pc, Winter, S1'!B3*Main!$B$5)+(_xlfn.IFNA(VLOOKUP($A3,'FL Ratio'!$A$3:$B$44,2,FALSE),0)*'FL Characterization'!B$2) -> 0.68473241 | C3: =('[1]Pc, Winter, S1'!C3*Main!$B$5)+(_xlfn.IFNA(VLOOKUP($A3,'FL Ratio'!$A$3:$B$44,2,FALSE),0)*'FL Characterization'!C$2) -> 0.66683173 | D3: =('[1]Pc, Winter, S1'!D3*Main!$B$5)+(_xlfn.IFNA(VLOOKUP($A3,'FL Ratio'!$A$3:$B$44,2,FALSE),0)*'FL Characterization'!D$2) -> 0.63686042 | E3: =('[1]Pc, Winter, S1'!E3*Main!$B$5)+(_xlfn.IFNA(VLOOKUP($A3,'FL Ratio'!$A$3:$B$44,2,FALSE),0)*'FL Characterization'!E$2) -> 0.63054521 | F3: =('[1]Pc, Winter, S1'!F3*Main!$B$5)+(_xlfn.IFNA(VLOOKUP($A3,'FL Ratio'!$A$3:$B$44,2,FALSE),0)*'FL Characterization'!F$2) -> 0.63258614 | G3: =('[1]Pc, Winter, S1'!G3*Main!$B$5)+(_xlfn.IFNA(VLOOKUP($A3,'FL Ratio'!$A$3:$B$44,2,FALSE),0)*'FL Characterization'!G$2) -> 0.67138052 | H3: =('[1]Pc, Winter, S1'!H3*Main!$B$5)+(_xlfn.IFNA(VLOOKUP($A3,'FL Ratio'!$A$3:$B$44,2,FALSE),0)*'FL Characterization'!H$2) -> 0.8096561 | I3: =('[1]Pc, Winter, S1'!I3*Main!$B$5)+(_xlfn.IFNA(VLOOKUP($A3,'FL Ratio'!$A$3:$B$44,2,FALSE),0)*'FL Characterization'!I$2) -> 0.92621426 | ... Y3: =('[1]Pc, Winter, S1'!Y3*Main!$B$5)+(_xlfn.IFNA(VLOOKUP($A3,'FL Ratio'!$A$3:$B$44,2,FALSE),0)*'FL Characterization'!Y$2) -> 0.78235088
A4: 3 | B4: =('[1]Pc, Winter, S1'!B4*Main!$B$5)+(_xlfn.IFNA(VLOOKUP($A4,'FL Ratio'!$A$3:$B$44,2,FALSE),0)*'FL Characterization'!B$2) -> 1.5056575 | C4: =('[1]Pc, Winter, S1'!C4*Main!$B$5)+(_xlfn.IFNA(VLOOKUP($A4,'FL Ratio'!$A$3:$B$44,2,FALSE),0)*'FL Characterization'!C$2) -> 1.4188611 | D4: =('[1]Pc, Winter, S1'!D4*Main!$B$5)+(_xlfn.IFNA(VLOOKUP($A4,'FL Ratio'!$A$3:$B$44,2,FALSE),0)*'FL Characterization'!D$2) -> 1.3704428 | E4: =('[1]Pc, Winter, S1'!E4*Main!$B$5)+(_xlfn.IFNA(VLOOKUP($A4,'FL Ratio'!$A$3:$B$44,2,FALSE),0)*'FL Characterization'!E$2) -> 1.3967957 | F4: =('[1]Pc, Winter, S1'!F4*Main!$B$5)+(_xlfn.IFNA(VLOOKUP($A4,'FL Ratio'!$A$3:$B$44,2,FALSE),0)*'FL Characterization'!F$2) -> 1.4042285 | G4: =('[1]Pc, Winter, S1'!G4*Main!$B$5)+(_xlfn.IFNA(VLOOKUP($A4,'FL Ratio'!$A$3:$B$44,2,FALSE),0)*'FL Characterization'!G$2) -> 1.5982913 | H4: =('[1]Pc, Winter, S1'!H4*Main!$B$5)+(_xlfn.IFNA(VLOOKUP($A4,'FL Ratio'!$A$3:$B$44,2,FALSE),0)*'FL Characterization'!H$2) -> 2.5730591 | I4: =('[1]Pc, Winter, S1'!I4*Main!$B$5)+(_xlfn.IFNA(VLOOKUP($A4,'FL Ratio'!$A$3:$B$44,2,FALSE),0)*'FL Characterization'!I$2) -> 2.9913003 | ... Y4: =('[1]Pc, Winter, S1'!Y4*Main!$B$5)+(_xlfn.IFNA(VLOOKUP($A4,'FL Ratio'!$A$3:$B$44,2,FALSE),0)*'FL Characterization'!Y$2) -> 1.7146334
A5: 4 | B5: =('[1]Pc, Winter, S1'!B5*Main!$B$5)+(_xlfn.IFNA(VLOOKUP($A5,'FL Ratio'!$A$3:$B$44,2,FALSE),0)*'FL Characterization'!B$2) -> 0.083441485 | C5: =('[1]Pc, Winter, S1'!C5*Main!$B$5)+(_xlfn.IFNA(VLOOKUP($A5,'FL Ratio'!$A$3:$B$44,2,FALSE),0)*'FL Characterization'!C$2) -> 0.060778081 | D5: =('[1]Pc, Winter, S1'!D5*Main!$B$5)+(_xlfn.IFNA(VLOOKUP($A5,'FL Ratio'!$A$3:$B$44,2,FALSE),0)*'FL Characterization'!D$2) -> 0.058949291 | E5: =('[1]Pc, Winter, S1'!E5*Main!$B$5)+(_xlfn.IFNA(VLOOKUP($A5,'FL Ratio'!$A$3:$B$44,2,FALSE),0)*'FL Characterization'!E$2) -> 0.053417995 | F5: =('[1]Pc, Winter, S1'!F5*Main!$B$5)+(_xlfn.IFNA(VLOOKUP($A5,'FL Ratio'!$A$3:$B$44,2,FALSE),0)*'FL Characterization'!F$2) -> 0.0527488 | G5: =('[1]Pc, Winter, S1'!G5*Main!$B$5)+(_xlfn.IFNA(VLOOKUP($A5,'FL Ratio'!$A$3:$B$44,2,FALSE),0)*'FL Characterization'!G$2) -> 0.092977137 | H5: =('[1]Pc, Winter, S1'!H5*Main!$B$5)+(_xlfn.IFNA(VLOOKUP($A5,'FL Ratio'!$A$3:$B$44,2,FALSE),0)*'FL Characterization'!H$2) -> 0.17827496 | I5: =('[1]Pc, Winter, S1'!I5*Main!$B$5)+(_xlfn.IFNA(VLOOKUP($A5,'FL Ratio'!$A$3:$B$44,2,FALSE),0)*'FL Characterization'!I$2) -> 0.20824353 | ... Y5: =('[1]Pc, Winter, S1'!Y5*Main!$B$5)+(_xlfn.IFNA(VLOOKUP($A5,'FL Ratio'!$A$3:$B$44,2,FALSE),0)*'FL Characterization'!Y$2) -> 0.14297626
A6: 5 | B6: =('[1]Pc, Winter, S1'!B6*Main!$B$5)+(_xlfn.IFNA(VLOOKUP($A6,'FL Ratio'!$A$3:$B$44,2,FALSE),0)*'FL Characterization'!B$2) -> 0.40145888 | C6: =('[1]Pc, Winter, S1'!C6*Main!$B$5)+(_xlfn.IFNA(VLOOKUP($A6,'FL Ratio'!$A$3:$B$44,2,FALSE),0)*'FL Characterization'!C$2) -> 0.3672713 | D6: =('[1]Pc, Winter, S1'!D6*Main!$B$5)+(_xlfn.IFNA(VLOOKUP($A6,'FL Ratio'!$A$3:$B$44,2,FALSE),0)*'FL Characterization'!D$2) -> 0.33619562 | E6: =('[1]Pc, Winter, S1'!E6*Main!$B$5)+(_xlfn.IFNA(VLOOKUP($A6,'FL Ratio'!$A$3:$B$44,2,FALSE),0)*'FL Characterization'!E$2) -> 0.33956445 | F6: =('[1]Pc, Winter, S1'!F6*Main!$B$5)+(_xlfn.IFNA(VLOOKUP($A6,'FL Ratio'!$A$3:$B$44,2,FALSE),0)*'FL Characterization'!F$2) -> 0.34408902 | G6: =('[1]Pc, Winter, S1'!G6*Main!$B$5)+(_xlfn.IFNA(VLOOKUP($A6,'FL Ratio'!$A$3:$B$44,2,FALSE),0)*'FL Characterization'!G$2) -> 0.38424228 | H6: =('[1]Pc, Winter, S1'!H6*Main!$B$5)+(_xlfn.IFNA(VLOOKUP($A6,'FL Ratio'!$A$3:$B$44,2,FALSE),0)*'FL Characterization'!H$2) -> 0.49596683 | I6: =('[1]Pc, Winter, S1'!I6*Main!$B$5)+(_xlfn.IFNA(VLOOKUP($A6,'FL Ratio'!$A$3:$B$44,2,FALSE),0)*'FL Characterization'!I$2) -> 0.53738668 | ... Y6: =('[1]Pc, Winter, S1'!Y6*Main!$B$5)+(_xlfn.IFNA(VLOOKUP($A6,'FL Ratio'!$A$3:$B$44,2,FALSE),0)*'FL Characterization'!Y$2) -> 0.50539268
A7: 6 | B7: =('[1]Pc, Winter, S1'!B7*Main!$B$5)+(_xlfn.IFNA(VLOOKUP($A7,'FL Ratio'!$A$3:$B$44,2,FALSE),0)*'FL Characterization'!B$2) -> 2.8457179 | C7: =('[1]Pc, Winter, S1'!C7*Main!$B$5)+(_xlfn.IFNA(VLOOKUP($A7,'FL Ratio'!$A$3:$B$44,2,FALSE),0)*'FL Characterization'!C$2) -> 2.6810967 | D7: =('[1]Pc, Winter, S1'!D7*Main!$B$5)+(_xlfn.IFNA(VLOOKUP($A7,'FL Ratio'!$A$3:$B$44,2,FALSE),0)*'FL Characterization'!D$2) -> 2.6082787 | E7: =('[1]Pc, Winter, S1'!E7*Main!$B$5)+(_xlfn.IFNA(VLOOKUP($A7,'FL Ratio'!$A$3:$B$44,2,FALSE),0)*'FL Characterization'!E$2) -> 2.6366452 | F7: =('[1]Pc, Winter, S1'!F7*Main!$B$5)+(_xlfn.IFNA(VLOOKUP($A7,'FL Ratio'!$A$3:$B$44,2,FALSE),0)*'FL Characterization'!F$2) -> 2.6559213 | G7: =('[1]Pc, Winter, S1'!G7*Main!$B$5)+(_xlfn.IFNA(VLOOKUP($A7,'FL Ratio'!$A$3:$B$44,2,FALSE),0)*'FL Characterization'!G$2) -> 2.8685645 | H7: =('[1]Pc, Winter, S1'!H7*Main!$B$5)+(_xlfn.IFNA(VLOOKUP($A7,'FL Ratio'!$A$3:$B$44,2,FALSE),0)*'FL Characterization'!H$2) -> 3.2435491 | I7: =('[1]Pc, Winter, S1'!I7*Main!$B$5)+(_xlfn.IFNA(VLOOKUP($A7,'FL Ratio'!$A$3:$B$44,2,FALSE),0)*'FL Characterization'!I$2) -> 3.8890018 | ... Y7: =('[1]Pc, Winter, S1'!Y7*Main!$B$5)+(_xlfn.IFNA(VLOOKUP($A7,'FL Ratio'!$A$3:$B$44,2,FALSE),0)*'FL Characterization'!Y$2) -> 2.991045
A8: 7 | B8: =('[1]Pc, Winter, S1'!B8*Main!$B$5)+(_xlfn.IFNA(VLOOKUP($A8,'FL Ratio'!$A$3:$B$44,2,FALSE),0)*'FL Characterization'!B$2) -> 1.1785864 | C8: =('[1]Pc, Winter, S1'!C8*Main!$B$5)+(_xlfn.IFNA(VLOOKUP($A8,'FL Ratio'!$A$3:$B$44,2,FALSE),0)*'FL Characterization'!C$2) -> 1.0926081 | D8: =('[1]Pc, Winter, S1'!D8*Main!$B$5)+(_xlfn.IFNA(VLOOKUP($A8,'FL Ratio'!$A$3:$B$44,2,FALSE),0)*'FL Characterization'!D$2) -> 1.0777042 | E8: =('[1]Pc, Winter, S1'!E8*Main!$B$5)+(_xlfn.IFNA(VLOOKUP($A8,'FL Ratio'!$A$3:$B$44,2,FALSE),0)*'FL Characterization'!E$2) -> 1.0541574 | F8: =('[1]Pc, Winter, S1'!F8*Main!$B$5)+(_xlfn.IFNA(VLOOKUP($A8,'FL Ratio'!$A$3:$B$44,2,FALSE),0)*'FL Characterization'!F$2) -> 1.0802379 | G8: =('[1]Pc, Winter, S1'!G8*Main!$B$5)+(_xlfn.IFNA(VLOOKUP($A8,'FL Ratio'!$A$3:$B$44,2,FALSE),0)*'FL Characterization'!G$2) -> 1.2292647 | H8: =('[1]Pc, Winter, S1'!H8*Main!$B$5)+(_xlfn.IFNA(VLOOKUP($A8,'FL Ratio'!$A$3:$B$44,2,FALSE),0)*'FL Characterization'!H$2) -> 1.5592714 | I8: =('[1]Pc, Winter, S1'!I8*Main!$B$5)+(_xlfn.IFNA(VLOOKUP($A8,'FL Ratio'!$A$3:$B$44,2,FALSE),0)*'FL Characterization'!I$2) -> 1.8621812 | ... Y8: =('[1]Pc, Winter, S1'!Y8*Main!$B$5)+(_xlfn.IFNA(VLOOKUP($A8,'FL Ratio'!$A$3:$B$44,2,FALSE),0)*'FL Characterization'!Y$2) -> 1.3420995
A9: 8 | B9: =('[1]Pc, Winter, S1'!B9*Main!$B$5)+(_xlfn.IFNA(VLOOKUP($A9,'FL Ratio'!$A$3:$B$44,2,FALSE),0)*'FL Characterization'!B$2) -> 0.24263038 | C9: =('[1]Pc, Winter, S1'!C9*Main!$B$5)+(_xlfn.IFNA(VLOOKUP($A9,'FL Ratio'!$A$3:$B$44,2,FALSE),0)*'FL Characterization'!C$2) -> 0.23132727 | D9: =('[1]Pc, Winter, S1'!D9*Main!$B$5)+(_xlfn.IFNA(VLOOKUP($A9,'FL Ratio'!$A$3:$B$44,2,FALSE),0)*'FL Characterization'!D$2) -> 0.22474155 | E9: =('[1]Pc, Winter, S1'!E9*Main!$B$5)+(_xlfn.IFNA(VLOOKUP($A9,'FL Ratio'!$A$3:$B$44,2,FALSE),0)*'FL Characterization'!E$2) -> 0.22166686 | F9: =('[1]Pc, Winter, S1'!F9*Main!$B$5)+(_xlfn.IFNA(VLOOKUP($A9,'FL Ratio'!$A$3:$B$44,2,FALSE),0)*'FL Characterization'!F$2) -> 0.23124421 | G9: =('[1]Pc, Winter, S1'!G9*Main!$B$5)+(_xlfn.IFNA(VLOOKUP($A9,'FL Ratio'!$A$3:$B$44,2,FALSE),0)*'FL Characterization'!G$2) -> 0.27751271 | H9: =('[1]Pc, Winter, S1'!H9*Main!$B$5)+(_xlfn.IFNA(VLOOKUP($A9,'FL Ratio'!$A$3:$B$44,2,FALSE),0)*'FL Characterization'!H$2) -> 0.45139351 | I9: =('[1]Pc, Winter, S1'!I9*Main!$B$5)+(_xlfn.IFNA(VLOOKUP($A9,'FL Ratio'!$A$3:$B$44,2,FALSE),0)*'FL Characterization'!I$2) -> 0.52982963 | ... Y9: =('[1]Pc, Winter, S1'!Y9*Main!$B$5)+(_xlfn.IFNA(VLOOKUP($A9,'FL Ratio'!$A$3:$B$44,2,FALSE),0)*'FL Characterization'!Y$2) -> 0.28557101
A10: 9 | B10: =('[1]Pc, Winter, S1'!B10*Main!$B$5)+(_xlfn.IFNA(VLOOKUP($A10,'FL Ratio'!$A$3:$B$44,2,FALSE),0)*'FL Characterization'!B$2) -> 0.2613613 | C10: =('[1]Pc, Winter, S1'!C10*Main!$B$5)+(_xlfn.IFNA(VLOOKUP($A10,'FL Ratio'!$A$3:$B$44,2,FALSE),0)*'FL Characterization'!C$2) -> 0.26193219 | D10: =('[1]Pc, Winter, S1'!D10*Main!$B$5)+(_xlfn.IFNA(VLOOKUP($A10,'FL Ratio'!$A$3:$B$44,2,FALSE),0)*'FL Characterization'!D$2) -> 0.26008304 | E10: =('[1]Pc, Winter, S1'!E10*Main!$B$5)+(_xlfn.IFNA(VLOOKUP($A10,'FL Ratio'!$A$3:$B$44,2,FALSE),0)*'FL Characterization'!E$2) -> 0.25925733 | F10: =('[1]Pc, Winter, S1'!F10*Main!$B$5)+(_xlfn.IFNA(VLOOKUP($A10,'FL Ratio'!$A$3:$B$44,2,FALSE),0)*'FL Characterization'!F$2) -> 0.25654488 | G10: =('[1]Pc, Winter, S1'!G10*Main!$B$5)+(_xlfn.IFNA(VLOOKUP($A10,'FL Ratio'!$A$3:$B$44,2,FALSE),0)*'FL Characterization'!G$2) -> 0.25468459 | H10: =('[1]Pc, Winter, S1'!H10*Main!$B$5)+(_xlfn.IFNA(VLOOKUP($A10,'FL Ratio'!$A$3:$B$44,2,FALSE),0)*'FL Characterization'!H$2) -> 0.25701134 | I10: =('[1]Pc, Winter, S1'!I10*Main!$B$5)+(_xlfn.IFNA(VLOOKUP($A10,'FL Ratio'!$A$3:$B$44,2,FALSE),0)*'FL Characterization'!I$2) -> 0.24646369 | ... Y10: =('[1]Pc, Winter, S1'!Y10*Main!$B$5)+(_xlfn.IFNA(VLOOKUP($A10,'FL Ratio'!$A$3:$B$44,2,FALSE),0)*'FL Characterization'!Y$2) -> 0.25992988
A11: 10 | B11: =('[1]Pc, Winter, S1'!B11*Main!$B$5)+(_xlfn.IFNA(VLOOKUP($A11,'FL Ratio'!$A$3:$B$44,2,FALSE),0)*'FL Characterization'!B$2) -> 0.45083405 | C11: =('[1]Pc, Winter, S1'!C11*Main!$B$5)+(_xlfn.IFNA(VLOOKUP($A11,'FL Ratio'!$A$3:$B$44,2,FALSE),0)*'FL Characterization'!C$2) -> 0.41754366 | D11: =('[1]Pc, Winter, S1'!D11*Main!$B$5)+(_xlfn.IFNA(VLOOKUP($A11,'FL Ratio'!$A$3:$B$44,2,FALSE),0)*'FL Characterization'!D$2) -> 0.39750618 | E11: =('[1]Pc, Winter, S1'!E11*Main!$B$5)+(_xlfn.IFNA(VLOOKUP($A11,'FL Ratio'!$A$3:$B$44,2,FALSE),0)*'FL Characterization'!E$2) -> 0.40073728 | F11: =('[1]Pc, Winter, S1'!F11*Main!$B$5)+(_xlfn.IFNA(VLOOKUP($A11,'FL Ratio'!$A$3:$B$44,2,FALSE),0)*'FL Characterization'!F$2) -> 0.40183407 | G11: =('[1]Pc, Winter, S1'!G11*Main!$B$5)+(_xlfn.IFNA(VLOOKUP($A11,'FL Ratio'!$A$3:$B$44,2,FALSE),0)*'FL Characterization'!G$2) -> 0.45992958 | H11: =('[1]Pc, Winter, S1'!H11*Main!$B$5)+(_xlfn.IFNA(VLOOKUP($A11,'FL Ratio'!$A$3:$B$44,2,FALSE),0)*'FL Characterization'!H$2) -> 0.60089666 | I11: =('[1]Pc, Winter, S1'!I11*Main!$B$5)+(_xlfn.IFNA(VLOOKUP($A11,'FL Ratio'!$A$3:$B$44,2,FALSE),0)*'FL Characterization'!I$2) -> 0.69404177 | ... Y11: =('[1]Pc, Winter, S1'!Y11*Main!$B$5)+(_xlfn.IFNA(VLOOKUP($A11,'FL Ratio'!$A$3:$B$44,2,FALSE),0)*'FL Characterization'!Y$2) -> 0.5492113
A12: 11 | B12: =('[1]Pc, Winter, S1'!B12*Main!$B$5)+(_xlfn.IFNA(VLOOKUP($A12,'FL Ratio'!$A$3:$B$44,2,FALSE),0)*'FL Characterization'!B$2) -> 0.24109014 | C12: =('[1]Pc, Winter, S1'!C12*Main!$B$5)+(_xlfn.IFNA(VLOOKUP($A12,'FL Ratio'!$A$3:$B$44,2,FALSE),0)*'FL Characterization'!C$2) -> 0.2227483 | D12: =('[1]Pc, Winter, S1'!D12*Main!$B$5)+(_xlfn.IFNA(VLOOKUP($A12,'FL Ratio'!$A$3:$B$44,2,FALSE),0)*'FL Characterization'!D$2) -> 0.21066114 | E12: =('[1]Pc, Winter, S1'!E12*Main!$B$5)+(_xlfn.IFNA(VLOOKUP($A12,'FL Ratio'!$A$3:$B$44,2,FALSE),0)*'FL Characterization'!E$2) -> 0.20884754 | F12: =('[1]Pc, Winter, S1'!F12*Main!$B$5)+(_xlfn.IFNA(VLOOKUP($A12,'FL Ratio'!$A$3:$B$44,2,FALSE),0)*'FL Characterization'!F$2) -> 0.21219017 | G12: =('[1]Pc, Winter, S1'!G12*Main!$B$5)+(_xlfn.IFNA(VLOOKUP($A12,'FL Ratio'!$A$3:$B$44,2,FALSE),0)*'FL Characterization'!G$2) -> 0.25887408 | H12: =('[1]Pc, Winter, S1'!H12*Main!$B$5)+(_xlfn.IFNA(VLOOKUP($A12,'FL Ratio'!$A$3:$B$44,2,FALSE),0)*'FL Characterization'!H$2) -> 0.344045 | I12: =('[1]Pc, Winter, S1'!I12*Main!$B$5)+(_xlfn.IFNA(VLOOKUP($A12,'FL Ratio'!$A$3:$B$44,2,FALSE),0)*'FL Characterization'!I$2) -> 0.36839266 | ... Y12: =('[1]Pc, Winter, S1'!Y12*Main!$B$5)+(_xlfn.IFNA(VLOOKUP($A12,'FL Ratio'!$A$3:$B$44,2,FALSE),0)*'FL Characterization'!Y$2) -> 0.31149301
A13: 12 | B13: =('[1]Pc, Winter, S1'!B13*Main!$B$5)+(_xlfn.IFNA(VLOOKUP($A13,'FL Ratio'!$A$3:$B$44,2,FALSE),0)*'FL Characterization'!B$2) -> 0.91669443 | C13: =('[1]Pc, Winter, S1'!C13*Main!$B$5)+(_xlfn.IFNA(VLOOKUP($A13,'FL Ratio'!$A$3:$B$44,2,FALSE),0)*'FL Characterization'!C$2) -> 0.91297859 | D13: =('[1]Pc, Winter, S1'!D13*Main!$B$5)+(_xlfn.IFNA(VLOOKUP($A13,'FL Ratio'!$A$3:$B$44,2,FALSE),0)*'FL Characterization'!D$2) -> 0.91075585 | E13: =('[1]Pc, Winter, S1'!E13*Main!$B$5)+(_xlfn.IFNA(VLOOKUP($A13,'FL Ratio'!$A$3:$B$44,2,FALSE),0)*'FL Characterization'!E$2) -> 0.93606156 | F13: =('[1]Pc, Winter, S1'!F13*Main!$B$5)+(_xlfn.IFNA(VLOOKUP($A13,'FL Ratio'!$A$3:$B$44,2,FALSE),0)*'FL Characterization'!F$2) -> 0.92902033 | G13: =('[1]Pc, Winter, S1'!G13*Main!$B$5)+(_xlfn.IFNA(VLOOKUP($A13,'FL Ratio'!$A$3:$B$44,2,FALSE),0)*'FL Characterization'!G$2) -> 0.95231674 | H13: =('[1]Pc, Winter, S1'!H13*Main!$B$5)+(_xlfn.IFNA(VLOOKUP($A13,'FL Ratio'!$A$3:$B$44,2,FALSE),0)*'FL Characterization'!H$2) -> 0.99042794 | I13: =('[1]Pc, Winter, S1'!I13*Main!$B$5)+(_xlfn.IFNA(VLOOKUP($A13,'FL Ratio'!$A$3:$B$44,2,FALSE),0)*'FL Characterization'!I$2) -> 0.95022929 | ... Y13: =('[1]Pc, Winter, S1'!Y13*Main!$B$5)+(_xlfn.IFNA(VLOOKUP($A13,'FL Ratio'!$A$3:$B$44,2,FALSE),0)*'FL Characterization'!Y$2) -> 1.1250761
... A33: 32 | B33: =('[1]Pc, Winter, S1'!B33*Main!$B$5)+(_xlfn.IFNA(VLOOKUP($A33,'FL Ratio'!$A$3:$B$44,2,FALSE),0)*'FL Characterization'!B$2) -> 1.1548917 | C33: =('[1]Pc, Winter, S1'!C33*Main!$B$5)+(_xlfn.IFNA(VLOOKUP($A33,'FL Ratio'!$A$3:$B$44,2,FALSE),0)*'FL Characterization'!C$2) -> 1.0875208 | D33: =('[1]Pc, Winter, S1'!D33*Main!$B$5)+(_xlfn.IFNA(VLOOKUP($A33,'FL Ratio'!$A$3:$B$44,2,FALSE),0)*'FL Characterization'!D$2) -> 1.0584767 | E33: =('[1]Pc, Winter, S1'!E33*Main!$B$5)+(_xlfn.IFNA(VLOOKUP($A33,'FL Ratio'!$A$3:$B$44,2,FALSE),0)*'FL Characterization'!E$2) -> 1.0703475 | F33: =('[1]Pc, Winter, S1'!F33*Main!$B$5)+(_xlfn.IFNA(VLOOKUP($A33,'FL Ratio'!$A$3:$B$44,2,FALSE),0)*'FL Characterization'!F$2) -> 1.0791886 | G33: =('[1]Pc, Winter, S1'!G33*Main!$B$5)+(_xlfn.IFNA(VLOOKUP($A33,'FL Ratio'!$A$3:$B$44,2,FALSE),0)*'FL Characterization'!G$2) -> 1.1666168 | H33: =('[1]Pc, Winter, S1'!H33*Main!$B$5)+(_xlfn.IFNA(VLOOKUP($A33,'FL Ratio'!$A$3:$B$44,2,FALSE),0)*'FL Characterization'!H$2) -> 1.3187729 | I33: =('[1]Pc, Winter, S1'!I33*Main!$B$5)+(_xlfn.IFNA(VLOOKUP($A33,'FL Ratio'!$A$3:$B$44,2,FALSE),0)*'FL Characterization'!I$2) -> 1.5859147 | ... Y33: =('[1]Pc, Winter, S1'!Y33*Main!$B$5)+(_xlfn.IFNA(VLOOKUP($A33,'FL Ratio'!$A$3:$B$44,2,FALSE),0)*'FL Characterization'!Y$2) -> 1.2147005

Sheet Pc, Winter, S3
A1: LoadID | B1: 0 | C1: 1 | D1: 2 | E1: 3 | F1: 4 | G1: 5 | H1: 6 | I1: 7 | J1: 8 | K1: 9 | L1: 10 | M1: 11 | N1: 12 | O1: 13 | P1: 14 | Q1: 15 | R1: 16 | S1: 17 | T1: 18 | U1: 19 | V1: 20 | W1: 21 | X1: 22 | Y1: 23
A2: 1 | B2: =('[1]Pc, Winter, S1'!B2*Main!$B$5)+(_xlfn.IFNA(VLOOKUP($A2,'FL Ratio'!$A$3:$B$44,2,FALSE),0)*'FL Characterization'!B$2) -> 1.2613173 | C2: =('[1]Pc, Winter, S1'!C2*Main!$B$5)+(_xlfn.IFNA(VLOOKUP($A2,'FL Ratio'!$A$3:$B$44,2,FALSE),0)*'FL Characterization'!C$2) -> 1.2141805 | D2: =('[1]Pc, Winter, S1'!D2*Main!$B$5)+(_xlfn.IFNA(VLOOKUP($A2,'FL Ratio'!$A$3:$B$44,2,FALSE),0)*'FL Characterization'!D$2) -> 1.1709325 | E2: =('[1]Pc, Winter, S1'!E2*Main!$B$5)+(_xlfn.IFNA(VLOOKUP($A2,'FL Ratio'!$A$3:$B$44,2,FALSE),0)*'FL Characterization'!E$2) -> 1.2062737 | F2: =('[1]Pc, Winter, S1'!F2*Main!$B$5)+(_xlfn.IFNA(VLOOKUP($A2,'FL Ratio'!$A$3:$B$44,2,FALSE),0)*'FL Characterization'!F$2) -> 1.1722353 | G2: =('[1]Pc, Winter, S1'!G2*Main!$B$5)+(_xlfn.IFNA(VLOOKUP($A2,'FL Ratio'!$A$3:$B$44,2,FALSE),0)*'FL Characterization'!G$2) -> 1.1737966 | H2: =('[1]Pc, Winter, S1'!H2*Main!$B$5)+(_xlfn.IFNA(VLOOKUP($A2,'FL Ratio'!$A$3:$B$44,2,FALSE),0)*'FL Characterization'!H$2) -> 1.1846307 | I2: =('[1]Pc, Winter, S1'!I2*Main!$B$5)+(_xlfn.IFNA(VLOOKUP($A2,'FL Ratio'!$A$3:$B$44,2,FALSE),0)*'FL Characterization'!I$2) -> 1.5376466 | ... Y2: =('[1]Pc, Winter, S1'!Y2*Main!$B$5)+(_xlfn.IFNA(VLOOKUP($A2,'FL Ratio'!$A$3:$B$44,2,FALSE),0)*'FL Characterization'!Y$2) -> 1.1674547
A3: 2 | B3: =('[1]Pc, Winter, S1'!B3*Main!$B$5)+(_xlfn.IFNA(VLOOKUP($A3,'FL Ratio'!$A$3:$B$44,2,FALSE),0)*'FL Characterization'!B$2) -> 0.68473241 | C3: =('[1]Pc, Winter, S1'!C3*Main!$B$5)+(_xlfn.IFNA(VLOOKUP($A3,'FL Ratio'!$A$3:$B$44,2,FALSE),0)*'FL Characterization'!C$2) -> 0.66683173 | D3: =('[1]Pc, Winter, S1'!D3*Main!$B$5)+(_xlfn.IFNA(VLOOKUP($A3,'FL Ratio'!$A$3:$B$44,2,FALSE),0)*'FL Characterization'!D$2) -> 0.63686042 | E3: =('[1]Pc, Winter, S1'!E3*Main!$B$5)+(_xlfn.IFNA(VLOOKUP($A3,'FL Ratio'!$A$3:$B$44,2,FALSE),0)*'FL Characterization'!E$2) -> 0.63054521 | F3: =('[1]Pc, Winter, S1'!F3*Main!$B$5)+(_xlfn.IFNA(VLOOKUP($A3,'FL Ratio'!$A$3:$B$44,2,FALSE),0)*'FL Characterization'!F$2) -> 0.63258614 | G3: =('[1]Pc, Winter, S1'!G3*Main!$B$5)+(_xlfn.IFNA(VLOOKUP($A3,'FL Ratio'!$A$3:$B$44,2,FALSE),0)*'FL Characterization'!G$2) -> 0.67138052 | H3: =('[1]Pc, Winter, S1'!H3*Main!$B$5)+(_xlfn.IFNA(VLOOKUP($A3,'FL Ratio'!$A$3:$B$44,2,FALSE),0)*'FL Characterization'!H$2) -> 0.8096561 | I3: =('[1]Pc, Winter, S1'!I3*Main!$B$5)+(_xlfn.IFNA(VLOOKUP($A3,'FL Ratio'!$A$3:$B$44,2,FALSE),0)*'FL Characterization'!I$2) -> 0.92621426 | ... Y3: =('[1]Pc, Winter, S1'!Y3*Main!$B$5)+(_xlfn.IFNA(VLOOKUP($A3,'FL Ratio'!$A$3:$B$44,2,FALSE),0)*'FL Characterization'!Y$2) -> 0.78235088
A4: 3 | B4: =('[1]Pc, Winter, S1'!B4*Main!$B$5)+(_xlfn.IFNA(VLOOKUP($A4,'FL Ratio'!$A$3:$B$44,2,FALSE),0)*'FL Characterization'!B$2) -> 1.5056575 | C4: =('[1]Pc, Winter, S1'!C4*Main!$B$5)+(_xlfn.IFNA(VLOOKUP($A4,'FL Ratio'!$A$3:$B$44,2,FALSE),0)*'FL Characterization'!C$2) -> 1.4188611 | D4: =('[1]Pc, Winter, S1'!D4*Main!$B$5)+(_xlfn.IFNA(VLOOKUP($A4,'FL Ratio'!$A$3:$B$44,2,FALSE),0)*'FL Characterization'!D$2) -> 1.3704428 | E4: =('[1]Pc, Winter, S1'!E4*Main!$B$5)+(_xlfn.IFNA(VLOOKUP($A4,'FL Ratio'!$A$3:$B$44,2,FALSE),0)*'FL Characterization'!E$2) -> 1.3967957 | F4: =('[1]Pc, Winter, S1'!F4*Main!$B$5)+(_xlfn.IFNA(VLOOKUP($A4,'FL Ratio'!$A$3:$B$44,2,FALSE),0)*'FL Characterization'!F$2) -> 1.4042285 | G4: =('[1]Pc, Winter, S1'!G4*Main!$B$5)+(_xlfn.IFNA(VLOOKUP($A4,'FL Ratio'!$A$3:$B$44,2,FALSE),0)*'FL Characterization'!G$2) -> 1.5982913 | H4: =('[1]Pc, Winter, S1'!H4*Main!$B$5)+(_xlfn.IFNA(VLOOKUP($A4,'FL Ratio'!$A$3:$B$44,2,FALSE),0)*'FL Characterization'!H$2) -> 2.5730591 | I4: =('[1]Pc, Winter, S1'!I4*Main!$B$5)+(_xlfn.IFNA(VLOOKUP($A4,'FL Ratio'!$A$3:$B$44,2,FALSE),0)*'FL Characterization'!I$2) -> 2.9913003 | ... Y4: =('[1]Pc, Winter, S1'!Y4*Main!$B$5)+(_xlfn.IFNA(VLOOKUP($A4,'FL Ratio'!$A$3:$B$44,2,FALSE),0)*'FL Characterization'!Y$2) -> 1.7146334
A5: 4 | B5: =('[1]Pc, Winter, S1'!B5*Main!$B$5)+(_xlfn.IFNA(VLOOKUP($A5,'FL Ratio'!$A$3:$B$44,2,FALSE),0)*'FL Characterization'!B$2) -> 0.083441485 | C5: =('[1]Pc, Winter, S1'!C5*Main!$B$5)+(_xlfn.IFNA(VLOOKUP($A5,'FL Ratio'!$A$3:$B$44,2,FALSE),0)*'FL Characterization'!C$2) -> 0.060778081 | D5: =('[1]Pc, Winter, S1'!D5*Main!$B$5)+(_xlfn.IFNA(VLOOKUP($A5,'FL Ratio'!$A$3:$B$44,2,FALSE),0)*'FL Characterization'!D$2) -> 0.058949291 | E5: =('[1]Pc, Winter, S1'!E5*Main!$B$5)+(_xlfn.IFNA(VLOOKUP($A5,'FL Ratio'!$A$3:$B$44,2,FALSE),0)*'FL Characterization'!E$2) -> 0.053417995 | F5: =('[1]Pc, Winter, S1'!F5*Main!$B$5)+(_xlfn.IFNA(VLOOKUP($A5,'FL Ratio'!$A$3:$B$44,2,FALSE),0)*'FL Characterization'!F$2) -> 0.0527488 | G5: =('[1]Pc, Winter, S1'!G5*Main!$B$5)+(_xlfn.IFNA(VLOOKUP($A5,'FL Ratio'!$A$3:$B$44,2,FALSE),0)*'FL Characterization'!G$2) -> 0.092977137 | H5: =('[1]Pc, Winter, S1'!H5*Main!$B$5)+(_xlfn.IFNA(VLOOKUP($A5,'FL Ratio'!$A$3:$B$44,2,FALSE),0)*'FL Characterization'!H$2) -> 0.17827496 | I5: =('[1]Pc, Winter, S1'!I5*Main!$B$5)+(_xlfn.IFNA(VLOOKUP($A5,'FL Ratio'!$A$3:$B$44,2,FALSE),0)*'FL Characterization'!I$2) -> 0.20824353 | ... Y5: =('[1]Pc, Winter, S1'!Y5*Main!$B$5)+(_xlfn.IFNA(VLOOKUP($A5,'FL Ratio'!$A$3:$B$44,2,FALSE),0)*'FL Characterization'!Y$2) -> 0.14297626
A6: 5 | B6: =('[1]Pc, Winter, S1'!B6*Main!$B$5)+(_xlfn.IFNA(VLOOKUP($A6,'FL Ratio'!$A$3:$B$44,2,FALSE),0)*'FL Characterization'!B$2) -> 0.40145888 | C6: =('[1]Pc, Winter, S1'!C6*Main!$B$5)+(_xlfn.IFNA(VLOOKUP($A6,'FL Ratio'!$A$3:$B$44,2,FALSE),0)*'FL Characterization'!C$2) -> 0.3672713 | D6: =('[1]Pc, Winter, S1'!D6*Main!$B$5)+(_xlfn.IFNA(VLOOKUP($A6,'FL Ratio'!$A$3:$B$44,2,FALSE),0)*'FL Characterization'!D$2) -> 0.33619562 | E6: =('[1]Pc, Winter, S1'!E6*Main!$B$5)+(_xlfn.IFNA(VLOOKUP($A6,'FL Ratio'!$A$3:$B$44,2,FALSE),0)*'FL Characterization'!E$2) -> 0.33956445 | F6: =('[1]Pc, Winter, S1'!F6*Main!$B$5)+(_xlfn.IFNA(VLOOKUP($A6,'FL Ratio'!$A$3:$B$44,2,FALSE),0)*'FL Characterization'!F$2) -> 0.34408902 | G6: =('[1]Pc, Winter, S1'!G6*Main!$B$5)+(_xlfn.IFNA(VLOOKUP($A6,'FL Ratio'!$A$3:$B$44,2,FALSE),0)*'FL Characterization'!G$2) -> 0.38424228 | H6: =('[1]Pc, Winter, S1'!H6*Main!$B$5)+(_xlfn.IFNA(VLOOKUP($A6,'FL Ratio'!$A$3:$B$44,2,FALSE),0)*'FL Characterization'!H$2) -> 0.49596683 | I6: =('[1]Pc, Winter, S1'!I6*Main!$B$5)+(_xlfn.IFNA(VLOOKUP($A6,'FL Ratio'!$A$3:$B$44,2,FALSE),0)*'FL Characterization'!I$2) -> 0.53738668 | ... Y6: =('[1]Pc, Winter, S1'!Y6*Main!$B$5)+(_xlfn.IFNA(VLOOKUP($A6,'FL Ratio'!$A$3:$B$44,2,FALSE),0)*'FL Characterization'!Y$2) -> 0.50539268
A7: 6 | B7: =('[1]Pc, Winter, S1'!B7*Main!$B$5)+(_xlfn.IFNA(VLOOKUP($A7,'FL Ratio'!$A$3:$B$44,2,FALSE),0)*'FL Characterization'!B$2) -> 2.8457179 | C7: =('[1]Pc, Winter, S1'!C7*Main!$B$5)+(_xlfn.IFNA(VLOOKUP($A7,'FL Ratio'!$A$3:$B$44,2,FALSE),0)*'FL Characterization'!C$2) -> 2.6810967 | D7: =('[1]Pc, Winter, S1'!D7*Main!$B$5)+(_xlfn.IFNA(VLOOKUP($A7,'FL Ratio'!$A$3:$B$44,2,FALSE),0)*'FL Characterization'!D$2) -> 2.6082787 | E7: =('[1]Pc, Winter, S1'!E7*Main!$B$5)+(_xlfn.IFNA(VLOOKUP($A7,'FL Ratio'!$A$3:$B$44,2,FALSE),0)*'FL Characterization'!E$2) -> 2.6366452 | F7: =('[1]Pc, Winter, S1'!F7*Main!$B$5)+(_xlfn.IFNA(VLOOKUP($A7,'FL Ratio'!$A$3:$B$44,2,FALSE),0)*'FL Characterization'!F$2) -> 2.6559213 | G7: =('[1]Pc, Winter, S1'!G7*Main!$B$5)+(_xlfn.IFNA(VLOOKUP($A7,'FL Ratio'!$A$3:$B$44,2,FALSE),0)*'FL Characterization'!G$2) -> 2.8685645 | H7: =('[1]Pc, Winter, S1'!H7*Main!$B$5)+(_xlfn.IFNA(VLOOKUP($A7,'FL Ratio'!$A$3:$B$44,2,FALSE),0)*'FL Characterization'!H$2) -> 3.2435491 | I7: =('[1]Pc, Winter, S1'!I7*Main!$B$5)+(_xlfn.IFNA(VLOOKUP($A7,'FL Ratio'!$A$3:$B$44,2,FALSE),0)*'FL Characterization'!I$2) -> 3.8890018 | ... Y7: =('[1]Pc, Winter, S1'!Y7*Main!$B$5)+(_xlfn.IFNA(VLOOKUP($A7,'FL Ratio'!$A$3:$B$44,2,FALSE),0)*'FL Characterization'!Y$2) -> 2.991045
A8: 7 | B8: =('[1]Pc, Winter, S1'!B8*Main!$B$5)+(_xlfn.IFNA(VLOOKUP($A8,'FL Ratio'!$A$3:$B$44,2,FALSE),0)*'FL Characterization'!B$2) -> 1.1785864 | C8: =('[1]Pc, Winter, S1'!C8*Main!$B$5)+(_xlfn.IFNA(VLOOKUP($A8,'FL Ratio'!$A$3:$B$44,2,FALSE),0)*'FL Characterization'!C$2) -> 1.0926081 | D8: =('[1]Pc, Winter, S1'!D8*Main!$B$5)+(_xlfn.IFNA(VLOOKUP($A8,'FL Ratio'!$A$3:$B$44,2,FALSE),0)*'FL Characterization'!D$2) -> 1.0777042 | E8: =('[1]Pc, Winter, S1'!E8*Main!$B$5)+(_xlfn.IFNA(VLOOKUP($A8,'FL Ratio'!$A$3:$B$44,2,FALSE),0)*'FL Characterization'!E$2) -> 1.0541574 | F8: =('[1]Pc, Winter, S1'!F8*Main!$B$5)+(_xlfn.IFNA(VLOOKUP($A8,'FL Ratio'!$A$3:$B$44,2,FALSE),0)*'FL Characterization'!F$2) -> 1.0802379 | G8: =('[1]Pc, Winter, S1'!G8*Main!$B$5)+(_xlfn.IFNA(VLOOKUP($A8,'FL Ratio'!$A$3:$B$44,2,FALSE),0)*'FL Characterization'!G$2) -> 1.2292647 | H8: =('[1]Pc, Winter, S1'!H8*Main!$B$5)+(_xlfn.IFNA(VLOOKUP($A8,'FL Ratio'!$A$3:$B$44,2,FALSE),0)*'FL Characterization'!H$2) -> 1.5592714 | I8: =('[1]Pc, Winter, S1'!I8*Main!$B$5)+(_xlfn.IFNA(VLOOKUP($A8,'FL Ratio'!$A$3:$B$44,2,FALSE),0)*'FL Characterization'!I$2) -> 1.8621812 | ... Y8: =('[1]Pc, Winter, S1'!Y8*Main!$B$5)+(_xlfn.IFNA(VLOOKUP($A8,'FL Ratio'!$A$3:$B$44,2,FALSE),0)*'FL Characterization'!Y$2) -> 1.3420995
A9: 8 | B9: =('[1]Pc, Winter, S1'!B9*Main!$B$5)+(_xlfn.IFNA(VLOOKUP($A9,'FL Ratio'!$A$3:$B$44,2,FALSE),0)*'FL Characterization'!B$2) -> 0.24263038 | C9: =('[1]Pc, Winter, S1'!C9*Main!$B$5)+(_xlfn.IFNA(VLOOKUP($A9,'FL Ratio'!$A$3:$B$44,2,FALSE),0)*'FL Characterization'!C$2) -> 0.23132727 | D9: =('[1]Pc, Winter, S1'!D9*Main!$B$5)+(_xlfn.IFNA(VLOOKUP($A9,'FL Ratio'!$A$3:$B$44,2,FALSE),0)*'FL Characterization'!D$2) -> 0.22474155 | E9: =('[1]Pc, Winter, S1'!E9*Main!$B$5)+(_xlfn.IFNA(VLOOKUP($A9,'FL Ratio'!$A$3:$B$44,2,FALSE),0)*'FL Characterization'!E$2) -> 0.22166686 | F9: =('[1]Pc, Winter, S1'!F9*Main!$B$5)+(_xlfn.IFNA(VLOOKUP($A9,'FL Ratio'!$A$3:$B$44,2,FALSE),0)*'FL Characterization'!F$2) -> 0.23124421 | G9: =('[1]Pc, Winter, S1'!G9*Main!$B$5)+(_xlfn.IFNA(VLOOKUP($A9,'FL Ratio'!$A$3:$B$44,2,FALSE),0)*'FL Characterization'!G$2) -> 0.27751271 | H9: =('[1]Pc, Winter, S1'!H9*Main!$B$5)+(_xlfn.IFNA(VLOOKUP($A9,'FL Ratio'!$A$3:$B$44,2,FALSE),0)*'FL Characterization'!H$2) -> 0.45139351 | I9: =('[1]Pc, Winter, S1'!I9*Main!$B$5)+(_xlfn.IFNA(VLOOKUP($A9,'FL Ratio'!$A$3:$B$44,2,FALSE),0)*'FL Characterization'!I$2) -> 0.52982963 | ... Y9: =('[1]Pc, Winter, S1'!Y9*Main!$B$5)+(_xlfn.IFNA(VLOOKUP($A9,'FL Ratio'!$A$3:$B$44,2,FALSE),0)*'FL Characterization'!Y$2) -> 0.28557101
A10: 9 | B10: =('[1]Pc, Winter, S1'!B10*Main!$B$5)+(_xlfn.IFNA(VLOOKUP($A10,'FL Ratio'!$A$3:$B$44,2,FALSE),0)*'FL Characterization'!B$2) -> 0.2613613 | C10: =('[1]Pc, Winter, S1'!C10*Main!$B$5)+(_xlfn.IFNA(VLOOKUP($A10,'FL Ratio'!$A$3:$B$44,2,FALSE),0)*'FL Characterization'!C$2) -> 0.26193219 | D10: =('[1]Pc, Winter, S1'!D10*Main!$B$5)+(_xlfn.IFNA(VLOOKUP($A10,'FL Ratio'!$A$3:$B$44,2,FALSE),0)*'FL Characterization'!D$2) -> 0.26008304 | E10: =('[1]Pc, Winter, S1'!E10*Main!$B$5)+(_xlfn.IFNA(VLOOKUP($A10,'FL Ratio'!$A$3:$B$44,2,FALSE),0)*'FL Characterization'!E$2) -> 0.25925733 | F10: =('[1]Pc, Winter, S1'!F10*Main!$B$5)+(_xlfn.IFNA(VLOOKUP($A10,'FL Ratio'!$A$3:$B$44,2,FALSE),0)*'FL Characterization'!F$2) -> 0.25654488 | G10: =('[1]Pc, Winter, S1'!G10*Main!$B$5)+(_xlfn.IFNA(VLOOKUP($A10,'FL Ratio'!$A$3:$B$44,2,FALSE),0)*'FL Characterization'!G$2) -> 0.25468459 | H10: =('[1]Pc, Winter, S1'!H10*Main!$B$5)+(_xlfn.IFNA(VLOOKUP($A10,'FL Ratio'!$A$3:$B$44,2,FALSE),0)*'FL Characterization'!H$2) -> 0.25701134 | I10: =('[1]Pc, Winter, S1'!I10*Main!$B$5)+(_xlfn.IFNA(VLOOKUP($A10,'FL Ratio'!$A$3:$B$44,2,FALSE),0)*'FL Characterization'!I$2) -> 0.24646369 | ... Y10: =('[1]Pc, Winter, S1'!Y10*Main!$B$5)+(_xlfn.IFNA(VLOOKUP($A10,'FL Ratio'!$A$3:$B$44,2,FALSE),0)*'FL Characterization'!Y$2) -> 0.25992988
A11: 10 | B11: =('[1]Pc, Winter, S1'!B11*Main!$B$5)+(_xlfn.IFNA(VLOOKUP($A11,'FL Ratio'!$A$3:$B$44,2,FALSE),0)*'FL Characterization'!B$2) -> 0.45083405 | C11: =('[1]Pc, Winter, S1'!C11*Main!$B$5)+(_xlfn.IFNA(VLOOKUP($A11,'FL Ratio'!$A$3:$B$44,2,FALSE),0)*'FL Characterization'!C$2) -> 0.41754366 | D11: =('[1]Pc, Winter, S1'!D11*Main!$B$5)+(_xlfn.IFNA(VLOOKUP($A11,'FL Ratio'!$A$3:$B$44,2,FALSE),0)*'FL Characterization'!D$2) -> 0.39750618 | E11: =('[1]Pc, Winter, S1'!E11*Main!$B$5)+(_xlfn.IFNA(VLOOKUP($A11,'FL Ratio'!$A$3:$B$44,2,FALSE),0)*'FL Characterization'!E$2) -> 0.40073728 | F11: =('[1]Pc, Winter, S1'!F11*Main!$B$5)+(_xlfn.IFNA(VLOOKUP($A11,'FL Ratio'!$A$3:$B$44,2,FALSE),0)*'FL Characterization'!F$2) -> 0.40183407 | G11: =('[1]Pc, Winter, S1'!G11*Main!$B$5)+(_xlfn.IFNA(VLOOKUP($A11,'FL Ratio'!$A$3:$B$44,2,FALSE),0)*'FL Characterization'!G$2) -> 0.45992958 | H11: =('[1]Pc, Winter, S1'!H11*Main!$B$5)+(_xlfn.IFNA(VLOOKUP($A11,'FL Ratio'!$A$3:$B$44,2,FALSE),0)*'FL Characterization'!H$2) -> 0.60089666 | I11: =('[1]Pc, Winter, S1'!I11*Main!$B$5)+(_xlfn.IFNA(VLOOKUP($A11,'FL Ratio'!$A$3:$B$44,2,FALSE),0)*'FL Characterization'!I$2) -> 0.69404177 | ... Y11: =('[1]Pc, Winter, S1'!Y11*Main!$B$5)+(_xlfn.IFNA(VLOOKUP($A11,'FL Ratio'!$A$3:$B$44,2,FALSE),0)*'FL Characterization'!Y$2) -> 0.5492113
A12: 11 | B12: =('[1]Pc, Winter, S1'!B12*Main!$B$5)+(_xlfn.IFNA(VLOOKUP($A12,'FL Ratio'!$A$3:$B$44,2,FALSE),0)*'FL Characterization'!B$2) -> 0.24109014 | C12: =('[1]Pc, Winter, S1'!C12*Main!$B$5)+(_xlfn.IFNA(VLOOKUP($A12,'FL Ratio'!$A$3:$B$44,2,FALSE),0)*'FL Characterization'!C$2) -> 0.2227483 | D12: =('[1]Pc, Winter, S1'!D12*Main!$B$5)+(_xlfn.IFNA(VLOOKUP($A12,'FL Ratio'!$A$3:$B$44,2,FALSE),0)*'FL Characterization'!D$2) -> 0.21066114 | E12: =('[1]Pc, Winter, S1'!E12*Main!$B$5)+(_xlfn.IFNA(VLOOKUP($A12,'FL Ratio'!$A$3:$B$44,2,FALSE),0)*'FL Characterization'!E$2) -> 0.20884754 | F12: =('[1]Pc, Winter, S1'!F12*Main!$B$5)+(_xlfn.IFNA(VLOOKUP($A12,'FL Ratio'!$A$3:$B$44,2,FALSE),0)*'FL Characterization'!F$2) -> 0.21219017 | G12: =('[1]Pc, Winter, S1'!G12*Main!$B$5)+(_xlfn.IFNA(VLOOKUP($A12,'FL Ratio'!$A$3:$B$44,2,FALSE),0)*'FL Characterization'!G$2) -> 0.25887408 | H12: =('[1]Pc, Winter, S1'!H12*Main!$B$5)+(_xlfn.IFNA(VLOOKUP($A12,'FL Ratio'!$A$3:$B$44,2,FALSE),0)*'FL Characterization'!H$2) -> 0.344045 | I12: =('[1]Pc, Winter, S1'!I12*Main!$B$5)+(_xlfn.IFNA(VLOOKUP($A12,'FL Ratio'!$A$3:$B$44,2,FALSE),0)*'FL Characterization'!I$2) -> 0.36839266 | ... Y12: =('[1]Pc, Winter, S1'!Y12*Main!$B$5)+(_xlfn.IFNA(VLOOKUP($A12,'FL Ratio'!$A$3:$B$44,2,FALSE),0)*'FL Characterization'!Y$2) -> 0.31149301
A13: 12 | B13: =('[1]Pc, Winter, S1'!B13*Main!$B$5)+(_xlfn.IFNA(VLOOKUP($A13,'FL Ratio'!$A$3:$B$44,2,FALSE),0)*'FL Characterization'!B$2) -> 0.91669443 | C13: =('[1]Pc, Winter, S1'!C13*Main!$B$5)+(_xlfn.IFNA(VLOOKUP($A13,'FL Ratio'!$A$3:$B$44,2,FALSE),0)*'FL Characterization'!C$2) -> 0.91297859 | D13: =('[1]Pc, Winter, S1'!D13*Main!$B$5)+(_xlfn.IFNA(VLOOKUP($A13,'FL Ratio'!$A$3:$B$44,2,FALSE),0)*'FL Characterization'!D$2) -> 0.91075585 | E13: =('[1]Pc, Winter, S1'!E13*Main!$B$5)+(_xlfn.IFNA(VLOOKUP($A13,'FL Ratio'!$A$3:$B$44,2,FALSE),0)*'FL Characterization'!E$2) -> 0.93606156 | F13: =('[1]Pc, Winter, S1'!F13*Main!$B$5)+(_xlfn.IFNA(VLOOKUP($A13,'FL Ratio'!$A$3:$B$44,2,FALSE),0)*'FL Characterization'!F$2) -> 0.92902033 | G13: =('[1]Pc, Winter, S1'!G13*Main!$B$5)+(_xlfn.IFNA(VLOOKUP($A13,'FL Ratio'!$A$3:$B$44,2,FALSE),0)*'FL Characterization'!G$2) -> 0.95231674 | H13: =('[1]Pc, Winter, S1'!H13*Main!$B$5)+(_xlfn.IFNA(VLOOKUP($A13,'FL Ratio'!$A$3:$B$44,2,FALSE),0)*'FL Characterization'!H$2) -> 0.99042794 | I13: =('[1]Pc, Winter, S1'!I13*Main!$B$5)+(_xlfn.IFNA(VLOOKUP($A13,'FL Ratio'!$A$3:$B$44,2,FALSE),0)*'FL Characterization'!I$2) -> 0.95022929 | ... Y13: =('[1]Pc, Winter, S1'!Y13*Main!$B$5)+(_xlfn.IFNA(VLOOKUP($A13,'FL Ratio'!$A$3:$B$44,2,FALSE),0)*'FL Characterization'!Y$2) -> 1.1250761
... A33: 32 | B33: =('[1]Pc, Winter, S1'!B33*Main!$B$5)+(_xlfn.IFNA(VLOOKUP($A33,'FL Ratio'!$A$3:$B$44,2,FALSE),0)*'FL Characterization'!B$2) -> 1.1548917 | C33: =('[1]Pc, Winter, S1'!C33*Main!$B$5)+(_xlfn.IFNA(VLOOKUP($A33,'FL Ratio'!$A$3:$B$44,2,FALSE),0)*'FL Characterization'!C$2) -> 1.0875208 | D33: =('[1]Pc, Winter, S1'!D33*Main!$B$5)+(_xlfn.IFNA(VLOOKUP($A33,'FL Ratio'!$A$3:$B$44,2,FALSE),0)*'FL Characterization'!D$2) -> 1.0584767 | E33: =('[1]Pc, Winter, S1'!E33*Main!$B$5)+(_xlfn.IFNA(VLOOKUP($A33,'FL Ratio'!$A$3:$B$44,2,FALSE),0)*'FL Characterization'!E$2) -> 1.0703475 | F33: =('[1]Pc, Winter, S1'!F33*Main!$B$5)+(_xlfn.IFNA(VLOOKUP($A33,'FL Ratio'!$A$3:$B$44,2,FALSE),0)*'FL Characterization'!F$2) -> 1.0791886 | G33: =('[1]Pc, Winter, S1'!G33*Main!$B$5)+(_xlfn.IFNA(VLOOKUP($A33,'FL Ratio'!$A$3:$B$44,2,FALSE),0)*'FL Characterization'!G$2) -> 1.1666168 | H33: =('[1]Pc, Winter, S1'!H33*Main!$B$5)+(_xlfn.IFNA(VLOOKUP($A33,'FL Ratio'!$A$3:$B$44,2,FALSE),0)*'FL Characterization'!H$2) -> 1.3187729 | I33: =('[1]Pc, Winter, S1'!I33*Main!$B$5)+(_xlfn.IFNA(VLOOKUP($A33,'FL Ratio'!$A$3:$B$44,2,FALSE),0)*'FL Characterization'!I$2) -> 1.5859147 | ... Y33: =('[1]Pc, Winter, S1'!Y33*Main!$B$5)+(_xlfn.IFNA(VLOOKUP($A33,'FL Ratio'!$A$3:$B$44,2,FALSE),0)*'FL Characterization'!Y$2) -> 1.2147005

Sheet Pc, Winter, S4
A1: LoadID | B1: 0 | C1: 1 | D1: 2 | E1: 3 | F1: 4 | G1: 5 | H1: 6 | I1: 7 | J1: 8 | K1: 9 | L1: 10 | M1: 11 | N1: 12 | O1: 13 | P1: 14 | Q1: 15 | R1: 16 | S1: 17 | T1: 18 | U1: 19 | V1: 20 | W1: 21 | X1: 22 | Y1: 23
A2: 1 | B2: =('[1]Pc, Winter, S2'!B2*Main!$B$5)+(_xlfn.IFNA(VLOOKUP($A2,'FL Ratio'!$A$3:$B$44,2,FALSE),0)*'FL Characterization'!B$2) -> 1.31177 | C2: =('[1]Pc, Winter, S2'!C2*Main!$B$5)+(_xlfn.IFNA(VLOOKUP($A2,'FL Ratio'!$A$3:$B$44,2,FALSE),0)*'FL Characterization'!C$2) -> 1.2627477 | D2: =('[1]Pc, Winter, S2'!D2*Main!$B$5)+(_xlfn.IFNA(VLOOKUP($A2,'FL Ratio'!$A$3:$B$44,2,FALSE),0)*'FL Characterization'!D$2) -> 1.2177698 | E2: =('[1]Pc, Winter, S2'!E2*Main!$B$5)+(_xlfn.IFNA(VLOOKUP($A2,'FL Ratio'!$A$3:$B$44,2,FALSE),0)*'FL Characterization'!E$2) -> 1.2545246 | F2: =('[1]Pc, Winter, S2'!F2*Main!$B$5)+(_xlfn.IFNA(VLOOKUP($A2,'FL Ratio'!$A$3:$B$44,2,FALSE),0)*'FL Characterization'!F$2) -> 1.2191247 | G2: =('[1]Pc, Winter, S2'!G2*Main!$B$5)+(_xlfn.IFNA(VLOOKUP($A2,'FL Ratio'!$A$3:$B$44,2,FALSE),0)*'FL Characterization'!G$2) -> 1.2207485 | H2: =('[1]Pc, Winter, S2'!H2*Main!$B$5)+(_xlfn.IFNA(VLOOKUP($A2,'FL Ratio'!$A$3:$B$44,2,FALSE),0)*'FL Characterization'!H$2) -> 1.232016 | I2: =('[1]Pc, Winter, S2'!I2*Main!$B$5)+(_xlfn.IFNA(VLOOKUP($A2,'FL Ratio'!$A$3:$B$44,2,FALSE),0)*'FL Characterization'!I$2) -> 1.5991524 | ... Y2: =('[1]Pc, Winter, S2'!Y2*Main!$B$5)+(_xlfn.IFNA(VLOOKUP($A2,'FL Ratio'!$A$3:$B$44,2,FALSE),0)*'FL Characterization'!Y$2) -> 1.2141529
A3: 2 | B3: =('[1]Pc, Winter, S2'!B3*Main!$B$5)+(_xlfn.IFNA(VLOOKUP($A3,'FL Ratio'!$A$3:$B$44,2,FALSE),0)*'FL Characterization'!B$2) -> 0.71109485 | C3: =('[1]Pc, Winter, S2'!C3*Main!$B$5)+(_xlfn.IFNA(VLOOKUP($A3,'FL Ratio'!$A$3:$B$44,2,FALSE),0)*'FL Characterization'!C$2) -> 0.69244388 | D3: =('[1]Pc, Winter, S2'!D3*Main!$B$5)+(_xlfn.IFNA(VLOOKUP($A3,'FL Ratio'!$A$3:$B$44,2,FALSE),0)*'FL Characterization'!D$2) -> 0.66138467 | E3: =('[1]Pc, Winter, S2'!E3*Main!$B$5)+(_xlfn.IFNA(VLOOKUP($A3,'FL Ratio'!$A$3:$B$44,2,FALSE),0)*'FL Characterization'!E$2) -> 0.65486639 | F3: =('[1]Pc, Winter, S2'!F3*Main!$B$5)+(_xlfn.IFNA(VLOOKUP($A3,'FL Ratio'!$A$3:$B$44,2,FALSE),0)*'FL Characterization'!F$2) -> 0.6571517 | G3: =('[1]Pc, Winter, S2'!G3*Main!$B$5)+(_xlfn.IFNA(VLOOKUP($A3,'FL Ratio'!$A$3:$B$44,2,FALSE),0)*'FL Characterization'!G$2) -> 0.69760949 | H3: =('[1]Pc, Winter, S2'!H3*Main!$B$5)+(_xlfn.IFNA(VLOOKUP($A3,'FL Ratio'!$A$3:$B$44,2,FALSE),0)*'FL Characterization'!H$2) -> 0.84127648 | I3: =('[1]Pc, Winter, S2'!I3*Main!$B$5)+(_xlfn.IFNA(VLOOKUP($A3,'FL Ratio'!$A$3:$B$44,2,FALSE),0)*'FL Characterization'!I$2) -> 0.96312983 | ... Y3: =('[1]Pc, Winter, S2'!Y3*Main!$B$5)+(_xlfn.IFNA(VLOOKUP($A3,'FL Ratio'!$A$3:$B$44,2,FALSE),0)*'FL Characterization'!Y$2) -> 0.81270394
A4: 3 | B4: =('[1]Pc, Winter, S2'!B4*Main!$B$5)+(_xlfn.IFNA(VLOOKUP($A4,'FL Ratio'!$A$3:$B$44,2,FALSE),0)*'FL Characterization'!B$2) -> 1.5645146 | C4: =('[1]Pc, Winter, S2'!C4*Main!$B$5)+(_xlfn.IFNA(VLOOKUP($A4,'FL Ratio'!$A$3:$B$44,2,FALSE),0)*'FL Characterization'!C$2) -> 1.4742007 | D4: =('[1]Pc, Winter, S2'!D4*Main!$B$5)+(_xlfn.IFNA(VLOOKUP($A4,'FL Ratio'!$A$3:$B$44,2,FALSE),0)*'FL Characterization'!D$2) -> 1.4239936 | E4: =('[1]Pc, Winter, S2'!E4*Main!$B$5)+(_xlfn.IFNA(VLOOKUP($A4,'FL Ratio'!$A$3:$B$44,2,FALSE),0)*'FL Characterization'!E$2) -> 1.4514667 | F4: =('[1]Pc, Winter, S2'!F4*Main!$B$5)+(_xlfn.IFNA(VLOOKUP($A4,'FL Ratio'!$A$3:$B$44,2,FALSE),0)*'FL Characterization'!F$2) -> 1.4594138 | G4: =('[1]Pc, Winter, S2'!G4*Main!$B$5)+(_xlfn.IFNA(VLOOKUP($A4,'FL Ratio'!$A$3:$B$44,2,FALSE),0)*'FL Characterization'!G$2) -> 1.661388 | H4: =('[1]Pc, Winter, S2'!H4*Main!$B$5)+(_xlfn.IFNA(VLOOKUP($A4,'FL Ratio'!$A$3:$B$44,2,FALSE),0)*'FL Characterization'!H$2) -> 2.6749603 | I4: =('[1]Pc, Winter, S2'!I4*Main!$B$5)+(_xlfn.IFNA(VLOOKUP($A4,'FL Ratio'!$A$3:$B$44,2,FALSE),0)*'FL Characterization'!I$2) -> 3.1107749 | ... Y4: =('[1]Pc, Winter, S2'!Y4*Main!$B$5)+(_xlfn.IFNA(VLOOKUP($A4,'FL Ratio'!$A$3:$B$44,2,FALSE),0)*'FL Characterization'!Y$2) -> 1.7819641
A5: 4 | B5: =('[1]Pc, Winter, S2'!B5*Main!$B$5)+(_xlfn.IFNA(VLOOKUP($A5,'FL Ratio'!$A$3:$B$44,2,FALSE),0)*'FL Characterization'!B$2) -> 0.08609457 | C5: =('[1]Pc, Winter, S2'!C5*Main!$B$5)+(_xlfn.IFNA(VLOOKUP($A5,'FL Ratio'!$A$3:$B$44,2,FALSE),0)*'FL Characterization'!C$2) -> 0.062501795 | D5: =('[1]Pc, Winter, S2'!D5*Main!$B$5)+(_xlfn.IFNA(VLOOKUP($A5,'FL Ratio'!$A$3:$B$44,2,FALSE),0)*'FL Characterization'!D$2) -> 0.060673818 | E5: =('[1]Pc, Winter, S2'!E5*Main!$B$5)+(_xlfn.IFNA(VLOOKUP($A5,'FL Ratio'!$A$3:$B$44,2,FALSE),0)*'FL Characterization'!E$2) -> 0.054954299 | F5: =('[1]Pc, Winter, S2'!F5*Main!$B$5)+(_xlfn.IFNA(VLOOKUP($A5,'FL Ratio'!$A$3:$B$44,2,FALSE),0)*'FL Characterization'!F$2) -> 0.054366835 | G5: =('[1]Pc, Winter, S2'!G5*Main!$B$5)+(_xlfn.IFNA(VLOOKUP($A5,'FL Ratio'!$A$3:$B$44,2,FALSE),0)*'FL Characterization'!G$2) -> 0.096278717 | H5: =('[1]Pc, Winter, S2'!H5*Main!$B$5)+(_xlfn.IFNA(VLOOKUP($A5,'FL Ratio'!$A$3:$B$44,2,FALSE),0)*'FL Characterization'!H$2) -> 0.18489538 | I5: =('[1]Pc, Winter, S2'!I5*Main!$B$5)+(_xlfn.IFNA(VLOOKUP($A5,'FL Ratio'!$A$3:$B$44,2,FALSE),0)*'FL Characterization'!I$2) -> 0.2164846 | ... Y5: =('[1]Pc, Winter, S2'!Y5*Main!$B$5)+(_xlfn.IFNA(VLOOKUP($A5,'FL Ratio'!$A$3:$B$44,2,FALSE),0)*'FL Characterization'!Y$2) -> 0.14806799
