Workbook

Sheet Main
A1: numScenarios | B1: 1 | C1: =1/$B$1 -> 1 | D1: =1/$B$1 -> 1 | E1: =1/$B$1 -> 1 | F1: =1/$B$1 -> 1 | G1: =1/$B$1 -> 1 | H1: =1/$B$1 -> 1 | I1: =1/$B$1 -> 1 | J1: =1/$B$1 -> 1 | K1: =1/$B$1 -> 1
A3: Year | B3: 2043
A4: Load Scale Factor | B4: 1
A5: Load Growth (cumul.) | B5: =((1+[1]Main!$B$2)^($B$3-2020))*$B$4 -> 1.257163
A6: Flex. Load Growth | B6: =((1+[1]Main!$B$3)^($B$3-2020))*$B$4 -> 1.7646107
A7: RES Installed, [MW] | B7: =SUM('RES installed'!$C$2:$C$7) -> 335
A8: ESS Installed, [MWh] | B8: =SUM('ES installed'!$C$2:$C$4) -> 0

Sheet RES installed
A1: GenID | B1: NodeID | C1: Pinst, [MW]
A2: 4 | B2: 4 | C2: 45
A3: 5 | B3: 6 | C3: 60
A4: 6 | B4: 8 | C4: 45
A5: 7 | B5: 4 | C5: 75
A6: 8 | B6: 6 | C6: 50
A7: 9 | B7: 8 | C7: 60

Sheet ES installed
A1: ESS ID | B1: Node ID | C1: Pinst, [MW]
A2: 1 | B2: N/A | C2: 0
A3: 2 | B3: N/A | C3: 0
A4: 3 | B4: N/A | C4: 0

Sheet FL Ratio
A1: LoadID | B1: Ratio, [%]
A2: 1 | B2: =1/COUNT($A$2:$A$21) -> 0.33333333
A3: 2 | B3: =1/COUNT($A$2:$A$21) -> 0.33333333
A4: 3 | B4: =1/COUNT($A$2:$A$21) -> 0.33333333

Sheet FL Characterization
A1: Time | B1: 0 | C1: 1 | D1: 2 | E1: 3 | F1: 4 | G1: 5 | H1: 6 | I1: 7 | J1: 8 | K1: 9 | L1: 10 | M1: 11 | N1: 12 | O1: 13 | P1: 14 | Q1: 15 | R1: 16 | S1: 17 | T1: 18 | U1: 19 | V1: 20 | W1: 21 | X1: 22 | Y1: 23
A2: FL, [MW] | B2: ='[1]EV Profiles'!B2*Main!$B$6 -> 8.675532 | C2: ='[1]EV Profiles'!C2*Main!$B$6 -> 8.9649281 | D2: ='[1]EV Profiles'!D2*Main!$B$6 -> 8.0275669 | E2: ='[1]EV Profiles'!E2*Main!$B$6 -> 7.6090013 | F2: ='[1]EV Profiles'!F2*Main!$B$6 -> 6.2340166 | G2: ='[1]EV Profiles'!G2*Main!$B$6 -> 5.2910087 | H2: ='[1]EV Profiles'!H2*Main!$B$6 -> 6.4704745 | I2: ='[1]EV Profiles'!I2*Main!$B$6 -> 1.1237041 | ... Y2: ='[1]EV Profiles'!Y2*Main!$B$6 -> 7.949924
A3: Minimum FL, [MW] | B3: ='[1]EV Profiles'!B3*Main!$B$6 -> -19.587179 | C3: ='[1]EV Profiles'!C3*Main!$B$6 -> -20.945223 | D3: ='[1]EV Profiles'!D3*Main!$B$6 -> -23.556847 | E3: ='[1]EV Profiles'!E3*Main!$B$6 -> -25.4111 | F3: ='[1]EV Profiles'!F3*Main!$B$6 -> -27.160888 | G3: ='[1]EV Profiles'!G3*Main!$B$6 -> -29.64193 | H3: ='[1]EV Profiles'!H3*Main!$B$6 -> -28.283886 | I3: ='[1]EV Profiles'!I3*Main!$B$6 -> -31.727277 | ... Y3: ='[1]EV Profiles'!Y3*Main!$B$6 -> -17.28895
A4: Maximum FL, [MW] | B4: ='[1]EV Profiles'!B4*Main!$B$6 -> 18.86997 | C4: ='[1]EV Profiles'!C4*Main!$B$6 -> 20.187711 | D4: ='[1]EV Profiles'!D4*Main!$B$6 -> 22.635085 | E4: ='[1]EV Profiles'!E4*Main!$B$6 -> 24.355933 | F4: ='[1]EV Profiles'!F4*Main!$B$6 -> 25.924601 | G4: ='[1]EV Profiles'!G4*Main!$B$6 -> 28.307885 | H4: ='[1]EV Profiles'!H4*Main!$B$6 -> 26.987956 | I4: ='[1]EV Profiles'!I4*Main!$B$6 -> 30.455698 | ... Y4: ='[1]EV Profiles'!Y4*Main!$B$6 -> 16.666395

Sheet Pc, Winter, S1
A1: LoadID | B1: 0 | C1: 1 | D1: 2 | E1: 3 | F1: 4 | G1: 5 | H1: 6 | I1: 7 | J1: 8 | K1: 9 | L1: 10 | M1: 11 | N1: 12 | O1: 13 | P1: 14 | Q1: 15 | R1: 16 | S1: 17 | T1: 18 | U1: 19 | V1: 20 | W1: 21 | X1: 22 | Y1: 23
A2: 1 | B2: =('[1]Pc, Winter, S1'!B2*Main!$B$5)+(_xlfn.IFNA(VLOOKUP($A2,'FL Ratio'!$A$3:$B$10,2,FALSE),0)*'FL Characterization'!B$2) -> 36.006041 | C2: =('[1]Pc, Winter, S1'!C2*Main!$B$5)+(_xlfn.IFNA(VLOOKUP($A2,'FL Ratio'!$A$3:$B$10,2,FALSE),0)*'FL Characterization'!C$2) -> 33.584574 | D2: =('[1]Pc, Winter, S1'!D2*Main!$B$5)+(_xlfn.IFNA(VLOOKUP($A2,'FL Ratio'!$A$3:$B$10,2,FALSE),0)*'FL Characterization'!D$2) -> 31.822416 | E2: =('[1]Pc, Winter, S1'!E2*Main!$B$5)+(_xlfn.IFNA(VLOOKUP($A2,'FL Ratio'!$A$3:$B$10,2,FALSE),0)*'FL Characterization'!E$2) -> 31.597254 | F2: =('[1]Pc, Winter, S1'!F2*Main!$B$5)+(_xlfn.IFNA(VLOOKUP($A2,'FL Ratio'!$A$3:$B$10,2,FALSE),0)*'FL Characterization'!F$2) -> 31.978389 | G2: =('[1]Pc, Winter, S1'!G2*Main!$B$5)+(_xlfn.IFNA(VLOOKUP($A2,'FL Ratio'!$A$3:$B$10,2,FALSE),0)*'FL Characterization'!G$2) -> 35.151154 | H2: =('[1]Pc, Winter, S1'!H2*Main!$B$5)+(_xlfn.IFNA(VLOOKUP($A2,'FL Ratio'!$A$3:$B$10,2,FALSE),0)*'FL Characterization'!H$2) -> 41.943893 | I2: =('[1]Pc, Winter, S1'!I2*Main!$B$5)+(_xlfn.IFNA(VLOOKUP($A2,'FL Ratio'!$A$3:$B$10,2,FALSE),0)*'FL Characterization'!I$2) -> 50.48766 | ... Y2: =('[1]Pc, Winter, S1'!Y2*Main!$B$5)+(_xlfn.IFNA(VLOOKUP($A2,'FL Ratio'!$A$3:$B$10,2,FALSE),0)*'FL Characterization'!Y$2) -> 40.356746
A3: 2 | B3: =('[1]Pc, Winter, S1'!B3*Main!$B$5)+(_xlfn.IFNA(VLOOKUP($A3,'FL Ratio'!$A$3:$B$10,2,FALSE),0)*'FL Characterization'!B$2) -> 38.49308 | C3: =('[1]Pc, Winter, S1'!C3*Main!$B$5)+(_xlfn.IFNA(VLOOKUP($A3,'FL Ratio'!$A$3:$B$10,2,FALSE),0)*'FL Characterization'!C$2) -> 36.070811 | D3: =('[1]Pc, Winter, S1'!D3*Main!$B$5)+(_xlfn.IFNA(VLOOKUP($A3,'FL Ratio'!$A$3:$B$10,2,FALSE),0)*'FL Characterization'!D$2) -> 32.613953 | E3: =('[1]Pc, Winter, S1'!E3*Main!$B$5)+(_xlfn.IFNA(VLOOKUP($A3,'FL Ratio'!$A$3:$B$10,2,FALSE),0)*'FL Characterization'!E$2) -> 34.736476 | F3: =('[1]Pc, Winter, S1'!F3*Main!$B$5)+(_xlfn.IFNA(VLOOKUP($A3,'FL Ratio'!$A$3:$B$10,2,FALSE),0)*'FL Characterization'!F$2) -> 34.165846 | G3: =('[1]Pc, Winter, S1'!G3*Main!$B$5)+(_xlfn.IFNA(VLOOKUP($A3,'FL Ratio'!$A$3:$B$10,2,FALSE),0)*'FL Characterization'!G$2) -> 35.215148 | H3: =('[1]Pc, Winter, S1'!H3*Main!$B$5)+(_xlfn.IFNA(VLOOKUP($A3,'FL Ratio'!$A$3:$B$10,2,FALSE),0)*'FL Characterization'!H$2) -> 51.940001 | I3: =('[1]Pc, Winter, S1'!I3*Main!$B$5)+(_xlfn.IFNA(VLOOKUP($A3,'FL Ratio'!$A$3:$B$10,2,FALSE),0)*'FL Characterization'!I$2) -> 55.820894 | ... Y3: =('[1]Pc, Winter, S1'!Y3*Main!$B$5)+(_xlfn.IFNA(VLOOKUP($A3,'FL Ratio'!$A$3:$B$10,2,FALSE),0)*'FL Characterization'!Y$2) -> 41.556051
A4: 3 | B4: =('[1]Pc, Winter, S1'!B4*Main!$B$5)+(_xlfn.IFNA(VLOOKUP($A4,'FL Ratio'!$A$3:$B$10,2,FALSE),0)*'FL Characterization'!B$2) -> 54.639092 | C4: =('[1]Pc, Winter, S1'!C4*Main!$B$5)+(_xlfn.IFNA(VLOOKUP($A4,'FL Ratio'!$A$3:$B$10,2,FALSE),0)*'FL Characterization'!C$2) -> 48.518888 | D4: =('[1]Pc, Winter, S1'!D4*Main!$B$5)+(_xlfn.IFNA(VLOOKUP($A4,'FL Ratio'!$A$3:$B$10,2,FALSE),0)*'FL Characterization'!D$2) -> 45.540791 | E4: =('[1]Pc, Winter, S1'!E4*Main!$B$5)+(_xlfn.IFNA(VLOOKUP($A4,'FL Ratio'!$A$3:$B$10,2,FALSE),0)*'FL Characterization'!E$2) -> 44.892228 | F4: =('[1]Pc, Winter, S1'!F4*Main!$B$5)+(_xlfn.IFNA(VLOOKUP($A4,'FL Ratio'!$A$3:$B$10,2,FALSE),0)*'FL Characterization'!F$2) -> 46.412069 | G4: =('[1]Pc, Winter, S1'!G4*Main!$B$5)+(_xlfn.IFNA(VLOOKUP($A4,'FL Ratio'!$A$3:$B$10,2,FALSE),0)*'FL Characterization'!G$2) -> 49.631324 | H4: =('[1]Pc, Winter, S1'!H4*Main!$B$5)+(_xlfn.IFNA(VLOOKUP($A4,'FL Ratio'!$A$3:$B$10,2,FALSE),0)*'FL Characterization'!H$2) -> 59.917525 | I4: =('[1]Pc, Winter, S1'!I4*Main!$B$5)+(_xlfn.IFNA(VLOOKUP($A4,'FL Ratio'!$A$3:$B$10,2,FALSE),0)*'FL Characterization'!I$2) -> 64.947311 | ... Y4: =('[1]Pc, Winter, S1'!Y4*Main!$B$5)+(_xlfn.IFNA(VLOOKUP($A4,'FL Ratio'!$A$3:$B$10,2,FALSE),0)*'FL Characterization'!Y$2) -> 61.287062

Sheet Pc, Winter, S2
A1: LoadID | B1: 0 | C1: 1 | D1: 2 | E1: 3 | F1: 4 | G1: 5 | H1: 6 | I1: 7 | J1: 8 | K1: 9 | L1: 10 | M1: 11 | N1: 12 | O1: 13 | P1: 14 | Q1: 15 | R1: 16 | S1: 17 | T1: 18 | U1: 19 | V1: 20 | W1: 21 | X1: 22 | Y1: 23
A2: 1 | B2: =('[1]Pc, Winter, S1'!B2*Main!$B$5)+(_xlfn.IFNA(VLOOKUP($A2,'FL Ratio'!$A$3:$B$10,2,FALSE),0)*'FL Characterization'!B$2) -> 36.006041 | C2: =('[1]Pc, Winter, S1'!C2*Main!$B$5)+(_xlfn.IFNA(VLOOKUP($A2,'FL Ratio'!$A$3:$B$10,2,FALSE),0)*'FL Characterization'!C$2) -> 33.584574 | D2: =('[1]Pc, Winter, S1'!D2*Main!$B$5)+(_xlfn.IFNA(VLOOKUP($A2,'FL Ratio'!$A$3:$B$10,2,FALSE),0)*'FL Characterization'!D$2) -> 31.822416 | E2: =('[1]Pc, Winter, S1'!E2*Main!$B$5)+(_xlfn.IFNA(VLOOKUP($A2,'FL Ratio'!$A$3:$B$10,2,FALSE),0)*'FL Characterization'!E$2) -> 31.597254 | F2: =('[1]Pc, Winter, S1'!F2*Main!$B$5)+(_xlfn.IFNA(VLOOKUP($A2,'FL Ratio'!$A$3:$B$10,2,FALSE),0)*'FL Characterization'!F$2) -> 31.978389 | G2: =('[1]Pc, Winter, S1'!G2*Main!$B$5)+(_xlfn.IFNA(VLOOKUP($A2,'FL Ratio'!$A$3:$B$10,2,FALSE),0)*'FL Characterization'!G$2) -> 35.151154 | H2: =('[1]Pc, Winter, S1'!H2*Main!$B$5)+(_xlfn.IFNA(VLOOKUP($A2,'FL Ratio'!$A$3:$B$10,2,FALSE),0)*'FL Characterization'!H$2) -> 41.943893 | I2: =('[1]Pc, Winter, S1'!I2*Main!$B$5)+(_xlfn.IFNA(VLOOKUP($A2,'FL Ratio'!$A$3:$B$10,2,FALSE),0)*'FL Characterization'!I$2) -> 50.48766 | ... Y2: =('[1]Pc, Winter, S1'!Y2*Main!$B$5)+(_xlfn.IFNA(VLOOKUP($A2,'FL Ratio'!$A$3:$B$10,2,FALSE),0)*'FL Characterization'!Y$2) -> 40.356746
A3: 2 | B3: =('[1]Pc, Winter, S1'!B3*Main!$B$5)+(_xlfn.IFNA(VLOOKUP($A3,'FL Ratio'!$A$3:$B$10,2,FALSE),0)*'FL Characterization'!B$2) -> 38.49308 | C3: =('[1]Pc, Winter, S1'!C3*Main!$B$5)+(_xlfn.IFNA(VLOOKUP($A3,'FL Ratio'!$A$3:$B$10,2,FALSE),0)*'FL Characterization'!C$2) -> 36.070811 | D3: =('[1]Pc, Winter, S1'!D3*Main!$B$5)+(_xlfn.IFNA(VLOOKUP($A3,'FL Ratio'!$A$3:$B$10,2,FALSE),0)*'FL Characterization'!D$2) -> 32.613953 | E3: =('[1]Pc, Winter, S1'!E3*Main!$B$5)+(_xlfn.IFNA(VLOOKUP($A3,'FL Ratio'!$A$3:$B$10,2,FALSE),0)*'FL Characterization'!E$2) -> 34.736476 | F3: =('[1]Pc, Winter, S1'!F3*Main!$B$5)+(_xlfn.IFNA(VLOOKUP($A3,'FL Ratio'!$A$3:$B$10,2,FALSE),0)*'FL Characterization'!F$2) -> 34.165846 | G3: =('[1]Pc, Winter, S1'!G3*Main!$B$5)+(_xlfn.IFNA(VLOOKUP($A3,'FL Ratio'!$A$3:$B$10,2,FALSE),0)*'FL Characterization'!G$2) -> 35.215148 | H3: =('[1]Pc, Winter, S1'!H3*Main!$B$5)+(_xlfn.IFNA(VLOOKUP($A3,'FL Ratio'!$A$3:$B$10,2,FALSE),0)*'FL Characterization'!H$2) -> 51.940001 | I3: =('[1]Pc, Winter, S1'!I3*Main!$B$5)+(_xlfn.IFNA(VLOOKUP($A3,'FL Ratio'!$A$3:$B$10,2,FALSE),0)*'FL Characterization'!I$2) -> 55.820894 | ... Y3: =('[1]Pc, Winter, S1'!Y3*Main!$B$5)+(_xlfn.IFNA(VLOOKUP($A3,'FL Ratio'!$A$3:$B$10,2,FALSE),0)*'FL Characterization'!Y$2) -> 41.556051
A4: 3 | B4: =('[1]Pc, Winter, S1'!B4*Main!$B$5)+(_xlfn.IFNA(VLOOKUP($A4,'FL Ratio'!$A$3:$B$10,2,FALSE),0)*'FL Characterization'!B$2) -> 54.639092 | C4: =('[1]Pc, Winter, S1'!C4*Main!$B$5)+(_xlfn.IFNA(VLOOKUP($A4,'FL Ratio'!$A$3:$B$10,2,FALSE),0)*'FL Characterization'!C$2) -> 48.518888 | D4: =('[1]Pc, Winter, S1'!D4*Main!$B$5)+(_xlfn.IFNA(VLOOKUP($A4,'FL Ratio'!$A$3:$B$10,2,FALSE),0)*'FL Characterization'!D$2) -> 45.540791 | E4: =('[1]Pc, Winter, S1'!E4*Main!$B$5)+(_xlfn.IFNA(VLOOKUP($A4,'FL Ratio'!$A$3:$B$10,2,FALSE),0)*'FL Characterization'!E$2) -> 44.892228 | F4: =('[1]Pc, Winter, S1'!F4*Main!$B$5)+(_xlfn.IFNA(VLOOKUP($A4,'FL Ratio'!$A$3:$B$10,2,FALSE),0)*'FL Characterization'!F$2) -> 46.412069 | G4: =('[1]Pc, Winter, S1'!G4*Main!$B$5)+(_xlfn.IFNA(VLOOKUP($A4,'FL Ratio'!$A$3:$B$10,2,FALSE),0)*'FL Characterization'!G$2) -> 49.631324 | H4: =('[1]Pc, Winter, S1'!H4*Main!$B$5)+(_xlfn.IFNA(VLOOKUP($A4,'FL Ratio'!$A$3:$B$10,2,FALSE),0)*'FL Characterization'!H$2) -> 59.917525 | I4: =('[1]Pc, Winter, S1'!I4*Main!$B$5)+(_xlfn.IFNA(VLOOKUP($A4,'FL Ratio'!$A$3:$B$10,2,FALSE),0)*'FL Characterization'!I$2) -> 64.947311 | ... Y4: =('[1]Pc, Winter, S1'!Y4*Main!$B$5)+(_xlfn.IFNA(VLOOKUP($A4,'FL Ratio'!$A$3:$B$10,2,FALSE),0)*'FL Characterization'!Y$2) -> 61.287062

Sheet Pc, Winter, S3
A1: LoadID | B1: 0 | C1: 1 | D1: 2 | E1: 3 | F1: 4 | G1: 5 | H1: 6 | I1: 7 | J1: 8 | K1: 9 | L1: 10 | M1: 11 | N1: 12 | O1: 13 | P1: 14 | Q1: 15 | R1: 16 | S1: 17 | T1: 18 | U1: 19 | V1: 20 | W1: 21 | X1: 22 | Y1: 23
A2: 1 | B2: =('[1]Pc, Winter, S1'!B2*Main!$B$5)+(_xlfn.IFNA(VLOOKUP($A2,'FL Ratio'!$A$3:$B$10,2,FALSE),0)*'FL Characterization'!B$2) -> 36.006041 | C2: =('[1]Pc, Winter, S1'!C2*Main!$B$5)+(_xlfn.IFNA(VLOOKUP($A2,'FL Ratio'!$A$3:$B$10,2,FALSE),0)*'FL Characterization'!C$2) -> 33.584574 | D2: =('[1]Pc, Winter, S1'!D2*Main!$B$5)+(_xlfn.IFNA(VLOOKUP($A2,'FL Ratio'!$A$3:$B$10,2,FALSE),0)*'FL Characterization'!D$2) -> 31.822416 | E2: =('[1]Pc, Winter, S1'!E2*Main!$B$5)+(_xlfn.IFNA(VLOOKUP($A2,'FL Ratio'!$A$3:$B$10,2,FALSE),0)*'FL Characterization'!E$2) -> 31.597254 | F2: =('[1]Pc, Winter, S1'!F2*Main!$B$5)+(_xlfn.IFNA(VLOOKUP($A2,'FL Ratio'!$A$3:$B$10,2,FALSE),0)*'FL Characterization'!F$2) -> 31.978389 | G2: =('[1]Pc, Winter, S1'!G2*Main!$B$5)+(_xlfn.IFNA(VLOOKUP($A2,'FL Ratio'!$A$3:$B$10,2,FALSE),0)*'FL Characterization'!G$2) -> 35.151154 | H2: =('[1]Pc, Winter, S1'!H2*Main!$B$5)+(_xlfn.IFNA(VLOOKUP($A2,'FL Ratio'!$A$3:$B$10,2,FALSE),0)*'FL Characterization'!H$2) -> 41.943893 | I2: =('[1]Pc, Winter, S1'!I2*Main!$B$5)+(_xlfn.IFNA(VLOOKUP($A2,'FL Ratio'!$A$3:$B$10,2,FALSE),0)*'FL Characterization'!I$2) -> 50.48766 | ... Y2: =('[1]Pc, Winter, S1'!Y2*Main!$B$5)+(_xlfn.IFNA(VLOOKUP($A2,'FL Ratio'!$A$3:$B$10,2,FALSE),0)*'FL Characterization'!Y$2) -> 40.356746
A3: 2 | B3: =('[1]Pc, Winter, S1'!B3*Main!$B$5)+(_xlfn.IFNA(VLOOKUP($A3,'FL Ratio'!$A$3:$B$10,2,FALSE),0)*'FL Characterization'!B$2) -> 38.49308 | C3: =('[1]Pc, Winter, S1'!C3*Main!$B$5)+(_xlfn.IFNA(VLOOKUP($A3,'FL Ratio'!$A$3:$B$10,2,FALSE),0)*'FL Characterization'!C$2) -> 36.070811 | D3: =('[1]Pc, Winter, S1'!D3*Main!$B$5)+(_xlfn.IFNA(VLOOKUP($A3,'FL Ratio'!$A$3:$B$10,2,FALSE),0)*'FL Characterization'!D$2) -> 32.613953 | E3: =('[1]Pc, Winter, S1'!E3*Main!$B$5)+(_xlfn.IFNA(VLOOKUP($A3,'FL Ratio'!$A$3:$B$10,2,FALSE),0)*'FL Characterization'!E$2) -> 34.736476 | F3: =('[1]Pc, Winter, S1'!F3*Main!$B$5)+(_xlfn.IFNA(VLOOKUP($A3,'FL Ratio'!$A$3:$B$10,2,FALSE),0)*'FL Characterization'!F$2) -> 34.165846 | G3: =('[1]Pc, Winter, S1'!G3*Main!$B$5)+(_xlfn.IFNA(VLOOKUP($A3,'FL Ratio'!$A$3:$B$10,2,FALSE),0)*'FL Characterization'!G$2) -> 35.215148 | H3: =('[1]Pc, Winter, S1'!H3*Main!$B$5)+(_xlfn.IFNA(VLOOKUP($A3,'FL Ratio'!$A$3:$B$10,2,FALSE),0)*'FL Characterization'!H$2) -> 51.940001 | I3: =('[1]Pc, Winter, S1'!I3*Main!$B$5)+(_xlfn.IFNA(VLOOKUP($A3,'FL Ratio'!$A$3:$B$10,2,FALSE),0)*'FL Characterization'!I$2) -> 55.820894 | ... Y3: =('[1]Pc, Winter, S1'!Y3*Main!$B$5)+(_xlfn.IFNA(VLOOKUP($A3,'FL Ratio'!$A$3:$B$10,2,FALSE),0)*'FL Characterization'!Y$2) -> 41.556051
A4: 3 | B4: =('[1]Pc, Winter, S1'!B4*Main!$B$5)+(_xlfn.IFNA(VLOOKUP($A4,'FL Ratio'!$A$3:$B$10,2,FALSE),0)*'FL Characterization'!B$2) -> 54.639092 | C4: =('[1]Pc, Winter, S1'!C4*Main!$B$5)+(_xlfn.IFNA(VLOOKUP($A4,'FL Ratio'!$A$3:$B$10,2,FALSE),0)*'FL Characterization'!C$2) -> 48.518888 | D4: =('[1]Pc, Winter, S1'!D4*Main!$B$5)+(_xlfn.IFNA(VLOOKUP($A4,'FL Ratio'!$A$3:$B$10,2,FALSE),0)*'FL Characterization'!D$2) -> 45.540791 | E4: =('[1]Pc, Winter, S1'!E4*Main!$B$5)+(_xlfn.IFNA(VLOOKUP($A4,'FL Ratio'!$A$3:$B$10,2,FALSE),0)*'FL Characterization'!E$2) -> 44.892228 | F4: =('[1]Pc, Winter, S1'!F4*Main!$B$5)+(_xlfn.IFNA(VLOOKUP($A4,'FL Ratio'!$A$3:$B$10,2,FALSE),0)*'FL Characterization'!F$2) -> 46.412069 | G4: =('[1]Pc, Winter, S1'!G4*Main!$B$5)+(_xlfn.IFNA(VLOOKUP($A4,'FL Ratio'!$A$3:$B$10,2,FALSE),0)*'FL Characterization'!G$2) -> 49.631324 | H4: =('[1]Pc, Winter, S1'!H4*Main!$B$5)+(_xlfn.IFNA(VLOOKUP($A4,'FL Ratio'!$A$3:$B$10,2,FALSE),0)*'FL Characterization'!H$2) -> 59.917525 | I4: =('[1]Pc, Winter, S1'!I4*Main!$B$5)+(_xlfn.IFNA(VLOOKUP($A4,'FL Ratio'!$A$3:$B$10,2,FALSE),0)*'FL Characterization'!I$2) -> 64.947311 | ... Y4: =('[1]Pc, Winter, S1'!Y4*Main!$B$5)+(_xlfn.IFNA(VLOOKUP($A4,'FL Ratio'!$A$3:$B$10,2,FALSE),0)*'FL Characterization'!Y$2) -> 61.287062

Sheet Pc, Winter, S4
A1: LoadID | B1: 0 | C1: 1 | D1: 2 | E1: 3 | F1: 4 | G1: 5 | H1: 6 | I1: 7 | J1: 8 | K1: 9 | L1: 10 | M1: 11 | N1: 12 | O1: 13 | P1: 14 | Q1: 15 | R1: 16 | S1: 17 | T1: 18 | U1: 19 | V1: 20 | W1: 21 | X1: 22 | Y1: 23
A2: 1 | B2: =('[1]Pc, Winter, S2'!B2*Main!$B$5)+(_xlfn.IFNA(VLOOKUP($A2,'FL Ratio'!$A$3:$B$10,2,FALSE),0)*'FL Characterization'!B$2) -> 37.086223 | C2: =('[1]Pc, Winter, S2'!C2*Main!$B$5)+(_xlfn.IFNA(VLOOKUP($A2,'FL Ratio'!$A$3:$B$10,2,FALSE),0)*'FL Characterization'!C$2) -> 34.592111 | D2: =('[1]Pc, Winter, S2'!D2*Main!$B$5)+(_xlfn.IFNA(VLOOKUP($A2,'FL Ratio'!$A$3:$B$10,2,FALSE),0)*'FL Characterization'!D$2) -> 32.777088 | E2: =('[1]Pc, Winter, S2'!E2*Main!$B$5)+(_xlfn.IFNA(VLOOKUP($A2,'FL Ratio'!$A$3:$B$10,2,FALSE),0)*'FL Characterization'!E$2) -> 32.545172 | F2: =('[1]Pc, Winter, S2'!F2*Main!$B$5)+(_xlfn.IFNA(VLOOKUP($A2,'FL Ratio'!$A$3:$B$10,2,FALSE),0)*'FL Characterization'!F$2) -> 32.937741 | G2: =('[1]Pc, Winter, S2'!G2*Main!$B$5)+(_xlfn.IFNA(VLOOKUP($A2,'FL Ratio'!$A$3:$B$10,2,FALSE),0)*'FL Characterization'!G$2) -> 36.205689 | H2: =('[1]Pc, Winter, S2'!H2*Main!$B$5)+(_xlfn.IFNA(VLOOKUP($A2,'FL Ratio'!$A$3:$B$10,2,FALSE),0)*'FL Characterization'!H$2) -> 43.20221 | I2: =('[1]Pc, Winter, S2'!I2*Main!$B$5)+(_xlfn.IFNA(VLOOKUP($A2,'FL Ratio'!$A$3:$B$10,2,FALSE),0)*'FL Characterization'!I$2) -> 52.002289 | ... Y2: =('[1]Pc, Winter, S2'!Y2*Main!$B$5)+(_xlfn.IFNA(VLOOKUP($A2,'FL Ratio'!$A$3:$B$10,2,FALSE),0)*'FL Characterization'!Y$2) -> 41.567448
A3: 2 | B3: =('[1]Pc, Winter, S2'!B3*Main!$B$5)+(_xlfn.IFNA(VLOOKUP($A3,'FL Ratio'!$A$3:$B$10,2,FALSE),0)*'FL Characterization'!B$2) -> 39.561117 | C3: =('[1]Pc, Winter, S2'!C3*Main!$B$5)+(_xlfn.IFNA(VLOOKUP($A3,'FL Ratio'!$A$3:$B$10,2,FALSE),0)*'FL Characterization'!C$2) -> 37.063286 | D3: =('[1]Pc, Winter, S2'!D3*Main!$B$5)+(_xlfn.IFNA(VLOOKUP($A3,'FL Ratio'!$A$3:$B$10,2,FALSE),0)*'FL Characterization'!D$2) -> 33.512096 | E3: =('[1]Pc, Winter, S2'!E3*Main!$B$5)+(_xlfn.IFNA(VLOOKUP($A3,'FL Ratio'!$A$3:$B$10,2,FALSE),0)*'FL Characterization'!E$2) -> 35.70248 | F3: =('[1]Pc, Winter, S2'!F3*Main!$B$5)+(_xlfn.IFNA(VLOOKUP($A3,'FL Ratio'!$A$3:$B$10,2,FALSE),0)*'FL Characterization'!F$2) -> 35.128481 | G3: =('[1]Pc, Winter, S2'!G3*Main!$B$5)+(_xlfn.IFNA(VLOOKUP($A3,'FL Ratio'!$A$3:$B$10,2,FALSE),0)*'FL Characterization'!G$2) -> 36.218693 | H3: =('[1]Pc, Winter, S2'!H3*Main!$B$5)+(_xlfn.IFNA(VLOOKUP($A3,'FL Ratio'!$A$3:$B$10,2,FALSE),0)*'FL Characterization'!H$2) -> 53.433496 | I3: =('[1]Pc, Winter, S2'!I3*Main!$B$5)+(_xlfn.IFNA(VLOOKUP($A3,'FL Ratio'!$A$3:$B$10,2,FALSE),0)*'FL Characterization'!I$2) -> 57.484283 | ... Y3: =('[1]Pc, Winter, S2'!Y3*Main!$B$5)+(_xlfn.IFNA(VLOOKUP($A3,'FL Ratio'!$A$3:$B$10,2,FALSE),0)*'FL Characterization'!Y$2) -> 42.723233
A4: 3 | B4: =('[1]Pc, Winter, S2'!B4*Main!$B$5)+(_xlfn.IFNA(VLOOKUP($A4,'FL Ratio'!$A$3:$B$10,2,FALSE),0)*'FL Characterization'!B$2) -> 56.191509 | C4: =('[1]Pc, Winter, S2'!C4*Main!$B$5)+(_xlfn.IFNA(VLOOKUP($A4,'FL Ratio'!$A$3:$B$10,2,FALSE),0)*'FL Characterization'!C$2) -> 49.884805 | D4: =('[1]Pc, Winter, S2'!D4*Main!$B$5)+(_xlfn.IFNA(VLOOKUP($A4,'FL Ratio'!$A$3:$B$10,2,FALSE),0)*'FL Characterization'!D$2) -> 46.826739 | E4: =('[1]Pc, Winter, S2'!E4*Main!$B$5)+(_xlfn.IFNA(VLOOKUP($A4,'FL Ratio'!$A$3:$B$10,2,FALSE),0)*'FL Characterization'!E$2) -> 46.162905 | F4: =('[1]Pc, Winter, S2'!F4*Main!$B$5)+(_xlfn.IFNA(VLOOKUP($A4,'FL Ratio'!$A$3:$B$10,2,FALSE),0)*'FL Characterization'!F$2) -> 47.742091 | G4: =('[1]Pc, Winter, S2'!G4*Main!$B$5)+(_xlfn.IFNA(VLOOKUP($A4,'FL Ratio'!$A$3:$B$10,2,FALSE),0)*'FL Characterization'!G$2) -> 51.067354 | H4: =('[1]Pc, Winter, S2'!H4*Main!$B$5)+(_xlfn.IFNA(VLOOKUP($A4,'FL Ratio'!$A$3:$B$10,2,FALSE),0)*'FL Characterization'!H$2) -> 61.650346 | I4: =('[1]Pc, Winter, S2'!I4*Main!$B$5)+(_xlfn.IFNA(VLOOKUP($A4,'FL Ratio'!$A$3:$B$10,2,FALSE),0)*'FL Characterization'!I$2) -> 66.884493 | ... Y4: =('[1]Pc, Winter, S2'!Y4*Main!$B$5)+(_xlfn.IFNA(VLOOKUP($A4,'FL Ratio'!$A$3:$B$10,2,FALSE),0)*'FL Characterization'!Y$2) -> 63.046174

Sheet Pc, Winter, S5
A1: LoadID | B1: 0 | C1: 1 | D1: 2 | E1: 3 | F1: 4 | G1: 5 | H1: 6 | I1: 7 | J1: 8 | K1: 9 | L1: 10 | M1: 11 | N1: 12 | O1: 13 | P1: 14 | Q1: 15 | R1: 16 | S1: 17 | T1: 18 | U1: 19 | V1: 20 | W1: 21 | X1: 22 | Y1: 23
A2: 1 | B2: =('[1]Pc, Winter, S2'!B2*Main!$B$5)+(_xlfn.IFNA(VLOOKUP($A2,'FL Ratio'!$A$3:$B$10,2,FALSE),0)*'FL Characterization'!B$2) -> 37.086223 | C2: =('[1]Pc, Winter, S2'!C2*Main!$B$5)+(_xlfn.IFNA(VLOOKUP($A2,'FL Ratio'!$A$3:$B$10,2,FALSE),0)*'FL Characterization'!C$2) -> 34.592111 | D2: =('[1]Pc, Winter, S2'!D2*Main!$B$5)+(_xlfn.IFNA(VLOOKUP($A2,'FL Ratio'!$A$3:$B$10,2,FALSE),0)*'FL Characterization'!D$2) -> 32.777088 | E2: =('[1]Pc, Winter, S2'!E2*Main!$B$5)+(_xlfn.IFNA(VLOOKUP($A2,'FL Ratio'!$A$3:$B$10,2,FALSE),0)*'FL Characterization'!E$2) -> 32.545172 | F2: =('[1]Pc, Winter, S2'!F2*Main!$B$5)+(_xlfn.IFNA(VLOOKUP($A2,'FL Ratio'!$A$3:$B$10,2,FALSE),0)*'FL Characterization'!F$2) -> 32.937741 | G2: =('[1]Pc, Winter, S2'!G2*Main!$B$5)+(_xlfn.IFNA(VLOOKUP($A2,'FL Ratio'!$A$3:$B$10,2,FALSE),0)*'FL Characterization'!G$2) -> 36.205689 | H2: =('[1]Pc, Winter, S2'!H2*Main!$B$5)+(_xlfn.IFNA(VLOOKUP($A2,'FL Ratio'!$A$3:$B$10,2,FALSE),0)*'FL Characterization'!H$2) -> 43.20221 | I2: =('[1]Pc, Winter, S2'!I2*Main!$B$5)+(_xlfn.IFNA(VLOOKUP($A2,'FL Ratio'!$A$3:$B$10,2,FALSE),0)*'FL Characterization'!I$2) -> 52.002289 | ... Y2: =('[1]Pc, Winter, S2'!Y2*Main!$B$5)+(_xlfn.IFNA(VLOOKUP($A2,'FL Ratio'!$A$3:$B$10,2,FALSE),0)*'FL Characterization'!Y$2) -> 41.567448
A3: 2 | B3: =('[1]Pc, Winter, S2'!B3*Main!$B$5)+(_xlfn.IFNA(VLOOKUP($A3,'FL Ratio'!$A$3:$B$10,2,FALSE),0)*'FL Characterization'!B$2) -> 39.561117 | C3: =('[1]Pc, Winter, S2'!C3*Main!$B$5)+(_xlfn.IFNA(VLOOKUP($A3,'FL Ratio'!$A$3:$B$10,2,FALSE),0)*'FL Characterization'!C$2) -> 37.063286 | D3: =('[1]Pc, Winter, S2'!D3*Main!$B$5)+(_xlfn.IFNA(VLOOKUP($A3,'FL Ratio'!$A$3:$B$10,2,FALSE),0)*'FL Characterization'!D$2) -> 33.512096 | E3: =('[1]Pc, Winter, S2'!E3*Main!$B$5)+(_xlfn.IFNA(VLOOKUP($A3,'FL Ratio'!$A$3:$B$10,2,FALSE),0)*'FL Characterization'!E$2) -> 35.70248 | F3: =('[1]Pc, Winter, S2'!F3*Main!$B$5)+(_xlfn.IFNA(VLOOKUP($A3,'FL Ratio'!$A$3:$B$10,2,FALSE),0)*'FL Characterization'!F$2) -> 35.128481 | G3: =('[1]Pc, Winter, S2'!G3*Main!$B$5)+(_xlfn.IFNA(VLOOKUP($A3,'FL Ratio'!$A$3:$B$10,2,FALSE),0)*'FL Characterization'!G$2) -> 36.218693 | H3: =('[1]Pc, Winter, S2'!H3*Main!$B$5)+(_xlfn.IFNA(VLOOKUP($A3,'FL Ratio'!$A$3:$B$10,2,FALSE),0)*'FL Characterization'!H$2) -> 53.433496 | I3: =('[1]Pc, Winter, S2'!I3*Main!$B$5)+(_xlfn.IFNA(VLOOKUP($A3,'FL Ratio'!$A$3:$B$10,2,FALSE),0)*'FL Characterization'!I$2) -> 57.484283 | ... Y3: =('[1]Pc, Winter, S2'!Y3*Main!$B$5)+(_xlfn.IFNA(VLOOKUP($A3,'FL Ratio'!$A$3:$B$10,2,FALSE),0)*'FL Characterization'!Y$2) -> 42.723233
A4: 3 | B4: =('[1]Pc, Winter, S2'!B4*Main!$B$5)+(_xlfn.IFNA(VLOOKUP($A4,'FL Ratio'!$A$3:$B$10,2,FALSE),0)*'FL Characterization'!B$2) -> 56.191509 | C4: =('[1]Pc, Winter, S2'!C4*Main!$B$5)+(_xlfn.IFNA(VLOOKUP($A4,'FL Ratio'!$A$3:$B$10,2,FALSE),0)*'FL Characterization'!C$2) -> 49.884805 | D4: =('[1]Pc, Winter, S2'!D4*Main!$B$5)+(_xlfn.IFNA(VLOOKUP($A4,'FL Ratio'!$A$3:$B$10,2,FALSE),0)*'FL Characterization'!D$2) -> 46.826739 | E4: =('[1]Pc, Winter, S2'!E4*Main!$B$5)+(_xlfn.IFNA(VLOOKUP($A4,'FL Ratio'!$A$3:$B$10,2,FALSE),0)*'FL Characterization'!E$2) -> 46.162905 | F4: =('[1]Pc, Winter, S2'!F4*Main!$B$5)+(_xlfn.IFNA(VLOOKUP($A4,'FL Ratio'!$A$3:$B$10,2,FALSE),0)*'FL Characterization'!F$2) -> 47.742091 | G4: =('[1]Pc, Winter, S2'!G4*Main!$B$5)+(_xlfn.IFNA(VLOOKUP($A4,'FL Ratio'!$A$3:$B$10,2,FALSE),0)*'FL Characterization'!G$2) -> 51.067354 | H4: =('[1]Pc, Winter, S2'!H4*Main!$B$5)+(_xlfn.IFNA(VLOOKUP($A4,'FL Ratio'!$A$3:$B$10,2,FALSE),0)*'FL Characterization'!H$2) -> 61.650346 | I4: =('[1]Pc, Winter, S2'!I4*Main!$B$5)+(_xlfn.IFNA(VLOOKUP($A4,'FL Ratio'!$A$3:$B$10,2,FALSE),0)*'FL Characterization'!I$2) -> 66.884493 | ... Y4: =('[1]Pc, Winter, S2'!Y4*Main!$B$5)+(_xlfn.IFNA(VLOOKUP($A4,'FL Ratio'!$A$3:$B$10,2,FALSE),0)*'FL Characterization'!Y$2) -> 63.046174

Sheet Pc, Winter, S6
A1: LoadID | B1: 0 | C1: 1 | D1: 2 | E1: 3 | F1: 4 | G1: 5 | H1: 6 | I1: 7 | J1: 8 | K1: 9 | L1: 10 | M1: 11 | N1: 12 | O1: 13 | P1: 14 | Q1: 15 | R1: 16 | S1: 17 | T1: 18 | U1: 19 | V1: 20 | W1: 21 | X1: 22 | Y1: 23
A2: 1 | B2: =('[1]Pc, Winter, S2'!B2*Main!$B$5)+(_xlfn.IFNA(VLOOKUP($A2,'FL Ratio'!$A$3:$B$10,2,FALSE),0)*'FL Characterization'!B$2) -> 37.086223 | C2: =('[1]Pc, Winter, S2'!C2*Main!$B$5)+(_xlfn.IFNA(VLOOKUP($A2,'FL Ratio'!$A$3:$B$10,2,FALSE),0)*'FL Characterization'!C$2) -> 34.592111 | D2: =('[1]Pc, Winter, S2'!D2*Main!$B$5)+(_xlfn.IFNA(VLOOKUP($A2,'FL Ratio'!$A$3:$B$10,2,FALSE),0)*'FL Characterization'!D$2) -> 32.777088 | E2: =('[1]Pc, Winter, S2'!E2*Main!$B$5)+(_xlfn.IFNA(VLOOKUP($A2,'FL Ratio'!$A$3:$B$10,2,FALSE),0)*'FL Characterization'!E$2) -> 32.545172 | F2: =('[1]Pc, Winter, S2'!F2*Main!$B$5)+(_xlfn.IFNA(VLOOKUP($A2,'FL Ratio'!$A$3:$B$10,2,FALSE),0)*'FL Characterization'!F$2) -> 32.937741 | G2: =('[1]Pc, Winter, S2'!G2*Main!$B$5)+(_xlfn.IFNA(VLOOKUP($A2,'FL Ratio'!$A$3:$B$10,2,FALSE),0)*'FL Characterization'!G$2) -> 36.205689 | H2: =('[1]Pc, Winter, S2'!H2*Main!$B$5)+(_xlfn.IFNA(VLOOKUP($A2,'FL Ratio'!$A$3:$B$10,2,FALSE),0)*'FL Characterization'!H$2) -> 43.20221 | I2: =('[1]Pc, Winter, S2'!I2*Main!$B$5)+(_xlfn.IFNA(VLOOKUP($A2,'FL Ratio'!$A$3:$B$10,2,FALSE),0)*'FL Characterization'!I$2) -> 52.002289 | ... Y2: =('[1]Pc, Winter, S2'!Y2*Main!$B$5)+(_xlfn.IFNA(VLOOKUP($A2,'FL Ratio'!$A$3:$B$10,2,FALSE),0)*'FL Characterization'!Y$2) -> 41.567448
A3: 2 | B3: =('[1]Pc, Winter, S2'!B3*Main!$B$5)+(_xlfn.IFNA(VLOOKUP($A3,'FL Ratio'!$A$3:$B$10,2,FALSE),0)*'FL Characterization'!B$2) -> 39.561117 | C3: =('[1]Pc, Winter, S2'!C3*Main!$B$5)+(_xlfn.IFNA(VLOOKUP($A3,'FL Ratio'!$A$3:$B$10,2,FALSE),0)*'FL Characterization'!C$2) -> 37.063286 | D3: =('[1]Pc, Winter, S2'!D3*Main!$B$5)+(_xlfn.IFNA(VLOOKUP($A3,'FL Ratio'!$A$3:$B$10,2,FALSE),0)*'FL Characterization'!D$2) -> 33.512096 | E3: =('[1]Pc, Winter, S2'!E3*Main!$B$5)+(_xlfn.IFNA(VLOOKUP($A3,'FL Ratio'!$A$3:$B$10,2,FALSE),0)*'FL Characterization'!E$2) -> 35.70248 | F3: =('[1]Pc, Winter, S2'!F3*Main!$B$5)+(_xlfn.IFNA(VLOOKUP($A3,'FL Ratio'!$A$3:$B$10,2,FALSE),0)*'FL Characterization'!F$2) -> 35.128481 | G3: =('[1]Pc, Winter, S2'!G3*Main!$B$5)+(_xlfn.IFNA(VLOOKUP($A3,'FL Ratio'!$A$3:$B$10,2,FALSE),0)*'FL Characterization'!G$2) -> 36.218693 | H3: =('[1]Pc, Winter, S2'!H3*Main!$B$5)+(_xlfn.IFNA(VLOOKUP($A3,'FL Ratio'!$A$3:$B$10,2,FALSE),0)*'FL Characterization'!H$2) -> 53.433496 | I3: =('[1]Pc, Winter, S2'!I3*Main!$B$5)+(_xlfn.IFNA(VLOOKUP($A3,'FL Ratio'!$A$3:$B$10,2,FALSE),0)*'FL Characterization'!I$2) -> 57.484283 | ... Y3: =('[1]Pc, Winter, S2'!Y3*Main!$B$5)+(_xlfn.IFNA(VLOOKUP($A3,'FL Ratio'!$A$3:$B$10,2,FALSE),0)*'FL Characterization'!Y$2) -> 42.723233
A4: 3 | B4: =('[1]Pc, Winter, S2'!B4*Main!$B$5)+(_xlfn.IFNA(VLOOKUP($A4,'FL Ratio'!$A$3:$B$10,2,FALSE),0)*'FL Characterization'!B$2) -> 56.191509 | C4: =('[1]Pc, Winter, S2'!C4*Main!$B$5)+(_xlfn.IFNA(VLOOKUP($A4,'FL Ratio'!$A$3:$B$10,2,FALSE),0)*'FL Characterization'!C$2) -> 49.884805 | D4: =('[1]Pc, Winter, S2'!D4*Main!$B$5)+(_xlfn.IFNA(VLOOKUP($A4,'FL Ratio'!$A$3:$B$10,2,FALSE),0)*'FL Characterization'!D$2) -> 46.826739 | E4: =('[1]Pc, Winter, S2'!E4*Main!$B$5)+(_xlfn.IFNA(VLOOKUP($A4,'FL Ratio'!$A$3:$B$10,2,FALSE),0)*'FL Characterization'!E$2) -> 46.162905 | F4: =('[1]Pc, Winter, S2'!F4*Main!$B$5)+(_xlfn.IFNA(VLOOKUP($A4,'FL Ratio'!$A$3:$B$10,2,FALSE),0)*'FL Characterization'!F$2) -> 47.742091 | G4: =('[1]Pc, Winter, S2'!G4*Main!$B$5)+(_xlfn.IFNA(VLOOKUP($A4,'FL Ratio'!$A$3:$B$10,2,FALSE),0)*'FL Characterization'!G$2) -> 51.067354 | H4: =('[1]Pc, Winter, S2'!H4*Main!$B$5)+(_xlfn.IFNA(VLOOKUP($A4,'FL Ratio'!$A$3:$B$10,2,FALSE),0)*'FL Characterization'!H$2) -> 61.650346 | I4: =('[1]Pc, Winter, S2'!I4*Main!$B$5)+(_xlfn.IFNA(VLOOKUP($A4,'FL Ratio'!$A$3:$B$10,2,FALSE),0)*'FL Characterization'!I$2) -> 66.884493 | ... Y4: =('[1]Pc, Winter, S2'!Y4*Main!$B$5)+(_xlfn.IFNA(VLOOKUP($A4,'FL Ratio'!$A$3:$B$10,2,FALSE),0)*'FL Characterization'!Y$2) -> 63.046174

Sheet Pc, Winter, S7
A1: LoadID | B1: 0 | C1: 1 | D1: 2 | E1: 3 | F1: 4 | G1: 5 | H1: 6 | I1: 7 | J1: 8 | K1: 9 | L1: 10 | M1: 11 | N1: 12 | O1: 13 | P1: 14 | Q1: 15 | R1: 16 | S1: 17 | T1: 18 | U1: 19 | V1: 20 | W1: 21 | X1: 22 | Y1: 23
A2: 1 | B2: =('[1]Pc, Winter, S3'!B2*Main!$B$5)+(_xlfn.IFNA(VLOOKUP($A2,'FL Ratio'!$A$3:$B$10,2,FALSE),0)*'FL Characterization'!B$2) -> 35.28592 | C2: =('[1]Pc, Winter, S3'!C2*Main!$B$5)+(_xlfn.IFNA(VLOOKUP($A2,'FL Ratio'!$A$3:$B$10,2,FALSE),0)*'FL Characterization'!C$2) -> 32.912882 | D2: =('[1]Pc, Winter, S3'!D2*Main!$B$5)+(_xlfn.IFNA(VLOOKUP($A2,'FL Ratio'!$A$3:$B$10,2,FALSE),0)*'FL Characterization'!D$2) -> 31.185967 | E2: =('[1]Pc, Winter, S3'!E2*Main!$B$5)+(_xlfn.IFNA(VLOOKUP($A2,'FL Ratio'!$A$3:$B$10,2,FALSE),0)*'FL Characterization'!E$2) -> 30.965309 | F2: =('[1]Pc, Winter, S3'!F2*Main!$B$5)+(_xlfn.IFNA(VLOOKUP($A2,'FL Ratio'!$A$3:$B$10,2,FALSE),0)*'FL Characterization'!F$2) -> 31.338821 | G2: =('[1]Pc, Winter, S3'!G2*Main!$B$5)+(_xlfn.IFNA(VLOOKUP($A2,'FL Ratio'!$A$3:$B$10,2,FALSE),0)*'FL Characterization'!G$2) -> 34.448131 | H2: =('[1]Pc, Winter, S3'!H2*Main!$B$5)+(_xlfn.IFNA(VLOOKUP($A2,'FL Ratio'!$A$3:$B$10,2,FALSE),0)*'FL Characterization'!H$2) -> 41.105015 | I2: =('[1]Pc, Winter, S3'!I2*Main!$B$5)+(_xlfn.IFNA(VLOOKUP($A2,'FL Ratio'!$A$3:$B$10,2,FALSE),0)*'FL Characterization'!I$2) -> 49.477906 | ... Y2: =('[1]Pc, Winter, S3'!Y2*Main!$B$5)+(_xlfn.IFNA(VLOOKUP($A2,'FL Ratio'!$A$3:$B$10,2,FALSE),0)*'FL Characterization'!Y$2) -> 39.549611
A3: 2 | B3: =('[1]Pc, Winter, S3'!B3*Main!$B$5)+(_xlfn.IFNA(VLOOKUP($A3,'FL Ratio'!$A$3:$B$10,2,FALSE),0)*'FL Characterization'!B$2) -> 37.781055 | C3: =('[1]Pc, Winter, S3'!C3*Main!$B$5)+(_xlfn.IFNA(VLOOKUP($A3,'FL Ratio'!$A$3:$B$10,2,FALSE),0)*'FL Characterization'!C$2) -> 35.409161 | D3: =('[1]Pc, Winter, S3'!D3*Main!$B$5)+(_xlfn.IFNA(VLOOKUP($A3,'FL Ratio'!$A$3:$B$10,2,FALSE),0)*'FL Characterization'!D$2) -> 32.015191 | E3: =('[1]Pc, Winter, S3'!E3*Main!$B$5)+(_xlfn.IFNA(VLOOKUP($A3,'FL Ratio'!$A$3:$B$10,2,FALSE),0)*'FL Characterization'!E$2) -> 34.092473 | F3: =('[1]Pc, Winter, S3'!F3*Main!$B$5)+(_xlfn.IFNA(VLOOKUP($A3,'FL Ratio'!$A$3:$B$10,2,FALSE),0)*'FL Characterization'!F$2) -> 33.524089 | G3: =('[1]Pc, Winter, S3'!G3*Main!$B$5)+(_xlfn.IFNA(VLOOKUP($A3,'FL Ratio'!$A$3:$B$10,2,FALSE),0)*'FL Characterization'!G$2) -> 34.546119 | H3: =('[1]Pc, Winter, S3'!H3*Main!$B$5)+(_xlfn.IFNA(VLOOKUP($A3,'FL Ratio'!$A$3:$B$10,2,FALSE),0)*'FL Characterization'!H$2) -> 50.944338 | I3: =('[1]Pc, Winter, S3'!I3*Main!$B$5)+(_xlfn.IFNA(VLOOKUP($A3,'FL Ratio'!$A$3:$B$10,2,FALSE),0)*'FL Characterization'!I$2) -> 54.711967 | ... Y3: =('[1]Pc, Winter, S3'!Y3*Main!$B$5)+(_xlfn.IFNA(VLOOKUP($A3,'FL Ratio'!$A$3:$B$10,2,FALSE),0)*'FL Characterization'!Y$2) -> 40.777929
A4: 3 | B4: =('[1]Pc, Winter, S3'!B4*Main!$B$5)+(_xlfn.IFNA(VLOOKUP($A4,'FL Ratio'!$A$3:$B$10,2,FALSE),0)*'FL Characterization'!B$2) -> 53.604147 | C4: =('[1]Pc, Winter, S3'!C4*Main!$B$5)+(_xlfn.IFNA(VLOOKUP($A4,'FL Ratio'!$A$3:$B$10,2,FALSE),0)*'FL Characterization'!C$2) -> 47.608276 | D4: =('[1]Pc, Winter, S3'!D4*Main!$B$5)+(_xlfn.IFNA(VLOOKUP($A4,'FL Ratio'!$A$3:$B$10,2,FALSE),0)*'FL Characterization'!D$2) -> 44.683493 | E4: =('[1]Pc, Winter, S3'!E4*Main!$B$5)+(_xlfn.IFNA(VLOOKUP($A4,'FL Ratio'!$A$3:$B$10,2,FALSE),0)*'FL Characterization'!E$2) -> 44.04511 | F4: =('[1]Pc, Winter, S3'!F4*Main!$B$5)+(_xlfn.IFNA(VLOOKUP($A4,'FL Ratio'!$A$3:$B$10,2,FALSE),0)*'FL Characterization'!F$2) -> 45.525388 | G4: =('[1]Pc, Winter, S3'!G4*Main!$B$5)+(_xlfn.IFNA(VLOOKUP($A4,'FL Ratio'!$A$3:$B$10,2,FALSE),0)*'FL Characterization'!G$2) -> 48.673971 | H4: =('[1]Pc, Winter, S3'!H4*Main!$B$5)+(_xlfn.IFNA(VLOOKUP($A4,'FL Ratio'!$A$3:$B$10,2,FALSE),0)*'FL Characterization'!H$2) -> 58.762311 | I4: =('[1]Pc, Winter, S3'!I4*Main!$B$5)+(_xlfn.IFNA(VLOOKUP($A4,'FL Ratio'!$A$3:$B$10,2,FALSE),0)*'FL Characterization'!I$2) -> 63.655856 | ... Y4: =('[1]Pc, Winter, S3'!Y4*Main!$B$5)+(_xlfn.IFNA(VLOOKUP($A4,'FL Ratio'!$A$3:$B$10,2,FALSE),0)*'FL Characterization'!Y$2) -> 60.11432

Sheet Pc, Winter, S8
A1: LoadID | B1: 0 | C1: 1 | D1: 2 | E1: 3 | F1: 4 | G1: 5 | H1: 6 | I1: 7 | J1: 8 | K1: 9 | L1: 10 | M1: 11 | N1: 12 | O1: 13 | P1: 14 | Q1: 15 | R1: 16 | S1: 17 | T1: 18 | U1: 19 | V1: 20 | W1: 21 | X1: 22 | Y1: 23
A2: 1 | B2: =('[1]Pc, Winter, S3'!B2*Main!$B$5)+(_xlfn.IFNA(VLOOKUP($A2,'FL Ratio'!$A$3:$B$10,2,FALSE),0)*'FL Characterization'!B$2) -> 35.28592 | C2: =('[1]Pc, Winter, S3'!C2*Main!$B$5)+(_xlfn.IFNA(VLOOKUP($A2,'FL Ratio'!$A$3:$B$10,2,FALSE),0)*'FL Characterization'!C$2) -> 32.912882 | D2: =('[1]Pc, Winter, S3'!D2*Main!$B$5)+(_xlfn.IFNA(VLOOKUP($A2,'FL Ratio'!$A$3:$B$10,2,FALSE),0)*'FL Characterization'!D$2) -> 31.185967 | E2: =('[1]Pc, Winter, S3'!E2*Main!$B$5)+(_xlfn.IFNA(VLOOKUP($A2,'FL Ratio'!$A$3:$B$10,2,FALSE),0)*'FL Characterization'!E$2) -> 30.965309 | F2: =('[1]Pc, Winter, S3'!F2*Main!$B$5)+(_xlfn.IFNA(VLOOKUP($A2,'FL Ratio'!$A$3:$B$10,2,FALSE),0)*'FL Characterization'!F$2) -> 31.338821 | G2: =('[1]Pc, Winter, S3'!G2*Main!$B$5)+(_xlfn.IFNA(VLOOKUP($A2,'FL Ratio'!$A$3:$B$10,2,FALSE),0)*'FL Characterization'!G$2) -> 34.448131 | H2: =('[1]Pc, Winter, S3'!H2*Main!$B$5)+(_xlfn.IFNA(VLOOKUP($A2,'FL Ratio'!$A$3:$B$10,2,FALSE),0)*'FL Characterization'!H$2) -> 41.105015 | I2: =('[1]Pc, Winter, S3'!I2*Main!$B$5)+(_xlfn.IFNA(VLOOKUP($A2,'FL Ratio'!$A$3:$B$10,2,FALSE),0)*'FL Characterization'!I$2) -> 49.477906 | ... Y2: =('[1]Pc, Winter, S3'!Y2*Main!$B$5)+(_xlfn.IFNA(VLOOKUP($A2,'FL Ratio'!$A$3:$B$10,2,FALSE),0)*'FL Characterization'!Y$2) -> 39.549611
A3: 2 | B3: =('[1]Pc, Winter, S3'!B3*Main!$B$5)+(_xlfn.IFNA(VLOOKUP($A3,'FL Ratio'!$A$3:$B$10,2,FALSE),0)*'FL Characterization'!B$2) -> 37.781055 | C3: =('[1]Pc, Winter, S3'!C3*Main!$B$5)+(_xlfn.IFNA(VLOOKUP($A3,'FL Ratio'!$A$3:$B$10,2,FALSE),0)*'FL Characterization'!C$2) -> 35.409161 | D3: =('[1]Pc, Winter, S3'!D3*Main!$B$5)+(_xlfn.IFNA(VLOOKUP($A3,'FL Ratio'!$A$3:$B$10,2,FALSE),0)*'FL Characterization'!D$2) -> 32.015191 | E3: =('[1]Pc, Winter, S3'!E3*Main!$B$5)+(_xlfn.IFNA(VLOOKUP($A3,'FL Ratio'!$A$3:$B$10,2,FALSE),0)*'FL Characterization'!E$2) -> 34.092473 | F3: =('[1]Pc, Winter, S3'!F3*Main!$B$5)+(_xlfn.IFNA(VLOOKUP($A3,'FL Ratio'!$A$3:$B$10,2,FALSE),0)*'FL Characterization'!F$2) -> 33.524089 | G3: =('[1]Pc, Winter, S3'!G3*Main!$B$5)+(_xlfn.IFNA(VLOOKUP($A3,'FL Ratio'!$A$3:$B$10,2,FALSE),0)*'FL Characterization'!G$2) -> 34.546119 | H3: =('[1]Pc, Winter, S3'!H3*Main!$B$5)+(_xlfn.IFNA(VLOOKUP($A3,'FL Ratio'!$A$3:$B$10,2,FALSE),0)*'FL Characterization'!H$2) -> 50.944338 | I3: =('[1]Pc, Winter, S3'!I3*Main!$B$5)+(_xlfn.IFNA(VLOOKUP($A3,'FL Ratio'!$A$3:$B$10,2,FALSE),0)*'FL Characterization'!I$2) -> 54.711967 | ... Y3: =('[1]Pc, Winter, S3'!Y3*Main!$B$5)+(_xlfn.IFNA(VLOOKUP($A3,'FL Ratio'!$A$3:$B$10,2,FALSE),0)*'FL Characterization'!Y$2) -> 40.777929
A4: 3 | B4: =('[1]Pc, Winter, S3'!B4*Main!$B$5)+(_xlfn.IFNA(VLOOKUP($A4,'FL Ratio'!$A$3:$B$10,2,FALSE),0)*'FL Characterization'!B$2) -> 53.604147 | C4: =('[1]Pc, Winter, S3'!C4*Main!$B$5)+(_xlfn.IFNA(VLOOKUP($A4,'FL Ratio'!$A$3:$B$10,2,FALSE),0)*'FL Characterization'!C$2) -> 47.608276 | D4: =('[1]Pc, Winter, S3'!D4*Main!$B$5)+(_xlfn.IFNA(VLOOKUP($A4,'FL Ratio'!$A$3:$B$10,2,FALSE),0)*'FL Characterization'!D$2) -> 44.683493 | E4: =('[1]Pc, Winter, S3'!E4*Main!$B$5)+(_xlfn.IFNA(VLOOKUP($A4,'FL Ratio'!$A$3:$B$10,2,FALSE),0)*'FL Characterization'!E$2) -> 44.04511 | F4: =('[1]Pc, Winter, S3'!F4*Main!$B$5)+(_xlfn.IFNA(VLOOKUP($A4,'FL Ratio'!$A$3:$B$10,2,FALSE),0)*'FL Characterization'!F$2) -> 45.525388 | G4: =('[1]Pc, Winter, S3'!G4*Main!$B$5)+(_xlfn.IFNA(VLOOKUP($A4,'FL Ratio'!$A$3:$B$10,2,FALSE),0)*'FL Characterization'!G$2) -> 48.673971 | H4: =('[1]Pc, Winter, S3'!H4*Main!$B$5)+(_xlfn.IFNA(VLOOKUP($A4,'FL Ratio'!$A$3:$B$10,2,FALSE),0)*'FL Characterization'!H$2) -> 58.762311 | I4: =('[1]Pc, Winter, S3'!I4*Main!$B$5)+(_xlfn.IFNA(VLOOKUP($A4,'FL Ratio'!$A$3:$B$10,2,FALSE),0)*'FL Characterization'!I$2) -> 63.655856 | ... Y4: =('[1]Pc, Winter, S3'!Y4*Main!$B$5)+(_xlfn.IFNA(VLOOKUP($A4,'FL Ratio'!$A$3:$B$10,2,FALSE),0)*'FL Characterization'!Y$2) -> 60.11432

Sheet Pc, Winter, S9
A1: LoadID | B1: 0 | C1: 1 | D1: 2 | E1: 3 | F1: 4 | G1: 5 | H1: 6 | I1: 7 | J1: 8 | K1: 9 | L1: 10 | M1: 11 | N1: 12 | O1: 13 | P1: 14 | Q1: 15 | R1: 16 | S1: 17 | T1: 18 | U1: 19 | V1: 20 | W1: 21 | X1: 22 | Y1: 23
A2: 1 | B2: =('[1]Pc, Winter, S3'!B2*Main!$B$5)+(_xlfn.IFNA(VLOOKUP($A2,'FL Ratio'!$A$3:$B$10,2,FALSE),0)*'FL Characterization'!B$2) -> 35.28592 | C2: =('[1]Pc, Winter, S3'!C2*Main!$B$5)+(_xlfn.IFNA(VLOOKUP($A2,'FL Ratio'!$A$3:$B$10,2,FALSE),0)*'FL Characterization'!C$2) -> 32.912882 | D2: =('[1]Pc, Winter, S3'!D2*Main!$B$5)+(_xlfn.IFNA(VLOOKUP($A2,'FL Ratio'!$A$3:$B$10,2,FALSE),0)*'FL Characterization'!D$2) -> 31.185967 | E2: =('[1]Pc, Winter, S3'!E2*Main!$B$5)+(_xlfn.IFNA(VLOOKUP($A2,'FL Ratio'!$A$3:$B$10,2,FALSE),0)*'FL Characterization'!E$2) -> 30.965309 | F2: =('[1]Pc, Winter, S3'!F2*Main!$B$5)+(_xlfn.IFNA(VLOOKUP($A2,'FL Ratio'!$A$3:$B$10,2,FALSE),0)*'FL Characterization'!F$2) -> 31.338821 | G2: =('[1]Pc, Winter, S3'!G2*Main!$B$5)+(_xlfn.IFNA(VLOOKUP($A2,'FL Ratio'!$A$3:$B$10,2,FALSE),0)*'FL Characterization'!G$2) -> 34.448131 | H2: =('[1]Pc, Winter, S3'!H2*Main!$B$5)+(_xlfn.IFNA(VLOOKUP($A2,'FL Ratio'!$A$3:$B$10,2,FALSE),0)*'FL Characterization'!H$2) -> 41.105015 | I2: =('[1]Pc, Winter, S3'!I2*Main!$B$5)+(_xlfn.IFNA(VLOOKUP($A2,'FL Ratio'!$A$3:$B$10,2,FALSE),0)*'FL Characterization'!I$2) -> 49.477906 | ... Y2: =('[1]Pc, Winter, S3'!Y2*Main!$B$5)+(_xlfn.IFNA(VLOOKUP($A2,'FL Ratio'!$A$3:$B$10,2,FALSE),0)*'FL Characterization'!Y$2) -> 39.549611
A3: 2 | B3: =('[1]Pc, Winter, S3'!B3*Main!$B$5)+(_xlfn.IFNA(VLOOKUP($A3,'FL Ratio'!$A$3:$B$10,2,FALSE),0)*'FL Characterization'!B$2) -> 37.781055 | C3: =('[1]Pc, Winter, S3'!C3*Main!$B$5)+(_xlfn.IFNA(VLOOKUP($A3,'FL Ratio'!$A$3:$B$10,2,FALSE),0)*'FL Characterization'!C$2) -> 35.409161 | D3: =('[1]Pc, Winter, S3'!D3*Main!$B$5)+(_xlfn.IFNA(VLOOKUP($A3,'FL Ratio'!$A$3:$B$10,2,FALSE),0)*'FL Characterization'!D$2) -> 32.015191 | E3: =('[1]Pc, Winter, S3'!E3*Main!$B$5)+(_xlfn.IFNA(VLOOKUP($A3,'FL Ratio'!$A$3:$B$10,2,FALSE),0)*'FL Characterization'!E$2) -> 34.092473 | F3: =('[1]Pc, Winter, S3'!F3*Main!$B$5)+(_xlfn.IFNA(VLOOKUP($A3,'FL Ratio'!$A$3:$B$10,2,FALSE),0)*'FL Characterization'!F$2) -> 33.524089 | G3: =('[1]Pc, Winter, S3'!G3*Main!$B$5)+(_xlfn.IFNA(VLOOKUP($A3,'FL Ratio'!$A$3:$B$10,2,FALSE),0)*'FL Characterization'!G$2) -> 34.546119 | H3: =('[1]Pc, Winter, S3'!H3*Main!$B$5)+(_xlfn.IFNA(VLOOKUP($A3,'FL Ratio'!$A$3:$B$10,2,FALSE),0)*'FL Characterization'!H$2) -> 50.944338 | I3: =('[1]Pc, Winter, S3'!I3*Main!$B$5)+(_xlfn.IFNA(VLOOKUP($A3,'FL Ratio'!$A$3:$B$10,2,FALSE),0)*'FL Characterization'!I$2) -> 54.711967 | ... Y3: =('[1]Pc, Winter, S3'!Y3*Main!$B$5)+(_xlfn.IFNA(VLOOKUP($A3,'FL Ratio'!$A$3:$B$10,2,FALSE),0)*'FL Characterization'!Y$2) -> 40.777929
A4: 3 | B4: =('[1]Pc, Winter, S3'!B4*Main!$B$5)+(_xlfn.IFNA(VLOOKUP($A4,'FL Ratio'!$A$3:$B$10,2,FALSE),0)*'FL Characterization'!B$2) -> 53.604147 | C4: =('[1]Pc, Winter, S3'!C4*Main!$B$5)+(_xlfn.IFNA(VLOOKUP($A4,'FL Ratio'!$A$3:$B$10,2,FALSE),0)*'FL Characterization'!C$2) -> 47.608276 | D4: =('[1]Pc, Winter, S3'!D4*Main!$B$5)+(_xlfn.IFNA(VLOOKUP($A4,'FL Ratio'!$A$3:$B$10,2,FALSE),0)*'FL Characterization'!D$2) -> 44.683493 | E4: =('[1]Pc, Winter, S3'!E4*Main!$B$5)+(_xlfn.IFNA(VLOOKUP($A4,'FL Ratio'!$A$3:$B$10,2,FALSE),0)*'FL Characterization'!E$2) -> 44.04511 | F4: =('[1]Pc, Winter, S3'!F4*Main!$B$5)+(_xlfn.IFNA(VLOOKUP($A4,'FL Ratio'!$A$3:$B$10,2,FALSE),0)*'FL Characterization'!F$2) -> 45.525388 | G4: =('[1]Pc, Winter, S3'!G4*Main!$B$5)+(_xlfn.IFNA(VLOOKUP($A4,'FL Ratio'!$A$3:$B$10,2,FALSE),0)*'FL Characterization'!G$2) -> 48.673971 | H4: =('[1]Pc, Winter, S3'!H4*Main!$B$5)+(_xlfn.IFNA(VLOOKUP($A4,'FL Ratio'!$A$3:$B$10,2,FALSE),0)*'FL Characterization'!H$2) -> 58.762311 | I4: =('[1]Pc, Winter, S3'!I4*Main!$B$5)+(_xlfn.IFNA(VLOOKUP($A4,'FL Ratio'!$A$3:$B$10,2,FALSE),0)*'FL Characterization'!I$2) -> 63.655856 | ... Y4: =('[1]Pc, Winter, S3'!Y4*Main!$B$5)+(_xlfn.IFNA(VLOOKUP($A4,'FL Ratio'!$A$3:$B$10,2,FALSE),0)*'FL Characterization'!Y$2) -> 60.11432

Sheet Qc, Winter, S1
A1: LoadID | B1: 0 | C1: 1 | D1: 2 | E1: 3 | F1: 4 | G1: 5 | H1: 6 | I1: 7 | J1: 8 | K1: 9 | L1: 10 | M1: 11 | N1: 12 | O1: 13 | P1: 14 | Q1: 15 | R1: 16 | S1: 17 | T1: 18 | U1: 19 | V1: 20 | W1: 21 | X1: 22 | Y1: 23
A2: 1 | B2: =('[1]Qc, Winter, S1'!B2*Main!$B$5) -> -15.676553 | C2: =('[1]Qc, Winter, S1'!C2*Main!$B$5) -> -17.038261 | D2: =('[1]Qc, Winter, S1'!D2*Main!$B$5) -> -18.352559 | E2: =('[1]Qc, Winter, S1'!E2*Main!$B$5) -> -18.218958 | F2: =('[1]Qc, Winter, S1'!F2*Main!$B$5) -> -18.857445 | G2: =('[1]Qc, Winter, S1'!G2*Main!$B$5) -> -16.786676 | H2: =('[1]Qc, Winter, S1'!H2*Main!$B$5) -> -12.500796 | I2: =('[1]Qc, Winter, S1'!I2*Main!$B$5) -> -5.1455762 | ... Y2: =('[1]Qc, Winter, S1'!Y2*Main!$B$5) -> -13.594183
A3: 2 | B3: =('[1]Qc, Winter, S1'!B3*Main!$B$5) -> 17.760628 | C3: =('[1]Qc, Winter, S1'!C3*Main!$B$5) -> 22.000353 | D3: =('[1]Qc, Winter, S1'!D3*Main!$B$5) -> 22.000353 | E3: =('[1]Qc, Winter, S1'!E3*Main!$B$5) -> 22.000353 | F3: =('[1]Qc, Winter, S1'!F3*Main!$B$5) -> 22.000353 | G3: =('[1]Qc, Winter, S1'!G3*Main!$B$5) -> 17.825857 | H3: =('[1]Qc, Winter, S1'!H3*Main!$B$5) -> 8.0853672 | I3: =('[1]Qc, Winter, S1'!I3*Main!$B$5) -> 1.0409072 | ... Y3: =('[1]Qc, Winter, S1'!Y3*Main!$B$5) -> 16.347387
A4: 3 | B4: =('[1]Qc, Winter, S1'!B4*Main!$B$5) -> 12.051448 | C4: =('[1]Qc, Winter, S1'!C4*Main!$B$5) -> 9.2961559 | D4: =('[1]Qc, Winter, S1'!D4*Main!$B$5) -> 7.9579852 | E4: =('[1]Qc, Winter, S1'!E4*Main!$B$5) -> 7.7874174 | F4: =('[1]Qc, Winter, S1'!F4*Main!$B$5) -> 8.8508731 | G4: =('[1]Qc, Winter, S1'!G4*Main!$B$5) -> 10.989579 | H4: =('[1]Qc, Winter, S1'!H4*Main!$B$5) -> 17.050421 | I4: =('[1]Qc, Winter, S1'!I4*Main!$B$5) -> 20.815302 | ... Y4: =('[1]Qc, Winter, S1'!Y4*Main!$B$5) -> 15.672062

Sheet Qc, Winter, S2
A1: LoadID | B1: 0 | C1: 1 | D1: 2 | E1: 3 | F1: 4 | G1: 5 | H1: 6 | I1: 7 | J1: 8 | K1: 9 | L1: 10 | M1: 11 | N1: 12 | O1: 13 | P1: 14 | Q1: 15 | R1: 16 | S1: 17 | T1: 18 | U1: 19 | V1: 20 | W1: 21 | X1: 22 | Y1: 23
A2: 1 | B2: =('[1]Qc, Winter, S1'!B2*Main!$B$5) -> -15.676553 | C2: =('[1]Qc, Winter, S1'!C2*Main!$B$5) -> -17.038261 | D2: =('[1]Qc, Winter, S1'!D2*Main!$B$5) -> -18.352559 | E2: =('[1]Qc, Winter, S1'!E2*Main!$B$5) -> -18.218958 | F2: =('[1]Qc, Winter, S1'!F2*Main!$B$5) -> -18.857445 | G2: =('[1]Qc, Winter, S1'!G2*Main!$B$5) -> -16.786676 | H2: =('[1]Qc, Winter, S1'!H2*Main!$B$5) -> -12.500796 | I2: =('[1]Qc, Winter, S1'!I2*Main!$B$5) -> -5.1455762 | ... Y2: =('[1]Qc, Winter, S1'!Y2*Main!$B$5) -> -13.594183
A3: 2 | B3: =('[1]Qc, Winter, S1'!B3*Main!$B$5) -> 17.760628 | C3: =('[1]Qc, Winter, S1'!C3*Main!$B$5) -> 22.000353 | D3: =('[1]Qc, Winter, S1'!D3*Main!$B$5) -> 22.000353 | E3: =('[1]Qc, Winter, S1'!E3*Main!$B$5) -> 22.000353 | F3: =('[1]Qc, Winter, S1'!F3*Main!$B$5) -> 22.000353 | G3: =('[1]Qc, Winter, S1'!G3*Main!$B$5) -> 17.825857 | H3: =('[1]Qc, Winter, S1'!H3*Main!$B$5) -> 8.0853672 | I3: =('[1]Qc, Winter, S1'!I3*Main!$B$5) -> 1.0409072 | ... Y3: =('[1]Qc, Winter, S1'!Y3*Main!$B$5) -> 16.347387
A4: 3 | B4: =('[1]Qc, Winter, S1'!B4*Main!$B$5) -> 12.051448 | C4: =('[1]Qc, Winter, S1'!C4*Main!$B$5) -> 9.2961559 | D4: =('[1]Qc, Winter, S1'!D4*Main!$B$5) -> 7.9579852 | E4: =('[1]Qc, Winter, S1'!E4*Main!$B$5) -> 7.7874174 | F4: =('[1]Qc, Winter, S1'!F4*Main!$B$5) -> 8.8508731 | G4: =('[1]Qc, Winter, S1'!G4*Main!$B$5) -> 10.989579 | H4: =('[1]Qc, Winter, S1'!H4*Main!$B$5) -> 17.050421 | I4: =('[1]Qc, Winter, S1'!I4*Main!$B$5) -> 20.815302 | ... Y4: =('[1]Qc, Winter, S1'!Y4*Main!$B$5) -> 15.672062

Sheet Qc, Winter, S3
A1: LoadID | B1: 0 | C1: 1 | D1: 2 | E1: 3 | F1: 4 | G1: 5 | H1: 6 | I1: 7 | J1: 8 | K1: 9 | L1: 10 | M1: 11 | N1: 12 | O1: 13 | P1: 14 | Q1: 15 | R1: 16 | S1: 17 | T1: 18 | U1: 19 | V1: 20 | W1: 21 | X1: 22 | Y1: 23
A2: 1 | B2: =('[1]Qc, Winter, S1'!B2*Main!$B$5) -> -15.676553 | C2: =('[1]Qc, Winter, S1'!C2*Main!$B$5) -> -17.038261 | D2: =('[1]Qc, Winter, S1'!D2*Main!$B$5) -> -18.352559 | E2: =('[1]Qc, Winter, S1'!E2*Main!$B$5) -> -18.218958 | F2: =('[1]Qc, Winter, S1'!F2*Main!$B$5) -> -18.857445 | G2: =('[1]Qc, Winter, S1'!G2*Main!$B$5) -> -16.786676 | H2: =('[1]Qc, Winter, S1'!H2*Main!$B$5) -> -12.500796 | I2: =('[1]Qc, Winter, S1'!I2*Main!$B$5) -> -5.1455762 | ... Y2: =('[1]Qc, Winter, S1'!Y2*Main!$B$5) -> -13.594183
A3: 2 | B3: =('[1]Qc, Winter, S1'!B3*Main!$B$5) -> 17.760628 | C3: =('[1]Qc, Winter, S1'!C3*Main!$B$5) -> 22.000353 | D3: =('[1]Qc, Winter, S1'!D3*Main!$B$5) -> 22.000353 | E3: =('[1]Qc, Winter, S1'!E3*Main!$B$5) -> 22.000353 | F3: =('[1]Qc, Winter, S1'!F3*Main!$B$5) -> 22.000353 | G3: =('[1]Qc, Winter, S1'!G3*Main!$B$5) -> 17.825857 | H3: =('[1]Qc, Winter, S1'!H3*Main!$B$5) -> 8.0853672 | I3: =('[1]Qc, Winter, S1'!I3*Main!$B$5) -> 1.0409072 | ... Y3: =('[1]Qc, Winter, S1'!Y3*Main!$B$5) -> 16.347387
A4: 3 | B4: =('[1]Qc, Winter, S1'!B4*Main!$B$5) -> 12.051448 | C4: =('[1]Qc, Winter, S1'!C4*Main!$B$5) -> 9.2961559 | D4: =('[1]Qc, Winter, S1'!D4*Main!$B$5) -> 7.9579852 | E4: =('[1]Qc, Winter, S1'!E4*Main!$B$5) -> 7.7874174 | F4: =('[1]Qc, Winter, S1'!F4*Main!$B$5) -> 8.8508731 | G4: =('[1]Qc, Winter, S1'!G4*Main!$B$5) -> 10.989579 | H4: =('[1]Qc, Winter, S1'!H4*Main!$B$5) -> 17.050421 | I4: =('[1]Qc, Winter, S1'!I4*Main!$B$5) -> 20.815302 | ... Y4: =('[1]Qc, Winter, S1'!Y4*Main!$B$5) -> 15.672062

Sheet Qc, Winter, S4
A1: LoadID | B1: 0 | C1: 1 | D1: 2 | E1: 3 | F1: 4 | G1: 5 | H1: 6 | I1: 7 | J1: 8 | K1: 9 | L1: 10 | M1: 11 | N1: 12 | O1: 13 | P1: 14 | Q1: 15 | R1: 16 | S1: 17 | T1: 18 | U1: 19 | V1: 20 | W1: 21 | X1: 22 | Y1: 23
A2: 1 | B2: =('[1]Qc, Winter, S2'!B2*Main!$B$5) -> -16.14685 | C2: =('[1]Qc, Winter, S2'!C2*Main!$B$5) -> -17.549408 | D2: =('[1]Qc, Winter, S2'!D2*Main!$B$5) -> -18.903136 | E2: =('[1]Qc, Winter, S2'!E2*Main!$B$5) -> -18.765526 | F2: =('[1]Qc, Winter, S2'!F2*Main!$B$5) -> -19.423169 | G2: =('[1]Qc, Winter, S2'!G2*Main!$B$5) -> -17.290276 | H2: =('[1]Qc, Winter, S2'!H2*Main!$B$5) -> -12.875819 | I2: =('[1]Qc, Winter, S2'!I2*Main!$B$5) -> -5.2999435 | ... Y2: =('[1]Qc, Winter, S2'!Y2*Main!$B$5) -> -14.002008
A3: 2 | B3: =('[1]Qc, Winter, S2'!B3*Main!$B$5) -> 18.293447 | C3: =('[1]Qc, Winter, S2'!C3*Main!$B$5) -> 22.660363 | D3: =('[1]Qc, Winter, S2'!D3*Main!$B$5) -> 22.660363 | E3: =('[1]Qc, Winter, S2'!E3*Main!$B$5) -> 22.660363 | F3: =('[1]Qc, Winter, S2'!F3*Main!$B$5) -> 22.660363 | G3: =('[1]Qc, Winter, S2'!G3*Main!$B$5) -> 18.360633 | H3: =('[1]Qc, Winter, S2'!H3*Main!$B$5) -> 8.3279282 | I3: =('[1]Qc, Winter, S2'!I3*Main!$B$5) -> 1.0721344 | ... Y3: =('[1]Qc, Winter, S2'!Y3*Main!$B$5) -> 16.837808
A4: 3 | B4: =('[1]Qc, Winter, S2'!B4*Main!$B$5) -> 12.412991 | C4: =('[1]Qc, Winter, S2'!C4*Main!$B$5) -> 9.5750406 | D4: =('[1]Qc, Winter, S2'!D4*Main!$B$5) -> 8.1967248 | E4: =('[1]Qc, Winter, S2'!E4*Main!$B$5) -> 8.0210399 | F4: =('[1]Qc, Winter, S2'!F4*Main!$B$5) -> 9.1163993 | G4: =('[1]Qc, Winter, S2'!G4*Main!$B$5) -> 11.319266 | H4: =('[1]Qc, Winter, S2'!H4*Main!$B$5) -> 17.561934 | I4: =('[1]Qc, Winter, S2'!I4*Main!$B$5) -> 21.439761 | ... Y4: =('[1]Qc, Winter, S2'!Y4*Main!$B$5) -> 16.142224

Sheet Qc, Winter, S5
A1: LoadID | B1: 0 | C1: 1 | D1: 2 | E1: 3 | F1: 4 | G1: 5 | H1: 6 | I1: 7 | J1: 8 | K1: 9 | L1: 10 | M1: 11 | N1: 12 | O1: 13 | P1: 14 | Q1: 15 | R1: 16 | S1: 17 | T1: 18 | U1: 19 | V1: 20 | W1: 21 | X1: 22 | Y1: 23
A2: 1 | B2: =('[1]Qc, Winter, S2'!B2*Main!$B$5) -> -16.14685 | C2: =('[1]Qc, Winter, S2'!C2*Main!$B$5) -> -17.549408 | D2: =('[1]Qc, Winter, S2'!D2*Main!$B$5) -> -18.903136 | E2: =('[1]Qc, Winter, S2'!E2*Main!$B$5) -> -18.765526 | F2: =('[1]Qc, Winter, S2'!F2*Main!$B$5) -> -19.423169 | G2: =('[1]Qc, Winter, S2'!G2*Main!$B$5) -> -17.290276 | H2: =('[1]Qc, Winter, S2'!H2*Main!$B$5) -> -12.875819 | I2: =('[1]Qc, Winter, S2'!I2*Main!$B$5) -> -5.2999435 | ... Y2: =('[1]Qc, Winter, S2'!Y2*Main!$B$5) -> -14.002008
A3: 2 | B3: =('[1]Qc, Winter, S2'!B3*Main!$B$5) -> 18.293447 | C3: =('[1]Qc, Winter, S2'!C3*Main!$B$5) -> 22.660363 | D3: =('[1]Qc, Winter, S2'!D3*Main!$B$5) -> 22.660363 | E3: =('[1]Qc, Winter, S2'!E3*Main!$B$5) -> 22.660363 | F3: =('[1]Qc, Winter, S2'!F3*Main!$B$5) -> 22.660363 | G3: =('[1]Qc, Winter, S2'!G3*Main!$B$5) -> 18.360633 | H3: =('[1]Qc, Winter, S2'!H3*Main!$B$5) -> 8.3279282 | I3: =('[1]Qc, Winter, S2'!I3*Main!$B$5) -> 1.0721344 | ... Y3: =('[1]Qc, Winter, S2'!Y3*Main!$B$5) -> 16.837808
A4: 3 | B4: =('[1]Qc, Winter, S2'!B4*Main!$B$5) -> 12.412991 | C4: =('[1]Qc, Winter, S2'!C4*Main!$B$5) -> 9.5750406 | D4: =('[1]Qc, Winter, S2'!D4*Main!$B$5) -> 8.1967248 | E4: =('[1]Qc, Winter, S2'!E4*Main!$B$5) -> 8.0210399 | F4: =('[1]Qc, Winter, S2'!F4*Main!$B$5) -> 9.1163993 | G4: =('[1]Qc, Winter, S2'!G4*Main!$B$5) -> 11.319266 | H4: =('[1]Qc, Winter, S2'!H4*Main!$B$5) -> 17.561934 | I4: =('[1]Qc, Winter, S2'!I4*Main!$B$5) -> 21.439761 | ... Y4: =('[1]Qc, Winter, S2'!Y4*Main!$B$5) -> 16.142224

Sheet Qc, Winter, S6
A1: LoadID | B1: 0 | C1: 1 | D1: 2 | E1: 3 | F1: 4 | G1: 5 | H1: 6 | I1: 7 | J1: 8 | K1: 9 | L1: 10 | M1: 11 | N1: 12 | O1: 13 | P1: 14 | Q1: 15 | R1: 16 | S1: 17 | T1: 18 | U1: 19 | V1: 20 | W1: 21 | X1: 22 | Y1: 23
A2: 1 | B2: =('[1]Qc, Winter, S2'!B2*Main!$B$5) -> -16.14685 | C2: =('[1]Qc, Winter, S2'!C2*Main!$B$5) -> -17.549408 | D2: =('[1]Qc, Winter, S2'!D2*Main!$B$5) -> -18.903136 | E2: =('[1]Qc, Winter, S2'!E2*Main!$B$5) -> -18.765526 | F2: =('[1]Qc, Winter, S2'!F2*Main!$B$5) -> -19.423169 | G2: =('[1]Qc, Winter, S2'!G2*Main!$B$5) -> -17.290276 | H2: =('[1]Qc, Winter, S2'!H2*Main!$B$5) -> -12.875819 | I2: =('[1]Qc, Winter, S2'!I2*Main!$B$5) -> -5.2999435 | ... Y2: =('[1]Qc, Winter, S2'!Y2*Main!$B$5) -> -14.002008
A3: 2 | B3: =('[1]Qc, Winter, S2'!B3*Main!$B$5) -> 18.293447 | C3: =('[1]Qc, Winter, S2'!C3*Main!$B$5) -> 22.660363 | D3: =('[1]Qc, Winter, S2'!D3*Main!$B$5) -> 22.660363 | E3: =('[1]Qc, Winter, S2'!E3*Main!$B$5) -> 22.660363 | F3: =('[1]Qc, Winter, S2'!F3*Main!$B$5) -> 22.660363 | G3: =('[1]Qc, Winter, S2'!G3*Main!$B$5) -> 18.360633 | H3: =('[1]Qc, Winter, S2'!H3*Main!$B$5) -> 8.3279282 | I3: =('[1]Qc, Winter, S2'!I3*Main!$B$5) -> 1.0721344 | ... Y3: =('[1]Qc, Winter, S2'!Y3*Main!$B$5) -> 16.837808
A4: 3 | B4: =('[1]Qc, Winter, S2'!B4*Main!$B$5) -> 12.412991 | C4: =('[1]Qc, Winter, S2'!C4*Main!$B$5) -> 9.5750406 | D4: =('[1]Qc, Winter, S2'!D4*Main!$B$5) -> 8.1967248 | E4: =('[1]Qc, Winter, S2'!E4*Main!$B$5) -> 8.0210399 | F4: =('[1]Qc, Winter, S2'!F4*Main!$B$5) -> 9.1163993 | G4: =('[1]Qc, Winter, S2'!G4*Main!$B$5) -> 11.319266 | H4: =('[1]Qc, Winter, S2'!H4*Main!$B$5) -> 17.561934 | I4: =('[1]Qc, Winter, S2'!I4*Main!$B$5) -> 21.439761 | ... Y4: =('[1]Qc, Winter, S2'!Y4*Main!$B$5) -> 16.142224

Sheet Qc, Winter, S7
A1: LoadID | B1: 0 | C1: 1 | D1: 2 | E1: 3 | F1: 4 | G1: 5 | H1: 6 | I1: 7 | J1: 8 | K1: 9 | L1: 10 | M1: 11 | N1: 12 | O1: 13 | P1: 14 | Q1: 15 | R1: 16 | S1: 17 | T1: 18 | U1: 19 | V1: 20 | W1: 21 | X1: 22 | Y1: 23
A2: 1 | B2: =('[1]Qc, Winter, S3'!B2*Main!$B$5) -> -15.363022 | C2: =('[1]Qc, Winter, S3'!C2*Main!$B$5) -> -16.697495 | D2: =('[1]Qc, Winter, S3'!D2*Main!$B$5) -> -17.985508 | E2: =('[1]Qc, Winter, S3'!E2*Main!$B$5) -> -17.854578 | F2: =('[1]Qc, Winter, S3'!F2*Main!$B$5) -> -18.480296 | G2: =('[1]Qc, Winter, S3'!G2*Main!$B$5) -> -16.450942 | H2: =('[1]Qc, Winter, S3'!H2*Main!$B$5) -> -12.25078 | I2: =('[1]Qc, Winter, S3'!I2*Main!$B$5) -> -5.0426646 | ... Y2: =('[1]Qc, Winter, S3'!Y2*Main!$B$5) -> -13.322299
A3: 2 | B3: =('[1]Qc, Winter, S3'!B3*Main!$B$5) -> 17.405416 | C3: =('[1]Qc, Winter, S3'!C3*Main!$B$5) -> 21.560346 | D3: =('[1]Qc, Winter, S3'!D3*Main!$B$5) -> 21.560346 | E3: =('[1]Qc, Winter, S3'!E3*Main!$B$5) -> 21.560346 | F3: =('[1]Qc, Winter, S3'!F3*Main!$B$5) -> 21.560346 | G3: =('[1]Qc, Winter, S3'!G3*Main!$B$5) -> 17.46934 | H3: =('[1]Qc, Winter, S3'!H3*Main!$B$5) -> 7.9236599 | I3: =('[1]Qc, Winter, S3'!I3*Main!$B$5) -> 1.0200891 | ... Y3: =('[1]Qc, Winter, S3'!Y3*Main!$B$5) -> 16.020439
A4: 3 | B4: =('[1]Qc, Winter, S3'!B4*Main!$B$5) -> 11.810419 | C4: =('[1]Qc, Winter, S3'!C4*Main!$B$5) -> 9.1102328 | D4: =('[1]Qc, Winter, S3'!D4*Main!$B$5) -> 7.7988255 | E4: =('[1]Qc, Winter, S3'!E4*Main!$B$5) -> 7.631669 | F4: =('[1]Qc, Winter, S3'!F4*Main!$B$5) -> 8.6738556 | G4: =('[1]Qc, Winter, S3'!G4*Main!$B$5) -> 10.769787 | H4: =('[1]Qc, Winter, S3'!H4*Main!$B$5) -> 16.709413 | I4: =('[1]Qc, Winter, S3'!I4*Main!$B$5) -> 20.398996 | ... Y4: =('[1]Qc, Winter, S3'!Y4*Main!$B$5) -> 15.358621

Sheet Qc, Winter, S8
A1: LoadID | B1: 0 | C1: 1 | D1: 2 | E1: 3 | F1: 4 | G1: 5 | H1: 6 | I1: 7 | J1: 8 | K1: 9 | L1: 10 | M1: 11 | N1: 12 | O1: 13 | P1: 14 | Q1: 15 | R1: 16 | S1: 17 | T1: 18 | U1: 19 | V1: 20 | W1: 21 | X1: 22 | Y1: 23
A2: 1 | B2: =('[1]Qc, Winter, S3'!B2*Main!$B$5) -> -15.363022 | C2: =('[1]Qc, Winter, S3'!C2*Main!$B$5) -> -16.697495 | D2: =('[1]Qc, Winter, S3'!D2*Main!$B$5) -> -17.985508 | E2: =('[1]Qc, Winter, S3'!E2*Main!$B$5) -> -17.854578 | F2: =('[1]Qc, Winter, S3'!F2*Main!$B$5) -> -18.480296 | G2: =('[1]Qc, Winter, S3'!G2*Main!$B$5) -> -16.450942 | H2: =('[1]Qc, Winter, S3'!H2*Main!$B$5) -> -12.25078 | I2: =('[1]Qc, Winter, S3'!I2*Main!$B$5) -> -5.0426646 | ... Y2: =('[1]Qc, Winter, S3'!Y2*Main!$B$5) -> -13.322299
A3: 2 | B3: =('[1]Qc, Winter, S3'!B3*Main!$B$5) -> 17.405416 | C3: =('[1]Qc, Winter, S3'!C3*Main!$B$5) -> 21.560346 | D3: =('[1]Qc, Winter, S3'!D3*Main!$B$5) -> 21.560346 | E3: =('[1]Qc, Winter, S3'!E3*Main!$B$5) -> 21.560346 | F3: =('[1]Qc, Winter, S3'!F3*Main!$B$5) -> 21.560346 | G3: =('[1]Qc, Winter, S3'!G3*Main!$B$5) -> 17.46934 | H3: =('[1]Qc, Winter, S3'!H3*Main!$B$5) -> 7.9236599 | I3: =('[1]Qc, Winter, S3'!I3*Main!$B$5) -> 1.0200891 | ... Y3: =('[1]Qc, Winter, S3'!Y3*Main!$B$5) -> 16.020439
A4: 3 | B4: =('[1]Qc, Winter, S3'!B4*Main!$B$5) -> 11.810419 | C4: =('[1]Qc, Winter, S3'!C4*Main!$B$5) -> 9.1102328 | D4: =('[1]Qc, Winter, S3'!D4*Main!$B$5) -> 7.7988255 | E4: =('[1]Qc, Winter, S3'!E4*Main!$B$5) -> 7.631669 | F4: =('[1]Qc, Winter, S3'!F4*Main!$B$5) -> 8.6738556 | G4: =('[1]Qc, Winter, S3'!G4*Main!$B$5) -> 10.769787 | H4: =('[1]Qc, Winter, S3'!H4*Main!$B$5) -> 16.709413 | I4: =('[1]Qc, Winter, S3'!I4*Main!$B$5) -> 20.398996 | ... Y4: =('[1]Qc, Winter, S3'!Y4*Main!$B$5) -> 15.358621

Sheet Qc, Winter, S9
A1: LoadID | B1: 0 | C1: 1 | D1: 2 | E1: 3 | F1: 4 | G1: 5 | H1: 6 | I1: 7 | J1: 8 | K1: 9 | L1: 10 | M1: 11 | N1: 12 | O1: 13 | P1: 14 | Q1: 15 | R1: 16 | S1: 17 | T1: 18 | U1: 19 | V1: 20 | W1: 21 | X1: 22 | Y1: 23
A2: 1 | B2: =('[1]Qc, Winter, S3'!B2*Main!$B$5) -> -15.363022 | C2: =('[1]Qc, Winter, S3'!C2*Main!$B$5) -> -16.697495 | D2: =('[1]Qc, Winter, S3'!D2*Main!$B$5) -> -17.985508 | E2: =('[1]Qc, Winter, S3'!E2*Main!$B$5) -> -17.854578 | F2: =('[1]Qc, Winter, S3'!F2*Main!$B$5) -> -18.480296 | G2: =('[1]Qc, Winter, S3'!G2*Main!$B$5) -> -16.450942 | H2: =('[1]Qc, Winter, S3'!H2*Main!$B$5) -> -12.25078 | I2: =('[1]Qc, Winter, S3'!I2*Main!$B$5) -> -5.0426646 | ... Y2: =('[1]Qc, Winter, S3'!Y2*Main!$B$5) -> -13.322299
A3: 2 | B3: =('[1]Qc, Winter, S3'!B3*Main!$B$5) -> 17.405416 | C3: =('[1]Qc, Winter, S3'!C3*Main!$B$5) -> 21.560346 | D3: =('[1]Qc, Winter, S3'!D3*Main!$B$5) -> 21.560346 | E3: =('[1]Qc, Winter, S3'!E3*Main!$B$5) -> 21.560346 | F3: =('[1]Qc, Winter, S3'!F3*Main!$B$5) -> 21.560346 | G3: =('[1]Qc, Winter, S3'!G3*Main!$B$5) -> 17.46934 | H3: =('[1]Qc, Winter, S3'!H3*Main!$B$5) -> 7.9236599 | I3: =('[1]Qc, Winter, S3'!I3*Main!$B$5) -> 1.0200891 | ... Y3: =('[1]Qc, Winter, S3'!Y3*Main!$B$5) -> 16.020439
A4: 3 | B4: =('[1]Qc, Winter, S3'!B4*Main!$B$5) -> 11.810419 | C4: =('[1]Qc, Winter, S3'!C4*Main!$B$5) -> 9.1102328 | D4: =('[1]Qc, Winter, S3'!D4*Main!$B$5) -> 7.7988255 | E4: =('[1]Qc, Winter, S3'!E4*Main!$B$5) -> 7.631669 | F4: =('[1]Qc, Winter, S3'!F4*Main!$B$5) -> 8.6738556 | G4: =('[1]Qc, Winter, S3'!G4*Main!$B$5) -> 10.769787 | H4: =('[1]Qc, Winter, S3'!H4*Main!$B$5) -> 16.709413 | I4: =('[1]Qc, Winter, S3'!I4*Main!$B$5) -> 20.398996 | ... Y4: =('[1]Qc, Winter, S3'!Y4*Main!$B$5) -> 15.358621

Sheet UpFlex, Winter
A1: LoadID | B1: 0 | C1: 1 | D1: 2 | E1: 3 | F1: 4 | G1: 5 | H1: 6 | I1: 7 | J1: 8 | K1: 9 | L1: 10 | M1: 11 | N1: 12 | O1: 13 | P1: 14 | Q1: 15 | R1: 16 | S1: 17 | T1: 18 | U1: 19 | V1: 20 | W1: 21 | X1: 22 | Y1: 23
A2: 1 | B2: =('FL Characterization'!B$4-'FL Characterization'!B$2)*VLOOKUP($A2,'FL Ratio'!$A$2:$B$21,2,FALSE) -> 3.3981461 | C2: =('FL Characterization'!C$4-'FL Characterization'!C$2)*VLOOKUP($A2,'FL Ratio'!$A$2:$B$21,2,FALSE) -> 3.7409276 | D2: =('FL Characterization'!D$4-'FL Characterization'!D$2)*VLOOKUP($A2,'FL Ratio'!$A$2:$B$21,2,FALSE) -> 4.8691726 | E2: =('FL Characterization'!E$4-'FL Characterization'!E$2)*VLOOKUP($A2,'FL Ratio'!$A$2:$B$21,2,FALSE) -> 5.5823106 | F2: =('FL Characterization'!F$4-'FL Characterization'!F$2)*VLOOKUP($A2,'FL Ratio'!$A$2:$B$21,2,FALSE) -> 6.5635283 | G2: =('FL Characterization'!G$4-'FL Characterization'!G$2)*VLOOKUP($A2,'FL Ratio'!$A$2:$B$21,2,FALSE) -> 7.672292 | H2: =('FL Characterization'!H$4-'FL Characterization'!H$2)*VLOOKUP($A2,'FL Ratio'!$A$2:$B$21,2,FALSE) -> 6.8391604 | I2: =('FL Characterization'!I$4-'FL Characterization'!I$2)*VLOOKUP($A2,'FL Ratio'!$A$2:$B$21,2,FALSE) -> 9.7773313 | ... Y2: =('FL Characterization'!Y$4-'FL Characterization'!Y$2)*VLOOKUP($A2,'FL Ratio'!$A$2:$B$21,2,FALSE) -> 2.9054903
A3: 2 | B3: =('FL Characterization'!B$4-'FL Characterization'!B$2)*VLOOKUP($A3,'FL Ratio'!$A$2:$B$21,2,FALSE) -> 3.3981461 | C3: =('FL Characterization'!C$4-'FL Characterization'!C$2)*VLOOKUP($A3,'FL Ratio'!$A$2:$B$21,2,FALSE) -> 3.7409276 | D3: =('FL Characterization'!D$4-'FL Characterization'!D$2)*VLOOKUP($A3,'FL Ratio'!$A$2:$B$21,2,FALSE) -> 4.8691726 | E3: =('FL Characterization'!E$4-'FL Characterization'!E$2)*VLOOKUP($A3,'FL Ratio'!$A$2:$B$21,2,FALSE) -> 5.5823106 | F3: =('FL Characterization'!F$4-'FL Characterization'!F$2)*VLOOKUP($A3,'FL Ratio'!$A$2:$B$21,2,FALSE) -> 6.5635283 | G3: =('FL Characterization'!G$4-'FL Characterization'!G$2)*VLOOKUP($A3,'FL Ratio'!$A$2:$B$21,2,FALSE) -> 7.672292 | H3: =('FL Characterization'!H$4-'FL Characterization'!H$2)*VLOOKUP($A3,'FL Ratio'!$A$2:$B$21,2,FALSE) -> 6.8391604 | I3: =('FL Characterization'!I$4-'FL Characterization'!I$2)*VLOOKUP($A3,'FL Ratio'!$A$2:$B$21,2,FALSE) -> 9.7773313 | ... Y3: =('FL Characterization'!Y$4-'FL Characterization'!Y$2)*VLOOKUP($A3,'FL Ratio'!$A$2:$B$21,2,FALSE) -> 2.9054903
A4: 3 | B4: =('FL Characterization'!B$4-'FL Characterization'!B$2)*VLOOKUP($A4,'FL Ratio'!$A$2:$B$21,2,FALSE) -> 3.3981461 | C4: =('FL Characterization'!C$4-'FL Characterization'!C$2)*VLOOKUP($A4,'FL Ratio'!$A$2:$B$21,2,FALSE) -> 3.7409276 | D4: =('FL Characterization'!D$4-'FL Characterization'!D$2)*VLOOKUP($A4,'FL Ratio'!$A$2:$B$21,2,FALSE) -> 4.8691726 | E4: =('FL Characterization'!E$4-'FL Characterization'!E$2)*VLOOKUP($A4,'FL Ratio'!$A$2:$B$21,2,FALSE) -> 5.5823106 | F4: =('FL Characterization'!F$4-'FL Characterization'!F$2)*VLOOKUP($A4,'FL Ratio'!$A$2:$B$21,2,FALSE) -> 6.5635283 | G4: =('FL Characterization'!G$4-'FL Characterization'!G$2)*VLOOKUP($A4,'FL Ratio'!$A$2:$B$21,2,FALSE) -> 7.672292 | H4: =('FL Characterization'!H$4-'FL Characterization'!H$2)*VLOOKUP($A4,'FL Ratio'!$A$2:$B$21,2,FALSE) -> 6.8391604 | I4: =('FL Characterization'!I$4-'FL Characterization'!I$2)*VLOOKUP($A4,'FL Ratio'!$A$2:$B$21,2,FALSE) -> 9.7773313 | ... Y4: =('FL Characterization'!Y$4-'FL Characterization'!Y$2)*VLOOKUP($A4,'FL Ratio'!$A$2:$B$21,2,FALSE) -> 2.9054903

Sheet DownFlex, Winter
A1: LoadID | B1: 0 | C1: 1 | D1: 2 | E1: 3 | F1: 4 | G1: 5 | H1: 6 | I1: 7 | J1: 8 | K1: 9 | L1: 10 | M1: 11 | N1: 12 | O1: 13 | P1: 14 | Q1: 15 | R1: 16 | S1: 17 | T1: 18 | U1: 19 | V1: 20 | W1: 21 | X1: 22 | Y1: 23
A2: 1 | B2: =('FL Characterization'!B$2-'FL Characterization'!B$3)*VLOOKUP($A2,'FL Ratio'!$A$2:$B$21,2,FALSE) -> 9.4209035 | C2: =('FL Characterization'!C$2-'FL Characterization'!C$3)*VLOOKUP($A2,'FL Ratio'!$A$2:$B$21,2,FALSE) -> 9.9700504 | D2: =('FL Characterization'!D$2-'FL Characterization'!D$3)*VLOOKUP($A2,'FL Ratio'!$A$2:$B$21,2,FALSE) -> 10.528138 | E2: =('FL Characterization'!E$2-'FL Characterization'!E$3)*VLOOKUP($A2,'FL Ratio'!$A$2:$B$21,2,FALSE) -> 11.0067 | F2: =('FL Characterization'!F$2-'FL Characterization'!F$3)*VLOOKUP($A2,'FL Ratio'!$A$2:$B$21,2,FALSE) -> 11.131635 | G2: =('FL Characterization'!G$2-'FL Characterization'!G$3)*VLOOKUP($A2,'FL Ratio'!$A$2:$B$21,2,FALSE) -> 11.644313 | H2: =('FL Characterization'!H$2-'FL Characterization'!H$3)*VLOOKUP($A2,'FL Ratio'!$A$2:$B$21,2,FALSE) -> 11.584787 | I2: =('FL Characterization'!I$2-'FL Characterization'!I$3)*VLOOKUP($A2,'FL Ratio'!$A$2:$B$21,2,FALSE) -> 10.950327 | ... Y2: =('FL Characterization'!Y$2-'FL Characterization'!Y$3)*VLOOKUP($A2,'FL Ratio'!$A$2:$B$21,2,FALSE) -> 8.4129579
