Workbook

Sheet Characterization
A1: LoadID | B1: Pc | C1: Qc | D1: FL Ratio | G1: Pc_prev | H1: Qc_prev
A2: 1 | B2: 3.699 | C2: 3.153 | D2: =B2/SUM($B$2:$B$27) -> 0.0091438928 | G2: {=MAX(ABS('Pc, Original'!$D2:$AA2))} -> 3.413 | H2: {=MAX(ABS('Qc, Original'!$D2:$AA2))} -> 1.746
A3: 2 | B3: 25.397 | C3: -0.4 | D3: =B3/SUM($B$2:$B$27) -> 0.062781143 | G3: {=MAX(ABS('Pc, Original'!$D3:$AA3))} -> 28.921 | H3: {=MAX(ABS('Qc, Original'!$D3:$AA3))} -> 1.4321956
A4: 3 | B4: 38.622 | C4: 2.379 | D4: =B4/SUM($B$2:$B$27) -> 0.095473217 | G4: {=MAX(ABS('Pc, Original'!$D4:$AA4))} -> 34.794 | H4: {=MAX(ABS('Qc, Original'!$D4:$AA4))} -> 1.3238855
A5: 4 | B5: 46.624 | C5: 7.775 | D5: =B5/SUM($B$2:$B$27) -> 0.11525408 | G5: {=MAX(ABS('Pc, Original'!$D5:$AA5))} -> 93.512 | H5: {=MAX(ABS('Qc, Original'!$D5:$AA5))} -> 1.2717971
A6: 5 | B6: 9.816 | C6: 1.853 | D6: =B6/SUM($B$2:$B$27) -> 0.024265059 | G6: {=MAX(ABS('Pc, Original'!$D6:$AA6))} -> 11.846 | H6: {=MAX(ABS('Qc, Original'!$D6:$AA6))} -> 4.177
A7: 6 | B7: 0 | C7: 0 | D7: =B7/SUM($B$2:$B$27) -> 0 | G7: {=MAX(ABS('Pc, Original'!$D7:$AA7))} -> 0 | H7: {=MAX(ABS('Qc, Original'!$D7:$AA7))} -> 2.1778489
A8: 7 | B8: 18.896 | C8: 8.754 | D8: =B8/SUM($B$2:$B$27) -> 0.046710732 | G8: {=MAX(ABS('Pc, Original'!$D8:$AA8))} -> 33.956 | H8: {=MAX(ABS('Qc, Original'!$D8:$AA8))} -> 3.4942609
A9: 8 | B9: 32.695 | C9: 4.319 | D9: =B9/SUM($B$2:$B$27) -> 0.080821729 | G9: {=MAX(ABS('Pc, Original'!$D9:$AA9))} -> 46.826 | H9: {=MAX(ABS('Qc, Original'!$D9:$AA9))} -> 2.8115218
A10: 9 | B10: 18.8523 | C10: -1.46 | D10: =B10/SUM($B$2:$B$27) -> 0.046602706 | G10: {=MAX(ABS('Pc, Original'!$D10:$AA10))} -> 306.237 | H10: {=MAX(ABS('Qc, Original'!$D10:$AA10))} -> 4.493
A11: 10 | B11: 4.318 | C11: -7.359 | D11: =B11/SUM($B$2:$B$27) -> 0.010674055 | G11: {=MAX(ABS('Pc, Original'!$D11:$AA11))} -> 5.977 | H11: {=MAX(ABS('Qc, Original'!$D11:$AA11))} -> 4.740963
A12: 11 | B12: 33.231 | C12: 3.907 | D12: =B12/SUM($B$2:$B$27) -> 0.082146716 | G12: {=MAX(ABS('Pc, Original'!$D12:$AA12))} -> 50.107 | H12: {=MAX(ABS('Qc, Original'!$D12:$AA12))} -> 1.799825
A13: 12 | B13: 8.225 | C13: -0.011 | D13: =B13/SUM($B$2:$B$27) -> 0.020332122 | G13: {=MAX(ABS('Pc, Original'!$D13:$AA13))} -> 10.687 | H13: {=MAX(ABS('Qc, Original'!$D13:$AA13))} -> 1.9473087
... A25: 24 | B25: 42.909 | C25: 12.673 | D25: =B25/SUM($B$2:$B$27) -> 0.10607064 | G25: {=MAX(ABS('Pc, Original'!$D25:$AA25))} -> 34.15 | H25: {=MAX(ABS('Qc, Original'!$D25:$AA25))} -> 102.11979
A26: 25 | B26: 0 | C26: 0 | D26: =B26/SUM($B$2:$B$27) -> 0
A27: 26 | B27: 0 | C27: 0 | D27: =B27/SUM($B$2:$B$27) -> 0

Sheet Growth Factors
A1: Growth Factor | B1: Value, [%]
A2: Load | B2: 0.01
A3: Flexible Load | B3: 0.025

Sheet Pc, Original
A1: LoadID | B1: Season | C1: Scenario | D1: 0 | E1: 1 | F1: 2 | G1: 3 | H1: 4 | I1: 5 | J1: 6 | K1: 7 | L1: 8 | M1: 9 | N1: 10 | O1: 11 | P1: 12 | Q1: 13 | R1: 14 | S1: 15 | T1: 16 | U1: 17 | V1: 18 | W1: 19 | X1: 20 | Y1: 21 | Z1: 22 | AA1: 23
A2: 1 | B2: Winter | C2: 1 | D2: 2.202 | E2: 0.946 | F2: 2.041 | G2: 0.763 | H2: 0.727 | I2: 1.575 | J2: 1.56 | K2: 2.392 | L2: 0.852 | M2: 2.421 | N2: 0.52 | O2: 1.631 | P2: 0.714 | Q2: 1.675 | R2: 3.331 | S2: 0.948 | T2: 0.214 | U2: 3.413 | V2: 3.074 | W2: 0.613 | X2: 2.726 | Y2: 2.07 | Z2: 1.522 | AA2: 0.546
A3: 2 | B3: Winter | C3: 1 | D3: 18.407 | E3: 17.169 | F3: 16.268 | G3: 16.153 | H3: 16.348 | I3: 17.97 | J3: 21.443 | K3: 25.81 | L3: 28.101 | M3: 28.451 | N3: 27.684 | O3: 27.826 | P3: 27.803 | Q3: 27.349 | R3: 25.791 | S3: 25.052 | T3: 26.09 | U3: 28.921 | V3: 28.817 | W3: 28.22 | X3: 27.735 | Y3: 25.995 | Z3: 22.741 | AA3: 20.632
A4: 3 | B4: Winter | C4: 1 | D4: 19.706 | E4: 18.312 | F4: 16.572 | G4: 17.824 | H4: 17.762 | I4: 18.516 | J4: 27.557 | K4: 30.691 | L4: 33.648 | M4: 33.666 | N4: 31.801 | O4: 34.794 | P4: 32.814 | Q4: 30.718 | R4: 29.786 | S4: 27.832 | T4: 27.85 | U4: 29.484 | V4: 29.484 | W4: 29.928 | X4: 29.12 | Y4: 26.313 | Z4: 22.255 | AA4: 21.536
A5: 4 | B5: Winter | C5: 1 | D5: 61.586 | E5: 54.187 | F5: 51.015 | G5: 50.408 | H5: 52.763 | I5: 56.968 | J5: 68.743 | K5: 76.85 | L5: 81.339 | M5: 84.106 | N5: 84.875 | O5: 83.989 | P5: 83.513 | Q5: 81.792 | R5: 79.188 | S5: 77.754 | T5: 80.53 | U5: 91.171 | V5: 92.959 | W5: 93.512 | X5: 90.73 | Y5: 86.583 | Z5: 78.952 | AA5: 69.786
A6: 5 | B6: Winter | C6: 1 | D6: -6.975 | E6: -7.764 | F6: -8.514 | G6: -8.446 | H6: -8.181 | I6: 8.283 | J6: 9.944 | K6: 11.846 | L6: 5.426 | M6: -2.087 | N6: -2.938 | O6: -3.04 | P6: -2.818 | Q6: -3.85 | R6: -3.644 | S6: -4.68 | T6: -4.714 | U6: -2.715 | V6: -2.953 | W6: -2.719 | X6: -2.716 | Y6: -2.787 | Z6: -3.201 | AA6: -5.183
A7: 6 | B7: Winter | C7: 1 | D7: 0 | E7: 0 | F7: 0 | G7: 0 | H7: 0 | I7: 0 | J7: 0 | K7: 0 | L7: 0 | M7: 0 | N7: 0 | O7: 0 | P7: 0 | Q7: 0 | R7: 0 | S7: 0 | T7: 0 | U7: 0 | V7: 0 | W7: 0 | X7: 0 | Y7: 0 | Z7: 0 | AA7: 0
A8: 7 | B8: Winter | C8: 1 | D8: 25.284 | E8: 26.898 | F8: 28.245 | G8: 31.85 | H8: 33.742 | I8: 20.721 | J8: 6.664 | K8: -19.903 | L8: -33.956 | M8: -24.656 | N8: -11.614 | O8: -8.803 | P8: -19.111 | Q8: -7.787 | R8: -8.959 | S8: -10.924 | T8: -14.737 | U8: -21.925 | V8: -23.223 | W8: -24.985 | X8: -24.98 | Y8: -14.324 | Z8: 5.07 | AA8: 22.432
A9: 8 | B9: Winter | C9: 1 | D9: 27.685 | E9: 25.509 | F9: 24.327 | G9: 23.831 | H9: 23.504 | I9: 24.915 | J9: 31.036 | K9: 35.316 | L9: 42.141 | M9: 45.347 | N9: 45.366 | O9: 46.19 | P9: 44.659 | Q9: 43.762 | R9: 43.309 | S9: 41.729 | T9: 41.88 | U9: 46.826 | V9: 40.63 | W9: 40.356 | X9: 40.476 | Y9: 38.536 | Z9: 33.446 | AA9: 29.6
A10: 9 | B10: Winter | C10: 1 | D10: 170.681 | E10: 149.541 | F10: 141.931 | G10: 138.574 | H10: 136.14 | I10: 154.669 | J10: 212.674 | K10: 256.557 | L10: 277.197 | M10: 274.157 | N10: 289.152 | O10: 296.415 | P10: 283.667 | Q10: 279.161 | R10: 260.77 | S10: 251.579 | T10: 260.755 | U10: 306.237 | V10: 305.034 | W10: 304.848 | X10: 303.585 | Y10: 286.204 | Z10: 248.786 | AA10: 212.409
A11: 10 | B11: Winter | C11: 1 | D11: 3.704 | E11: 3.621 | F11: 3.465 | G11: 3.508 | H11: 3.49 | I11: 3.71 | J11: 4.708 | K11: 5.345 | L11: 5.736 | M11: 5.977 | N11: 5.572 | O11: 5.755 | P11: 5.678 | Q11: 5.464 | R11: 5.186 | S11: 4.859 | T11: 4.885 | U11: 5.522 | V11: 5.547 | W11: 5.673 | X11: 5.496 | Y11: 5.331 | Z11: 4.67 | AA11: 4.133
A12: 11 | B12: Winter | C12: 1 | D12: 26.453 | E12: 25.649 | F12: 25.425 | G12: 25.599 | H12: 26.886 | I12: 30.725 | J12: 41.437 | K12: 48.474 | L12: 50.107 | M12: 46.856 | N12: 47.347 | O12: 47.479 | P12: 44.658 | Q12: 44.907 | R12: 42.016 | S12: 41.405 | T12: 42.244 | U12: 44.602 | V12: 43.831 | W12: 42.906 | X12: 41.851 | Y12: 37.4 | Z12: 32.894 | AA12: 28.629
A13: 12 | B13: Winter | C13: 1 | D13: 6.737 | E13: 6.536 | F13: 5.771 | G13: 6.059 | H13: 6.234 | I13: 7.067 | J13: 8.124 | K13: 9.754 | L13: 9.755 | M13: 10.094 | N13: 8.868 | O13: 9.269 | P13: 8.712 | Q13: 8.323 | R13: 8.571 | S13: 8.921 | T13: 9.948 | U13: 10.536 | V13: 10.005 | W13: 10.679 | X13: 10.687 | Y13: 9.3 | Z13: 7.92 | AA13: 7.791
... A53: 26 | B53: Summer | C53: 1 | D53: 0 | E53: 0 | F53: 0 | G53: 0 | H53: 0 | I53: 0 | J53: 0 | K53: 0 | L53: 0 | M53: 0 | N53: 0 | O53: 0 | P53: 0 | Q53: 0 | R53: 0 | S53: 0 | T53: 0 | U53: 0 | V53: 0 | W53: 0 | X53: 0 | Y53: 0 | Z53: 0 | AA53: 0
A54: 1 | B54: Spring | C54: 1 | D54: =SUMIFS(D$2:D$51,$A$2:$A$51,$A54,$B$2:$B$51,"Winter",$C$2:$C$51,$C54)*(2/3)+SUMIFS(D$2:D$51,$A$2:$A$51,$A54,$B$2:$B$51,"Summer",$C$2:$C$51,$C54)*(1/3) -> 1.5407594 | E54: =SUMIFS(E$2:E$51,$A$2:$A$51,$A54,$B$2:$B$51,"Winter",$C$2:$C$51,$C54)*(2/3)+SUMIFS(E$2:E$51,$A$2:$A$51,$A54,$B$2:$B$51,"Summer",$C$2:$C$51,$C54)*(1/3) -> 0.75746584 | F54: =SUMIFS(F$2:F$51,$A$2:$A$51,$A54,$B$2:$B$51,"Winter",$C$2:$C$51,$C54)*(2/3)+SUMIFS(F$2:F$51,$A$2:$A$51,$A54,$B$2:$B$51,"Summer",$C$2:$C$51,$C54)*(1/3) -> 1.6832617 | G54: =SUMIFS(G$2:G$51,$A$2:$A$51,$A54,$B$2:$B$51,"Winter",$C$2:$C$51,$C54)*(2/3)+SUMIFS(G$2:G$51,$A$2:$A$51,$A54,$B$2:$B$51,"Summer",$C$2:$C$51,$C54)*(1/3) -> 0.71036856 | H54: =SUMIFS(H$2:H$51,$A$2:$A$51,$A54,$B$2:$B$51,"Winter",$C$2:$C$51,$C54)*(2/3)+SUMIFS(H$2:H$51,$A$2:$A$51,$A54,$B$2:$B$51,"Summer",$C$2:$C$51,$C54)*(1/3) -> 0.94093793 | I54: =SUMIFS(I$2:I$51,$A$2:$A$51,$A54,$B$2:$B$51,"Winter",$C$2:$C$51,$C54)*(2/3)+SUMIFS(I$2:I$51,$A$2:$A$51,$A54,$B$2:$B$51,"Summer",$C$2:$C$51,$C54)*(1/3) -> 1.8354703 | J54: =SUMIFS(J$2:J$51,$A$2:$A$51,$A54,$B$2:$B$51,"Winter",$C$2:$C$51,$C54)*(2/3)+SUMIFS(J$2:J$51,$A$2:$A$51,$A54,$B$2:$B$51,"Summer",$C$2:$C$51,$C54)*(1/3) -> 1.5665563 | K54: =SUMIFS(K$2:K$51,$A$2:$A$51,$A54,$B$2:$B$51,"Winter",$C$2:$C$51,$C54)*(2/3)+SUMIFS(K$2:K$51,$A$2:$A$51,$A54,$B$2:$B$51,"Summer",$C$2:$C$51,$C54)*(1/3) -> 1.6563292 | ... AA54: =SUMIFS(AA$2:AA$51,$A$2:$A$51,$A54,$B$2:$B$51,"Winter",$C$2:$C$51,$C54)*(2/3)+SUMIFS(AA$2:AA$51,$A$2:$A$51,$A54,$B$2:$B$51,"Summer",$C$2:$C$51,$C54)*(1/3) -> 1.2376791
A55: 2 | B55: Spring | C55: 1 | D55: =SUMIFS(D$2:D$51,$A$2:$A$51,$A55,$B$2:$B$51,"Winter",$C$2:$C$51,$C55)*(2/3)+SUMIFS(D$2:D$51,$A$2:$A$51,$A55,$B$2:$B$51,"Summer",$C$2:$C$51,$C55)*(1/3) -> 18.776454 | E55: =SUMIFS(E$2:E$51,$A$2:$A$51,$A55,$B$2:$B$51,"Winter",$C$2:$C$51,$C55)*(2/3)+SUMIFS(E$2:E$51,$A$2:$A$51,$A55,$B$2:$B$51,"Summer",$C$2:$C$51,$C55)*(1/3) -> 17.356194 | F55: =SUMIFS(F$2:F$51,$A$2:$A$51,$A55,$B$2:$B$51,"Winter",$C$2:$C$51,$C55)*(2/3)+SUMIFS(F$2:F$51,$A$2:$A$51,$A55,$B$2:$B$51,"Summer",$C$2:$C$51,$C55)*(1/3) -> 16.652291 | G55: =SUMIFS(G$2:G$51,$A$2:$A$51,$A55,$B$2:$B$51,"Winter",$C$2:$C$51,$C55)*(2/3)+SUMIFS(G$2:G$51,$A$2:$A$51,$A55,$B$2:$B$51,"Summer",$C$2:$C$51,$C55)*(1/3) -> 16.56079 | H55: =SUMIFS(H$2:H$51,$A$2:$A$51,$A55,$B$2:$B$51,"Winter",$C$2:$C$51,$C55)*(2/3)+SUMIFS(H$2:H$51,$A$2:$A$51,$A55,$B$2:$B$51,"Summer",$C$2:$C$51,$C55)*(1/3) -> 16.691247 | I55: =SUMIFS(I$2:I$51,$A$2:$A$51,$A55,$B$2:$B$51,"Winter",$C$2:$C$51,$C55)*(2/3)+SUMIFS(I$2:I$51,$A$2:$A$51,$A55,$B$2:$B$51,"Summer",$C$2:$C$51,$C55)*(1/3) -> 17.721352 | J55: =SUMIFS(J$2:J$51,$A$2:$A$51,$A55,$B$2:$B$51,"Winter",$C$2:$C$51,$C55)*(2/3)+SUMIFS(J$2:J$51,$A$2:$A$51,$A55,$B$2:$B$51,"Summer",$C$2:$C$51,$C55)*(1/3) -> 20.493636 | K55: =SUMIFS(K$2:K$51,$A$2:$A$51,$A55,$B$2:$B$51,"Winter",$C$2:$C$51,$C55)*(2/3)+SUMIFS(K$2:K$51,$A$2:$A$51,$A55,$B$2:$B$51,"Summer",$C$2:$C$51,$C55)*(1/3) -> 24.565566 | ... AA55: =SUMIFS(AA$2:AA$51,$A$2:$A$51,$A55,$B$2:$B$51,"Winter",$C$2:$C$51,$C55)*(2/3)+SUMIFS(AA$2:AA$51,$A$2:$A$51,$A55,$B$2:$B$51,"Summer",$C$2:$C$51,$C55)*(1/3) -> 21.067732
A56: 3 | B56: Spring | C56: 1 | D56: =SUMIFS(D$2:D$51,$A$2:$A$51,$A56,$B$2:$B$51,"Winter",$C$2:$C$51,$C56)*(2/3)+SUMIFS(D$2:D$51,$A$2:$A$51,$A56,$B$2:$B$51,"Summer",$C$2:$C$51,$C56)*(1/3) -> 21.970989 | E56: =SUMIFS(E$2:E$51,$A$2:$A$51,$A56,$B$2:$B$51,"Winter",$C$2:$C$51,$C56)*(2/3)+SUMIFS(E$2:E$51,$A$2:$A$51,$A56,$B$2:$B$51,"Summer",$C$2:$C$51,$C56)*(1/3) -> 20.251309 | F56: =SUMIFS(F$2:F$51,$A$2:$A$51,$A56,$B$2:$B$51,"Winter",$C$2:$C$51,$C56)*(2/3)+SUMIFS(F$2:F$51,$A$2:$A$51,$A56,$B$2:$B$51,"Summer",$C$2:$C$51,$C56)*(1/3) -> 18.697616 | G56: =SUMIFS(G$2:G$51,$A$2:$A$51,$A56,$B$2:$B$51,"Winter",$C$2:$C$51,$C56)*(2/3)+SUMIFS(G$2:G$51,$A$2:$A$51,$A56,$B$2:$B$51,"Summer",$C$2:$C$51,$C56)*(1/3) -> 19.259955 | H56: =SUMIFS(H$2:H$51,$A$2:$A$51,$A56,$B$2:$B$51,"Winter",$C$2:$C$51,$C56)*(2/3)+SUMIFS(H$2:H$51,$A$2:$A$51,$A56,$B$2:$B$51,"Summer",$C$2:$C$51,$C56)*(1/3) -> 19.218622 | I56: =SUMIFS(I$2:I$51,$A$2:$A$51,$A56,$B$2:$B$51,"Winter",$C$2:$C$51,$C56)*(2/3)+SUMIFS(I$2:I$51,$A$2:$A$51,$A56,$B$2:$B$51,"Summer",$C$2:$C$51,$C56)*(1/3) -> 20.254105 | J56: =SUMIFS(J$2:J$51,$A$2:$A$51,$A56,$B$2:$B$51,"Winter",$C$2:$C$51,$C56)*(2/3)+SUMIFS(J$2:J$51,$A$2:$A$51,$A56,$B$2:$B$51,"Summer",$C$2:$C$51,$C56)*(1/3) -> 28.282461 | K56: =SUMIFS(K$2:K$51,$A$2:$A$51,$A56,$B$2:$B$51,"Winter",$C$2:$C$51,$C56)*(2/3)+SUMIFS(K$2:K$51,$A$2:$A$51,$A56,$B$2:$B$51,"Summer",$C$2:$C$51,$C56)*(1/3) -> 32.656981 | ... AA56: =SUMIFS(AA$2:AA$51,$A$2:$A$51,$A56,$B$2:$B$51,"Winter",$C$2:$C$51,$C56)*(2/3)+SUMIFS(AA$2:AA$51,$A$2:$A$51,$A56,$B$2:$B$51,"Summer",$C$2:$C$51,$C56)*(1/3) -> 24.386863
A57: 4 | B57: Spring | C57: 1 | D57: =SUMIFS(D$2:D$51,$A$2:$A$51,$A57,$B$2:$B$51,"Winter",$C$2:$C$51,$C57)*(2/3)+SUMIFS(D$2:D$51,$A$2:$A$51,$A57,$B$2:$B$51,"Summer",$C$2:$C$51,$C57)*(1/3) -> 54.034095 | E57: =SUMIFS(E$2:E$51,$A$2:$A$51,$A57,$B$2:$B$51,"Winter",$C$2:$C$51,$C57)*(2/3)+SUMIFS(E$2:E$51,$A$2:$A$51,$A57,$B$2:$B$51,"Summer",$C$2:$C$51,$C57)*(1/3) -> 47.54814 | F57: =SUMIFS(F$2:F$51,$A$2:$A$51,$A57,$B$2:$B$51,"Winter",$C$2:$C$51,$C57)*(2/3)+SUMIFS(F$2:F$51,$A$2:$A$51,$A57,$B$2:$B$51,"Summer",$C$2:$C$51,$C57)*(1/3) -> 44.812119 | G57: =SUMIFS(G$2:G$51,$A$2:$A$51,$A57,$B$2:$B$51,"Winter",$C$2:$C$51,$C57)*(2/3)+SUMIFS(G$2:G$51,$A$2:$A$51,$A57,$B$2:$B$51,"Summer",$C$2:$C$51,$C57)*(1/3) -> 44.06485 | H57: =SUMIFS(H$2:H$51,$A$2:$A$51,$A57,$B$2:$B$51,"Winter",$C$2:$C$51,$C57)*(2/3)+SUMIFS(H$2:H$51,$A$2:$A$51,$A57,$B$2:$B$51,"Summer",$C$2:$C$51,$C57)*(1/3) -> 46.263401 | I57: =SUMIFS(I$2:I$51,$A$2:$A$51,$A57,$B$2:$B$51,"Winter",$C$2:$C$51,$C57)*(2/3)+SUMIFS(I$2:I$51,$A$2:$A$51,$A57,$B$2:$B$51,"Summer",$C$2:$C$51,$C57)*(1/3) -> 48.134624 | J57: =SUMIFS(J$2:J$51,$A$2:$A$51,$A57,$B$2:$B$51,"Winter",$C$2:$C$51,$C57)*(2/3)+SUMIFS(J$2:J$51,$A$2:$A$51,$A57,$B$2:$B$51,"Summer",$C$2:$C$51,$C57)*(1/3) -> 57.739751 | K57: =SUMIFS(K$2:K$51,$A$2:$A$51,$A57,$B$2:$B$51,"Winter",$C$2:$C$51,$C57)*(2/3)+SUMIFS(K$2:K$51,$A$2:$A$51,$A57,$B$2:$B$51,"Summer",$C$2:$C$51,$C57)*(1/3) -> 65.058325 | ... AA57: =SUMIFS(AA$2:AA$51,$A$2:$A$51,$A57,$B$2:$B$51,"Winter",$C$2:$C$51,$C57)*(2/3)+SUMIFS(AA$2:AA$51,$A$2:$A$51,$A57,$B$2:$B$51,"Summer",$C$2:$C$51,$C57)*(1/3) -> 61.730958
A58: 5 | B58: Spring | C58: 1 | D58: =SUMIFS(D$2:D$51,$A$2:$A$51,$A58,$B$2:$B$51,"Winter",$C$2:$C$51,$C58)*(2/3)+SUMIFS(D$2:D$51,$A$2:$A$51,$A58,$B$2:$B$51,"Summer",$C$2:$C$51,$C58)*(1/3) -> -9.2898903 | E58: =SUMIFS(E$2:E$51,$A$2:$A$51,$A58,$B$2:$B$51,"Winter",$C$2:$C$51,$C58)*(2/3)+SUMIFS(E$2:E$51,$A$2:$A$51,$A58,$B$2:$B$51,"Summer",$C$2:$C$51,$C58)*(1/3) -> -9.1591123 | F58: =SUMIFS(F$2:F$51,$A$2:$A$51,$A58,$B$2:$B$51,"Winter",$C$2:$C$51,$C58)*(2/3)+SUMIFS(F$2:F$51,$A$2:$A$51,$A58,$B$2:$B$51,"Summer",$C$2:$C$51,$C58)*(1/3) -> -8.2583201 | G58: =SUMIFS(G$2:G$51,$A$2:$A$51,$A58,$B$2:$B$51,"Winter",$C$2:$C$51,$C58)*(2/3)+SUMIFS(G$2:G$51,$A$2:$A$51,$A58,$B$2:$B$51,"Summer",$C$2:$C$51,$C58)*(1/3) -> -8.0771564 | H58: =SUMIFS(H$2:H$51,$A$2:$A$51,$A58,$B$2:$B$51,"Winter",$C$2:$C$51,$C58)*(2/3)+SUMIFS(H$2:H$51,$A$2:$A$51,$A58,$B$2:$B$51,"Summer",$C$2:$C$51,$C58)*(1/3) -> -7.8241379 | I58: =SUMIFS(I$2:I$51,$A$2:$A$51,$A58,$B$2:$B$51,"Winter",$C$2:$C$51,$C58)*(2/3)+SUMIFS(I$2:I$51,$A$2:$A$51,$A58,$B$2:$B$51,"Summer",$C$2:$C$51,$C58)*(1/3) -> 3.1020238 | J58: =SUMIFS(J$2:J$51,$A$2:$A$51,$A58,$B$2:$B$51,"Winter",$C$2:$C$51,$C58)*(2/3)+SUMIFS(J$2:J$51,$A$2:$A$51,$A58,$B$2:$B$51,"Summer",$C$2:$C$51,$C58)*(1/3) -> 4.8433021 | K58: =SUMIFS(K$2:K$51,$A$2:$A$51,$A58,$B$2:$B$51,"Winter",$C$2:$C$51,$C58)*(2/3)+SUMIFS(K$2:K$51,$A$2:$A$51,$A58,$B$2:$B$51,"Summer",$C$2:$C$51,$C58)*(1/3) -> 7.0156141 | ... AA58: =SUMIFS(AA$2:AA$51,$A$2:$A$51,$A58,$B$2:$B$51,"Winter",$C$2:$C$51,$C58)*(2/3)+SUMIFS(AA$2:AA$51,$A$2:$A$51,$A58,$B$2:$B$51,"Summer",$C$2:$C$51,$C58)*(1/3) -> -3.7390863
A59: 6 | B59: Spring | C59: 1 | D59: =SUMIFS(D$2:D$51,$A$2:$A$51,$A59,$B$2:$B$51,"Winter",$C$2:$C$51,$C59)*(2/3)+SUMIFS(D$2:D$51,$A$2:$A$51,$A59,$B$2:$B$51,"Summer",$C$2:$C$51,$C59)*(1/3) -> 0 | E59: =SUMIFS(E$2:E$51,$A$2:$A$51,$A59,$B$2:$B$51,"Winter",$C$2:$C$51,$C59)*(2/3)+SUMIFS(E$2:E$51,$A$2:$A$51,$A59,$B$2:$B$51,"Summer",$C$2:$C$51,$C59)*(1/3) -> 0 | F59: =SUMIFS(F$2:F$51,$A$2:$A$51,$A59,$B$2:$B$51,"Winter",$C$2:$C$51,$C59)*(2/3)+SUMIFS(F$2:F$51,$A$2:$A$51,$A59,$B$2:$B$51,"Summer",$C$2:$C$51,$C59)*(1/3) -> 0 | G59: =SUMIFS(G$2:G$51,$A$2:$A$51,$A59,$B$2:$B$51,"Winter",$C$2:$C$51,$C59)*(2/3)+SUMIFS(G$2:G$51,$A$2:$A$51,$A59,$B$2:$B$51,"Summer",$C$2:$C$51,$C59)*(1/3) -> 0 | H59: =SUMIFS(H$2:H$51,$A$2:$A$51,$A59,$B$2:$B$51,"Winter",$C$2:$C$51,$C59)*(2/3)+SUMIFS(H$2:H$51,$A$2:$A$51,$A59,$B$2:$B$51,"Summer",$C$2:$C$51,$C59)*(1/3) -> 0 | I59: =SUMIFS(I$2:I$51,$A$2:$A$51,$A59,$B$2:$B$51,"Winter",$C$2:$C$51,$C59)*(2/3)+SUMIFS(I$2:I$51,$A$2:$A$51,$A59,$B$2:$B$51,"Summer",$C$2:$C$51,$C59)*(1/3) -> 0 | J59: =SUMIFS(J$2:J$51,$A$2:$A$51,$A59,$B$2:$B$51,"Winter",$C$2:$C$51,$C59)*(2/3)+SUMIFS(J$2:J$51,$A$2:$A$51,$A59,$B$2:$B$51,"Summer",$C$2:$C$51,$C59)*(1/3) -> 0 | K59: =SUMIFS(K$2:K$51,$A$2:$A$51,$A59,$B$2:$B$51,"Winter",$C$2:$C$51,$C59)*(2/3)+SUMIFS(K$2:K$51,$A$2:$A$51,$A59,$B$2:$B$51,"Summer",$C$2:$C$51,$C59)*(1/3) -> 0 | ... AA59: =SUMIFS(AA$2:AA$51,$A$2:$A$51,$A59,$B$2:$B$51,"Winter",$C$2:$C$51,$C59)*(2/3)+SUMIFS(AA$2:AA$51,$A$2:$A$51,$A59,$B$2:$B$51,"Summer",$C$2:$C$51,$C59)*(1/3) -> 0
A60: 7 | B60: Spring | C60: 1 | D60: =SUMIFS(D$2:D$51,$A$2:$A$51,$A60,$B$2:$B$51,"Winter",$C$2:$C$51,$C60)*(2/3)+SUMIFS(D$2:D$51,$A$2:$A$51,$A60,$B$2:$B$51,"Summer",$C$2:$C$51,$C60)*(1/3) -> 21.86396 | E60: =SUMIFS(E$2:E$51,$A$2:$A$51,$A60,$B$2:$B$51,"Winter",$C$2:$C$51,$C60)*(2/3)+SUMIFS(E$2:E$51,$A$2:$A$51,$A60,$B$2:$B$51,"Summer",$C$2:$C$51,$C60)*(1/3) -> 21.038534 | F60: =SUMIFS(F$2:F$51,$A$2:$A$51,$A60,$B$2:$B$51,"Winter",$C$2:$C$51,$C60)*(2/3)+SUMIFS(F$2:F$51,$A$2:$A$51,$A60,$B$2:$B$51,"Summer",$C$2:$C$51,$C60)*(1/3) -> 23.286951 | G60: =SUMIFS(G$2:G$51,$A$2:$A$51,$A60,$B$2:$B$51,"Winter",$C$2:$C$51,$C60)*(2/3)+SUMIFS(G$2:G$51,$A$2:$A$51,$A60,$B$2:$B$51,"Summer",$C$2:$C$51,$C60)*(1/3) -> 25.357367 | H60: =SUMIFS(H$2:H$51,$A$2:$A$51,$A60,$B$2:$B$51,"Winter",$C$2:$C$51,$C60)*(2/3)+SUMIFS(H$2:H$51,$A$2:$A$51,$A60,$B$2:$B$51,"Summer",$C$2:$C$51,$C60)*(1/3) -> 27.225471 | I60: =SUMIFS(I$2:I$51,$A$2:$A$51,$A60,$B$2:$B$51,"Winter",$C$2:$C$51,$C60)*(2/3)+SUMIFS(I$2:I$51,$A$2:$A$51,$A60,$B$2:$B$51,"Summer",$C$2:$C$51,$C60)*(1/3) -> 15.427307 | J60: =SUMIFS(J$2:J$51,$A$2:$A$51,$A60,$B$2:$B$51,"Winter",$C$2:$C$51,$C60)*(2/3)+SUMIFS(J$2:J$51,$A$2:$A$51,$A60,$B$2:$B$51,"Summer",$C$2:$C$51,$C60)*(1/3) -> 0.61698117 | K60: =SUMIFS(K$2:K$51,$A$2:$A$51,$A60,$B$2:$B$51,"Winter",$C$2:$C$51,$C60)*(2/3)+SUMIFS(K$2:K$51,$A$2:$A$51,$A60,$B$2:$B$51,"Summer",$C$2:$C$51,$C60)*(1/3) -> -12.991013 | ... AA60: =SUMIFS(AA$2:AA$51,$A$2:$A$51,$A60,$B$2:$B$51,"Winter",$C$2:$C$51,$C60)*(2/3)+SUMIFS(AA$2:AA$51,$A$2:$A$51,$A60,$B$2:$B$51,"Summer",$C$2:$C$51,$C60)*(1/3) -> 18.167349
A61: 8 | B61: Spring | C61: 1 | D61: =SUMIFS(D$2:D$51,$A$2:$A$51,$A61,$B$2:$B$51,"Winter",$C$2:$C$51,$C61)*(2/3)+SUMIFS(D$2:D$51,$A$2:$A$51,$A61,$B$2:$B$51,"Summer",$C$2:$C$51,$C61)*(1/3) -> 25.73649 | E61: =SUMIFS(E$2:E$51,$A$2:$A$51,$A61,$B$2:$B$51,"Winter",$C$2:$C$51,$C61)*(2/3)+SUMIFS(E$2:E$51,$A$2:$A$51,$A61,$B$2:$B$51,"Summer",$C$2:$C$51,$C61)*(1/3) -> 23.177607 | F61: =SUMIFS(F$2:F$51,$A$2:$A$51,$A61,$B$2:$B$51,"Winter",$C$2:$C$51,$C61)*(2/3)+SUMIFS(F$2:F$51,$A$2:$A$51,$A61,$B$2:$B$51,"Summer",$C$2:$C$51,$C61)*(1/3) -> 22.384391 | G61: =SUMIFS(G$2:G$51,$A$2:$A$51,$A61,$B$2:$B$51,"Winter",$C$2:$C$51,$C61)*(2/3)+SUMIFS(G$2:G$51,$A$2:$A$51,$A61,$B$2:$B$51,"Summer",$C$2:$C$51,$C61)*(1/3) -> 21.493816 | H61: =SUMIFS(H$2:H$51,$A$2:$A$51,$A61,$B$2:$B$51,"Winter",$C$2:$C$51,$C61)*(2/3)+SUMIFS(H$2:H$51,$A$2:$A$51,$A61,$B$2:$B$51,"Summer",$C$2:$C$51,$C61)*(1/3) -> 21.327267 | I61: =SUMIFS(I$2:I$51,$A$2:$A$51,$A61,$B$2:$B$51,"Winter",$C$2:$C$51,$C61)*(2/3)+SUMIFS(I$2:I$51,$A$2:$A$51,$A61,$B$2:$B$51,"Summer",$C$2:$C$51,$C61)*(1/3) -> 22.265991 | J61: =SUMIFS(J$2:J$51,$A$2:$A$51,$A61,$B$2:$B$51,"Winter",$C$2:$C$51,$C61)*(2/3)+SUMIFS(J$2:J$51,$A$2:$A$51,$A61,$B$2:$B$51,"Summer",$C$2:$C$51,$C61)*(1/3) -> 27.526568 | K61: =SUMIFS(K$2:K$51,$A$2:$A$51,$A61,$B$2:$B$51,"Winter",$C$2:$C$51,$C61)*(2/3)+SUMIFS(K$2:K$51,$A$2:$A$51,$A61,$B$2:$B$51,"Summer",$C$2:$C$51,$C61)*(1/3) -> 32.891073 | ... AA61: =SUMIFS(AA$2:AA$51,$A$2:$A$51,$A61,$B$2:$B$51,"Winter",$C$2:$C$51,$C61)*(2/3)+SUMIFS(AA$2:AA$51,$A$2:$A$51,$A61,$B$2:$B$51,"Summer",$C$2:$C$51,$C61)*(1/3) -> 27.48
A62: 9 | B62: Spring | C62: 1 | D62: =SUMIFS(D$2:D$51,$A$2:$A$51,$A62,$B$2:$B$51,"Winter",$C$2:$C$51,$C62)*(2/3)+SUMIFS(D$2:D$51,$A$2:$A$51,$A62,$B$2:$B$51,"Summer",$C$2:$C$51,$C62)*(1/3) -> 152.94528 | E62: =SUMIFS(E$2:E$51,$A$2:$A$51,$A62,$B$2:$B$51,"Winter",$C$2:$C$51,$C62)*(2/3)+SUMIFS(E$2:E$51,$A$2:$A$51,$A62,$B$2:$B$51,"Summer",$C$2:$C$51,$C62)*(1/3) -> 134.64442 | F62: =SUMIFS(F$2:F$51,$A$2:$A$51,$A62,$B$2:$B$51,"Winter",$C$2:$C$51,$C62)*(2/3)+SUMIFS(F$2:F$51,$A$2:$A$51,$A62,$B$2:$B$51,"Summer",$C$2:$C$51,$C62)*(1/3) -> 127.30117 | G62: =SUMIFS(G$2:G$51,$A$2:$A$51,$A62,$B$2:$B$51,"Winter",$C$2:$C$51,$C62)*(2/3)+SUMIFS(G$2:G$51,$A$2:$A$51,$A62,$B$2:$B$51,"Summer",$C$2:$C$51,$C62)*(1/3) -> 124.09201 | H62: =SUMIFS(H$2:H$51,$A$2:$A$51,$A62,$B$2:$B$51,"Winter",$C$2:$C$51,$C62)*(2/3)+SUMIFS(H$2:H$51,$A$2:$A$51,$A62,$B$2:$B$51,"Summer",$C$2:$C$51,$C62)*(1/3) -> 143.74063 | I62: =SUMIFS(I$2:I$51,$A$2:$A$51,$A62,$B$2:$B$51,"Winter",$C$2:$C$51,$C62)*(2/3)+SUMIFS(I$2:I$51,$A$2:$A$51,$A62,$B$2:$B$51,"Summer",$C$2:$C$51,$C62)*(1/3) -> 153.88115 | J62: =SUMIFS(J$2:J$51,$A$2:$A$51,$A62,$B$2:$B$51,"Winter",$C$2:$C$51,$C62)*(2/3)+SUMIFS(J$2:J$51,$A$2:$A$51,$A62,$B$2:$B$51,"Summer",$C$2:$C$51,$C62)*(1/3) -> 176.9448 | K62: =SUMIFS(K$2:K$51,$A$2:$A$51,$A62,$B$2:$B$51,"Winter",$C$2:$C$51,$C62)*(2/3)+SUMIFS(K$2:K$51,$A$2:$A$51,$A62,$B$2:$B$51,"Summer",$C$2:$C$51,$C62)*(1/3) -> 216.64297 | ... AA62: =SUMIFS(AA$2:AA$51,$A$2:$A$51,$A62,$B$2:$B$51,"Winter",$C$2:$C$51,$C62)*(2/3)+SUMIFS(AA$2:AA$51,$A$2:$A$51,$A62,$B$2:$B$51,"Summer",$C$2:$C$51,$C62)*(1/3) -> 186.10471
A63: 10 | B63: Spring | C63: 1 | D63: =SUMIFS(D$2:D$51,$A$2:$A$51,$A63,$B$2:$B$51,"Winter",$C$2:$C$51,$C63)*(2/3)+SUMIFS(D$2:D$51,$A$2:$A$51,$A63,$B$2:$B$51,"Summer",$C$2:$C$51,$C63)*(1/3) -> 3.6094503 | E63: =SUMIFS(E$2:E$51,$A$2:$A$51,$A63,$B$2:$B$51,"Winter",$C$2:$C$51,$C63)*(2/3)+SUMIFS(E$2:E$51,$A$2:$A$51,$A63,$B$2:$B$51,"Summer",$C$2:$C$51,$C63)*(1/3) -> 3.4824538 | F63: =SUMIFS(F$2:F$51,$A$2:$A$51,$A63,$B$2:$B$51,"Winter",$C$2:$C$51,$C63)*(2/3)+SUMIFS(F$2:F$51,$A$2:$A$51,$A63,$B$2:$B$51,"Summer",$C$2:$C$51,$C63)*(1/3) -> 3.2775407 | G63: =SUMIFS(G$2:G$51,$A$2:$A$51,$A63,$B$2:$B$51,"Winter",$C$2:$C$51,$C63)*(2/3)+SUMIFS(G$2:G$51,$A$2:$A$51,$A63,$B$2:$B$51,"Summer",$C$2:$C$51,$C63)*(1/3) -> 3.3313952 | H63: =SUMIFS(H$2:H$51,$A$2:$A$51,$A63,$B$2:$B$51,"Winter",$C$2:$C$51,$C63)*(2/3)+SUMIFS(H$2:H$51,$A$2:$A$51,$A63,$B$2:$B$51,"Summer",$C$2:$C$51,$C63)*(1/3) -> 3.3189063 | I63: =SUMIFS(I$2:I$51,$A$2:$A$51,$A63,$B$2:$B$51,"Winter",$C$2:$C$51,$C63)*(2/3)+SUMIFS(I$2:I$51,$A$2:$A$51,$A63,$B$2:$B$51,"Summer",$C$2:$C$51,$C63)*(1/3) -> 3.5078239 | J63: =SUMIFS(J$2:J$51,$A$2:$A$51,$A63,$B$2:$B$51,"Winter",$C$2:$C$51,$C63)*(2/3)+SUMIFS(J$2:J$51,$A$2:$A$51,$A63,$B$2:$B$51,"Summer",$C$2:$C$51,$C63)*(1/3) -> 4.3226594 | K63: =SUMIFS(K$2:K$51,$A$2:$A$51,$A63,$B$2:$B$51,"Winter",$C$2:$C$51,$C63)*(2/3)+SUMIFS(K$2:K$51,$A$2:$A$51,$A63,$B$2:$B$51,"Summer",$C$2:$C$51,$C63)*(1/3) -> 5.0229306 | ... AA63: =SUMIFS(AA$2:AA$51,$A$2:$A$51,$A63,$B$2:$B$51,"Winter",$C$2:$C$51,$C63)*(2/3)+SUMIFS(AA$2:AA$51,$A$2:$A$51,$A63,$B$2:$B$51,"Summer",$C$2:$C$51,$C63)*(1/3) -> 4.0655906
A64: 11 | B64: Spring | C64: 1 | D64: =SUMIFS(D$2:D$51,$A$2:$A$51,$A64,$B$2:$B$51,"Winter",$C$2:$C$51,$C64)*(2/3)+SUMIFS(D$2:D$51,$A$2:$A$51,$A64,$B$2:$B$51,"Summer",$C$2:$C$51,$C64)*(1/3) -> 24.423333 | E64: =SUMIFS(E$2:E$51,$A$2:$A$51,$A64,$B$2:$B$51,"Winter",$C$2:$C$51,$C64)*(2/3)+SUMIFS(E$2:E$51,$A$2:$A$51,$A64,$B$2:$B$51,"Summer",$C$2:$C$51,$C64)*(1/3) -> 24.004333 | F64: =SUMIFS(F$2:F$51,$A$2:$A$51,$A64,$B$2:$B$51,"Winter",$C$2:$C$51,$C64)*(2/3)+SUMIFS(F$2:F$51,$A$2:$A$51,$A64,$B$2:$B$51,"Summer",$C$2:$C$51,$C64)*(1/3) -> 23.390667 | G64: =SUMIFS(G$2:G$51,$A$2:$A$51,$A64,$B$2:$B$51,"Winter",$C$2:$C$51,$C64)*(2/3)+SUMIFS(G$2:G$51,$A$2:$A$51,$A64,$B$2:$B$51,"Summer",$C$2:$C$51,$C64)*(1/3) -> 23.895333 | H64: =SUMIFS(H$2:H$51,$A$2:$A$51,$A64,$B$2:$B$51,"Winter",$C$2:$C$51,$C64)*(2/3)+SUMIFS(H$2:H$51,$A$2:$A$51,$A64,$B$2:$B$51,"Summer",$C$2:$C$51,$C64)*(1/3) -> 24.672333 | I64: =SUMIFS(I$2:I$51,$A$2:$A$51,$A64,$B$2:$B$51,"Winter",$C$2:$C$51,$C64)*(2/3)+SUMIFS(I$2:I$51,$A$2:$A$51,$A64,$B$2:$B$51,"Summer",$C$2:$C$51,$C64)*(1/3) -> 27.606667 | J64: =SUMIFS(J$2:J$51,$A$2:$A$51,$A64,$B$2:$B$51,"Winter",$C$2:$C$51,$C64)*(2/3)+SUMIFS(J$2:J$51,$A$2:$A$51,$A64,$B$2:$B$51,"Summer",$C$2:$C$51,$C64)*(1/3) -> 37.149 | K64: =SUMIFS(K$2:K$51,$A$2:$A$51,$A64,$B$2:$B$51,"Winter",$C$2:$C$51,$C64)*(2/3)+SUMIFS(K$2:K$51,$A$2:$A$51,$A64,$B$2:$B$51,"Summer",$C$2:$C$51,$C64)*(1/3) -> 43.01 | ... AA64: =SUMIFS(AA$2:AA$51,$A$2:$A$51,$A64,$B$2:$B$51,"Winter",$C$2:$C$51,$C64)*(2/3)+SUMIFS(AA$2:AA$51,$A$2:$A$51,$A64,$B$2:$B$51,"Summer",$C$2:$C$51,$C64)*(1/3) -> 26.898667
A65: 12 | B65: Spring | C65: 1 | D65: =SUMIFS(D$2:D$51,$A$2:$A$51,$A65,$B$2:$B$51,"Winter",$C$2:$C$51,$C65)*(2/3)+SUMIFS(D$2:D$51,$A$2:$A$51,$A65,$B$2:$B$51,"Summer",$C$2:$C$51,$C65)*(1/3) -> 6.5215912 | E65: =SUMIFS(E$2:E$51,$A$2:$A$51,$A65,$B$2:$B$51,"Winter",$C$2:$C$51,$C65)*(2/3)+SUMIFS(E$2:E$51,$A$2:$A$51,$A65,$B$2:$B$51,"Summer",$C$2:$C$51,$C65)*(1/3) -> 6.4663358 | F65: =SUMIFS(F$2:F$51,$A$2:$A$51,$A65,$B$2:$B$51,"Winter",$C$2:$C$51,$C65)*(2/3)+SUMIFS(F$2:F$51,$A$2:$A$51,$A65,$B$2:$B$51,"Summer",$C$2:$C$51,$C65)*(1/3) -> 5.5479922 | G65: =SUMIFS(G$2:G$51,$A$2:$A$51,$A65,$B$2:$B$51,"Winter",$C$2:$C$51,$C65)*(2/3)+SUMIFS(G$2:G$51,$A$2:$A$51,$A65,$B$2:$B$51,"Summer",$C$2:$C$51,$C65)*(1/3) -> 5.8844937 | H65: =SUMIFS(H$2:H$51,$A$2:$A$51,$A65,$B$2:$B$51,"Winter",$C$2:$C$51,$C65)*(2/3)+SUMIFS(H$2:H$51,$A$2:$A$51,$A65,$B$2:$B$51,"Summer",$C$2:$C$51,$C65)*(1/3) -> 6.0249432 | I65: =SUMIFS(I$2:I$51,$A$2:$A$51,$A65,$B$2:$B$51,"Winter",$C$2:$C$51,$C65)*(2/3)+SUMIFS(I$2:I$51,$A$2:$A$51,$A65,$B$2:$B$51,"Summer",$C$2:$C$51,$C65)*(1/3) -> 6.4454186 | J65: =SUMIFS(J$2:J$51,$A$2:$A$51,$A65,$B$2:$B$51,"Winter",$C$2:$C$51,$C65)*(2/3)+SUMIFS(J$2:J$51,$A$2:$A$51,$A65,$B$2:$B$51,"Summer",$C$2:$C$51,$C65)*(1/3) -> 7.4332679 | K65: =SUMIFS(K$2:K$51,$A$2:$A$51,$A65,$B$2:$B$51,"Winter",$C$2:$C$51,$C65)*(2/3)+SUMIFS(K$2:K$51,$A$2:$A$51,$A65,$B$2:$B$51,"Summer",$C$2:$C$51,$C65)*(1/3) -> 8.8096347 | ... AA65: =SUMIFS(AA$2:AA$51,$A$2:$A$51,$A65,$B$2:$B$51,"Winter",$C$2:$C$51,$C65)*(2/3)+SUMIFS(AA$2:AA$51,$A$2:$A$51,$A65,$B$2:$B$51,"Summer",$C$2:$C$51,$C65)*(1/3) -> 7.4121447
... A77: 24 | B77: Spring | C77: 1 | D77: =SUMIFS(D$2:D$51,$A$2:$A$51,$A77,$B$2:$B$51,"Winter",$C$2:$C$51,$C77)*(2/3)+SUMIFS(D$2:D$51,$A$2:$A$51,$A77,$B$2:$B$51,"Summer",$C$2:$C$51,$C77)*(1/3) -> 15.468773 | E77: =SUMIFS(E$2:E$51,$A$2:$A$51,$A77,$B$2:$B$51,"Winter",$C$2:$C$51,$C77)*(2/3)+SUMIFS(E$2:E$51,$A$2:$A$51,$A77,$B$2:$B$51,"Summer",$C$2:$C$51,$C77)*(1/3) -> 10.699285 | F77: =SUMIFS(F$2:F$51,$A$2:$A$51,$A77,$B$2:$B$51,"Winter",$C$2:$C$51,$C77)*(2/3)+SUMIFS(F$2:F$51,$A$2:$A$51,$A77,$B$2:$B$51,"Summer",$C$2:$C$51,$C77)*(1/3) -> 11.438572 | G77: =SUMIFS(G$2:G$51,$A$2:$A$51,$A77,$B$2:$B$51,"Winter",$C$2:$C$51,$C77)*(2/3)+SUMIFS(G$2:G$51,$A$2:$A$51,$A77,$B$2:$B$51,"Summer",$C$2:$C$51,$C77)*(1/3) -> 8.5763099 | H77: =SUMIFS(H$2:H$51,$A$2:$A$51,$A77,$B$2:$B$51,"Winter",$C$2:$C$51,$C77)*(2/3)+SUMIFS(H$2:H$51,$A$2:$A$51,$A77,$B$2:$B$51,"Summer",$C$2:$C$51,$C77)*(1/3) -> 8.9107631 | I77: =SUMIFS(I$2:I$51,$A$2:$A$51,$A77,$B$2:$B$51,"Winter",$C$2:$C$51,$C77)*(2/3)+SUMIFS(I$2:I$51,$A$2:$A$51,$A77,$B$2:$B$51,"Summer",$C$2:$C$51,$C77)*(1/3) -> 10.81581 | J77: =SUMIFS(J$2:J$51,$A$2:$A$51,$A77,$B$2:$B$51,"Winter",$C$2:$C$51,$C77)*(2/3)+SUMIFS(J$2:J$51,$A$2:$A$51,$A77,$B$2:$B$51,"Summer",$C$2:$C$51,$C77)*(1/3) -> 16.349683 | K77: =SUMIFS(K$2:K$51,$A$2:$A$51,$A77,$B$2:$B$51,"Winter",$C$2:$C$51,$C77)*(2/3)+SUMIFS(K$2:K$51,$A$2:$A$51,$A77,$B$2:$B$51,"Summer",$C$2:$C$51,$C77)*(1/3) -> 28.513852 | ... AA77: =SUMIFS(AA$2:AA$51,$A$2:$A$51,$A77,$B$2:$B$51,"Winter",$C$2:$C$51,$C77)*(2/3)+SUMIFS(AA$2:AA$51,$A$2:$A$51,$A77,$B$2:$B$51,"Summer",$C$2:$C$51,$C77)*(1/3) -> 13.739217
A78: 25 | B78: Spring | C78: 1 | D78: 0 | E78: 0 | F78: 0 | G78: 0 | H78: 0 | I78: 0 | J78: 0 | K78: 0 | L78: 0 | M78: 0 | N78: 0 | O78: 0 | P78: 0 | Q78: 0 | R78: 0 | S78: 0 | T78: 0 | U78: 0 | V78: 0 | W78: 0 | X78: 0 | Y78: 0 | Z78: 0 | AA78: 0
A79: 26 | B79: Spring | C79: 1 | D79: 0 | E79: 0 | F79: 0 | G79: 0 | H79: 0 | I79: 0 | J79: 0 | K79: 0 | L79: 0 | M79: 0 | N79: 0 | O79: 0 | P79: 0 | Q79: 0 | R79: 0 | S79: 0 | T79: 0 | U79: 0 | V79: 0 | W79: 0 | X79: 0 | Y79: 0 | Z79: 0 | AA79: 0
A80: 1 | B80: Autumn | C80: 1 | D80: =SUMIFS(D$2:D$51,$A$2:$A$51,$A80,$B$2:$B$51,"Summer",$C$2:$C$51,$C80)*(2/3)+SUMIFS(D$2:D$51,$A$2:$A$51,$A80,$B$2:$B$51,"Winter",$C$2:$C$51,$C80)*(1/3) -> 0.87951876 | E80: =SUMIFS(E$2:E$51,$A$2:$A$51,$A80,$B$2:$B$51,"Summer",$C$2:$C$51,$C80)*(2/3)+SUMIFS(E$2:E$51,$A$2:$A$51,$A80,$B$2:$B$51,"Winter",$C$2:$C$51,$C80)*(1/3) -> 0.56893169 | F80: =SUMIFS(F$2:F$51,$A$2:$A$51,$A80,$B$2:$B$51,"Summer",$C$2:$C$51,$C80)*(2/3)+SUMIFS(F$2:F$51,$A$2:$A$51,$A80,$B$2:$B$51,"Winter",$C$2:$C$51,$C80)*(1/3) -> 1.3255234 | G80: =SUMIFS(G$2:G$51,$A$2:$A$51,$A80,$B$2:$B$51,"Summer",$C$2:$C$51,$C80)*(2/3)+SUMIFS(G$2:G$51,$A$2:$A$51,$A80,$B$2:$B$51,"Winter",$C$2:$C$51,$C80)*(1/3) -> 0.65773712 | H80: =SUMIFS(H$2:H$51,$A$2:$A$51,$A80,$B$2:$B$51,"Summer",$C$2:$C$51,$C80)*(2/3)+SUMIFS(H$2:H$51,$A$2:$A$51,$A80,$B$2:$B$51,"Winter",$C$2:$C$51,$C80)*(1/3) -> 1.1548759 | I80: =SUMIFS(I$2:I$51,$A$2:$A$51,$A80,$B$2:$B$51,"Summer",$C$2:$C$51,$C80)*(2/3)+SUMIFS(I$2:I$51,$A$2:$A$51,$A80,$B$2:$B$51,"Winter",$C$2:$C$51,$C80)*(1/3) -> 2.0959407 | J80: =SUMIFS(J$2:J$51,$A$2:$A$51,$A80,$B$2:$B$51,"Summer",$C$2:$C$51,$C80)*(2/3)+SUMIFS(J$2:J$51,$A$2:$A$51,$A80,$B$2:$B$51,"Winter",$C$2:$C$51,$C80)*(1/3) -> 1.5731126 | K80: =SUMIFS(K$2:K$51,$A$2:$A$51,$A80,$B$2:$B$51,"Summer",$C$2:$C$51,$C80)*(2/3)+SUMIFS(K$2:K$51,$A$2:$A$51,$A80,$B$2:$B$51,"Winter",$C$2:$C$51,$C80)*(1/3) -> 0.92065845 | ... AA80: =SUMIFS(AA$2:AA$51,$A$2:$A$51,$A80,$B$2:$B$51,"Summer",$C$2:$C$51,$C80)*(2/3)+SUMIFS(AA$2:AA$51,$A$2:$A$51,$A80,$B$2:$B$51,"Winter",$C$2:$C$51,$C80)*(1/3) -> 1.9293582
A81: 2 | B81: Autumn | C81: 1 | D81: =SUMIFS(D$2:D$51,$A$2:$A$51,$A81,$B$2:$B$51,"Summer",$C$2:$C$51,$C81)*(2/3)+SUMIFS(D$2:D$51,$A$2:$A$51,$A81,$B$2:$B$51,"Winter",$C$2:$C$51,$C81)*(1/3) -> 19.145909 | E81: =SUMIFS(E$2:E$51,$A$2:$A$51,$A81,$B$2:$B$51,"Summer",$C$2:$C$51,$C81)*(2/3)+SUMIFS(E$2:E$51,$A$2:$A$51,$A81,$B$2:$B$51,"Winter",$C$2:$C$51,$C81)*(1/3) -> 17.543387 | F81: =SUMIFS(F$2:F$51,$A$2:$A$51,$A81,$B$2:$B$51,"Summer",$C$2:$C$51,$C81)*(2/3)+SUMIFS(F$2:F$51,$A$2:$A$51,$A81,$B$2:$B$51,"Winter",$C$2:$C$51,$C81)*(1/3) -> 17.036582 | G81: =SUMIFS(G$2:G$51,$A$2:$A$51,$A81,$B$2:$B$51,"Summer",$C$2:$C$51,$C81)*(2/3)+SUMIFS(G$2:G$51,$A$2:$A$51,$A81,$B$2:$B$51,"Winter",$C$2:$C$51,$C81)*(1/3) -> 16.968581 | H81: =SUMIFS(H$2:H$51,$A$2:$A$51,$A81,$B$2:$B$51,"Summer",$C$2:$C$51,$C81)*(2/3)+SUMIFS(H$2:H$51,$A$2:$A$51,$A81,$B$2:$B$51,"Winter",$C$2:$C$51,$C81)*(1/3) -> 17.034494 | I81: =SUMIFS(I$2:I$51,$A$2:$A$51,$A81,$B$2:$B$51,"Summer",$C$2:$C$51,$C81)*(2/3)+SUMIFS(I$2:I$51,$A$2:$A$51,$A81,$B$2:$B$51,"Winter",$C$2:$C$51,$C81)*(1/3) -> 17.472705 | J81: =SUMIFS(J$2:J$51,$A$2:$A$51,$A81,$B$2:$B$51,"Summer",$C$2:$C$51,$C81)*(2/3)+SUMIFS(J$2:J$51,$A$2:$A$51,$A81,$B$2:$B$51,"Winter",$C$2:$C$51,$C81)*(1/3) -> 19.544272 | K81: =SUMIFS(K$2:K$51,$A$2:$A$51,$A81,$B$2:$B$51,"Summer",$C$2:$C$51,$C81)*(2/3)+SUMIFS(K$2:K$51,$A$2:$A$51,$A81,$B$2:$B$51,"Winter",$C$2:$C$51,$C81)*(1/3) -> 23.321132 | ... AA81: =SUMIFS(AA$2:AA$51,$A$2:$A$51,$A81,$B$2:$B$51,"Summer",$C$2:$C$51,$C81)*(2/3)+SUMIFS(AA$2:AA$51,$A$2:$A$51,$A81,$B$2:$B$51,"Winter",$C$2:$C$51,$C81)*(1/3) -> 21.503464
A82: 3 | B82: Autumn | C82: 1 | D82: =SUMIFS(D$2:D$51,$A$2:$A$51,$A82,$B$2:$B$51,"Summer",$C$2:$C$51,$C82)*(2/3)+SUMIFS(D$2:D$51,$A$2:$A$51,$A82,$B$2:$B$51,"Winter",$C$2:$C$51,$C82)*(1/3) -> 24.235978 | E82: =SUMIFS(E$2:E$51,$A$2:$A$51,$A82,$B$2:$B$51,"Summer",$C$2:$C$51,$C82)*(2/3)+SUMIFS(E$2:E$51,$A$2:$A$51,$A82,$B$2:$B$51,"Winter",$C$2:$C$51,$C82)*(1/3) -> 22.190618 | F82: =SUMIFS(F$2:F$51,$A$2:$A$51,$A82,$B$2:$B$51,"Summer",$C$2:$C$51,$C82)*(2/3)+SUMIFS(F$2:F$51,$A$2:$A$51,$A82,$B$2:$B$51,"Winter",$C$2:$C$51,$C82)*(1/3) -> 20.823232 | G82: =SUMIFS(G$2:G$51,$A$2:$A$51,$A82,$B$2:$B$51,"Summer",$C$2:$C$51,$C82)*(2/3)+SUMIFS(G$2:G$51,$A$2:$A$51,$A82,$B$2:$B$51,"Winter",$C$2:$C$51,$C82)*(1/3) -> 20.695911 | H82: =SUMIFS(H$2:H$51,$A$2:$A$51,$A82,$B$2:$B$51,"Summer",$C$2:$C$51,$C82)*(2/3)+SUMIFS(H$2:H$51,$A$2:$A$51,$A82,$B$2:$B$51,"Winter",$C$2:$C$51,$C82)*(1/3) -> 20.675244 | I82: =SUMIFS(I$2:I$51,$A$2:$A$51,$A82,$B$2:$B$51,"Summer",$C$2:$C$51,$C82)*(2/3)+SUMIFS(I$2:I$51,$A$2:$A$51,$A82,$B$2:$B$51,"Winter",$C$2:$C$51,$C82)*(1/3) -> 21.992211 | J82: =SUMIFS(J$2:J$51,$A$2:$A$51,$A82,$B$2:$B$51,"Summer",$C$2:$C$51,$C82)*(2/3)+SUMIFS(J$2:J$51,$A$2:$A$51,$A82,$B$2:$B$51,"Winter",$C$2:$C$51,$C82)*(1/3) -> 29.007922 | K82: =SUMIFS(K$2:K$51,$A$2:$A$51,$A82,$B$2:$B$51,"Summer",$C$2:$C$51,$C82)*(2/3)+SUMIFS(K$2:K$51,$A$2:$A$51,$A82,$B$2:$B$51,"Winter",$C$2:$C$51,$C82)*(1/3) -> 34.622962 | ... AA82: =SUMIFS(AA$2:AA$51,$A$2:$A$51,$A82,$B$2:$B$51,"Summer",$C$2:$C$51,$C82)*(2/3)+SUMIFS(AA$2:AA$51,$A$2:$A$51,$A82,$B$2:$B$51,"Winter",$C$2:$C$51,$C82)*(1/3) -> 27.237726
A83: 4 | B83: Autumn | C83: 1 | D83: =SUMIFS(D$2:D$51,$A$2:$A$51,$A83,$B$2:$B$51,"Summer",$C$2:$C$51,$C83)*(2/3)+SUMIFS(D$2:D$51,$A$2:$A$51,$A83,$B$2:$B$51,"Winter",$C$2:$C$51,$C83)*(1/3) -> 46.482191 | E83: =SUMIFS(E$2:E$51,$A$2:$A$51,$A83,$B$2:$B$51,"Summer",$C$2:$C$51,$C83)*(2/3)+SUMIFS(E$2:E$51,$A$2:$A$51,$A83,$B$2:$B$51,"Winter",$C$2:$C$51,$C83)*(1/3) -> 40.90928 | F83: =SUMIFS(F$2:F$51,$A$2:$A$51,$A83,$B$2:$B$51,"Summer",$C$2:$C$51,$C83)*(2/3)+SUMIFS(F$2:F$51,$A$2:$A$51,$A83,$B$2:$B$51,"Winter",$C$2:$C$51,$C83)*(1/3) -> 38.609237 | G83: =SUMIFS(G$2:G$51,$A$2:$A$51,$A83,$B$2:$B$51,"Summer",$C$2:$C$51,$C83)*(2/3)+SUMIFS(G$2:G$51,$A$2:$A$51,$A83,$B$2:$B$51,"Winter",$C$2:$C$51,$C83)*(1/3) -> 37.721701 | H83: =SUMIFS(H$2:H$51,$A$2:$A$51,$A83,$B$2:$B$51,"Summer",$C$2:$C$51,$C83)*(2/3)+SUMIFS(H$2:H$51,$A$2:$A$51,$A83,$B$2:$B$51,"Winter",$C$2:$C$51,$C83)*(1/3) -> 39.763801 | I83: =SUMIFS(I$2:I$51,$A$2:$A$51,$A83,$B$2:$B$51,"Summer",$C$2:$C$51,$C83)*(2/3)+SUMIFS(I$2:I$51,$A$2:$A$51,$A83,$B$2:$B$51,"Winter",$C$2:$C$51,$C83)*(1/3) -> 39.301247 | J83: =SUMIFS(J$2:J$51,$A$2:$A$51,$A83,$B$2:$B$51,"Summer",$C$2:$C$51,$C83)*(2/3)+SUMIFS(J$2:J$51,$A$2:$A$51,$A83,$B$2:$B$51,"Winter",$C$2:$C$51,$C83)*(1/3) -> 46.736502 | K83: =SUMIFS(K$2:K$51,$A$2:$A$51,$A83,$B$2:$B$51,"Summer",$C$2:$C$51,$C83)*(2/3)+SUMIFS(K$2:K$51,$A$2:$A$51,$A83,$B$2:$B$51,"Winter",$C$2:$C$51,$C83)*(1/3) -> 53.266651 | ... AA83: =SUMIFS(AA$2:AA$51,$A$2:$A$51,$A83,$B$2:$B$51,"Summer",$C$2:$C$51,$C83)*(2/3)+SUMIFS(AA$2:AA$51,$A$2:$A$51,$A83,$B$2:$B$51,"Winter",$C$2:$C$51,$C83)*(1/3) -> 53.675915
A84: 5 | B84: Autumn | C84: 1 | D84: =SUMIFS(D$2:D$51,$A$2:$A$51,$A84,$B$2:$B$51,"Summer",$C$2:$C$51,$C84)*(2/3)+SUMIFS(D$2:D$51,$A$2:$A$51,$A84,$B$2:$B$51,"Winter",$C$2:$C$51,$C84)*(1/3) -> -11.604781 | E84: =SUMIFS(E$2:E$51,$A$2:$A$51,$A84,$B$2:$B$51,"Summer",$C$2:$C$51,$C84)*(2/3)+SUMIFS(E$2:E$51,$A$2:$A$51,$A84,$B$2:$B$51,"Winter",$C$2:$C$51,$C84)*(1/3) -> -10.554225 | F84: =SUMIFS(F$2:F$51,$A$2:$A$51,$A84,$B$2:$B$51,"Summer",$C$2:$C$51,$C84)*(2/3)+SUMIFS(F$2:F$51,$A$2:$A$51,$A84,$B$2:$B$51,"Winter",$C$2:$C$51,$C84)*(1/3) -> -8.0026401 | G84: =SUMIFS(G$2:G$51,$A$2:$A$51,$A84,$B$2:$B$51,"Summer",$C$2:$C$51,$C84)*(2/3)+SUMIFS(G$2:G$51,$A$2:$A$51,$A84,$B$2:$B$51,"Winter",$C$2:$C$51,$C84)*(1/3) -> -7.7083128 | H84: =SUMIFS(H$2:H$51,$A$2:$A$51,$A84,$B$2:$B$51,"Summer",$C$2:$C$51,$C84)*(2/3)+SUMIFS(H$2:H$51,$A$2:$A$51,$A84,$B$2:$B$51,"Winter",$C$2:$C$51,$C84)*(1/3) -> -7.4672757 | I84: =SUMIFS(I$2:I$51,$A$2:$A$51,$A84,$B$2:$B$51,"Summer",$C$2:$C$51,$C84)*(2/3)+SUMIFS(I$2:I$51,$A$2:$A$51,$A84,$B$2:$B$51,"Winter",$C$2:$C$51,$C84)*(1/3) -> -2.0789525 | J84: =SUMIFS(J$2:J$51,$A$2:$A$51,$A84,$B$2:$B$51,"Summer",$C$2:$C$51,$C84)*(2/3)+SUMIFS(J$2:J$51,$A$2:$A$51,$A84,$B$2:$B$51,"Winter",$C$2:$C$51,$C84)*(1/3) -> -0.25739582 | K84: =SUMIFS(K$2:K$51,$A$2:$A$51,$A84,$B$2:$B$51,"Summer",$C$2:$C$51,$C84)*(2/3)+SUMIFS(K$2:K$51,$A$2:$A$51,$A84,$B$2:$B$51,"Winter",$C$2:$C$51,$C84)*(1/3) -> 2.1852283 | ... AA84: =SUMIFS(AA$2:AA$51,$A$2:$A$51,$A84,$B$2:$B$51,"Summer",$C$2:$C$51,$C84)*(2/3)+SUMIFS(AA$2:AA$51,$A$2:$A$51,$A84,$B$2:$B$51,"Winter",$C$2:$C$51,$C84)*(1/3) -> -2.2951725
A85: 6 | B85: Autumn | C85: 1 | D85: =SUMIFS(D$2:D$51,$A$2:$A$51,$A85,$B$2:$B$51,"Summer",$C$2:$C$51,$C85)*(2/3)+SUMIFS(D$2:D$51,$A$2:$A$51,$A85,$B$2:$B$51,"Winter",$C$2:$C$51,$C85)*(1/3) -> 0 | E85: =SUMIFS(E$2:E$51,$A$2:$A$51,$A85,$B$2:$B$51,"Summer",$C$2:$C$51,$C85)*(2/3)+SUMIFS(E$2:E$51,$A$2:$A$51,$A85,$B$2:$B$51,"Winter",$C$2:$C$51,$C85)*(1/3) -> 0 | F85: =SUMIFS(F$2:F$51,$A$2:$A$51,$A85,$B$2:$B$51,"Summer",$C$2:$C$51,$C85)*(2/3)+SUMIFS(F$2:F$51,$A$2:$A$51,$A85,$B$2:$B$51,"Winter",$C$2:$C$51,$C85)*(1/3) -> 0 | G85: =SUMIFS(G$2:G$51,$A$2:$A$51,$A85,$B$2:$B$51,"Summer",$C$2:$C$51,$C85)*(2/3)+SUMIFS(G$2:G$51,$A$2:$A$51,$A85,$B$2:$B$51,"Winter",$C$2:$C$51,$C85)*(1/3) -> 0 | H85: =SUMIFS(H$2:H$51,$A$2:$A$51,$A85,$B$2:$B$51,"Summer",$C$2:$C$51,$C85)*(2/3)+SUMIFS(H$2:H$51,$A$2:$A$51,$A85,$B$2:$B$51,"Winter",$C$2:$C$51,$C85)*(1/3) -> 0 | I85: =SUMIFS(I$2:I$51,$A$2:$A$51,$A85,$B$2:$B$51,"Summer",$C$2:$C$51,$C85)*(2/3)+SUMIFS(I$2:I$51,$A$2:$A$51,$A85,$B$2:$B$51,"Winter",$C$2:$C$51,$C85)*(1/3) -> 0 | J85: =SUMIFS(J$2:J$51,$A$2:$A$51,$A85,$B$2:$B$51,"Summer",$C$2:$C$51,$C85)*(2/3)+SUMIFS(J$2:J$51,$A$2:$A$51,$A85,$B$2:$B$51,"Winter",$C$2:$C$51,$C85)*(1/3) -> 0 | K85: =SUMIFS(K$2:K$51,$A$2:$A$51,$A85,$B$2:$B$51,"Summer",$C$2:$C$51,$C85)*(2/3)+SUMIFS(K$2:K$51,$A$2:$A$51,$A85,$B$2:$B$51,"Winter",$C$2:$C$51,$C85)*(1/3) -> 0 | ... AA85: =SUMIFS(AA$2:AA$51,$A$2:$A$51,$A85,$B$2:$B$51,"Summer",$C$2:$C$51,$C85)*(2/3)+SUMIFS(AA$2:AA$51,$A$2:$A$51,$A85,$B$2:$B$51,"Winter",$C$2:$C$51,$C85)*(1/3) -> 0
A86: 7 | B86: Autumn | C86: 1 | D86: =SUMIFS(D$2:D$51,$A$2:$A$51,$A86,$B$2:$B$51,"Summer",$C$2:$C$51,$C86)*(2/3)+SUMIFS(D$2:D$51,$A$2:$A$51,$A86,$B$2:$B$51,"Winter",$C$2:$C$51,$C86)*(1/3) -> 18.44392 | E86: =SUMIFS(E$2:E$51,$A$2:$A$51,$A86,$B$2:$B$51,"Summer",$C$2:$C$51,$C86)*(2/3)+SUMIFS(E$2:E$51,$A$2:$A$51,$A86,$B$2:$B$51,"Winter",$C$2:$C$51,$C86)*(1/3) -> 15.179067 | F86: =SUMIFS(F$2:F$51,$A$2:$A$51,$A86,$B$2:$B$51,"Summer",$C$2:$C$51,$C86)*(2/3)+SUMIFS(F$2:F$51,$A$2:$A$51,$A86,$B$2:$B$51,"Winter",$C$2:$C$51,$C86)*(1/3) -> 18.328901 | G86: =SUMIFS(G$2:G$51,$A$2:$A$51,$A86,$B$2:$B$51,"Summer",$C$2:$C$51,$C86)*(2/3)+SUMIFS(G$2:G$51,$A$2:$A$51,$A86,$B$2:$B$51,"Winter",$C$2:$C$51,$C86)*(1/3) -> 18.864734 | H86: =SUMIFS(H$2:H$51,$A$2:$A$51,$A86,$B$2:$B$51,"Summer",$C$2:$C$51,$C86)*(2/3)+SUMIFS(H$2:H$51,$A$2:$A$51,$A86,$B$2:$B$51,"Winter",$C$2:$C$51,$C86)*(1/3) -> 20.708942 | I86: =SUMIFS(I$2:I$51,$A$2:$A$51,$A86,$B$2:$B$51,"Summer",$C$2:$C$51,$C86)*(2/3)+SUMIFS(I$2:I$51,$A$2:$A$51,$A86,$B$2:$B$51,"Winter",$C$2:$C$51,$C86)*(1/3) -> 10.133615 | J86: =SUMIFS(J$2:J$51,$A$2:$A$51,$A86,$B$2:$B$51,"Summer",$C$2:$C$51,$C86)*(2/3)+SUMIFS(J$2:J$51,$A$2:$A$51,$A86,$B$2:$B$51,"Winter",$C$2:$C$51,$C86)*(1/3) -> -5.4300377 | K86: =SUMIFS(K$2:K$51,$A$2:$A$51,$A86,$B$2:$B$51,"Summer",$C$2:$C$51,$C86)*(2/3)+SUMIFS(K$2:K$51,$A$2:$A$51,$A86,$B$2:$B$51,"Winter",$C$2:$C$51,$C86)*(1/3) -> -6.0790253 | ... AA86: =SUMIFS(AA$2:AA$51,$A$2:$A$51,$A86,$B$2:$B$51,"Summer",$C$2:$C$51,$C86)*(2/3)+SUMIFS(AA$2:AA$51,$A$2:$A$51,$A86,$B$2:$B$51,"Winter",$C$2:$C$51,$C86)*(1/3) -> 13.902699
A87: 8 | B87: Autumn | C87: 1 | D87: =SUMIFS(D$2:D$51,$A$2:$A$51,$A87,$B$2:$B$51,"Summer",$C$2:$C$51,$C87)*(2/3)+SUMIFS(D$2:D$51,$A$2:$A$51,$A87,$B$2:$B$51,"Winter",$C$2:$C$51,$C87)*(1/3) -> 23.78798 | E87: =SUMIFS(E$2:E$51,$A$2:$A$51,$A87,$B$2:$B$51,"Summer",$C$2:$C$51,$C87)*(2/3)+SUMIFS(E$2:E$51,$A$2:$A$51,$A87,$B$2:$B$51,"Winter",$C$2:$C$51,$C87)*(1/3) -> 20.846215 | F87: =SUMIFS(F$2:F$51,$A$2:$A$51,$A87,$B$2:$B$51,"Summer",$C$2:$C$51,$C87)*(2/3)+SUMIFS(F$2:F$51,$A$2:$A$51,$A87,$B$2:$B$51,"Winter",$C$2:$C$51,$C87)*(1/3) -> 20.441783 | G87: =SUMIFS(G$2:G$51,$A$2:$A$51,$A87,$B$2:$B$51,"Summer",$C$2:$C$51,$C87)*(2/3)+SUMIFS(G$2:G$51,$A$2:$A$51,$A87,$B$2:$B$51,"Winter",$C$2:$C$51,$C87)*(1/3) -> 19.156631 | H87: =SUMIFS(H$2:H$51,$A$2:$A$51,$A87,$B$2:$B$51,"Summer",$C$2:$C$51,$C87)*(2/3)+SUMIFS(H$2:H$51,$A$2:$A$51,$A87,$B$2:$B$51,"Winter",$C$2:$C$51,$C87)*(1/3) -> 19.150534 | I87: =SUMIFS(I$2:I$51,$A$2:$A$51,$A87,$B$2:$B$51,"Summer",$C$2:$C$51,$C87)*(2/3)+SUMIFS(I$2:I$51,$A$2:$A$51,$A87,$B$2:$B$51,"Winter",$C$2:$C$51,$C87)*(1/3) -> 19.616981 | J87: =SUMIFS(J$2:J$51,$A$2:$A$51,$A87,$B$2:$B$51,"Summer",$C$2:$C$51,$C87)*(2/3)+SUMIFS(J$2:J$51,$A$2:$A$51,$A87,$B$2:$B$51,"Winter",$C$2:$C$51,$C87)*(1/3) -> 24.017135 | K87: =SUMIFS(K$2:K$51,$A$2:$A$51,$A87,$B$2:$B$51,"Summer",$C$2:$C$51,$C87)*(2/3)+SUMIFS(K$2:K$51,$A$2:$A$51,$A87,$B$2:$B$51,"Winter",$C$2:$C$51,$C87)*(1/3) -> 30.466145 | ... AA87: =SUMIFS(AA$2:AA$51,$A$2:$A$51,$A87,$B$2:$B$51,"Summer",$C$2:$C$51,$C87)*(2/3)+SUMIFS(AA$2:AA$51,$A$2:$A$51,$A87,$B$2:$B$51,"Winter",$C$2:$C$51,$C87)*(1/3) -> 25.36
A88: 9 | B88: Autumn | C88: 1 | D88: =SUMIFS(D$2:D$51,$A$2:$A$51,$A88,$B$2:$B$51,"Summer",$C$2:$C$51,$C88)*(2/3)+SUMIFS(D$2:D$51,$A$2:$A$51,$A88,$B$2:$B$51,"Winter",$C$2:$C$51,$C88)*(1/3) -> 135.20957 | E88: =SUMIFS(E$2:E$51,$A$2:$A$51,$A88,$B$2:$B$51,"Summer",$C$2:$C$51,$C88)*(2/3)+SUMIFS(E$2:E$51,$A$2:$A$51,$A88,$B$2:$B$51,"Winter",$C$2:$C$51,$C88)*(1/3) -> 119.74783 | F88: =SUMIFS(F$2:F$51,$A$2:$A$51,$A88,$B$2:$B$51,"Summer",$C$2:$C$51,$C88)*(2/3)+SUMIFS(F$2:F$51,$A$2:$A$51,$A88,$B$2:$B$51,"Winter",$C$2:$C$51,$C88)*(1/3) -> 112.67134 | G88: =SUMIFS(G$2:G$51,$A$2:$A$51,$A88,$B$2:$B$51,"Summer",$C$2:$C$51,$C88)*(2/3)+SUMIFS(G$2:G$51,$A$2:$A$51,$A88,$B$2:$B$51,"Winter",$C$2:$C$51,$C88)*(1/3) -> 109.61003 | H88: =SUMIFS(H$2:H$51,$A$2:$A$51,$A88,$B$2:$B$51,"Summer",$C$2:$C$51,$C88)*(2/3)+SUMIFS(H$2:H$51,$A$2:$A$51,$A88,$B$2:$B$51,"Winter",$C$2:$C$51,$C88)*(1/3) -> 151.34126 | I88: =SUMIFS(I$2:I$51,$A$2:$A$51,$A88,$B$2:$B$51,"Summer",$C$2:$C$51,$C88)*(2/3)+SUMIFS(I$2:I$51,$A$2:$A$51,$A88,$B$2:$B$51,"Winter",$C$2:$C$51,$C88)*(1/3) -> 153.09329 | J88: =SUMIFS(J$2:J$51,$A$2:$A$51,$A88,$B$2:$B$51,"Summer",$C$2:$C$51,$C88)*(2/3)+SUMIFS(J$2:J$51,$A$2:$A$51,$A88,$B$2:$B$51,"Winter",$C$2:$C$51,$C88)*(1/3) -> 141.21561 | K88: =SUMIFS(K$2:K$51,$A$2:$A$51,$A88,$B$2:$B$51,"Summer",$C$2:$C$51,$C88)*(2/3)+SUMIFS(K$2:K$51,$A$2:$A$51,$A88,$B$2:$B$51,"Winter",$C$2:$C$51,$C88)*(1/3) -> 176.72895 | ... AA88: =SUMIFS(AA$2:AA$51,$A$2:$A$51,$A88,$B$2:$B$51,"Summer",$C$2:$C$51,$C88)*(2/3)+SUMIFS(AA$2:AA$51,$A$2:$A$51,$A88,$B$2:$B$51,"Winter",$C$2:$C$51,$C88)*(1/3) -> 159.80043
A89: 10 | B89: Autumn | C89: 1 | D89: =SUMIFS(D$2:D$51,$A$2:$A$51,$A89,$B$2:$B$51,"Summer",$C$2:$C$51,$C89)*(2/3)+SUMIFS(D$2:D$51,$A$2:$A$51,$A89,$B$2:$B$51,"Winter",$C$2:$C$51,$C89)*(1/3) -> 3.5149007 | E89: =SUMIFS(E$2:E$51,$A$2:$A$51,$A89,$B$2:$B$51,"Summer",$C$2:$C$51,$C89)*(2/3)+SUMIFS(E$2:E$51,$A$2:$A$51,$A89,$B$2:$B$51,"Winter",$C$2:$C$51,$C89)*(1/3) -> 3.3439076 | F89: =SUMIFS(F$2:F$51,$A$2:$A$51,$A89,$B$2:$B$51,"Summer",$C$2:$C$51,$C89)*(2/3)+SUMIFS(F$2:F$51,$A$2:$A$51,$A89,$B$2:$B$51,"Winter",$C$2:$C$51,$C89)*(1/3) -> 3.0900815 | G89: =SUMIFS(G$2:G$51,$A$2:$A$51,$A89,$B$2:$B$51,"Summer",$C$2:$C$51,$C89)*(2/3)+SUMIFS(G$2:G$51,$A$2:$A$51,$A89,$B$2:$B$51,"Winter",$C$2:$C$51,$C89)*(1/3) -> 3.1547904 | H89: =SUMIFS(H$2:H$51,$A$2:$A$51,$A89,$B$2:$B$51,"Summer",$C$2:$C$51,$C89)*(2/3)+SUMIFS(H$2:H$51,$A$2:$A$51,$A89,$B$2:$B$51,"Winter",$C$2:$C$51,$C89)*(1/3) -> 3.1478126 | I89: =SUMIFS(I$2:I$51,$A$2:$A$51,$A89,$B$2:$B$51,"Summer",$C$2:$C$51,$C89)*(2/3)+SUMIFS(I$2:I$51,$A$2:$A$51,$A89,$B$2:$B$51,"Winter",$C$2:$C$51,$C89)*(1/3) -> 3.3056478 | J89: =SUMIFS(J$2:J$51,$A$2:$A$51,$A89,$B$2:$B$51,"Summer",$C$2:$C$51,$C89)*(2/3)+SUMIFS(J$2:J$51,$A$2:$A$51,$A89,$B$2:$B$51,"Winter",$C$2:$C$51,$C89)*(1/3) -> 3.9373187 | K89: =SUMIFS(K$2:K$51,$A$2:$A$51,$A89,$B$2:$B$51,"Summer",$C$2:$C$51,$C89)*(2/3)+SUMIFS(K$2:K$51,$A$2:$A$51,$A89,$B$2:$B$51,"Winter",$C$2:$C$51,$C89)*(1/3) -> 4.7008612 | ... AA89: =SUMIFS(AA$2:AA$51,$A$2:$A$51,$A89,$B$2:$B$51,"Summer",$C$2:$C$51,$C89)*(2/3)+SUMIFS(AA$2:AA$51,$A$2:$A$51,$A89,$B$2:$B$51,"Winter",$C$2:$C$51,$C89)*(1/3) -> 3.9981812
A90: 11 | B90: Autumn | C90: 1 | D90: =SUMIFS(D$2:D$51,$A$2:$A$51,$A90,$B$2:$B$51,"Summer",$C$2:$C$51,$C90)*(2/3)+SUMIFS(D$2:D$51,$A$2:$A$51,$A90,$B$2:$B$51,"Winter",$C$2:$C$51,$C90)*(1/3) -> 22.393667 | E90: =SUMIFS(E$2:E$51,$A$2:$A$51,$A90,$B$2:$B$51,"Summer",$C$2:$C$51,$C90)*(2/3)+SUMIFS(E$2:E$51,$A$2:$A$51,$A90,$B$2:$B$51,"Winter",$C$2:$C$51,$C90)*(1/3) -> 22.359667 | F90: =SUMIFS(F$2:F$51,$A$2:$A$51,$A90,$B$2:$B$51,"Summer",$C$2:$C$51,$C90)*(2/3)+SUMIFS(F$2:F$51,$A$2:$A$51,$A90,$B$2:$B$51,"Winter",$C$2:$C$51,$C90)*(1/3) -> 21.356333 | G90: =SUMIFS(G$2:G$51,$A$2:$A$51,$A90,$B$2:$B$51,"Summer",$C$2:$C$51,$C90)*(2/3)+SUMIFS(G$2:G$51,$A$2:$A$51,$A90,$B$2:$B$51,"Winter",$C$2:$C$51,$C90)*(1/3) -> 22.191667 | H90: =SUMIFS(H$2:H$51,$A$2:$A$51,$A90,$B$2:$B$51,"Summer",$C$2:$C$51,$C90)*(2/3)+SUMIFS(H$2:H$51,$A$2:$A$51,$A90,$B$2:$B$51,"Winter",$C$2:$C$51,$C90)*(1/3) -> 22.458667 | I90: =SUMIFS(I$2:I$51,$A$2:$A$51,$A90,$B$2:$B$51,"Summer",$C$2:$C$51,$C90)*(2/3)+SUMIFS(I$2:I$51,$A$2:$A$51,$A90,$B$2:$B$51,"Winter",$C$2:$C$51,$C90)*(1/3) -> 24.488333 | J90: =SUMIFS(J$2:J$51,$A$2:$A$51,$A90,$B$2:$B$51,"Summer",$C$2:$C$51,$C90)*(2/3)+SUMIFS(J$2:J$51,$A$2:$A$51,$A90,$B$2:$B$51,"Winter",$C$2:$C$51,$C90)*(1/3) -> 32.861 | K90: =SUMIFS(K$2:K$51,$A$2:$A$51,$A90,$B$2:$B$51,"Summer",$C$2:$C$51,$C90)*(2/3)+SUMIFS(K$2:K$51,$A$2:$A$51,$A90,$B$2:$B$51,"Winter",$C$2:$C$51,$C90)*(1/3) -> 37.546 | ... AA90: =SUMIFS(AA$2:AA$51,$A$2:$A$51,$A90,$B$2:$B$51,"Summer",$C$2:$C$51,$C90)*(2/3)+SUMIFS(AA$2:AA$51,$A$2:$A$51,$A90,$B$2:$B$51,"Winter",$C$2:$C$51,$C90)*(1/3) -> 25.168333
...

Sheet Qc, Original
A1: LoadID | B1: Season | C1: Scenario | D1: 0 | E1: 1 | F1: 2 | G1: 3 | H1: 4 | I1: 5 | J1: 6 | K1: 7 | L1: 8 | M1: 9 | N1: 10 | O1: 11 | P1: 12 | Q1: 13 | R1: 14 | S1: 15 | T1: 16 | U1: 17 | V1: 18 | W1: 19 | X1: 20 | Y1: 21 | Z1: 22 | AA1: 23
A2: 1 | B2: Winter | C2: 1 | D2: 0.521 | E2: 0.595 | F2: 1.326 | G2: 0.578 | H2: 0.511 | I2: 0.598 | J2: 0.641 | K2: 0.625 | L2: 0.426 | M2: 1.746 | N2: 0.159 | O2: 0.951 | P2: 0.352 | Q2: 0.443 | R2: 0.655 | S2: 0.823 | T2: 0.28 | U2: 1.186 | V2: 1.004 | W2: 0.398 | X2: 1.703 | Y2: 0.878 | Z2: 0.864 | AA2: 0.368
A3: 1 | B3: Summer | C3: 1 | D3: 0.32659953 | E3: 0.24118288 | F3: 0.29766986 | G3: -0.026231597 | H3: 0.98410756 | I3: 0.83632404 | J3: 0.69762632 | K3: -0.061785513 | L3: 0.58500499 | M3: 0.47965646 | N3: 0.085041632 | O3: 1.4321956 | P3: 0.37837021 | Q3: 0.15454809 | R3: 0.55458236 | S3: 0.55234239 | T3: 0.74650371 | U3: 0.85903774 | V3: 0.90570599 | W3: 0.2896854 | X3: 0.22165103 | Y3: -0.15655322 | Z3: 0.4901901 | AA3: 0.40190201
A4: 1 | B4: Spring | C4: 1 | D4: =SUMIFS(D$2:D$51,$A$2:$A$51,$A4,$B$2:$B$51,"Winter",$C$2:$C$51,$C4)*(2/3)+SUMIFS(D$2:D$51,$A$2:$A$51,$A4,$B$2:$B$51,"Summer",$C$2:$C$51,$C4)*(1/3) -> 0.45619984 | E4: =SUMIFS(E$2:E$51,$A$2:$A$51,$A4,$B$2:$B$51,"Winter",$C$2:$C$51,$C4)*(2/3)+SUMIFS(E$2:E$51,$A$2:$A$51,$A4,$B$2:$B$51,"Summer",$C$2:$C$51,$C4)*(1/3) -> 0.47706096 | F4: =SUMIFS(F$2:F$51,$A$2:$A$51,$A4,$B$2:$B$51,"Winter",$C$2:$C$51,$C4)*(2/3)+SUMIFS(F$2:F$51,$A$2:$A$51,$A4,$B$2:$B$51,"Summer",$C$2:$C$51,$C4)*(1/3) -> 0.98322329 | G4: =SUMIFS(G$2:G$51,$A$2:$A$51,$A4,$B$2:$B$51,"Winter",$C$2:$C$51,$C4)*(2/3)+SUMIFS(G$2:G$51,$A$2:$A$51,$A4,$B$2:$B$51,"Summer",$C$2:$C$51,$C4)*(1/3) -> 0.37658947 | H4: =SUMIFS(H$2:H$51,$A$2:$A$51,$A4,$B$2:$B$51,"Winter",$C$2:$C$51,$C4)*(2/3)+SUMIFS(H$2:H$51,$A$2:$A$51,$A4,$B$2:$B$51,"Summer",$C$2:$C$51,$C4)*(1/3) -> 0.66870252 | I4: =SUMIFS(I$2:I$51,$A$2:$A$51,$A4,$B$2:$B$51,"Winter",$C$2:$C$51,$C4)*(2/3)+SUMIFS(I$2:I$51,$A$2:$A$51,$A4,$B$2:$B$51,"Summer",$C$2:$C$51,$C4)*(1/3) -> 0.67744135 | J4: =SUMIFS(J$2:J$51,$A$2:$A$51,$A4,$B$2:$B$51,"Winter",$C$2:$C$51,$C4)*(2/3)+SUMIFS(J$2:J$51,$A$2:$A$51,$A4,$B$2:$B$51,"Summer",$C$2:$C$51,$C4)*(1/3) -> 0.65987544 | K4: =SUMIFS(K$2:K$51,$A$2:$A$51,$A4,$B$2:$B$51,"Winter",$C$2:$C$51,$C4)*(2/3)+SUMIFS(K$2:K$51,$A$2:$A$51,$A4,$B$2:$B$51,"Summer",$C$2:$C$51,$C4)*(1/3) -> 0.3960715 | ... AA4: =SUMIFS(AA$2:AA$51,$A$2:$A$51,$A4,$B$2:$B$51,"Winter",$C$2:$C$51,$C4)*(2/3)+SUMIFS(AA$2:AA$51,$A$2:$A$51,$A4,$B$2:$B$51,"Summer",$C$2:$C$51,$C4)*(1/3) -> 0.37930067
A5: 1 | B5: Autumn | C5: 1 | D5: =SUMIFS(D$2:D$51,$A$2:$A$51,$A5,$B$2:$B$51,"Summer",$C$2:$C$51,$C5)*(2/3)+SUMIFS(D$2:D$51,$A$2:$A$51,$A5,$B$2:$B$51,"Winter",$C$2:$C$51,$C5)*(1/3) -> 0.39139969 | E5: =SUMIFS(E$2:E$51,$A$2:$A$51,$A5,$B$2:$B$51,"Summer",$C$2:$C$51,$C5)*(2/3)+SUMIFS(E$2:E$51,$A$2:$A$51,$A5,$B$2:$B$51,"Winter",$C$2:$C$51,$C5)*(1/3) -> 0.35912192 | F5: =SUMIFS(F$2:F$51,$A$2:$A$51,$A5,$B$2:$B$51,"Summer",$C$2:$C$51,$C5)*(2/3)+SUMIFS(F$2:F$51,$A$2:$A$51,$A5,$B$2:$B$51,"Winter",$C$2:$C$51,$C5)*(1/3) -> 0.64044658 | G5: =SUMIFS(G$2:G$51,$A$2:$A$51,$A5,$B$2:$B$51,"Summer",$C$2:$C$51,$C5)*(2/3)+SUMIFS(G$2:G$51,$A$2:$A$51,$A5,$B$2:$B$51,"Winter",$C$2:$C$51,$C5)*(1/3) -> 0.17517894 | H5: =SUMIFS(H$2:H$51,$A$2:$A$51,$A5,$B$2:$B$51,"Summer",$C$2:$C$51,$C5)*(2/3)+SUMIFS(H$2:H$51,$A$2:$A$51,$A5,$B$2:$B$51,"Winter",$C$2:$C$51,$C5)*(1/3) -> 0.82640504 | I5: =SUMIFS(I$2:I$51,$A$2:$A$51,$A5,$B$2:$B$51,"Summer",$C$2:$C$51,$C5)*(2/3)+SUMIFS(I$2:I$51,$A$2:$A$51,$A5,$B$2:$B$51,"Winter",$C$2:$C$51,$C5)*(1/3) -> 0.75688269 | J5: =SUMIFS(J$2:J$51,$A$2:$A$51,$A5,$B$2:$B$51,"Summer",$C$2:$C$51,$C5)*(2/3)+SUMIFS(J$2:J$51,$A$2:$A$51,$A5,$B$2:$B$51,"Winter",$C$2:$C$51,$C5)*(1/3) -> 0.67875088 | K5: =SUMIFS(K$2:K$51,$A$2:$A$51,$A5,$B$2:$B$51,"Summer",$C$2:$C$51,$C5)*(2/3)+SUMIFS(K$2:K$51,$A$2:$A$51,$A5,$B$2:$B$51,"Winter",$C$2:$C$51,$C5)*(1/3) -> 0.16714299 | ... AA5: =SUMIFS(AA$2:AA$51,$A$2:$A$51,$A5,$B$2:$B$51,"Summer",$C$2:$C$51,$C5)*(2/3)+SUMIFS(AA$2:AA$51,$A$2:$A$51,$A5,$B$2:$B$51,"Winter",$C$2:$C$51,$C5)*(1/3) -> 0.39060134
A6: 2 | B6: Winter | C6: 1 | D6: -3.472 | E6: -3.774 | F6: -4.065 | G6: -4.035 | H6: -4.177 | I6: -3.718 | J6: -2.769 | K6: -1.14 | L6: -0.336 | M6: -0.052 | N6: -0.471 | O6: -0.347 | P6: -0.48 | Q6: -0.484 | R6: -1.223 | S6: -1.762 | T6: -1.567 | U6: -0.535 | V6: -0.778 | W6: -0.978 | X6: -1.536 | Y6: -1.994 | Z6: -2.675 | AA6: -3.011
A7: 2 | B7: Summer | C7: 1 | D7: -1.5187673 | E7: -1.974584 | F7: -2.1763726 | G7: -1.9860541 | H7: -2.1287828 | I7: -2.1778489 | J7: -1.8875205 | K7: -0.29365578 | L7: 0.94261344 | M7: 1.3722619 | N7: 1.0787206 | O7: 1.4368854 | P7: 1.2751207 | Q7: 1.313513 | R7: 0.67772451 | S7: 0.17133696 | T7: 0.38115646 | U7: 0.46297332 | V7: 0.27892399 | W7: -0.052032285 | X7: -0.20312568 | Y7: -0.1413198 | Z7: -0.67773339 | AA7: -0.91736732
A8: 2 | B8: Spring | C8: 1 | D8: =SUMIFS(D$2:D$51,$A$2:$A$51,$A8,$B$2:$B$51,"Winter",$C$2:$C$51,$C8)*(2/3)+SUMIFS(D$2:D$51,$A$2:$A$51,$A8,$B$2:$B$51,"Summer",$C$2:$C$51,$C8)*(1/3) -> -2.8209224 | E8: =SUMIFS(E$2:E$51,$A$2:$A$51,$A8,$B$2:$B$51,"Winter",$C$2:$C$51,$C8)*(2/3)+SUMIFS(E$2:E$51,$A$2:$A$51,$A8,$B$2:$B$51,"Summer",$C$2:$C$51,$C8)*(1/3) -> -3.1741947 | F8: =SUMIFS(F$2:F$51,$A$2:$A$51,$A8,$B$2:$B$51,"Winter",$C$2:$C$51,$C8)*(2/3)+SUMIFS(F$2:F$51,$A$2:$A$51,$A8,$B$2:$B$51,"Summer",$C$2:$C$51,$C8)*(1/3) -> -3.4354575 | G8: =SUMIFS(G$2:G$51,$A$2:$A$51,$A8,$B$2:$B$51,"Winter",$C$2:$C$51,$C8)*(2/3)+SUMIFS(G$2:G$51,$A$2:$A$51,$A8,$B$2:$B$51,"Summer",$C$2:$C$51,$C8)*(1/3) -> -3.352018 | H8: =SUMIFS(H$2:H$51,$A$2:$A$51,$A8,$B$2:$B$51,"Winter",$C$2:$C$51,$C8)*(2/3)+SUMIFS(H$2:H$51,$A$2:$A$51,$A8,$B$2:$B$51,"Summer",$C$2:$C$51,$C8)*(1/3) -> -3.4942609 | I8: =SUMIFS(I$2:I$51,$A$2:$A$51,$A8,$B$2:$B$51,"Winter",$C$2:$C$51,$C8)*(2/3)+SUMIFS(I$2:I$51,$A$2:$A$51,$A8,$B$2:$B$51,"Summer",$C$2:$C$51,$C8)*(1/3) -> -3.2046163 | J8: =SUMIFS(J$2:J$51,$A$2:$A$51,$A8,$B$2:$B$51,"Winter",$C$2:$C$51,$C8)*(2/3)+SUMIFS(J$2:J$51,$A$2:$A$51,$A8,$B$2:$B$51,"Summer",$C$2:$C$51,$C8)*(1/3) -> -2.4751735 | K8: =SUMIFS(K$2:K$51,$A$2:$A$51,$A8,$B$2:$B$51,"Winter",$C$2:$C$51,$C8)*(2/3)+SUMIFS(K$2:K$51,$A$2:$A$51,$A8,$B$2:$B$51,"Summer",$C$2:$C$51,$C8)*(1/3) -> -0.85788526 | ... AA8: =SUMIFS(AA$2:AA$51,$A$2:$A$51,$A8,$B$2:$B$51,"Winter",$C$2:$C$51,$C8)*(2/3)+SUMIFS(AA$2:AA$51,$A$2:$A$51,$A8,$B$2:$B$51,"Summer",$C$2:$C$51,$C8)*(1/3) -> -2.3131224
A9: 2 | B9: Autumn | C9: 1 | D9: =SUMIFS(D$2:D$51,$A$2:$A$51,$A9,$B$2:$B$51,"Summer",$C$2:$C$51,$C9)*(2/3)+SUMIFS(D$2:D$51,$A$2:$A$51,$A9,$B$2:$B$51,"Winter",$C$2:$C$51,$C9)*(1/3) -> -2.1698449 | E9: =SUMIFS(E$2:E$51,$A$2:$A$51,$A9,$B$2:$B$51,"Summer",$C$2:$C$51,$C9)*(2/3)+SUMIFS(E$2:E$51,$A$2:$A$51,$A9,$B$2:$B$51,"Winter",$C$2:$C$51,$C9)*(1/3) -> -2.5743893 | F9: =SUMIFS(F$2:F$51,$A$2:$A$51,$A9,$B$2:$B$51,"Summer",$C$2:$C$51,$C9)*(2/3)+SUMIFS(F$2:F$51,$A$2:$A$51,$A9,$B$2:$B$51,"Winter",$C$2:$C$51,$C9)*(1/3) -> -2.8059151 | G9: =SUMIFS(G$2:G$51,$A$2:$A$51,$A9,$B$2:$B$51,"Summer",$C$2:$C$51,$C9)*(2/3)+SUMIFS(G$2:G$51,$A$2:$A$51,$A9,$B$2:$B$51,"Winter",$C$2:$C$51,$C9)*(1/3) -> -2.669036 | H9: =SUMIFS(H$2:H$51,$A$2:$A$51,$A9,$B$2:$B$51,"Summer",$C$2:$C$51,$C9)*(2/3)+SUMIFS(H$2:H$51,$A$2:$A$51,$A9,$B$2:$B$51,"Winter",$C$2:$C$51,$C9)*(1/3) -> -2.8115218 | I9: =SUMIFS(I$2:I$51,$A$2:$A$51,$A9,$B$2:$B$51,"Summer",$C$2:$C$51,$C9)*(2/3)+SUMIFS(I$2:I$51,$A$2:$A$51,$A9,$B$2:$B$51,"Winter",$C$2:$C$51,$C9)*(1/3) -> -2.6912326 | J9: =SUMIFS(J$2:J$51,$A$2:$A$51,$A9,$B$2:$B$51,"Summer",$C$2:$C$51,$C9)*(2/3)+SUMIFS(J$2:J$51,$A$2:$A$51,$A9,$B$2:$B$51,"Winter",$C$2:$C$51,$C9)*(1/3) -> -2.181347 | K9: =SUMIFS(K$2:K$51,$A$2:$A$51,$A9,$B$2:$B$51,"Summer",$C$2:$C$51,$C9)*(2/3)+SUMIFS(K$2:K$51,$A$2:$A$51,$A9,$B$2:$B$51,"Winter",$C$2:$C$51,$C9)*(1/3) -> -0.57577052 | ... AA9: =SUMIFS(AA$2:AA$51,$A$2:$A$51,$A9,$B$2:$B$51,"Summer",$C$2:$C$51,$C9)*(2/3)+SUMIFS(AA$2:AA$51,$A$2:$A$51,$A9,$B$2:$B$51,"Winter",$C$2:$C$51,$C9)*(1/3) -> -1.6152449
A10: 3 | B10: Winter | C10: 1 | D10: 3.627 | E10: 4.493 | F10: 4.493 | G10: 4.493 | H10: 4.493 | I10: 3.64 | J10: 1.651 | K10: 0.213 | L10: -1.244 | M10: -1.244 | N10: -0.107 | O10: -1.297 | P10: -1.297 | Q10: -1.004 | R10: -0.125 | S10: 0.754 | T10: 1.047 | U10: 1.047 | V10: 1.047 | W10: 1.047 | X10: 1.047 | Y10: 2.184 | Z10: 3.338 | AA10: 3.338
A11: 3 | B11: Summer | C11: 1 | D11: -3.586525 | E11: -3.586525 | F11: -4.163744 | G11: -4.740963 | H11: -4.740963 | I11: -4.740963 | J11: -1.8903904 | K11: 0.39184475 | L11: 1.2443542 | M11: 1.2443542 | N11: 1.1377888 | O11: 1.5995617 | P11: 2.1679001 | Q11: 2.2345047 | R11: 1.2532339 | S11: 0.97794342 | T11: -0.15873337 | U11: -0.15873337 | V11: -0.15873337 | W11: -0.15873337 | X11: -1.0112438 | Y11: -1.295414 | Z11: -3.6220436 | AA11: -3.6220436
A12: 3 | B12: Spring | C12: 1 | D12: =SUMIFS(D$2:D$51,$A$2:$A$51,$A12,$B$2:$B$51,"Winter",$C$2:$C$51,$C12)*(2/3)+SUMIFS(D$2:D$51,$A$2:$A$51,$A12,$B$2:$B$51,"Summer",$C$2:$C$51,$C12)*(1/3) -> 1.2224917 | E12: =SUMIFS(E$2:E$51,$A$2:$A$51,$A12,$B$2:$B$51,"Winter",$C$2:$C$51,$C12)*(2/3)+SUMIFS(E$2:E$51,$A$2:$A$51,$A12,$B$2:$B$51,"Summer",$C$2:$C$51,$C12)*(1/3) -> 1.799825 | F12: =SUMIFS(F$2:F$51,$A$2:$A$51,$A12,$B$2:$B$51,"Winter",$C$2:$C$51,$C12)*(2/3)+SUMIFS(F$2:F$51,$A$2:$A$51,$A12,$B$2:$B$51,"Summer",$C$2:$C$51,$C12)*(1/3) -> 1.6074187 | G12: =SUMIFS(G$2:G$51,$A$2:$A$51,$A12,$B$2:$B$51,"Winter",$C$2:$C$51,$C12)*(2/3)+SUMIFS(G$2:G$51,$A$2:$A$51,$A12,$B$2:$B$51,"Summer",$C$2:$C$51,$C12)*(1/3) -> 1.4150123 | H12: =SUMIFS(H$2:H$51,$A$2:$A$51,$A12,$B$2:$B$51,"Winter",$C$2:$C$51,$C12)*(2/3)+SUMIFS(H$2:H$51,$A$2:$A$51,$A12,$B$2:$B$51,"Summer",$C$2:$C$51,$C12)*(1/3) -> 1.4150123 | I12: =SUMIFS(I$2:I$51,$A$2:$A$51,$A12,$B$2:$B$51,"Winter",$C$2:$C$51,$C12)*(2/3)+SUMIFS(I$2:I$51,$A$2:$A$51,$A12,$B$2:$B$51,"Summer",$C$2:$C$51,$C12)*(1/3) -> 0.84634567 | J12: =SUMIFS(J$2:J$51,$A$2:$A$51,$A12,$B$2:$B$51,"Winter",$C$2:$C$51,$C12)*(2/3)+SUMIFS(J$2:J$51,$A$2:$A$51,$A12,$B$2:$B$51,"Summer",$C$2:$C$51,$C12)*(1/3) -> 0.47053654 | K12: =SUMIFS(K$2:K$51,$A$2:$A$51,$A12,$B$2:$B$51,"Winter",$C$2:$C$51,$C12)*(2/3)+SUMIFS(K$2:K$51,$A$2:$A$51,$A12,$B$2:$B$51,"Summer",$C$2:$C$51,$C12)*(1/3) -> 0.27261492 | ... AA12: =SUMIFS(AA$2:AA$51,$A$2:$A$51,$A12,$B$2:$B$51,"Winter",$C$2:$C$51,$C12)*(2/3)+SUMIFS(AA$2:AA$51,$A$2:$A$51,$A12,$B$2:$B$51,"Summer",$C$2:$C$51,$C12)*(1/3) -> 1.0179855
A13: 3 | B13: Autumn | C13: 1 | D13: =SUMIFS(D$2:D$51,$A$2:$A$51,$A13,$B$2:$B$51,"Summer",$C$2:$C$51,$C13)*(2/3)+SUMIFS(D$2:D$51,$A$2:$A$51,$A13,$B$2:$B$51,"Winter",$C$2:$C$51,$C13)*(1/3) -> -1.1820166 | E13: =SUMIFS(E$2:E$51,$A$2:$A$51,$A13,$B$2:$B$51,"Summer",$C$2:$C$51,$C13)*(2/3)+SUMIFS(E$2:E$51,$A$2:$A$51,$A13,$B$2:$B$51,"Winter",$C$2:$C$51,$C13)*(1/3) -> -0.89334997 | F13: =SUMIFS(F$2:F$51,$A$2:$A$51,$A13,$B$2:$B$51,"Summer",$C$2:$C$51,$C13)*(2/3)+SUMIFS(F$2:F$51,$A$2:$A$51,$A13,$B$2:$B$51,"Winter",$C$2:$C$51,$C13)*(1/3) -> -1.2781626 | G13: =SUMIFS(G$2:G$51,$A$2:$A$51,$A13,$B$2:$B$51,"Summer",$C$2:$C$51,$C13)*(2/3)+SUMIFS(G$2:G$51,$A$2:$A$51,$A13,$B$2:$B$51,"Winter",$C$2:$C$51,$C13)*(1/3) -> -1.6629753 | H13: =SUMIFS(H$2:H$51,$A$2:$A$51,$A13,$B$2:$B$51,"Summer",$C$2:$C$51,$C13)*(2/3)+SUMIFS(H$2:H$51,$A$2:$A$51,$A13,$B$2:$B$51,"Winter",$C$2:$C$51,$C13)*(1/3) -> -1.6629753 | I13: =SUMIFS(I$2:I$51,$A$2:$A$51,$A13,$B$2:$B$51,"Summer",$C$2:$C$51,$C13)*(2/3)+SUMIFS(I$2:I$51,$A$2:$A$51,$A13,$B$2:$B$51,"Winter",$C$2:$C$51,$C13)*(1/3) -> -1.9473087 | J13: =SUMIFS(J$2:J$51,$A$2:$A$51,$A13,$B$2:$B$51,"Summer",$C$2:$C$51,$C13)*(2/3)+SUMIFS(J$2:J$51,$A$2:$A$51,$A13,$B$2:$B$51,"Winter",$C$2:$C$51,$C13)*(1/3) -> -0.70992693 | K13: =SUMIFS(K$2:K$51,$A$2:$A$51,$A13,$B$2:$B$51,"Summer",$C$2:$C$51,$C13)*(2/3)+SUMIFS(K$2:K$51,$A$2:$A$51,$A13,$B$2:$B$51,"Winter",$C$2:$C$51,$C13)*(1/3) -> 0.33222983 | ... AA13: =SUMIFS(AA$2:AA$51,$A$2:$A$51,$A13,$B$2:$B$51,"Summer",$C$2:$C$51,$C13)*(2/3)+SUMIFS(AA$2:AA$51,$A$2:$A$51,$A13,$B$2:$B$51,"Winter",$C$2:$C$51,$C13)*(1/3) -> -1.3020291
A14: 4 | B14: Winter | C14: 1 | D14: 7.679 | E14: 5.924 | F14: 5.071 | G14: 4.962 | H14: 5.64 | I14: 7.003 | J14: 10.865 | K14: 13.263 | L14: 15.324 | M14: 16.875 | N14: 17.018 | O14: 16.712 | P14: 16.783 | Q14: 16.612 | R14: 14.986 | S14: 14.239 | T14: 14.693 | U14: 20.027 | V14: 19.998 | W14: 19.388 | X14: 17.945 | Y14: 15.959 | Z14: 13.016 | AA14: 9.986
A15: 4 | B15: Summer | C15: 1 | D15: 4.2723774 | E15: 3.2734689 | F15: 3.1021022 | G15: 2.7092951 | H15: 3.1189349 | I15: 1.447546 | J15: 2.5256297 | K15: 4.8532959 | L15: 7.0600641 | M15: 8.3893197 | N15: 9.1585548 | O15: 9.4929236 | P15: 9.9196303 | Q15: 9.9946815 | R15: 9.9237395 | S15: 9.5933924 | T15: 9.1296433 | U15: 8.1015305 | V15: 8.0640485 | W15: 7.6713444 | X15: 6.9149351 | Y15: 8.2896568 | Z15: 7.4278342 | AA15: 5.9776219
A16: 4 | B16: Spring | C16: 1 | D16: =SUMIFS(D$2:D$51,$A$2:$A$51,$A16,$B$2:$B$51,"Winter",$C$2:$C$51,$C16)*(2/3)+SUMIFS(D$2:D$51,$A$2:$A$51,$A16,$B$2:$B$51,"Summer",$C$2:$C$51,$C16)*(1/3) -> 6.5434591 | E16: =SUMIFS(E$2:E$51,$A$2:$A$51,$A16,$B$2:$B$51,"Winter",$C$2:$C$51,$C16)*(2/3)+SUMIFS(E$2:E$51,$A$2:$A$51,$A16,$B$2:$B$51,"Summer",$C$2:$C$51,$C16)*(1/3) -> 5.0404896 | F16: =SUMIFS(F$2:F$51,$A$2:$A$51,$A16,$B$2:$B$51,"Winter",$C$2:$C$51,$C16)*(2/3)+SUMIFS(F$2:F$51,$A$2:$A$51,$A16,$B$2:$B$51,"Summer",$C$2:$C$51,$C16)*(1/3) -> 4.4147007 | G16: =SUMIFS(G$2:G$51,$A$2:$A$51,$A16,$B$2:$B$51,"Winter",$C$2:$C$51,$C16)*(2/3)+SUMIFS(G$2:G$51,$A$2:$A$51,$A16,$B$2:$B$51,"Summer",$C$2:$C$51,$C16)*(1/3) -> 4.2110984 | H16: =SUMIFS(H$2:H$51,$A$2:$A$51,$A16,$B$2:$B$51,"Winter",$C$2:$C$51,$C16)*(2/3)+SUMIFS(H$2:H$51,$A$2:$A$51,$A16,$B$2:$B$51,"Summer",$C$2:$C$51,$C16)*(1/3) -> 4.799645 | I16: =SUMIFS(I$2:I$51,$A$2:$A$51,$A16,$B$2:$B$51,"Winter",$C$2:$C$51,$C16)*(2/3)+SUMIFS(I$2:I$51,$A$2:$A$51,$A16,$B$2:$B$51,"Summer",$C$2:$C$51,$C16)*(1/3) -> 5.151182 | J16: =SUMIFS(J$2:J$51,$A$2:$A$51,$A16,$B$2:$B$51,"Winter",$C$2:$C$51,$C16)*(2/3)+SUMIFS(J$2:J$51,$A$2:$A$51,$A16,$B$2:$B$51,"Summer",$C$2:$C$51,$C16)*(1/3) -> 8.0852099 | K16: =SUMIFS(K$2:K$51,$A$2:$A$51,$A16,$B$2:$B$51,"Winter",$C$2:$C$51,$C16)*(2/3)+SUMIFS(K$2:K$51,$A$2:$A$51,$A16,$B$2:$B$51,"Summer",$C$2:$C$51,$C16)*(1/3) -> 10.459765 | ... AA16: =SUMIFS(AA$2:AA$51,$A$2:$A$51,$A16,$B$2:$B$51,"Winter",$C$2:$C$51,$C16)*(2/3)+SUMIFS(AA$2:AA$51,$A$2:$A$51,$A16,$B$2:$B$51,"Summer",$C$2:$C$51,$C16)*(1/3) -> 8.649874
